Workbook
Name a: #REF!
Name acdb: #REF!
Name acdb: #REF!
Name ACDB1: #REF!
Name acdf: #REF!
Name acdf: #REF!
Name acdh: #REF!
Name acdo: #REF!
Name acdo: #REF!
Name aceq: #REF!
Name aceq: [1]AE!$A:$IV
Name aceq: #REF!
Name acif: #REF!
Name acif: #REF!
Name acin: #REF!
Name acin: #REF!
Name ACIN1: #REF!
Name acti: #REF!
Name acti: #REF!
Name avc: #REF!
Name avc: [2]DORSAL!$A$2:$G$120
Name avc: #REF!
Name datos: #REF!
Name datos: [3]Datos!$A$2:$G$140
Name datos: #REF!
Name dorsal: #REF!
Name dorsal: [2]DORSAL!$A$2:$G$120
Name dorsal: #REF!
Name EQ: #REF!
Name EQ: [4]EQU!$A:$IV
Name EQ: #REF!
Name IN: #REF!
Name IN: [4]IND!$A:$IV
Name IN: #REF!
Name IND: #REF!
Name IND: [5]IN!$A$3:$IV$102
Name IND: #REF!
Name IPC_Member: #REF!
Name IPC_Member: #REF!
Name JBS: #REF!
Name JBS: [6]JB!$A$1:$E$100
Name JBS: #REF!
Name JGS: #REF!
Name JGS: #REF!
Name JUG: #REF!
Name JUG: [7]Jug!$A$2:$D$13
Name JUG: #REF!
Name PC: #REF!
Name PC: #REF!
Name PCS: #REF!
Name PCS: #REF!
Name PLAYERS: #REF!
Name PLAYERS: [8]Players!$B$4:$H$124
Name PLAYERS: #REF!
Name RK: #REF!
Name RK: #REF!
Name RKJB: #REF!
Name RKJB: #REF!
Name RKJG: #REF!
Name RKJG: #REF!

Sheet Tabulación
C1: Ganadores | F1: Perdedores | K1: 14 | L1: {=VLOOKUP(INDIRECT("'Grupo " & K1 & "'!J18"),INDIRECT("'Grupo " & K1 & "'!B12"):INDIRECT("'Grupo " & K1 & "'!J15"),2,FALSE)} -> #REF! | M1: {=VLOOKUP(IF(INDIRECT("'Grupo " & K1 & "'!J18")=INDIRECT("'Grupo " & K1 & "'!C18"),INDIRECT("'Grupo " & K1 & "'!C19"),INDIRECT("'Grupo " & K1 & "'!C18")),INDIRECT("'Grupo " & K1 & "'!B12"):INDIRECT("'Grupo " & K1 & "'!G15"),2,FALSE)} -> #REF! | O1: {=VLOOKUP(IF(INDIRECT("'Grupo " & K1 & "'!J18")=INDIRECT("'Grupo " & K1 & "'!C18"),INDIRECT("'Grupo " & K1 & "'!C19"),INDIRECT("'Grupo " & K1 & "'!C18")),INDIRECT("'Grupo " & K1 & "'!B12"):INDIRECT("'Grupo " & K1 & "'!G15"),2,FALSE)} -> #REF! | P1: {=VLOOKUP(INDIRECT("'Grupo " & K1 & "'!J18"),INDIRECT("'Grupo " & K1 & "'!B12"):INDIRECT("'Grupo " & K1 & "'!J15"),2,FALSE)} -> #REF!
B2: 1 | C2: {=VLOOKUP(INDIRECT("'Grupo " & B2 & "'!J18"),INDIRECT("'Grupo " & B2 & "'!B12"):INDIRECT("'Grupo " & B2 & "'!J15"),2,FALSE)} -> 4295 | D2: {=VLOOKUP(IF(INDIRECT("'Grupo " & B2 & "'!J18")=INDIRECT("'Grupo " & B2 & "'!C18"),INDIRECT("'Grupo " & B2 & "'!C19"),INDIRECT("'Grupo " & B2 & "'!C18")),INDIRECT("'Grupo " & B2 & "'!B12"):INDIRECT("'Grupo " & B2 & "'!G15"),2,FALSE)} -> 4834 | F2: {=VLOOKUP(IF(INDIRECT("'Grupo " & B2 & "'!J18")=INDIRECT("'Grupo " & B2 & "'!C18"),INDIRECT("'Grupo " & B2 & "'!C19"),INDIRECT("'Grupo " & B2 & "'!C18")),INDIRECT("'Grupo " & B2 & "'!B12"):INDIRECT("'Grupo " & B2 & "'!G15"),2,FALSE)} -> 4834 | G2: {=VLOOKUP(INDIRECT("'Grupo " & B2 & "'!J18"),INDIRECT("'Grupo " & B2 & "'!B12"):INDIRECT("'Grupo " & B2 & "'!J15"),2,FALSE)} -> 4295 | L2: {=VLOOKUP(INDIRECT("'Grupo " & K1 & "'!J20"),INDIRECT("'Grupo " & K1 & "'!B12"):INDIRECT("'Grupo " & K1 & "'!J15"),2,FALSE)} -> #REF! | M2: {=VLOOKUP(IF(INDIRECT("'Grupo " & K1 & "'!J20")=INDIRECT("'Grupo " & K1 & "'!C20"),INDIRECT("'Grupo " & K1 & "'!C21"),INDIRECT("'Grupo " & K1 & "'!C20")),INDIRECT("'Grupo " & K1 & "'!B12"):INDIRECT("'Grupo " & K1 & "'!G15"),2,FALSE)} -> #REF! | O2: {=VLOOKUP(IF(INDIRECT("'Grupo " & K1 & "'!J20")=INDIRECT("'Grupo " & K1 & "'!C20"),INDIRECT("'Grupo " & K1 & "'!C21"),INDIRECT("'Grupo " & K1 & "'!C20")),INDIRECT("'Grupo " & K1 & "'!B12"):INDIRECT("'Grupo " & K1 & "'!G15"),2,FALSE)} -> #REF! | P2: {=VLOOKUP(INDIRECT("'Grupo " & K1 & "'!J20"),INDIRECT("'Grupo " & K1 & "'!B12"):INDIRECT("'Grupo " & K1 & "'!J15"),2,FALSE)} -> #REF!
C3: {=VLOOKUP(INDIRECT("'Grupo " & B2 & "'!J20"),INDIRECT("'Grupo " & B2 & "'!B12"):INDIRECT("'Grupo " & B2 & "'!J15"),2,FALSE)} -> 4295 | D3: {=VLOOKUP(IF(INDIRECT("'Grupo " & B2 & "'!J20")=INDIRECT("'Grupo " & B2 & "'!C20"),INDIRECT("'Grupo " & B2 & "'!C21"),INDIRECT("'Grupo " & B2 & "'!C20")),INDIRECT("'Grupo " & B2 & "'!B12"):INDIRECT("'Grupo " & B2 & "'!G15"),2,FALSE)} -> 4718 | F3: {=VLOOKUP(IF(INDIRECT("'Grupo " & B2 & "'!J20")=INDIRECT("'Grupo " & B2 & "'!C20"),INDIRECT("'Grupo " & B2 & "'!C21"),INDIRECT("'Grupo " & B2 & "'!C20")),INDIRECT("'Grupo " & B2 & "'!B12"):INDIRECT("'Grupo " & B2 & "'!G15"),2,FALSE)} -> 4718 | G3: {=VLOOKUP(INDIRECT("'Grupo " & B2 & "'!J20"),INDIRECT("'Grupo " & B2 & "'!B12"):INDIRECT("'Grupo " & B2 & "'!J15"),2,FALSE)} -> 4295 | L3: {=VLOOKUP(INDIRECT("'Grupo " & K1 & "'!J22"),INDIRECT("'Grupo " & K1 & "'!B12"):INDIRECT("'Grupo " & K1 & "'!J15"),2,FALSE)} -> #REF! | M3: {=VLOOKUP(IF(INDIRECT("'Grupo " & K1 & "'!J22")=INDIRECT("'Grupo " & K1 & "'!C22"),INDIRECT("'Grupo " & K1 & "'!C23"),INDIRECT("'Grupo " & K1 & "'!C22")),INDIRECT("'Grupo " & K1 & "'!B12"):INDIRECT("'Grupo " & K1 & "'!G15"),2,FALSE)} -> #REF! | O3: {=VLOOKUP(IF(INDIRECT("'Grupo " & K1 & "'!J22")=INDIRECT("'Grupo " & K1 & "'!C22"),INDIRECT("'Grupo " & K1 & "'!C23"),INDIRECT("'Grupo " & K1 & "'!C22")),INDIRECT("'Grupo " & K1 & "'!B12"):INDIRECT("'Grupo " & K1 & "'!G15"),2,FALSE)} -> #REF! | P3: {=VLOOKUP(INDIRECT("'Grupo " & K1 & "'!J22"),INDIRECT("'Grupo " & K1 & "'!B12"):INDIRECT("'Grupo " & K1 & "'!J15"),2,FALSE)} -> #REF!
C4: {=VLOOKUP(INDIRECT("'Grupo " & B2 & "'!J22"),INDIRECT("'Grupo " & B2 & "'!B12"):INDIRECT("'Grupo " & B2 & "'!J15"),2,FALSE)} -> 4834 | D4: {=VLOOKUP(IF(INDIRECT("'Grupo " & B2 & "'!J22")=INDIRECT("'Grupo " & B2 & "'!C22"),INDIRECT("'Grupo " & B2 & "'!C23"),INDIRECT("'Grupo " & B2 & "'!C22")),INDIRECT("'Grupo " & B2 & "'!B12"):INDIRECT("'Grupo " & B2 & "'!G15"),2,FALSE)} -> 4718 | F4: {=VLOOKUP(IF(INDIRECT("'Grupo " & B2 & "'!J22")=INDIRECT("'Grupo " & B2 & "'!C22"),INDIRECT("'Grupo " & B2 & "'!C23"),INDIRECT("'Grupo " & B2 & "'!C22")),INDIRECT("'Grupo " & B2 & "'!B12"):INDIRECT("'Grupo " & B2 & "'!G15"),2,FALSE)} -> 4718 | G4: {=VLOOKUP(INDIRECT("'Grupo " & B2 & "'!J22"),INDIRECT("'Grupo " & B2 & "'!B12"):INDIRECT("'Grupo " & B2 & "'!J15"),2,FALSE)} -> 4834 | L4: {=VLOOKUP(INDIRECT("'Grupo " & K1 & "'!J24"),INDIRECT("'Grupo " & K1 & "'!B12"):INDIRECT("'Grupo " & K1 & "'!J15"),2,FALSE)} -> #REF! | M4: {=VLOOKUP(IF(INDIRECT("'Grupo " & K1 & "'!J24")=INDIRECT("'Grupo " & K1 & "'!C24"),INDIRECT("'Grupo " & K1 & "'!C25"),INDIRECT("'Grupo " & K1 & "'!C24")),INDIRECT("'Grupo " & K1 & "'!B12"):INDIRECT("'Grupo " & K1 & "'!G15"),2,FALSE)} -> #REF! | O4: {=VLOOKUP(IF(INDIRECT("'Grupo " & K1 & "'!J24")=INDIRECT("'Grupo " & K1 & "'!C24"),INDIRECT("'Grupo " & K1 & "'!C25"),INDIRECT("'Grupo " & K1 & "'!C24")),INDIRECT("'Grupo " & K1 & "'!B12"):INDIRECT("'Grupo " & K1 & "'!G15"),2,FALSE)} -> #REF! | P4: {=VLOOKUP(INDIRECT("'Grupo " & K1 & "'!J24"),INDIRECT("'Grupo " & K1 & "'!B12"):INDIRECT("'Grupo " & K1 & "'!J15"),2,FALSE)} -> #REF!
B5: =B2+1 -> 2 | C5: {=VLOOKUP(INDIRECT("'Grupo " & B5 & "'!J18"),INDIRECT("'Grupo " & B5 & "'!B12"):INDIRECT("'Grupo " & B5 & "'!J15"),2,FALSE)} -> 4149 | D5: {=VLOOKUP(IF(INDIRECT("'Grupo " & B5 & "'!J18")=INDIRECT("'Grupo " & B5 & "'!C18"),INDIRECT("'Grupo " & B5 & "'!C19"),INDIRECT("'Grupo " & B5 & "'!C18")),INDIRECT("'Grupo " & B5 & "'!B12"):INDIRECT("'Grupo " & B5 & "'!G15"),2,FALSE)} -> 4700 | F5: {=VLOOKUP(IF(INDIRECT("'Grupo " & B5 & "'!J18")=INDIRECT("'Grupo " & B5 & "'!C18"),INDIRECT("'Grupo " & B5 & "'!C19"),INDIRECT("'Grupo " & B5 & "'!C18")),INDIRECT("'Grupo " & B5 & "'!B12"):INDIRECT("'Grupo " & B5 & "'!G15"),2,FALSE)} -> 4700 | G5: {=VLOOKUP(INDIRECT("'Grupo " & B5 & "'!J18"),INDIRECT("'Grupo " & B5 & "'!B12"):INDIRECT("'Grupo " & B5 & "'!J15"),2,FALSE)} -> 4149 | L5: {=VLOOKUP(INDIRECT("'Grupo " & K1 & "'!J26"),INDIRECT("'Grupo " & K1 & "'!B12"):INDIRECT("'Grupo " & K1 & "'!J15"),2,FALSE)} -> #REF! | M5: {=VLOOKUP(IF(INDIRECT("'Grupo " & K1 & "'!J26")=INDIRECT("'Grupo " & K1 & "'!C26"),INDIRECT("'Grupo " & K1 & "'!C27"),INDIRECT("'Grupo " & K1 & "'!C26")),INDIRECT("'Grupo " & K1 & "'!B12"):INDIRECT("'Grupo " & K1 & "'!G15"),2,FALSE)} -> #REF! | O5: {=VLOOKUP(IF(INDIRECT("'Grupo " & K1 & "'!J26")=INDIRECT("'Grupo " & K1 & "'!C26"),INDIRECT("'Grupo " & K1 & "'!C27"),INDIRECT("'Grupo " & K1 & "'!C26")),INDIRECT("'Grupo " & K1 & "'!B12"):INDIRECT("'Grupo " & K1 & "'!G15"),2,FALSE)} -> #REF! | P5: {=VLOOKUP(INDIRECT("'Grupo " & K1 & "'!J26"),INDIRECT("'Grupo " & K1 & "'!B12"):INDIRECT("'Grupo " & K1 & "'!J15"),2,FALSE)} -> #REF!
C6: {=VLOOKUP(INDIRECT("'Grupo " & B5 & "'!J20"),INDIRECT("'Grupo " & B5 & "'!B12"):INDIRECT("'Grupo " & B5 & "'!J15"),2,FALSE)} -> 4149 | D6: {=VLOOKUP(IF(INDIRECT("'Grupo " & B5 & "'!J20")=INDIRECT("'Grupo " & B5 & "'!C20"),INDIRECT("'Grupo " & B5 & "'!C21"),INDIRECT("'Grupo " & B5 & "'!C20")),INDIRECT("'Grupo " & B5 & "'!B12"):INDIRECT("'Grupo " & B5 & "'!G15"),2,FALSE)} -> 4250 | F6: {=VLOOKUP(IF(INDIRECT("'Grupo " & B5 & "'!J20")=INDIRECT("'Grupo " & B5 & "'!C20"),INDIRECT("'Grupo " & B5 & "'!C21"),INDIRECT("'Grupo " & B5 & "'!C20")),INDIRECT("'Grupo " & B5 & "'!B12"):INDIRECT("'Grupo " & B5 & "'!G15"),2,FALSE)} -> 4250 | G6: {=VLOOKUP(INDIRECT("'Grupo " & B5 & "'!J20"),INDIRECT("'Grupo " & B5 & "'!B12"):INDIRECT("'Grupo " & B5 & "'!J15"),2,FALSE)} -> 4149 | L6: {=VLOOKUP(INDIRECT("'Grupo " & K1 & "'!J28"),INDIRECT("'Grupo " & K1 & "'!B12"):INDIRECT("'Grupo " & K1 & "'!J15"),2,FALSE)} -> #REF! | M6: {=VLOOKUP(IF(INDIRECT("'Grupo " & K1 & "'!J28")=INDIRECT("'Grupo " & K1 & "'!C28"),INDIRECT("'Grupo " & K1 & "'!C29"),INDIRECT("'Grupo " & K1 & "'!C28")),INDIRECT("'Grupo " & K1 & "'!B12"):INDIRECT("'Grupo " & K1 & "'!G15"),2,FALSE)} -> #REF! | O6: {=VLOOKUP(IF(INDIRECT("'Grupo " & K1 & "'!J28")=INDIRECT("'Grupo " & K1 & "'!C28"),INDIRECT("'Grupo " & K1 & "'!C29"),INDIRECT("'Grupo " & K1 & "'!C28")),INDIRECT("'Grupo " & K1 & "'!B12"):INDIRECT("'Grupo " & K1 & "'!G15"),2,FALSE)} -> #REF! | P6: {=VLOOKUP(INDIRECT("'Grupo " & K1 & "'!J28"),INDIRECT("'Grupo " & K1 & "'!B12"):INDIRECT("'Grupo " & K1 & "'!J15"),2,FALSE)} -> #REF!
C7: {=VLOOKUP(INDIRECT("'Grupo " & B5 & "'!J22"),INDIRECT("'Grupo " & B5 & "'!B12"):INDIRECT("'Grupo " & B5 & "'!J15"),2,FALSE)} -> 4250 | D7: {=VLOOKUP(IF(INDIRECT("'Grupo " & B5 & "'!J22")=INDIRECT("'Grupo " & B5 & "'!C22"),INDIRECT("'Grupo " & B5 & "'!C23"),INDIRECT("'Grupo " & B5 & "'!C22")),INDIRECT("'Grupo " & B5 & "'!B12"):INDIRECT("'Grupo " & B5 & "'!G15"),2,FALSE)} -> 4700 | F7: {=VLOOKUP(IF(INDIRECT("'Grupo " & B5 & "'!J22")=INDIRECT("'Grupo " & B5 & "'!C22"),INDIRECT("'Grupo " & B5 & "'!C23"),INDIRECT("'Grupo " & B5 & "'!C22")),INDIRECT("'Grupo " & B5 & "'!B12"):INDIRECT("'Grupo " & B5 & "'!G15"),2,FALSE)} -> 4700 | G7: {=VLOOKUP(INDIRECT("'Grupo " & B5 & "'!J22"),INDIRECT("'Grupo " & B5 & "'!B12"):INDIRECT("'Grupo " & B5 & "'!J15"),2,FALSE)} -> 4250
B8: =B5+1 -> 3 | C8: {=VLOOKUP(INDIRECT("'Grupo " & B8 & "'!J18"),INDIRECT("'Grupo " & B8 & "'!B12"):INDIRECT("'Grupo " & B8 & "'!J15"),2,FALSE)} -> 4391 | D8: {=VLOOKUP(IF(INDIRECT("'Grupo " & B8 & "'!J18")=INDIRECT("'Grupo " & B8 & "'!C18"),INDIRECT("'Grupo " & B8 & "'!C19"),INDIRECT("'Grupo " & B8 & "'!C18")),INDIRECT("'Grupo " & B8 & "'!B12"):INDIRECT("'Grupo " & B8 & "'!G15"),2,FALSE)} -> 4738 | F8: {=VLOOKUP(IF(INDIRECT("'Grupo " & B8 & "'!J18")=INDIRECT("'Grupo " & B8 & "'!C18"),INDIRECT("'Grupo " & B8 & "'!C19"),INDIRECT("'Grupo " & B8 & "'!C18")),INDIRECT("'Grupo " & B8 & "'!B12"):INDIRECT("'Grupo " & B8 & "'!G15"),2,FALSE)} -> 4738 | G8: {=VLOOKUP(INDIRECT("'Grupo " & B8 & "'!J18"),INDIRECT("'Grupo " & B8 & "'!B12"):INDIRECT("'Grupo " & B8 & "'!J15"),2,FALSE)} -> 4391
C9: {=VLOOKUP(INDIRECT("'Grupo " & B8 & "'!J20"),INDIRECT("'Grupo " & B8 & "'!B12"):INDIRECT("'Grupo " & B8 & "'!J15"),2,FALSE)} -> 4391 | D9: {=VLOOKUP(IF(INDIRECT("'Grupo " & B8 & "'!J20")=INDIRECT("'Grupo " & B8 & "'!C20"),INDIRECT("'Grupo " & B8 & "'!C21"),INDIRECT("'Grupo " & B8 & "'!C20")),INDIRECT("'Grupo " & B8 & "'!B12"):INDIRECT("'Grupo " & B8 & "'!G15"),2,FALSE)} -> 4699 | F9: {=VLOOKUP(IF(INDIRECT("'Grupo " & B8 & "'!J20")=INDIRECT("'Grupo " & B8 & "'!C20"),INDIRECT("'Grupo " & B8 & "'!C21"),INDIRECT("'Grupo " & B8 & "'!C20")),INDIRECT("'Grupo " & B8 & "'!B12"):INDIRECT("'Grupo " & B8 & "'!G15"),2,FALSE)} -> 4699 | G9: {=VLOOKUP(INDIRECT("'Grupo " & B8 & "'!J20"),INDIRECT("'Grupo " & B8 & "'!B12"):INDIRECT("'Grupo " & B8 & "'!J15"),2,FALSE)} -> 4391
C10: {=VLOOKUP(INDIRECT("'Grupo " & B8 & "'!J22"),INDIRECT("'Grupo " & B8 & "'!B12"):INDIRECT("'Grupo " & B8 & "'!J15"),2,FALSE)} -> 4699 | D10: {=VLOOKUP(IF(INDIRECT("'Grupo " & B8 & "'!J22")=INDIRECT("'Grupo " & B8 & "'!C22"),INDIRECT("'Grupo " & B8 & "'!C23"),INDIRECT("'Grupo " & B8 & "'!C22")),INDIRECT("'Grupo " & B8 & "'!B12"):INDIRECT("'Grupo " & B8 & "'!G15"),2,FALSE)} -> 4738 | F10: {=VLOOKUP(IF(INDIRECT("'Grupo " & B8 & "'!J22")=INDIRECT("'Grupo " & B8 & "'!C22"),INDIRECT("'Grupo " & B8 & "'!C23"),INDIRECT("'Grupo " & B8 & "'!C22")),INDIRECT("'Grupo " & B8 & "'!B12"):INDIRECT("'Grupo " & B8 & "'!G15"),2,FALSE)} -> 4738 | G10: {=VLOOKUP(INDIRECT("'Grupo " & B8 & "'!J22"),INDIRECT("'Grupo " & B8 & "'!B12"):INDIRECT("'Grupo " & B8 & "'!J15"),2,FALSE)} -> 4699
B11: 4 | C11: {=VLOOKUP(INDIRECT("'Grupo " & B11 & "'!J18"),INDIRECT("'Grupo " & B11 & "'!B12"):INDIRECT("'Grupo " & B11 & "'!J15"),2,FALSE)} -> 4520 | D11: {=VLOOKUP(IF(INDIRECT("'Grupo " & B11 & "'!J18")=INDIRECT("'Grupo " & B11 & "'!C18"),INDIRECT("'Grupo " & B11 & "'!C19"),INDIRECT("'Grupo " & B11 & "'!C18")),INDIRECT("'Grupo " & B11 & "'!B12"):INDIRECT("'Grupo " & B11 & "'!G15"),2,FALSE)} -> 4867 | F11: {=VLOOKUP(IF(INDIRECT("'Grupo " & B11 & "'!J18")=INDIRECT("'Grupo " & B11 & "'!C18"),INDIRECT("'Grupo " & B11 & "'!C19"),INDIRECT("'Grupo " & B11 & "'!C18")),INDIRECT("'Grupo " & B11 & "'!B12"):INDIRECT("'Grupo " & B11 & "'!G15"),2,FALSE)} -> 4867 | G11: {=VLOOKUP(INDIRECT("'Grupo " & B11 & "'!J18"),INDIRECT("'Grupo " & B11 & "'!B12"):INDIRECT("'Grupo " & B11 & "'!J15"),2,FALSE)} -> 4520
C12: {=VLOOKUP(INDIRECT("'Grupo " & B11 & "'!J20"),INDIRECT("'Grupo " & B11 & "'!B12"):INDIRECT("'Grupo " & B11 & "'!J15"),2,FALSE)} -> 4685 | D12: {=VLOOKUP(IF(INDIRECT("'Grupo " & B11 & "'!J20")=INDIRECT("'Grupo " & B11 & "'!C20"),INDIRECT("'Grupo " & B11 & "'!C21"),INDIRECT("'Grupo " & B11 & "'!C20")),INDIRECT("'Grupo " & B11 & "'!B12"):INDIRECT("'Grupo " & B11 & "'!G15"),2,FALSE)} -> 4871 | F12: {=VLOOKUP(IF(INDIRECT("'Grupo " & B11 & "'!J20")=INDIRECT("'Grupo " & B11 & "'!C20"),INDIRECT("'Grupo " & B11 & "'!C21"),INDIRECT("'Grupo " & B11 & "'!C20")),INDIRECT("'Grupo " & B11 & "'!B12"):INDIRECT("'Grupo " & B11 & "'!G15"),2,FALSE)} -> 4871 | G12: {=VLOOKUP(INDIRECT("'Grupo " & B11 & "'!J20"),INDIRECT("'Grupo " & B11 & "'!B12"):INDIRECT("'Grupo " & B11 & "'!J15"),2,FALSE)} -> 4685
C13: {=VLOOKUP(INDIRECT("'Grupo " & B11 & "'!J22"),INDIRECT("'Grupo " & B11 & "'!B12"):INDIRECT("'Grupo " & B11 & "'!J15"),2,FALSE)} -> 4520 | D13: {=VLOOKUP(IF(INDIRECT("'Grupo " & B11 & "'!J22")=INDIRECT("'Grupo " & B11 & "'!C22"),INDIRECT("'Grupo " & B11 & "'!C23"),INDIRECT("'Grupo " & B11 & "'!C22")),INDIRECT("'Grupo " & B11 & "'!B12"):INDIRECT("'Grupo " & B11 & "'!G15"),2,FALSE)} -> 4685 | F13: {=VLOOKUP(IF(INDIRECT("'Grupo " & B11 & "'!J22")=INDIRECT("'Grupo " & B11 & "'!C22"),INDIRECT("'Grupo " & B11 & "'!C23"),INDIRECT("'Grupo " & B11 & "'!C22")),INDIRECT("'Grupo " & B11 & "'!B12"):INDIRECT("'Grupo " & B11 & "'!G15"),2,FALSE)} -> 4685 | G13: {=VLOOKUP(INDIRECT("'Grupo " & B11 & "'!J22"),INDIRECT("'Grupo " & B11 & "'!B12"):INDIRECT("'Grupo " & B11 & "'!J15"),2,FALSE)} -> 4520
C14: {=VLOOKUP(INDIRECT("'Grupo " & B11 & "'!J24"),INDIRECT("'Grupo " & B11 & "'!B12"):INDIRECT("'Grupo " & B11 & "'!J15"),2,FALSE)} -> 4867 | D14: {=VLOOKUP(IF(INDIRECT("'Grupo " & B11 & "'!J24")=INDIRECT("'Grupo " & B11 & "'!C24"),INDIRECT("'Grupo " & B11 & "'!C25"),INDIRECT("'Grupo " & B11 & "'!C24")),INDIRECT("'Grupo " & B11 & "'!B12"):INDIRECT("'Grupo " & B11 & "'!G15"),2,FALSE)} -> 4871 | F14: {=VLOOKUP(IF(INDIRECT("'Grupo " & B11 & "'!J24")=INDIRECT("'Grupo " & B11 & "'!C24"),INDIRECT("'Grupo " & B11 & "'!C25"),INDIRECT("'Grupo " & B11 & "'!C24")),INDIRECT("'Grupo " & B11 & "'!B12"):INDIRECT("'Grupo " & B11 & "'!G15"),2,FALSE)} -> 4871 | G14: {=VLOOKUP(INDIRECT("'Grupo " & B11 & "'!J24"),INDIRECT("'Grupo " & B11 & "'!B12"):INDIRECT("'Grupo " & B11 & "'!J15"),2,FALSE)} -> 4867
C15: {=VLOOKUP(INDIRECT("'Grupo " & B11 & "'!J26"),INDIRECT("'Grupo " & B11 & "'!B12"):INDIRECT("'Grupo " & B11 & "'!J15"),2,FALSE)} -> 4520 | D15: {=VLOOKUP(IF(INDIRECT("'Grupo " & B11 & "'!J26")=INDIRECT("'Grupo " & B11 & "'!C26"),INDIRECT("'Grupo " & B11 & "'!C27"),INDIRECT("'Grupo " & B11 & "'!C26")),INDIRECT("'Grupo " & B11 & "'!B12"):INDIRECT("'Grupo " & B11 & "'!G15"),2,FALSE)} -> 4871 | F15: {=VLOOKUP(IF(INDIRECT("'Grupo " & B11 & "'!J26")=INDIRECT("'Grupo " & B11 & "'!C26"),INDIRECT("'Grupo " & B11 & "'!C27"),INDIRECT("'Grupo " & B11 & "'!C26")),INDIRECT("'Grupo " & B11 & "'!B12"):INDIRECT("'Grupo " & B11 & "'!G15"),2,FALSE)} -> 4871 | G15: {=VLOOKUP(INDIRECT("'Grupo " & B11 & "'!J26"),INDIRECT("'Grupo " & B11 & "'!B12"):INDIRECT("'Grupo " & B11 & "'!J15"),2,FALSE)} -> 4520
C16: {=VLOOKUP(INDIRECT("'Grupo " & B11 & "'!J28"),INDIRECT("'Grupo " & B11 & "'!B12"):INDIRECT("'Grupo " & B11 & "'!J15"),2,FALSE)} -> 4685 | D16: {=VLOOKUP(IF(INDIRECT("'Grupo " & B11 & "'!J28")=INDIRECT("'Grupo " & B11 & "'!C28"),INDIRECT("'Grupo " & B11 & "'!C29"),INDIRECT("'Grupo " & B11 & "'!C28")),INDIRECT("'Grupo " & B11 & "'!B12"):INDIRECT("'Grupo " & B11 & "'!G15"),2,FALSE)} -> 4867 | F16: {=VLOOKUP(IF(INDIRECT("'Grupo " & B11 & "'!J28")=INDIRECT("'Grupo " & B11 & "'!C28"),INDIRECT("'Grupo " & B11 & "'!C29"),INDIRECT("'Grupo " & B11 & "'!C28")),INDIRECT("'Grupo " & B11 & "'!B12"):INDIRECT("'Grupo " & B11 & "'!G15"),2,FALSE)} -> 4867 | G16: {=VLOOKUP(INDIRECT("'Grupo " & B11 & "'!J28"),INDIRECT("'Grupo " & B11 & "'!B12"):INDIRECT("'Grupo " & B11 & "'!J15"),2,FALSE)} -> 4685

Sheet Ranking Final
A1: Ranking | B1: CARNE | C1: NOMBRE | D1: CLUB | E1: PUNTOS
A2: 1 | B2: 4295 | C2: RICARDO MATEO CHAVES LEÓN | D2: ESPARZA | E2: 720
A3: 2 | B3: 4149 | C3: LUIS MANUEL GARCÍA ARAYA | D3: ESPARZA | E3: 649
A4: 3 | B4: 4520 | C4: GAEL SOLÍS VÁSQUEZ | D4: ESPARZA | E4: 628
A5: 4 | B5: 4391 | C5: EMANUEL UMAÑA RODRIGUEZ | D5: CURRIDABAT | E5: 615
A6: 5 | B6: 4685 | C6: GAEL ROMERO LEÓN | D6: ESCAZÚ | E6: 540
A7: 6 | B7: 4699 | C7: EZEQUIEL LEAL CHACÓN | D7: ESPARZA | E7: 505
A8: 7 | B8: 4435 | C8: JIM LUKA JIMÉNEZ DE LEÓN | D8: CORREDORES | E8: 495
A9: 7 | B9: 4250 | C9: KEVIN HERNÁNDEZ LÁSCAREZ | D9: CCDR SAN JOSÉ | E9: 495
A10: 9 | B10: 4834 | C10: PEDRO RIMOLO VILLAGRA | D10: CURRIDABAT | E10: 490
A11: 10 | B11: 4718 | C11: OWEN CABEZAS HAY | D11: CORREDORES | E11: 475
A12: 11 | B12: 4700 | C12: ITAMAR JAFET QUIRÓS VARGAS | D12: ESPARZA | E12: 460
A13: 12 | B13: 4738 | C13: EMANUEL MATAMOROS RIVERA | D13: SANTA ANA | E13: 449
... A44: 18 | B44: 3546 | C44: FABIAN ALBERTO GARBANZO ZUÑIGA | D44: MORAVIA | E44: 420

Sheet Inscripciones
B1: Ranking Nacional
B2: U9 MASCULINO
B4: CARNÉ | C4: NOMBRE | D4: CLUB | E4: RANKING | F4: PUNTOS | G4: Grupo
A5: =G5+0.1 -> 1.1 | B5: 4295 | C5: RICARDO MATEO CHAVES LEÓN | D5: ESPARZA | E5: 1 | F5: 676 | G5: 1
A6: =G6+0.2 -> 1.2 | B6: 4718 | C6: OWEN CABEZAS HAY | D6: CORREDORES | E6: 9 | F6: 483 | G6: 1
A7: =G7+0.3 -> 1.3 | B7: 4834 | C7: PEDRO RIMOLO VILLAGRA | D7: CURRIDABAT | E7: 10 | F7: 481 | G7: 1
A8: =G8+0.1 -> 2.1 | B8: 4149 | C8: LUIS MANUEL GARCÍA ARAYA | D8: ESPARZA | E8: 2 | F8: 632 | G8: 2
A9: =G9+0.2 -> 2.2 | B9: 4250 | C9: KEVIN HERNÁNDEZ LÁSCAREZ | D9: CCDR SAN JOSÉ | E9: 8 | F9: 488 | G9: 2
A10: =G10+0.3 -> 2.3 | B10: 4700 | C10: ITAMAR JAFET QUIRÓS VARGAS | D10: ESPARZA | E10: 11 | F10: 468 | G10: 2
A11: =G11+0.1 -> 3.1 | B11: 4391 | C11: EMANUEL UMAÑA RODRIGUEZ | D11: CURRIDABAT | E11: 3 | F11: 595 | G11: 3
A12: =G12+0.2 -> 3.2 | B12: 4699 | C12: EZEQUIEL LEAL CHACÓN | D12: ESPARZA | E12: 7 | F12: 500 | G12: 3
A13: =G13+0.3 -> 3.3 | B13: 4738 | C13: EMANUEL MATAMOROS RIVERA | D13: SANTA ANA | E13: 12 | F13: 457 | G13: 3
A14: =G14+0.1 -> 4.1 | B14: 4520 | C14: GAEL SOLÍS VÁSQUEZ | D14: ESPARZA | E14: 4 | F14: 587 | G14: 4
A15: =G15+0.2 -> 4.2 | B15: 4685 | C15: GAEL ROMERO LEÓN | D15: ESCAZÚ | E15: 5 | F15: 530 | G15: 4
A16: =G16+0.3 -> 4.3 | B16: 4867 | C16: SALOMON MUÑOZ MOYA | D16: GUARCO | E16: 13 | F16: 455 | G16: 4
A17: =G17+0.4 -> 4.4 | B17: 4871 | C17: FABIAN ANGULO BRENES | D17: CCDR SANTA CRUZ | E17: 14 | F17: 455 | G17: 4
A18: =G18+0.2 -> 0.2
A19: =G19+0.3 -> 0.3
A20: =G20+0.1 -> 0.1
A21: =G21+0.2 -> 0.2
A22: =G22+0.3 -> 0.3
A23: =G23+0.1 -> 0.1
A24: =G24+0.2 -> 0.2
A25: =G25+0.3 -> 0.3
A26: =G26+0.1 -> 0.1
A27: =G27+0.2 -> 0.2
A28: =G28+0.3 -> 0.3
A29: =G29+0.1 -> 0.1
A30: =G30+0.2 -> 0.2
A31: =G31+0.3 -> 0.3
A32: =G32+0.1 -> 0.1
A33: =G33+0.2 -> 0.2
A34: =G34+0.3 -> 0.3
A35: =G35+0.1 -> 0.1
A36: =G36+0.2 -> 0.2
A37: =G37+0.3 -> 0.3
A38: =G38+0.1 -> 0.1
A39: =G39+0.2 -> 0.2
A40: =G40+0.3 -> 0.3
A41: =G41+0.1 -> 0.1
...

Sheet Grupo 1
L5: En Caso de ocupar 3 de 5, mostrar columnas H - I En caso de 2 de 2, ocultarlas.
G7: Fecha: | J7: =TODAY() -> 46288
B9: Categoría | D9: =Inscripciones!B2 -> U9 MASCULINO | E9: Grupo nº | F9: 1 | G9: Mesa nº
B11: Orden | C11: Carné | D11: Jugadores | E11: Lugar | F11: Ranking | G11: Puntos
A12: =F9+0.1 -> 1.1 | B12: 1 | C12: =VLOOKUP(A12,Inscripciones!A5:G167,2,FALSE) -> 4295 | D12: =IF(ISBLANK(C12),"",VLOOKUP(C12,Inscripciones!$B$5:$F$200,2,FALSE)) -> RICARDO MATEO CHAVES LEÓN | E12: =IF(ISBLANK(C12),"",VLOOKUP(C12,Inscripciones!$B$5:$F$200,3,FALSE)) -> ESPARZA | F12: =IF(ISBLANK(C12),"",VLOOKUP(C12,Inscripciones!$B$5:$F$200,4,FALSE)) -> 1 | G12: =IF(ISBLANK(C12),"",VLOOKUP(C12,Inscripciones!$B$5:$F$200,5,FALSE)) -> 676 | J12: =IF(ISBLANK(J11)," ",(E18+F18+G18+E20+F20+G20+H18+I18+H20+I20)/(E19+F19+G19+E21+F21+G21+H19+I19+H21+I21))
A13: =F9+0.2 -> 1.2 | B13: 2 | C13: =VLOOKUP(A13,Inscripciones!A5:G168,2,FALSE) -> 4718 | D13: =IF(ISBLANK(C13),"",VLOOKUP(C13,Inscripciones!$B$5:$F$200,2,FALSE)) -> OWEN CABEZAS HAY | E13: =IF(ISBLANK(C13),"",VLOOKUP(C13,Inscripciones!$B$5:$F$200,3,FALSE)) -> CORREDORES | F13: =IF(ISBLANK(C13),"",VLOOKUP(C13,Inscripciones!$B$5:$F$200,4,FALSE)) -> 9 | G13: =IF(ISBLANK(C13),"",VLOOKUP(C13,Inscripciones!$B$5:$F$200,5,FALSE)) -> 483 | J13: =IF(ISBLANK(J11)," ",(E21+F21+G21+E22+F22+G22+H21+I21+H22+I22)/(E20+F20+G20+E23+F23+G23+H20+I20+H23+I23))
A14: =+F9+0.3 -> 1.3 | B14: 3 | C14: =VLOOKUP(A14,Inscripciones!A6:G169,2,FALSE) -> 4834 | D14: =IF(ISBLANK(C14),"",VLOOKUP(C14,Inscripciones!$B$7:$F$200,2,FALSE)) -> PEDRO RIMOLO VILLAGRA | E14: =IF(ISBLANK(C14),"",VLOOKUP(C14,Inscripciones!$B$7:$F$200,3,FALSE)) -> CURRIDABAT | F14: =IF(ISBLANK(C14),"",VLOOKUP(C14,Inscripciones!$B$7:$F$200,4,FALSE)) -> 10 | G14: =IF(ISBLANK(C14),"",VLOOKUP(C14,Inscripciones!$B$7:$F$200,5,FALSE)) -> 481 | J14: =IF(ISBLANK(J11)," ",(E19+F19+G19+E23+F23+G23+H19+I19+H23+I23)/(E18+F18+G18+E22+F22+G22+H18+I18+H22+I22))
B17: Partida | D17: JUGADOR | E17: 1º set | F17: 2º set | G17: 3º set | H17: 4º set | I17: 5º set | J17: Ganador
B18: 1 | C18: 1 | D18: =D12 -> RICARDO MATEO CHAVES LEÓN | E18: 11 | F18: 11 | J18: {=IF(AND(TRIM(E18)="WO",TRIM(E19)="WO"),"",IF(TRIM(E19)="WO",C18,IF(TRIM(E18)="WO",C19,IF(SUMPRODUCT(--(E18:I18>E19:I19))>SUMPRODUCT(--(E19:I19>E18:I18)),C18,IF(SUMPRODUCT(--(E19:I19>E18:I18))>SUMPRODUCT(--(E18:I18>E19:I19)),C19,"")))))} -> 1
C19: 3 | D19: =D14 -> PEDRO RIMOLO VILLAGRA | E19: 1 | F19: 6
B20: 2 | C20: 1 | D20: =D12 -> RICARDO MATEO CHAVES LEÓN | E20: 11 | F20: 11 | J20: {=IF(AND(TRIM(E20)="WO",TRIM(E21)="WO"),"",IF(TRIM(E21)="WO",C20,IF(TRIM(E20)="WO",C21,IF(SUMPRODUCT(--(E20:I20>E21:I21))>SUMPRODUCT(--(E21:I21>E20:I20)),C20,IF(SUMPRODUCT(--(E21:I21>E20:I20))>SUMPRODUCT(--(E20:I20>E21:I21)),C21,"")))))} -> 1
C21: 2 | D21: =D13 -> OWEN CABEZAS HAY | E21: 3 | F21: 8
B22: 3 | C22: 2 | D22: =D13 -> OWEN CABEZAS HAY | E22: 11 | F22: 8 | G22: 11 | J22: {=IF(AND(TRIM(E22)="WO",TRIM(E23)="WO"),"",IF(TRIM(E23)="WO",C22,IF(TRIM(E22)="WO",C23,IF(SUMPRODUCT(--(E22:I22>E23:I23))>SUMPRODUCT(--(E23:I23>E22:I22)),C22,IF(SUMPRODUCT(--(E23:I23>E22:I22))>SUMPRODUCT(--(E22:I22>E23:I23)),C23,"")))))} -> 3
C23: 3 | D23: =D14 -> PEDRO RIMOLO VILLAGRA | E23: 6 | F23: 11 | G23: 13
C32: Clasificados (# de carne) | F32: Revisión de Camisas y Raquetas
C33: Carnet | D33: Nombre | F33: Revisión de nombres y resultados
C34: 4295 | D34: =IF(ISBLANK(C34),"",VLOOKUP(C34,Inscripciones!$B$5:$F$200,2,FALSE)) -> RICARDO MATEO CHAVES LEÓN | F34: Árbitro
C35: 4834 | D35: =IF(ISBLANK(C35),"",VLOOKUP(C35,Inscripciones!$B$5:$F$200,2,FALSE)) -> PEDRO RIMOLO VILLAGRA | F35: Marque si hay informe

Sheet Grupo 2
B2: #VALUE!
L5: En Caso de ocupar 3 de 5, mostrar columnas H - I En caso de 2 de 2, ocultarlas.
G7: Fecha: | J7: =TODAY() -> 46288
B9: Categoría | D9: =Inscripciones!B2 -> U9 MASCULINO | E9: Grupo nº | F9: 2 | G9: Mesa nº
B11: Orden | C11: Carné | D11: Jugadores | E11: Lugar | F11: Ranking | G11: Puntos
A12: =F9+0.1 -> 2.1 | B12: 1 | C12: =VLOOKUP(A12,Inscripciones!A5:G167,2,FALSE) -> 4149 | D12: =IF(ISBLANK(C12),"",VLOOKUP(C12,Inscripciones!$B$5:$F$200,2,FALSE)) -> LUIS MANUEL GARCÍA ARAYA | E12: =IF(ISBLANK(C12),"",VLOOKUP(C12,Inscripciones!$B$5:$F$200,3,FALSE)) -> ESPARZA | F12: =IF(ISBLANK(C12),"",VLOOKUP(C12,Inscripciones!$B$5:$F$200,4,FALSE)) -> 2 | G12: =IF(ISBLANK(C12),"",VLOOKUP(C12,Inscripciones!$B$5:$F$200,5,FALSE)) -> 632 | J12: =IF(ISBLANK(J11)," ",(E18+F18+G18+E20+F20+G20+H18+I18+H20+I20)/(E19+F19+G19+E21+F21+G21+H19+I19+H21+I21))
A13: =F9+0.2 -> 2.2 | B13: 2 | C13: =VLOOKUP(A13,Inscripciones!A5:G168,2,FALSE) -> 4250 | D13: =IF(ISBLANK(C13),"",VLOOKUP(C13,Inscripciones!$B$5:$F$200,2,FALSE)) -> KEVIN HERNÁNDEZ LÁSCAREZ | E13: =IF(ISBLANK(C13),"",VLOOKUP(C13,Inscripciones!$B$5:$F$200,3,FALSE)) -> CCDR SAN JOSÉ | F13: =IF(ISBLANK(C13),"",VLOOKUP(C13,Inscripciones!$B$5:$F$200,4,FALSE)) -> 8 | G13: =IF(ISBLANK(C13),"",VLOOKUP(C13,Inscripciones!$B$5:$F$200,5,FALSE)) -> 488 | J13: =IF(ISBLANK(J11)," ",(E21+F21+G21+E22+F22+G22+H21+I21+H22+I22)/(E20+F20+G20+E23+F23+G23+H20+I20+H23+I23))
A14: =+F9+0.3 -> 2.3 | B14: 3 | C14: =VLOOKUP(A14,Inscripciones!A6:G169,2,FALSE) -> 4700 | D14: =IF(ISBLANK(C14),"",VLOOKUP(C14,Inscripciones!$B$7:$F$200,2,FALSE)) -> ITAMAR JAFET QUIRÓS VARGAS | E14: =IF(ISBLANK(C14),"",VLOOKUP(C14,Inscripciones!$B$7:$F$200,3,FALSE)) -> ESPARZA | F14: =IF(ISBLANK(C14),"",VLOOKUP(C14,Inscripciones!$B$7:$F$200,4,FALSE)) -> 11 | G14: =IF(ISBLANK(C14),"",VLOOKUP(C14,Inscripciones!$B$7:$F$200,5,FALSE)) -> 468 | J14: =IF(ISBLANK(J11)," ",(E19+F19+G19+E23+F23+G23+H19+I19+H23+I23)/(E18+F18+G18+E22+F22+G22+H18+I18+H22+I22))
B17: Partida | D17: JUGADOR | E17: 1º set | F17: 2º set | G17: 3º set | H17: 4º set | I17: 5º set | J17: Ganador
B18: 1 | C18: 1 | D18: =D12 -> LUIS MANUEL GARCÍA ARAYA | E18: 11 | F18: 11 | J18: {=IF(AND(TRIM(E18)="WO",TRIM(E19)="WO"),"",IF(TRIM(E19)="WO",C18,IF(TRIM(E18)="WO",C19,IF(SUMPRODUCT(--(E18:I18>E19:I19))>SUMPRODUCT(--(E19:I19>E18:I18)),C18,IF(SUMPRODUCT(--(E19:I19>E18:I18))>SUMPRODUCT(--(E18:I18>E19:I19)),C19,"")))))} -> 1
C19: 3 | D19: =D14 -> ITAMAR JAFET QUIRÓS VARGAS | E19: 2 | F19: 6
B20: 2 | C20: 1 | D20: =D12 -> LUIS MANUEL GARCÍA ARAYA | E20: 11 | F20: 11 | J20: {=IF(AND(TRIM(E20)="WO",TRIM(E21)="WO"),"",IF(TRIM(E21)="WO",C20,IF(TRIM(E20)="WO",C21,IF(SUMPRODUCT(--(E20:I20>E21:I21))>SUMPRODUCT(--(E21:I21>E20:I20)),C20,IF(SUMPRODUCT(--(E21:I21>E20:I20))>SUMPRODUCT(--(E20:I20>E21:I21)),C21,"")))))} -> 1
C21: 2 | D21: =D13 -> KEVIN HERNÁNDEZ LÁSCAREZ | E21: 4 | F21: 7
B22: 3 | C22: 2 | D22: =D13 -> KEVIN HERNÁNDEZ LÁSCAREZ | E22: 11 | F22: 11 | J22: {=IF(AND(TRIM(E22)="WO",TRIM(E23)="WO"),"",IF(TRIM(E23)="WO",C22,IF(TRIM(E22)="WO",C23,IF(SUMPRODUCT(--(E22:I22>E23:I23))>SUMPRODUCT(--(E23:I23>E22:I22)),C22,IF(SUMPRODUCT(--(E23:I23>E22:I22))>SUMPRODUCT(--(E22:I22>E23:I23)),C23,"")))))} -> 2
C23: 3 | D23: =D14 -> ITAMAR JAFET QUIRÓS VARGAS | E23: 7 | F23: 4
C32: Clasificados (# de carne) | F32: Revisión de Camisas y Raquetas
C33: Carnet | D33: Nombre | F33: Revisión de nombres y resultados
C34: 4149 | D34: =IF(ISBLANK(C34),"",VLOOKUP(C34,Inscripciones!$B$5:$F$200,2,FALSE)) -> LUIS MANUEL GARCÍA ARAYA | F34: Árbitro
C35: 4250 | D35: =IF(ISBLANK(C35),"",VLOOKUP(C35,Inscripciones!$B$5:$F$200,2,FALSE)) -> KEVIN HERNÁNDEZ LÁSCAREZ | F35: Marque si hay informe

Sheet Grupo 3
B2: #VALUE!
L5: En Caso de ocupar 3 de 5, mostrar columnas H - I En caso de 2 de 2, ocultarlas.
G7: Fecha: | J7: =TODAY() -> 46288
B9: Categoría | D9: =Inscripciones!B2 -> U9 MASCULINO | E9: Grupo nº | F9: 3 | G9: Mesa nº
B11: Orden | C11: Carné | D11: Jugadores | E11: Lugar | F11: Ranking | G11: Puntos
A12: =F9+0.1 -> 3.1 | B12: 1 | C12: =VLOOKUP(A12,Inscripciones!A5:G167,2,FALSE) -> 4391 | D12: =IF(ISBLANK(C12),"",VLOOKUP(C12,Inscripciones!$B$5:$F$200,2,FALSE)) -> EMANUEL UMAÑA RODRIGUEZ | E12: =IF(ISBLANK(C12),"",VLOOKUP(C12,Inscripciones!$B$5:$F$200,3,FALSE)) -> CURRIDABAT | F12: =IF(ISBLANK(C12),"",VLOOKUP(C12,Inscripciones!$B$5:$F$200,4,FALSE)) -> 3 | G12: =IF(ISBLANK(C12),"",VLOOKUP(C12,Inscripciones!$B$5:$F$200,5,FALSE)) -> 595 | J12: =IF(ISBLANK(J11)," ",(E18+F18+G18+E20+F20+G20+H18+I18+H20+I20)/(E19+F19+G19+E21+F21+G21+H19+I19+H21+I21))
A13: =F9+0.2 -> 3.2 | B13: 2 | C13: =VLOOKUP(A13,Inscripciones!A5:G168,2,FALSE) -> 4699 | D13: =IF(ISBLANK(C13),"",VLOOKUP(C13,Inscripciones!$B$5:$F$200,2,FALSE)) -> EZEQUIEL LEAL CHACÓN | E13: =IF(ISBLANK(C13),"",VLOOKUP(C13,Inscripciones!$B$5:$F$200,3,FALSE)) -> ESPARZA | F13: =IF(ISBLANK(C13),"",VLOOKUP(C13,Inscripciones!$B$5:$F$200,4,FALSE)) -> 7 | G13: =IF(ISBLANK(C13),"",VLOOKUP(C13,Inscripciones!$B$5:$F$200,5,FALSE)) -> 500 | J13: =IF(ISBLANK(J11)," ",(E21+F21+G21+E22+F22+G22+H21+I21+H22+I22)/(E20+F20+G20+E23+F23+G23+H20+I20+H23+I23))
A14: =+F9+0.3 -> 3.3 | B14: 3 | C14: =VLOOKUP(A14,Inscripciones!A6:G169,2,FALSE) -> 4738 | D14: =IF(ISBLANK(C14),"",VLOOKUP(C14,Inscripciones!$B$7:$F$200,2,FALSE)) -> EMANUEL MATAMOROS RIVERA | E14: =IF(ISBLANK(C14),"",VLOOKUP(C14,Inscripciones!$B$7:$F$200,3,FALSE)) -> SANTA ANA | F14: =IF(ISBLANK(C14),"",VLOOKUP(C14,Inscripciones!$B$7:$F$200,4,FALSE)) -> 12 | G14: =IF(ISBLANK(C14),"",VLOOKUP(C14,Inscripciones!$B$7:$F$200,5,FALSE)) -> 457 | J14: =IF(ISBLANK(J11)," ",(E19+F19+G19+E23+F23+G23+H19+I19+H23+I23)/(E18+F18+G18+E22+F22+G22+H18+I18+H22+I22))
B17: Partida | D17: JUGADOR | E17: 1º set | F17: 2º set | G17: 3º set | H17: 4º set | I17: 5º set | J17: Ganador
B18: 1 | C18: 1 | D18: =D12 -> EMANUEL UMAÑA RODRIGUEZ | E18: 11 | F18: 11 | J18: {=IF(AND(TRIM(E18)="WO",TRIM(E19)="WO"),"",IF(TRIM(E19)="WO",C18,IF(TRIM(E18)="WO",C19,IF(SUMPRODUCT(--(E18:I18>E19:I19))>SUMPRODUCT(--(E19:I19>E18:I18)),C18,IF(SUMPRODUCT(--(E19:I19>E18:I18))>SUMPRODUCT(--(E18:I18>E19:I19)),C19,"")))))} -> 1
C19: 3 | D19: =D14 -> EMANUEL MATAMOROS RIVERA | E19: 4 | F19: 5
B20: 2 | C20: 1 | D20: =D12 -> EMANUEL UMAÑA RODRIGUEZ | E20: 11 | F20: 11 | J20: {=IF(AND(TRIM(E20)="WO",TRIM(E21)="WO"),"",IF(TRIM(E21)="WO",C20,IF(TRIM(E20)="WO",C21,IF(SUMPRODUCT(--(E20:I20>E21:I21))>SUMPRODUCT(--(E21:I21>E20:I20)),C20,IF(SUMPRODUCT(--(E21:I21>E20:I20))>SUMPRODUCT(--(E20:I20>E21:I21)),C21,"")))))} -> 1
C21: 2 | D21: =D13 -> EZEQUIEL LEAL CHACÓN | E21: 5 | F21: 5
B22: 3 | C22: 2 | D22: =D13 -> EZEQUIEL LEAL CHACÓN | E22: 11 | F22: 11 | J22: {=IF(AND(TRIM(E22)="WO",TRIM(E23)="WO"),"",IF(TRIM(E23)="WO",C22,IF(TRIM(E22)="WO",C23,IF(SUMPRODUCT(--(E22:I22>E23:I23))>SUMPRODUCT(--(E23:I23>E22:I22)),C22,IF(SUMPRODUCT(--(E23:I23>E22:I22))>SUMPRODUCT(--(E22:I22>E23:I23)),C23,"")))))} -> 2
C23: 3 | D23: =D14 -> EMANUEL MATAMOROS RIVERA | E23: 3 | F23: 3
C32: Clasificados (# de carne) | F32: Revisión de Camisas y Raquetas
C33: Carnet | D33: Nombre | F33: Revisión de nombres y resultados
C34: 4391 | D34: =IF(ISBLANK(C34),"",VLOOKUP(C34,Inscripciones!$B$5:$F$200,2,FALSE)) -> EMANUEL UMAÑA RODRIGUEZ | F34: Árbitro
C35: 4699 | D35: =IF(ISBLANK(C35),"",VLOOKUP(C35,Inscripciones!$B$5:$F$200,2,FALSE)) -> EZEQUIEL LEAL CHACÓN | F35: Marque si hay informe

Sheet Grupo 4
B2: #VALUE!
L5: En Caso de ocupar 3 de 5, mostrar columnas H - I En caso de 2 de 2, ocultarlas. | O5: Todo | P5: Imprimir
O6: Par | P6: Todo
G7: Fecha: | J7: =TODAY() -> 46288 | O7: Impar
B9: Categoría: | D9: =Inscripciones!B2 -> U9 MASCULINO | E9: Grupo nº | F9: 4 | G9: Mesa nº
B11: Orden | C11: Carné | D11: Jugadores | E11: Lugar | F11: Ranking | G11: Puntos
A12: =$F$9+0.1 -> 4.1 | B12: 1 | C12: =VLOOKUP(A12,Inscripciones!$A$5:$G$167,2,FALSE) -> 4520 | D12: =IF(ISBLANK(C12),"",VLOOKUP(C12,Inscripciones!$B$7:$F$200,2,FALSE)) -> GAEL SOLÍS VÁSQUEZ | E12: =IF(ISBLANK(C12),"",VLOOKUP(C12,Inscripciones!$B$7:$F$200,3,FALSE)) -> ESPARZA | F12: =IF(ISBLANK(C12),"",VLOOKUP(C12,Inscripciones!$B$7:$F$200,4,FALSE)) -> 4 | G12: =IF(ISBLANK(C12),"",VLOOKUP(C12,Inscripciones!$B$7:$F$200,5,FALSE)) -> 587
A13: =$F$9+0.2 -> 4.2 | B13: 2 | C13: =VLOOKUP(A13,Inscripciones!$A$5:$G$167,2,FALSE) -> 4685 | D13: =IF(ISBLANK(C13),"",VLOOKUP(C13,Inscripciones!$B$7:$F$200,2,FALSE)) -> GAEL ROMERO LEÓN | E13: =IF(ISBLANK(C13),"",VLOOKUP(C13,Inscripciones!$B$7:$F$200,3,FALSE)) -> ESCAZÚ | F13: =IF(ISBLANK(C13),"",VLOOKUP(C13,Inscripciones!$B$7:$F$200,4,FALSE)) -> 5 | G13: =IF(ISBLANK(C13),"",VLOOKUP(C13,Inscripciones!$B$7:$F$200,5,FALSE)) -> 530
A14: =$F$9+0.3 -> 4.3 | B14: 3 | C14: =VLOOKUP(A14,Inscripciones!$A$5:$G$167,2,FALSE) -> 4867 | D14: =IF(ISBLANK(C14),"",VLOOKUP(C14,Inscripciones!$B$7:$F$200,2,FALSE)) -> SALOMON MUÑOZ MOYA | E14: =IF(ISBLANK(C14),"",VLOOKUP(C14,Inscripciones!$B$7:$F$200,3,FALSE)) -> GUARCO | F14: =IF(ISBLANK(C14),"",VLOOKUP(C14,Inscripciones!$B$7:$F$200,4,FALSE)) -> 13 | G14: =IF(ISBLANK(C14),"",VLOOKUP(C14,Inscripciones!$B$7:$F$200,5,FALSE)) -> 455
A15: =$F$9+0.4 -> 4.4 | B15: 4 | C15: =VLOOKUP(A15,Inscripciones!$A$5:$G$167,2,FALSE) -> 4871 | D15: =IF(ISBLANK(C15),"",VLOOKUP(C15,Inscripciones!$B$7:$F$200,2,FALSE)) -> FABIAN ANGULO BRENES | E15: =IF(ISBLANK(C15),"",VLOOKUP(C15,Inscripciones!$B$7:$F$200,3,FALSE)) -> CCDR SANTA CRUZ | F15: =IF(ISBLANK(C15),"",VLOOKUP(C15,Inscripciones!$B$7:$F$200,4,FALSE)) -> 14 | G15: =IF(ISBLANK(C15),"",VLOOKUP(C15,Inscripciones!$B$7:$F$200,5,FALSE)) -> 455
B17: Partida | C17: Nº | D17: JUGADOR | E17: 1º set | F17: 2º set | G17: 3º set | H17: 4º set | I17: 5º set | J17: Ganador
B18: 1 | C18: 1 | D18: =D12 -> GAEL SOLÍS VÁSQUEZ | E18: 11 | F18: 11 | J18: {=IF(AND(TRIM(E18)="WO",TRIM(E19)="WO"),"",IF(TRIM(E19)="WO",C18,IF(TRIM(E18)="WO",C19,IF(SUMPRODUCT(--(E18:I18>E19:I19))>SUMPRODUCT(--(E19:I19>E18:I18)),C18,IF(SUMPRODUCT(--(E19:I19>E18:I18))>SUMPRODUCT(--(E18:I18>E19:I19)),C19,"")))))} -> 1
C19: 3 | D19: =D14 -> SALOMON MUÑOZ MOYA | E19: 7 | F19: 0
B20: 2 | C20: 4 | D20: =D15 -> FABIAN ANGULO BRENES | E20: 3 | F20: 0 | J20: {=IF(AND(TRIM(E20)="WO",TRIM(E21)="WO"),"",IF(TRIM(E21)="WO",C20,IF(TRIM(E20)="WO",C21,IF(SUMPRODUCT(--(E20:I20>E21:I21))>SUMPRODUCT(--(E21:I21>E20:I20)),C20,IF(SUMPRODUCT(--(E21:I21>E20:I20))>SUMPRODUCT(--(E20:I20>E21:I21)),C21,"")))))} -> 2
C21: 2 | D21: =D13 -> GAEL ROMERO LEÓN | E21: 11 | F21: 11
B22: 3 | C22: 1 | D22: =D12 -> GAEL SOLÍS VÁSQUEZ | E22: 9 | F22: 11 | G22: 11 | J22: {=IF(AND(TRIM(E22)="WO",TRIM(E23)="WO"),"",IF(TRIM(E23)="WO",C22,IF(TRIM(E22)="WO",C23,IF(SUMPRODUCT(--(E22:I22>E23:I23))>SUMPRODUCT(--(E23:I23>E22:I22)),C22,IF(SUMPRODUCT(--(E23:I23>E22:I22))>SUMPRODUCT(--(E22:I22>E23:I23)),C23,"")))))} -> 1
C23: 2 | D23: =D13 -> GAEL ROMERO LEÓN | E23: 11 | F23: 3 | G23: 5
B24: 4 | C24: 3 | D24: =D19 -> SALOMON MUÑOZ MOYA | E24: 11 | F24: 18 | J24: {=IF(AND(TRIM(E24)="WO",TRIM(E25)="WO"),"",IF(TRIM(E25)="WO",C24,IF(TRIM(E24)="WO",C25,IF(SUMPRODUCT(--(E24:I24>E25:I25))>SUMPRODUCT(--(E25:I25>E24:I24)),C24,IF(SUMPRODUCT(--(E25:I25>E24:I24))>SUMPRODUCT(--(E24:I24>E25:I25)),C25,"")))))} -> 3
C25: 4 | D25: =D20 -> FABIAN ANGULO BRENES | E25: 8 | F25: 16
B26: 5 | C26: 1 | D26: =D12 -> GAEL SOLÍS VÁSQUEZ | E26: 11 | F26: 11 | J26: {=IF(AND(TRIM(E26)="WO",TRIM(E27)="WO"),"",IF(TRIM(E27)="WO",C26,IF(TRIM(E26)="WO",C27,IF(SUMPRODUCT(--(E26:I26>E27:I27))>SUMPRODUCT(--(E27:I27>E26:I26)),C26,IF(SUMPRODUCT(--(E27:I27>E26:I26))>SUMPRODUCT(--(E26:I26>E27:I27)),C27,"")))))} -> 1
C27: 4 | D27: =D15 -> FABIAN ANGULO BRENES | E27: 1 | F27: 3
B28: 6 | C28: 2 | D28: =D13 -> GAEL ROMERO LEÓN | E28: 11 | F28: 11 | J28: {=IF(AND(TRIM(E28)="WO",TRIM(E29)="WO"),"",IF(TRIM(E29)="WO",C28,IF(TRIM(E28)="WO",C29,IF(SUMPRODUCT(--(E28:I28>E29:I29))>SUMPRODUCT(--(E29:I29>E28:I28)),C28,IF(SUMPRODUCT(--(E29:I29>E28:I28))>SUMPRODUCT(--(E28:I28>E29:I29)),C29,"")))))} -> 2
C29: 3 | D29: =D24 -> SALOMON MUÑOZ MOYA | E29: 3 | F29: 5
C32: Clasificados (# de carne) | F32: Revisión de Camisas y Raquetas
C33: Carnet | D33: Nombre | F33: Revisión de nombres y resultados
C34: 4520 | D34: =IF(ISBLANK(C34),"",VLOOKUP(C34,Inscripciones!$B$5:$F$200,2,FALSE)) -> GAEL SOLÍS VÁSQUEZ | F34: Árbitro
C35: 4685 | D35: =IF(ISBLANK(C35),"",VLOOKUP(C35,Inscripciones!$B$5:$F$200,2,FALSE)) -> GAEL ROMERO LEÓN | F35: Marque si hay informe

Sheet SORTEO 8
B2: #VALUE!
B6: SORTEO LLAVE U9 MASCULINO
R8: PRIMEROS DE GRUPO
B9: 1ro G1 | C9: 1 | D9: =VLOOKUP(C9,$U$8:$W$258,2,FALSE) -> 4295 | E9: =IF(D9=0,0,VLOOKUP(D9,Inscripciones!$B$1:$M$194,2,FALSE)) -> RICARDO MATEO CHAVES LEÓN | F9: =IF(D9=0,0,VLOOKUP(D9,Inscripciones!$B$1:$M$194,3,FALSE)) -> ESPARZA | P9: Gr | Q9: 1 | R9: {=INDIRECT("'Grupo " & Q9 & "'!C34")} -> 4295 | S9: =IF(ISBLANK(R9),"",VLOOKUP(R9,Inscripciones!$B$1:$M$194,2,FALSE)) -> RICARDO MATEO CHAVES LEÓN | T9: =IF(ISBLANK(R9),"",VLOOKUP(R9,Inscripciones!$B$1:$M$194,3,FALSE)) -> ESPARZA | U9: 1 | V9: =R9 -> 4295 | W9: =IF(U9=0,0,IF(U9<5,"UP","DO")) -> UP
B10: 2do | C10: 2 | D10: =VLOOKUP(C10,$U$8:$W$258,2,FALSE) -> 4685 | E10: =IF(D10=0,0,VLOOKUP(D10,Inscripciones!$B$1:$M$194,2,FALSE)) -> GAEL ROMERO LEÓN | F10: =IF(D10=0,0,VLOOKUP(D10,Inscripciones!$B$1:$M$194,3,FALSE)) -> ESCAZÚ | P10: Gr | Q10: 2 | R10: {=INDIRECT("'Grupo " & Q10 & "'!C34")} -> 4149 | S10: =IF(ISBLANK(R10),"",VLOOKUP(R10,Inscripciones!$B$1:$M$194,2,FALSE)) -> LUIS MANUEL GARCÍA ARAYA | T10: =IF(ISBLANK(R10),"",VLOOKUP(R10,Inscripciones!$B$1:$M$194,3,FALSE)) -> ESPARZA | U10: 8 | V10: =R10 -> 4149 | W10: =IF(U10=0,0,IF(U10<5,"UP","DO")) -> DO
B11: 2do | C11: 3 | D11: =VLOOKUP(C11,$U$8:$W$258,2,FALSE) -> 4250 | E11: =IF(D11=0,0,VLOOKUP(D11,Inscripciones!$B$1:$M$194,2,FALSE)) -> KEVIN HERNÁNDEZ LÁSCAREZ | F11: =IF(D11=0,0,VLOOKUP(D11,Inscripciones!$B$1:$M$194,3,FALSE)) -> CCDR SAN JOSÉ | P11: Gr | Q11: 3 | R11: {=INDIRECT("'Grupo " & Q11 & "'!C34")} -> 4391 | S11: =IF(ISBLANK(R11),"",VLOOKUP(R11,Inscripciones!$B$1:$M$194,2,FALSE)) -> EMANUEL UMAÑA RODRIGUEZ | T11: =IF(ISBLANK(R11),"",VLOOKUP(R11,Inscripciones!$B$1:$M$194,3,FALSE)) -> CURRIDABAT | U11: 4 | V11: =R11 -> 4391 | W11: =IF(U11=0,0,IF(U11<5,"UP","DO")) -> UP
B12: 1ro G3-4 | C12: 4 | D12: =VLOOKUP(C12,$U$8:$W$258,2,FALSE) -> 4391 | E12: =IF(D12=0,0,VLOOKUP(D12,Inscripciones!$B$1:$M$194,2,FALSE)) -> EMANUEL UMAÑA RODRIGUEZ | F12: =IF(D12=0,0,VLOOKUP(D12,Inscripciones!$B$1:$M$194,3,FALSE)) -> CURRIDABAT | P12: Gr | Q12: 4 | R12: {=INDIRECT("'Grupo " & Q12 & "'!C34")} -> 4520 | S12: =IF(ISBLANK(R12),"",VLOOKUP(R12,Inscripciones!$B$1:$M$194,2,FALSE)) -> GAEL SOLÍS VÁSQUEZ | T12: =IF(ISBLANK(R12),"",VLOOKUP(R12,Inscripciones!$B$1:$M$194,3,FALSE)) -> ESPARZA | U12: 5 | V12: =R12 -> 4520 | W12: =IF(U12=0,0,IF(U12<5,"UP","DO")) -> DO
B13: 1ro G3-4 | C13: 5 | D13: =VLOOKUP(C13,$U$8:$W$258,2,FALSE) -> 4520 | E13: =IF(D13=0,0,VLOOKUP(D13,Inscripciones!$B$1:$M$194,2,FALSE)) -> GAEL SOLÍS VÁSQUEZ | F13: =IF(D13=0,0,VLOOKUP(D13,Inscripciones!$B$1:$M$194,3,FALSE)) -> ESPARZA | P13: Gr | Q13: 9 | S13: =IF(ISBLANK(R13),"",VLOOKUP(R13,Inscripciones!$B$1:$M$194,2,FALSE)) | T13: =IF(ISBLANK(R13),"",VLOOKUP(R13,Inscripciones!$B$1:$M$194,4,FALSE)) | V13: =R13 -> 0 | W13: =IF(U13=0,0,IF(U13<17,"UP","DO")) -> 0
B14: 2do | C14: 6 | D14: =VLOOKUP(C14,$U$8:$W$258,2,FALSE) -> 4699 | E14: =IF(D14=0,0,VLOOKUP(D14,Inscripciones!$B$1:$M$194,2,FALSE)) -> EZEQUIEL LEAL CHACÓN | F14: =IF(D14=0,0,VLOOKUP(D14,Inscripciones!$B$1:$M$194,3,FALSE)) -> ESPARZA | P14: Gr | Q14: 16 | S14: =IF(ISBLANK(R14),"",VLOOKUP(R14,Inscripciones!$B$1:$M$194,2,FALSE)) | T14: =IF(ISBLANK(R14),"",VLOOKUP(R14,Inscripciones!$B$1:$M$194,4,FALSE)) | V14: =R14 -> 0 | W14: =IF(U14=0,0,IF(U14<17,"UP","DO")) -> 0
B15: 2do | C15: 7 | D15: =VLOOKUP(C15,$U$8:$W$258,2,FALSE) -> 4834 | E15: =IF(D15=0,0,VLOOKUP(D15,Inscripciones!$B$1:$M$194,2,FALSE)) -> PEDRO RIMOLO VILLAGRA | F15: =IF(D15=0,0,VLOOKUP(D15,Inscripciones!$B$1:$M$194,3,FALSE)) -> CURRIDABAT | R15: SEGUNDOS DE GRUPO
B16: 1ro G2 | C16: 8 | D16: =VLOOKUP(C16,$U$8:$W$258,2,FALSE) -> 4149 | E16: =IF(D16=0,0,VLOOKUP(D16,Inscripciones!$B$1:$M$194,2,FALSE)) -> LUIS MANUEL GARCÍA ARAYA | F16: =IF(D16=0,0,VLOOKUP(D16,Inscripciones!$B$1:$M$194,3,FALSE)) -> ESPARZA | P16: Gr | Q16: 1 | R16: {=INDIRECT("'Grupo " & Q16 & "'!C35")} -> 4834 | S16: =IF(ISBLANK(R16),"",VLOOKUP(R16,Inscripciones!$B$1:$M$194,2,FALSE)) -> PEDRO RIMOLO VILLAGRA | T16: =IF(ISBLANK(R16),"",VLOOKUP(R16,Inscripciones!$B$1:$M$194,3,FALSE)) -> CURRIDABAT | U16: 7 | V16: =R16 -> 4834 | W16: =IF(W9="","",IF(W9="UP","DO",IF(W9="DO","UP",""))) -> DO
P17: Gr | Q17: 2 | R17: {=INDIRECT("'Grupo " & Q17 & "'!C35")} -> 4250 | S17: =IF(ISBLANK(R17),"",VLOOKUP(R17,Inscripciones!$B$1:$M$194,2,FALSE)) -> KEVIN HERNÁNDEZ LÁSCAREZ | T17: =IF(ISBLANK(R17),"",VLOOKUP(R17,Inscripciones!$B$1:$M$194,3,FALSE)) -> CCDR SAN JOSÉ | U17: 3 | V17: =R17 -> 4250 | W17: =IF(W10="","",IF(W10="UP","DO",IF(W10="DO","UP",""))) -> UP
P18: Gr | Q18: 3 | R18: {=INDIRECT("'Grupo " & Q18 & "'!C35")} -> 4699 | S18: =IF(ISBLANK(R18),"",VLOOKUP(R18,Inscripciones!$B$1:$M$194,2,FALSE)) -> EZEQUIEL LEAL CHACÓN | T18: =IF(ISBLANK(R18),"",VLOOKUP(R18,Inscripciones!$B$1:$M$194,3,FALSE)) -> ESPARZA | U18: 6 | V18: =R18 -> 4699 | W18: =IF(W11="","",IF(W11="UP","DO",IF(W11="DO","UP",""))) -> DO
P19: Gr | Q19: 4 | R19: {=INDIRECT("'Grupo " & Q19 & "'!C35")} -> 4685 | S19: =IF(ISBLANK(R19),"",VLOOKUP(R19,Inscripciones!$B$1:$M$194,2,FALSE)) -> GAEL ROMERO LEÓN | T19: =IF(ISBLANK(R19),"",VLOOKUP(R19,Inscripciones!$B$1:$M$194,3,FALSE)) -> ESCAZÚ | U19: 2 | V19: =R19 -> 4685 | W19: =IF(W12="","",IF(W12="UP","DO",IF(W12="DO","UP",""))) -> UP
U21: 1 | V21: -
U22: 2 | V22: -
U23: 3 | V23: -
U24: 4 | V24: -
U25: 5 | V25: -
U26: 6 | V26: -
U27: 7 | V27: -
U28: 8 | V28: -
U29: - | V29: -
U30: 0 | V30: -
V31: -

Sheet LLAVE 8
AV1: #VALUE!
AA2: 2 | AV2: =Inscripciones!$B$2 -> U9 MASCULINO
A3: Match | B3: Round | C3: Day | D3: Time | E3: T | G3: A | H3: B | I3: pla 1 | J3: Ass | K3: pla 2 | L3: Ass | AA3: G A | AB3: G X | AD3: Score | AE3: Games
A4: 1 | B4: QF | C4: 5-Jun | D4: 09:00 | E4: 1 | F4: =C4&"-"&D4&"- Table"&E4 -> 5-Jun-09:00- Table1 | G4: ='SORTEO 8'!D9 -> 4295 | H4: ='SORTEO 8'!D10 -> 4685 | I4: =IF(G4=0,0,VLOOKUP(G4,Inscripciones!$B$2:$K$499,2,FALSE)) -> RICARDO MATEO CHAVES LEÓN | J4: =IF(G4=0,0,VLOOKUP(G4,Inscripciones!$B$2:$N$399,3,FALSE)) -> ESPARZA | K4: =IF(I4=0,0,VLOOKUP(H4,Inscripciones!$B$2:$K$499,2,FALSE)) -> GAEL ROMERO LEÓN | L4: =IF(I4=0,0,VLOOKUP(H4,Inscripciones!$B$2:$N$399,3,FALSE)) -> ESCAZÚ | M4: 11 | N4: 2 | O4: 11 | P4: 2 | AA4: =IF(M4+N4<>0,SUM(AF4:AL4),"") -> 2 | AB4: =IF(M4+N4<>0,SUM(AF5:AL5),"") -> 0 | AC4: =IF(AA4>AB4,AD4&" "&AE4,IF(AB4>AA4,AD4&" "&AE5,"")) -> 2 - 0 (2, 2) | AD4: =IF(AA4>AB4,AA4&" - "&AB4,IF(AB4>AA4,AB4&" - "&AA4,"")) -> 2 - 0 | AE4: =CONCATENATE("(",AM4,AN4,AO4,AP4,AQ4,AR4,AS4,")") -> (2, 2) | AF4: =IF(M4>N4,1,0) -> 1 | AG4: =IF(O4>P4,1,0) -> 1 | AH4: =IF(Q4>R4,1,0) -> 0 | AI4: =IF(S4>T4,1,0) -> 0 | AJ4: =IF(U4>V4,1,0) -> 0 | AK4: =IF(W4>X4,1,0) -> 0 | AL4: =IF(Y4>Z4,1,0) -> 0 | AM4: =IF(M4>N4,N4,IF(N4>M4,-M4,"")) -> 2 | AN4: =IF(O4>P4,", "&P4,IF(P4>O4,", "&-O4,"")) -> , 2 | AO4: =IF(Q4>R4,", "&R4,IF(R4>Q4,", "&-Q4,"")) | AP4: =IF(S4>T4,", "&T4,IF(T4>S4,", "&-S4,"")) | AQ4: =IF(U4>V4,", "&V4,IF(V4>U4,", "&-U4,"")) | AR4: =IF(W4>X4,", "&X4,IF(X4>W4,", "&-W4,"")) | AS4: =IF(Y4>Z4,", "&Z4,IF(Z4>Y4,", "&-Y4,"")) | AU4: 1 | AV4: =VLOOKUP(AV5,$A$4:$L$35,7,FALSE) -> 4295 | AW4: =IF(AV4=0,0,VLOOKUP(AV4,Inscripciones!$B$2:$K$499,2,FALSE)) -> RICARDO MATEO CHAVES LEÓN | AX4: =IF(AV4=0,0,VLOOKUP(AV4,Inscripciones!$B$2:$N$399,3,FALSE)) -> ESPARZA | AZ4: =VLOOKUP(AV5,$A$4:$AD$35,29,FALSE) -> 2 - 0 (2, 2) | BL4: MATCH_ID | BM4: DAT | BN4: TIME | BO4: TABLE | BP4: EVT | BQ4: GRP | BR4: SEQ | BS4: P1ID_1 | BT4: P1ID_2 | BU4: P2ID_1 | BV4: P2ID_2 | BW4: WINNER ID | BY4: P1 | BZ4: P2 | CA4: EVENT | CB4: ROUND
I5: 0 | J5: 0 | K5: 0 | L5: 0 | AD5: =IF(AA4>AB4,AD4&" "&AE4,IF(AB4>AA4,AD4&" "&AE5,"")) -> 2 - 0 (2, 2) | AE5: =CONCATENATE("(",AM5,AN5,AO5,AP5,AQ5,AR5,AS5,")") -> (-2, -2) | AF5: =IF(N4>M4,1,0) -> 0 | AG5: =IF(P4>O4,1,0) -> 0 | AH5: =IF(R4>Q4,1,0) -> 0 | AI5: =IF(T4>S4,1,0) -> 0 | AJ5: =IF(V4>U4,1,0) -> 0 | AK5: =IF(X4>W4,1,0) -> 0 | AL5: =IF(Z4>Y4,1,0) -> 0 | AM5: =IF(N4>M4,M4,IF(M4>N4,-N4,"")) -> -2 | AN5: =IF(P4>O4,", "&O4,IF(O4>P4,", "&-P4,"")) -> , -2 | AO5: =IF(R4>Q4,", "&Q4,IF(Q4>R4,", "&-R4,"")) | AP5: =IF(T4>S4,", "&S4,IF(S4>T4,", "&-T4,"")) | AQ5: =IF(V4>U4,", "&U4,IF(U4>V4,", "&-V4,"")) | AR5: =IF(X4>W4,", "&W4,IF(W4>X4,", "&-X4,"")) | AS5: =IF(Z4>Y4,", "&Y4,IF(Y4>Z4,", "&-Z4,"")) | AV5: 1 | AW5: =VLOOKUP(AV5,$A$4:$L$35,6,FALSE) -> 5-Jun-09:00- Table1 | AY5: =VLOOKUP(AY7,$A$4:$L$39,7,FALSE) -> 4295 | AZ5: =IF(AY5=0,0,VLOOKUP(AY5,Inscripciones!$B$2:$K$499,2,FALSE)) -> RICARDO MATEO CHAVES LEÓN | BA5: =IF(AY5=0,0,VLOOKUP(AY5,Inscripciones!$B$2:$N$399,3,FALSE)) -> ESPARZA | BL5: 1 | BM5: =C4 -> 5-Jun | BN5: =D4 -> 09:00 | BO5: =E4 -> 1 | BP5: JBS | BR5: 1 | BS5: =VLOOKUP(BY6,Inscripciones!$B$2:$B$399,2,FALSE) -> #REF! | BU5: =VLOOKUP(BZ6,Inscripciones!$B$2:$B$399,2,FALSE) -> #REF! | BY5: =G4 -> 4295 | BZ5: =H4 -> 4685 | CA5: =Inscripciones!$B$2 -> U9 MASCULINO | CB5: Cuartos
A6: 2 | B6: QF | C6: 5-Jun | D6: 9:00 | E6: 2 | F6: =C6&"-"&D6&"- Table"&E6 -> 5-Jun-9:00- Table2 | G6: ='SORTEO 8'!D11 -> 4250 | H6: ='SORTEO 8'!D12 -> 4391 | I6: =IF(G6=0,0,VLOOKUP(G6,Inscripciones!$B$2:$K$499,2,FALSE)) -> KEVIN HERNÁNDEZ LÁSCAREZ | J6: =IF(G6=0,0,VLOOKUP(G6,Inscripciones!$B$2:$N$399,3,FALSE)) -> CCDR SAN JOSÉ | K6: =IF(I6=0,0,VLOOKUP(H6,Inscripciones!$B$2:$K$499,2,FALSE)) -> EMANUEL UMAÑA RODRIGUEZ | L6: =IF(I6=0,0,VLOOKUP(H6,Inscripciones!$B$2:$N$399,3,FALSE)) -> CURRIDABAT | M6: 4 | N6: 11 | O6: 8 | P6: 11 | AA6: =IF(M6+N6<>0,SUM(AF6:AL6),"") -> 0 | AB6: =IF(M6+N6<>0,SUM(AF7:AL7),"") -> 2 | AC6: =IF(AA6>AB6,AD6&" "&AE6,IF(AB6>AA6,AD6&" "&AE7,"")) -> 2 - 0 (4, 8) | AD6: =IF(AA6>AB6,AA6&" - "&AB6,IF(AB6>AA6,AB6&" - "&AA6,"")) -> 2 - 0 | AE6: =CONCATENATE("(",AM6,AN6,AO6,AP6,AQ6,AR6,AS6,")") -> (-4, -8) | AF6: =IF(M6>N6,1,0) -> 0 | AG6: =IF(O6>P6,1,0) -> 0 | AH6: =IF(Q6>R6,1,0) -> 0 | AI6: =IF(S6>T6,1,0) -> 0 | AJ6: =IF(U6>V6,1,0) -> 0 | AK6: =IF(W6>X6,1,0) -> 0 | AL6: =IF(Y6>Z6,1,0) -> 0 | AM6: =IF(M6>N6,N6,IF(N6>M6,-M6,"")) -> -4 | AN6: =IF(O6>P6,", "&P6,IF(P6>O6,", "&-O6,"")) -> , -8 | AO6: =IF(Q6>R6,", "&R6,IF(R6>Q6,", "&-Q6,"")) | AP6: =IF(S6>T6,", "&T6,IF(T6>S6,", "&-S6,"")) | AQ6: =IF(U6>V6,", "&V6,IF(V6>U6,", "&-U6,"")) | AR6: =IF(W6>X6,", "&X6,IF(X6>W6,", "&-W6,"")) | AS6: =IF(Y6>Z6,", "&Z6,IF(Z6>Y6,", "&-Y6,"")) | AU6: =1+AU4 -> 2 | AV6: =VLOOKUP(AV5,$A$4:$L$35,8,FALSE) -> 4685 | AW6: =IF(AV6=0,0,VLOOKUP(AV6,Inscripciones!$B$2:$K$499,2,FALSE)) -> GAEL ROMERO LEÓN | AX6: =IF(AV6=0,0,VLOOKUP(AV6,Inscripciones!$B$2:$N$399,3,FALSE)) -> ESCAZÚ | BC6: =VLOOKUP(AY7,$A$4:$AD$35,29,FALSE) -> 3 - 1 (7, 6, -10, 6) | BL6: =1+BL5 -> 2 | BM6: =C6 -> 5-Jun | BN6: =D6 -> 9:00 | BO6: =E6 -> 2 | BP6: JBS | BR6: 2 | BS6: =VLOOKUP(BY7,Inscripciones!$B$2:$B$399,2,FALSE) -> #REF! | BU6: =VLOOKUP(BZ7,Inscripciones!$B$2:$B$399,2,FALSE) -> #REF! | BY6: =G6 -> 4250 | BZ6: =H6 -> 4391 | CA6: =Inscripciones!$B$2 -> U9 MASCULINO | CB6: Cuartos
I7: 0 | J7: 0 | K7: 0 | L7: 0 | AD7: =IF(AA6>AB6,AD6&" "&AE6,IF(AB6>AA6,AD6&" "&AE7,"")) -> 2 - 0 (4, 8) | AE7: =CONCATENATE("(",AM7,AN7,AO7,AP7,AQ7,AR7,AS7,")") -> (4, 8) | AF7: =IF(N6>M6,1,0) -> 1 | AG7: =IF(P6>O6,1,0) -> 1 | AH7: =IF(R6>Q6,1,0) -> 0 | AI7: =IF(T6>S6,1,0) -> 0 | AJ7: =IF(V6>U6,1,0) -> 0 | AK7: =IF(X6>W6,1,0) -> 0 | AL7: =IF(Z6>Y6,1,0) -> 0 | AM7: =IF(N6>M6,M6,IF(M6>N6,-N6,"")) -> 4 | AN7: =IF(P6>O6,", "&O6,IF(O6>P6,", "&-P6,"")) -> , 8 | AO7: =IF(R6>Q6,", "&Q6,IF(Q6>R6,", "&-R6,"")) | AP7: =IF(T6>S6,", "&S6,IF(S6>T6,", "&-T6,"")) | AQ7: =IF(V6>U6,", "&U6,IF(U6>V6,", "&-V6,"")) | AR7: =IF(X6>W6,", "&W6,IF(W6>X6,", "&-X6,"")) | AS7: =IF(Z6>Y6,", "&Y6,IF(Y6>Z6,", "&-Z6,"")) | AY7: 5 | AZ7: =VLOOKUP(AY7,$A$4:$L$35,6,FALSE) -> 5-Jun-10:30- Table1 | BB7: =VLOOKUP(BB11,$A$4:$L$39,7,FALSE) -> 4295 | BC7: =IF(BB7=0,0,VLOOKUP(BB7,Inscripciones!$B$2:$K$499,2,FALSE)) -> RICARDO MATEO CHAVES LEÓN | BD7: =IF(BB7=0,0,VLOOKUP(BB7,Inscripciones!$B$2:$N$399,3,FALSE)) -> ESPARZA | BL7: =1+BL6 -> 3 | BM7: =C8 -> 5-Jun | BN7: =D8 -> 9:00 | BO7: =E8 -> 3 | BP7: JBS | BR7: 3 | BS7: =VLOOKUP(BY8,Inscripciones!$B$2:$B$399,2,FALSE) -> #REF! | BU7: =VLOOKUP(BZ8,Inscripciones!$B$2:$B$399,2,FALSE) -> #REF! | BY7: =G8 -> 4520 | BZ7: =H8 -> 4699 | CA7: =Inscripciones!$B$2 -> U9 MASCULINO | CB7: Cuartos
A8: 3 | B8: QF | C8: 5-Jun | D8: 9:00 | E8: 3 | F8: =C8&"-"&D8&"- Table"&E8 -> 5-Jun-9:00- Table3 | G8: ='SORTEO 8'!D13 -> 4520 | H8: ='SORTEO 8'!D14 -> 4699 | I8: =IF(G8=0,0,VLOOKUP(G8,Inscripciones!$B$2:$K$499,2,FALSE)) -> GAEL SOLÍS VÁSQUEZ | J8: =IF(G8=0,0,VLOOKUP(G8,Inscripciones!$B$2:$N$399,3,FALSE)) -> ESPARZA | K8: =IF(I8=0,0,VLOOKUP(H8,Inscripciones!$B$2:$K$499,2,FALSE)) -> EZEQUIEL LEAL CHACÓN | L8: =IF(I8=0,0,VLOOKUP(H8,Inscripciones!$B$2:$N$399,3,FALSE)) -> ESPARZA | M8: 11 | N8: 9 | O8: 8 | P8: 11 | Q8: 11 | R8: 5 | AA8: =IF(M8+N8<>0,SUM(AF8:AL8),"") -> 2 | AB8: =IF(M8+N8<>0,SUM(AF9:AL9),"") -> 1 | AC8: =IF(AA8>AB8,AD8&" "&AE8,IF(AB8>AA8,AD8&" "&AE9,"")) -> 2 - 1 (9, -8, 5) | AD8: =IF(AA8>AB8,AA8&" - "&AB8,IF(AB8>AA8,AB8&" - "&AA8,"")) -> 2 - 1 | AE8: =CONCATENATE("(",AM8,AN8,AO8,AP8,AQ8,AR8,AS8,")") -> (9, -8, 5) | AF8: =IF(M8>N8,1,0) -> 1 | AG8: =IF(O8>P8,1,0) -> 0 | AH8: =IF(Q8>R8,1,0) -> 1 | AI8: =IF(S8>T8,1,0) -> 0 | AJ8: =IF(U8>V8,1,0) -> 0 | AK8: =IF(W8>X8,1,0) -> 0 | AL8: =IF(Y8>Z8,1,0) -> 0 | AM8: =IF(M8>N8,N8,IF(N8>M8,-M8,"")) -> 9 | AN8: =IF(O8>P8,", "&P8,IF(P8>O8,", "&-O8,"")) -> , -8 | AO8: =IF(Q8>R8,", "&R8,IF(R8>Q8,", "&-Q8,"")) -> , 5 | AP8: =IF(S8>T8,", "&T8,IF(T8>S8,", "&-S8,"")) | AQ8: =IF(U8>V8,", "&V8,IF(V8>U8,", "&-U8,"")) | AR8: =IF(W8>X8,", "&X8,IF(X8>W8,", "&-W8,"")) | AS8: =IF(Y8>Z8,", "&Z8,IF(Z8>Y8,", "&-Y8,"")) | AU8: =1+AU6 -> 3 | AV8: =VLOOKUP(AV9,$A$4:$L$35,7,FALSE) -> 4250 | AW8: =IF(AV8=0,0,VLOOKUP(AV8,Inscripciones!$B$2:$K$499,2,FALSE)) -> KEVIN HERNÁNDEZ LÁSCAREZ | AX8: =IF(AV8=0,0,VLOOKUP(AV8,Inscripciones!$B$2:$N$399,3,FALSE)) -> CCDR SAN JOSÉ | BL8: =1+BL7 -> 4 | BM8: =C10 -> 5-Jun | BN8: =D10 -> 9:00 | BO8: =E10 -> 4 | BP8: JBS | BR8: 4 | BS8: =VLOOKUP(#REF!,Inscripciones!$B$2:$B$399,2,FALSE) -> #REF! | BU8: =VLOOKUP(#REF!,Inscripciones!$B$2:$B$399,2,FALSE) -> #REF! | BY8: =G10 -> 4834 | BZ8: =H10 -> 4149 | CA8: =Inscripciones!$B$2 -> U9 MASCULINO | CB8: Cuartos
I9: 0 | J9: 0 | K9: 0 | L9: 0 | AD9: =IF(AA8>AB8,AD8&" "&AE8,IF(AB8>AA8,AD8&" "&AE9,"")) -> 2 - 1 (9, -8, 5) | AE9: =CONCATENATE("(",AM9,AN9,AO9,AP9,AQ9,AR9,AS9,")") -> (-9, 8, -5) | AF9: =IF(N8>M8,1,0) -> 0 | AG9: =IF(P8>O8,1,0) -> 1 | AH9: =IF(R8>Q8,1,0) -> 0 | AI9: =IF(T8>S8,1,0) -> 0 | AJ9: =IF(V8>U8,1,0) -> 0 | AK9: =IF(X8>W8,1,0) -> 0 | AL9: =IF(Z8>Y8,1,0) -> 0 | AM9: =IF(N8>M8,M8,IF(M8>N8,-N8,"")) -> -9 | AN9: =IF(P8>O8,", "&O8,IF(O8>P8,", "&-P8,"")) -> , 8 | AO9: =IF(R8>Q8,", "&Q8,IF(Q8>R8,", "&-R8,"")) -> , -5 | AP9: =IF(T8>S8,", "&S8,IF(S8>T8,", "&-T8,"")) | AQ9: =IF(V8>U8,", "&U8,IF(U8>V8,", "&-V8,"")) | AR9: =IF(X8>W8,", "&W8,IF(W8>X8,", "&-X8,"")) | AS9: =IF(Z8>Y8,", "&Y8,IF(Y8>Z8,", "&-Z8,"")) | AV9: 2 | AW9: =VLOOKUP(AV9,$A$4:$L$35,6,FALSE) -> 5-Jun-9:00- Table2 | AY9: =VLOOKUP(AY7,$A$4:$L$39,8,FALSE) -> 4391 | AZ9: =IF(AY9=0,0,VLOOKUP(AY9,Inscripciones!$B$2:$K$499,2,FALSE)) -> EMANUEL UMAÑA RODRIGUEZ | BA9: =IF(AY9=0,0,VLOOKUP(AY9,Inscripciones!$B$2:$N$399,3,FALSE)) -> CURRIDABAT | BF9: CAMPEON: | BL9: =1+BL8 -> 5 | BM9: =C12 -> 5-Jun | BN9: =D12 -> 10:30 | BO9: =E12 -> 1 | BP9: JBS | BR9: 33 | BS9: =VLOOKUP(BY10,Inscripciones!$B$2:$B$399,2,FALSE) -> #REF! | BU9: =VLOOKUP(BZ10,Inscripciones!$B$2:$B$399,2,FALSE) -> #REF! | BY9: =G12 -> 4295 | BZ9: =H12 -> 4391 | CA9: =Inscripciones!$B$2 -> U9 MASCULINO | CB9: Semifinal
A10: 4 | B10: QF | C10: 5-Jun | D10: 9:00 | E10: 4 | F10: =C10&"-"&D10&"- Table"&E10 -> 5-Jun-9:00- Table4 | G10: ='SORTEO 8'!D15 -> 4834 | H10: ='SORTEO 8'!D16 -> 4149 | I10: =IF(G10=0,0,VLOOKUP(G10,Inscripciones!$B$2:$K$499,2,FALSE)) -> PEDRO RIMOLO VILLAGRA | J10: =IF(G10=0,0,VLOOKUP(G10,Inscripciones!$B$2:$N$399,3,FALSE)) -> CURRIDABAT | K10: =IF(I10=0,0,VLOOKUP(H10,Inscripciones!$B$2:$K$499,2,FALSE)) -> LUIS MANUEL GARCÍA ARAYA | L10: =IF(I10=0,0,VLOOKUP(H10,Inscripciones!$B$2:$N$399,3,FALSE)) -> ESPARZA | M10: 2 | N10: 11 | O10: 11 | P10: 13 | AA10: =IF(M10+N10<>0,SUM(AF10:AL10),"") -> 0 | AB10: =IF(M10+N10<>0,SUM(AF11:AL11),"") -> 2 | AC10: =IF(AA10>AB10,AD10&" "&AE10,IF(AB10>AA10,AD10&" "&AE11,"")) -> 2 - 0 (2, 11) | AD10: =IF(AA10>AB10,AA10&" - "&AB10,IF(AB10>AA10,AB10&" - "&AA10,"")) -> 2 - 0 | AE10: =CONCATENATE("(",AM10,AN10,AO10,AP10,AQ10,AR10,AS10,")") -> (-2, -11) | AF10: =IF(M10>N10,1,0) -> 0 | AG10: =IF(O10>P10,1,0) -> 0 | AH10: =IF(Q10>R10,1,0) -> 0 | AI10: =IF(S10>T10,1,0) -> 0 | AJ10: =IF(U10>V10,1,0) -> 0 | AK10: =IF(W10>X10,1,0) -> 0 | AL10: =IF(Y10>Z10,1,0) -> 0 | AM10: =IF(M10>N10,N10,IF(N10>M10,-M10,"")) -> -2 | AN10: =IF(O10>P10,", "&P10,IF(P10>O10,", "&-O10,"")) -> , -11 | AO10: =IF(Q10>R10,", "&R10,IF(R10>Q10,", "&-Q10,"")) | AP10: =IF(S10>T10,", "&T10,IF(T10>S10,", "&-S10,"")) | AQ10: =IF(U10>V10,", "&V10,IF(V10>U10,", "&-U10,"")) | AR10: =IF(W10>X10,", "&X10,IF(X10>W10,", "&-W10,"")) | AS10: =IF(Y10>Z10,", "&Z10,IF(Z10>Y10,", "&-Y10,"")) | AU10: =1+AU8 -> 4 | AV10: =VLOOKUP(AV9,$A$4:$L$35,8,FALSE) -> 4391 | AW10: =IF(AV10=0,0,VLOOKUP(AV10,Inscripciones!$B$2:$K$499,2,FALSE)) -> EMANUEL UMAÑA RODRIGUEZ | AX10: =IF(AV10=0,0,VLOOKUP(AV10,Inscripciones!$B$2:$N$399,3,FALSE)) -> CURRIDABAT | AZ10: =VLOOKUP(AV9,$A$4:$AD$39,29,FALSE) -> 2 - 0 (4, 8) | BF10: =VLOOKUP(BB11,$A$4:$AD$35,29,FALSE) -> 3 - 0 (6, 7, 9) | BL10: =1+BL9 -> 6 | BM10: =C14 -> 5-Jun | BN10: =D14 -> 10:30 | BO10: =E14 -> 2 | BP10: JBS | BR10: 34 | BS10: =VLOOKUP(#REF!,Inscripciones!$B$2:$B$399,2,FALSE) -> #REF! | BU10: =VLOOKUP(#REF!,Inscripciones!$B$2:$B$399,2,FALSE) -> #REF! | BY10: =G14 -> 4520 | BZ10: =H14 -> 4149 | CA10: =Inscripciones!$B$2 -> U9 MASCULINO | CB10: Semifinal
I11: 0 | J11: 0 | K11: 0 | L11: 0 | AD11: =IF(AA10>AB10,AD10&" "&AE10,IF(AB10>AA10,AD10&" "&AE11,"")) -> 2 - 0 (2, 11) | AE11: =CONCATENATE("(",AM11,AN11,AO11,AP11,AQ11,AR11,AS11,")") -> (2, 11) | AF11: =IF(N10>M10,1,0) -> 1 | AG11: =IF(P10>O10,1,0) -> 1 | AH11: =IF(R10>Q10,1,0) -> 0 | AI11: =IF(T10>S10,1,0) -> 0 | AJ11: =IF(V10>U10,1,0) -> 0 | AK11: =IF(X10>W10,1,0) -> 0 | AL11: =IF(Z10>Y10,1,0) -> 0 | AM11: =IF(N10>M10,M10,IF(M10>N10,-N10,"")) -> 2 | AN11: =IF(P10>O10,", "&O10,IF(O10>P10,", "&-P10,"")) -> , 11 | AO11: =IF(R10>Q10,", "&Q10,IF(Q10>R10,", "&-R10,"")) | AP11: =IF(T10>S10,", "&S10,IF(S10>T10,", "&-T10,"")) | AQ11: =IF(V10>U10,", "&U10,IF(U10>V10,", "&-V10,"")) | AR11: =IF(X10>W10,", "&W10,IF(W10>X10,", "&-X10,"")) | AS11: =IF(Z10>Y10,", "&Y10,IF(Y10>Z10,", "&-Z10,"")) | BB11: 8 | BC11: =VLOOKUP(BB11,$A$4:$L$35,6,FALSE) -> 5-Jun-17:00- Table1 | BE11: =G22 -> 4295 | BF11: =IF(BE11=0,0,VLOOKUP(BE11,Inscripciones!$B$2:$K$499,2,FALSE)) -> RICARDO MATEO CHAVES LEÓN | BG11: =IF(BE11=0,0,VLOOKUP(BE11,Inscripciones!$B$2:$N$399,3,FALSE)) -> ESPARZA | BL11: =1+BL10 -> 7 | BM11: =C16 -> 5-Jun | BN11: =D16 -> 16:00 | BO11: =E16 -> 1 | BP11: JBS | BR11: 63 | BS11: =VLOOKUP(BY12,Inscripciones!$B$2:$B$399,2,FALSE) -> #REF! | BU11: =VLOOKUP(BZ12,Inscripciones!$B$2:$B$399,2,FALSE) -> #REF! | BY11: =G16 -> 4391 | BZ11: =H16 -> 4149 | CA11: =Inscripciones!$B$2 -> U9 MASCULINO | CB11: 3 y 4 puesto
A12: 5 | B12: SF | C12: 5-Jun | D12: 10:30 | E12: 1 | F12: =C12&"-"&D12&"- Table"&E12 -> 5-Jun-10:30- Table1 | G12: =IF(M4="",0,IF(AA4>AB4,G4,H4)) -> 4295 | H12: =IF(M6="",0,IF(AA6>AB6,G6,H6)) -> 4391 | I12: =IF(G12=0,0,VLOOKUP(G12,Inscripciones!$B$2:$K$499,2,FALSE)) -> RICARDO MATEO CHAVES LEÓN | J12: =IF(G12=0,0,VLOOKUP(G12,Inscripciones!$B$2:$N$399,3,FALSE)) -> ESPARZA | K12: =IF(I12=0,0,VLOOKUP(H12,Inscripciones!$B$2:$K$499,2,FALSE)) -> EMANUEL UMAÑA RODRIGUEZ | L12: =IF(I12=0,0,VLOOKUP(H12,Inscripciones!$B$2:$N$399,3,FALSE)) -> CURRIDABAT | M12: 11 | N12: 7 | O12: 11 | P12: 6 | Q12: 10 | R12: 12 | S12: 11 | T12: 6 | AA12: =IF(M12+N12<>0,SUM(AF12:AL12),"") -> 3 | AB12: =IF(M12+N12<>0,SUM(AF13:AL13),"") -> 1 | AC12: =IF(AA12>AB12,AD12&" "&AE12,IF(AB12>AA12,AD12&" "&AE13,"")) -> 3 - 1 (7, 6, -10, 6) | AD12: =IF(AA12>AB12,AA12&" - "&AB12,IF(AB12>AA12,AB12&" - "&AA12,"")) -> 3 - 1 | AE12: =CONCATENATE("(",AM12,AN12,AO12,AP12,AQ12,AR12,AS12,")") -> (7, 6, -10, 6) | AF12: =IF(M12>N12,1,0) -> 1 | AG12: =IF(O12>P12,1,0) -> 1 | AH12: =IF(Q12>R12,1,0) -> 0 | AI12: =IF(S12>T12,1,0) -> 1 | AJ12: =IF(U12>V12,1,0) -> 0 | AK12: =IF(W12>X12,1,0) -> 0 | AL12: =IF(Y12>Z12,1,0) -> 0 | AM12: =IF(M12>N12,N12,IF(N12>M12,-M12,"")) -> 7 | AN12: =IF(O12>P12,", "&P12,IF(P12>O12,", "&-O12,"")) -> , 6 | AO12: =IF(Q12>R12,", "&R12,IF(R12>Q12,", "&-Q12,"")) -> , -10 | AP12: =IF(S12>T12,", "&T12,IF(T12>S12,", "&-S12,"")) -> , 6 | AQ12: =IF(U12>V12,", "&V12,IF(V12>U12,", "&-U12,"")) | AR12: =IF(W12>X12,", "&X12,IF(X12>W12,", "&-W12,"")) | AS12: =IF(Y12>Z12,", "&Z12,IF(Z12>Y12,", "&-Y12,"")) | AU12: =1+AU10 -> 5 | AV12: =VLOOKUP(AV13,$A$4:$L$35,7,FALSE) -> 4520 | AW12: =IF(AV12=0,0,VLOOKUP(AV12,Inscripciones!$B$2:$K$499,2,FALSE)) -> GAEL SOLÍS VÁSQUEZ | AX12: =IF(AV12=0,0,VLOOKUP(AV12,Inscripciones!$B$2:$N$399,3,FALSE)) -> ESPARZA | AZ12: =VLOOKUP(AV13,$A$4:$AD$35,29,FALSE) -> 2 - 1 (9, -8, 5) | BL12: =1+BL11 -> 8 | BM12: =C18 -> 5-Jun | BN12: =D18 -> 17:00 | BO12: =E18 -> 1 | BP12: JBS | BR12: 64 | BS12: =VLOOKUP(#REF!,Inscripciones!$B$2:$B$399,2,FALSE) -> #REF! | BU12: =VLOOKUP(#REF!,Inscripciones!$B$2:$B$399,2,FALSE) -> #REF! | BY12: =G18 -> 4295 | BZ12: =H18 -> 4520 | CA12: =Inscripciones!$B$2 -> U9 MASCULINO | CB12: FINAL
G13: - | H13: - | K13: 0 | L13: 0 | AD13: =IF(AA12>AB12,AD12&" "&AE12,IF(AB12>AA12,AD12&" "&AE13,"")) -> 3 - 1 (7, 6, -10, 6) | AE13: =CONCATENATE("(",AM13,AN13,AO13,AP13,AQ13,AR13,AS13,")") -> (-7, -6, 10, -6) | AF13: =IF(N12>M12,1,0) -> 0 | AG13: =IF(P12>O12,1,0) -> 0 | AH13: =IF(R12>Q12,1,0) -> 1 | AI13: =IF(T12>S12,1,0) -> 0 | AJ13: =IF(V12>U12,1,0) -> 0 | AK13: =IF(X12>W12,1,0) -> 0 | AL13: =IF(Z12>Y12,1,0) -> 0 | AM13: =IF(N12>M12,M12,IF(M12>N12,-N12,"")) -> -7 | AN13: =IF(P12>O12,", "&O12,IF(O12>P12,", "&-P12,"")) -> , -6 | AO13: =IF(R12>Q12,", "&Q12,IF(Q12>R12,", "&-R12,"")) -> , 10 | AP13: =IF(T12>S12,", "&S12,IF(S12>T12,", "&-T12,"")) -> , -6 | AQ13: =IF(V12>U12,", "&U12,IF(U12>V12,", "&-V12,"")) | AR13: =IF(X12>W12,", "&W12,IF(W12>X12,", "&-X12,"")) | AS13: =IF(Z12>Y12,", "&Y12,IF(Y12>Z12,", "&-Z12,"")) | AV13: 3 | AW13: =VLOOKUP(AV13,$A$4:$L$35,6,FALSE) -> 5-Jun-9:00- Table3 | AY13: =VLOOKUP(AY15,$A$4:$L$39,7,FALSE) -> 4520 | AZ13: =IF(AY13=0,0,VLOOKUP(AY13,Inscripciones!$B$2:$K$499,2,FALSE)) -> GAEL SOLÍS VÁSQUEZ | BA13: =IF(AY13=0,0,VLOOKUP(AY13,Inscripciones!$B$2:$N$399,3,FALSE)) -> ESPARZA
