Workbook
Name a: #REF!
Name acdb: #REF!
Name acdb: #REF!
Name acdb: #REF!
Name ACDB1: #REF!
Name acdf: #REF!
Name acdf: #REF!
Name acdf: #REF!
Name acdh: #REF!
Name acdo: #REF!
Name acdo: #REF!
Name acdo: #REF!
Name aceq: #REF!
Name aceq: [1]AE!$A:$IV
Name aceq: #REF!
Name acif: #REF!
Name acif: #REF!
Name acif: #REF!
Name acin: #REF!
Name acin: #REF!
Name acin: #REF!
Name ACIN1: #REF!
Name acti: #REF!
Name acti: #REF!
Name acti: #REF!
Name avc: #REF!
Name avc: [2]DORSAL!$A$2:$G$120
Name avc: #REF!
Name datos: #REF!
Name datos: [3]Datos!$A$2:$G$140
Name datos: #REF!
Name dorsal: #REF!
Name dorsal: [2]DORSAL!$A$2:$G$120
Name dorsal: #REF!
Name EQ: #REF!
Name EQ: [4]EQU!$A:$IV
Name EQ: #REF!
Name IN: #REF!
Name IN: [4]IND!$A:$IV
Name IN: #REF!
Name IND: #REF!
Name IND: [5]IN!$A$3:$IV$102
Name IND: #REF!
Name IPC_Member: #REF!
Name IPC_Member: #REF!
Name IPC_Member: #REF!
Name JBS: #REF!
Name JBS: #REF!
Name JBS: #REF!
Name JBS: [6]JB!$A$1:$E$100
Name JBS: #REF!
Name JGS: #REF!
Name JGS: #REF!
Name JGS: #REF!
Name JUG: #REF!
Name JUG: [7]Jug!$A$2:$D$13
Name JUG: #REF!
Name PC: #REF!
Name PC: #REF!
Name PC: #REF!

Sheet Tabulación
C1: Ganadores | F1: Perdedores | K1: 14 | L1: {=VLOOKUP(INDIRECT("'Grupo " & K1 & "'!J18"),INDIRECT("'Grupo " & K1 & "'!B12"):INDIRECT("'Grupo " & K1 & "'!J15"),2,FALSE)} -> 4151 | M1: {=VLOOKUP(IF(INDIRECT("'Grupo " & K1 & "'!J18")=INDIRECT("'Grupo " & K1 & "'!C18"),INDIRECT("'Grupo " & K1 & "'!C19"),INDIRECT("'Grupo " & K1 & "'!C18")),INDIRECT("'Grupo " & K1 & "'!B12"):INDIRECT("'Grupo " & K1 & "'!G15"),2,FALSE)} -> 4027 | O1: {=VLOOKUP(IF(INDIRECT("'Grupo " & K1 & "'!J18")=INDIRECT("'Grupo " & K1 & "'!C18"),INDIRECT("'Grupo " & K1 & "'!C19"),INDIRECT("'Grupo " & K1 & "'!C18")),INDIRECT("'Grupo " & K1 & "'!B12"):INDIRECT("'Grupo " & K1 & "'!G15"),2,FALSE)} -> 4027 | P1: {=VLOOKUP(INDIRECT("'Grupo " & K1 & "'!J18"),INDIRECT("'Grupo " & K1 & "'!B12"):INDIRECT("'Grupo " & K1 & "'!J15"),2,FALSE)} -> 4151
B2: 1 | C2: {=VLOOKUP(INDIRECT("'Grupo " & B2 & "'!J18"),INDIRECT("'Grupo " & B2 & "'!B12"):INDIRECT("'Grupo " & B2 & "'!J15"),2,FALSE)} -> 3790 | D2: {=VLOOKUP(IF(INDIRECT("'Grupo " & B2 & "'!J18")=INDIRECT("'Grupo " & B2 & "'!C18"),INDIRECT("'Grupo " & B2 & "'!C19"),INDIRECT("'Grupo " & B2 & "'!C18")),INDIRECT("'Grupo " & B2 & "'!B12"):INDIRECT("'Grupo " & B2 & "'!G15"),2,FALSE)} -> 4606 | F2: {=VLOOKUP(IF(INDIRECT("'Grupo " & B2 & "'!J18")=INDIRECT("'Grupo " & B2 & "'!C18"),INDIRECT("'Grupo " & B2 & "'!C19"),INDIRECT("'Grupo " & B2 & "'!C18")),INDIRECT("'Grupo " & B2 & "'!B12"):INDIRECT("'Grupo " & B2 & "'!G15"),2,FALSE)} -> 4606 | G2: {=VLOOKUP(INDIRECT("'Grupo " & B2 & "'!J18"),INDIRECT("'Grupo " & B2 & "'!B12"):INDIRECT("'Grupo " & B2 & "'!J15"),2,FALSE)} -> 3790 | L2: {=VLOOKUP(INDIRECT("'Grupo " & K1 & "'!J20"),INDIRECT("'Grupo " & K1 & "'!B12"):INDIRECT("'Grupo " & K1 & "'!J15"),2,FALSE)} -> 4151 | M2: {=VLOOKUP(IF(INDIRECT("'Grupo " & K1 & "'!J20")=INDIRECT("'Grupo " & K1 & "'!C20"),INDIRECT("'Grupo " & K1 & "'!C21"),INDIRECT("'Grupo " & K1 & "'!C20")),INDIRECT("'Grupo " & K1 & "'!B12"):INDIRECT("'Grupo " & K1 & "'!G15"),2,FALSE)} -> 4459 | O2: {=VLOOKUP(IF(INDIRECT("'Grupo " & K1 & "'!J20")=INDIRECT("'Grupo " & K1 & "'!C20"),INDIRECT("'Grupo " & K1 & "'!C21"),INDIRECT("'Grupo " & K1 & "'!C20")),INDIRECT("'Grupo " & K1 & "'!B12"):INDIRECT("'Grupo " & K1 & "'!G15"),2,FALSE)} -> 4459 | P2: {=VLOOKUP(INDIRECT("'Grupo " & K1 & "'!J20"),INDIRECT("'Grupo " & K1 & "'!B12"):INDIRECT("'Grupo " & K1 & "'!J15"),2,FALSE)} -> 4151
C3: {=VLOOKUP(INDIRECT("'Grupo " & B2 & "'!J20"),INDIRECT("'Grupo " & B2 & "'!B12"):INDIRECT("'Grupo " & B2 & "'!J15"),2,FALSE)} -> 3790 | D3: {=VLOOKUP(IF(INDIRECT("'Grupo " & B2 & "'!J20")=INDIRECT("'Grupo " & B2 & "'!C20"),INDIRECT("'Grupo " & B2 & "'!C21"),INDIRECT("'Grupo " & B2 & "'!C20")),INDIRECT("'Grupo " & B2 & "'!B12"):INDIRECT("'Grupo " & B2 & "'!G15"),2,FALSE)} -> 4050 | F3: {=VLOOKUP(IF(INDIRECT("'Grupo " & B2 & "'!J20")=INDIRECT("'Grupo " & B2 & "'!C20"),INDIRECT("'Grupo " & B2 & "'!C21"),INDIRECT("'Grupo " & B2 & "'!C20")),INDIRECT("'Grupo " & B2 & "'!B12"):INDIRECT("'Grupo " & B2 & "'!G15"),2,FALSE)} -> 4050 | G3: {=VLOOKUP(INDIRECT("'Grupo " & B2 & "'!J20"),INDIRECT("'Grupo " & B2 & "'!B12"):INDIRECT("'Grupo " & B2 & "'!J15"),2,FALSE)} -> 3790 | L3: {=VLOOKUP(INDIRECT("'Grupo " & K1 & "'!J22"),INDIRECT("'Grupo " & K1 & "'!B12"):INDIRECT("'Grupo " & K1 & "'!J15"),2,FALSE)} -> 4459 | M3: {=VLOOKUP(IF(INDIRECT("'Grupo " & K1 & "'!J22")=INDIRECT("'Grupo " & K1 & "'!C22"),INDIRECT("'Grupo " & K1 & "'!C23"),INDIRECT("'Grupo " & K1 & "'!C22")),INDIRECT("'Grupo " & K1 & "'!B12"):INDIRECT("'Grupo " & K1 & "'!G15"),2,FALSE)} -> 4027 | O3: {=VLOOKUP(IF(INDIRECT("'Grupo " & K1 & "'!J22")=INDIRECT("'Grupo " & K1 & "'!C22"),INDIRECT("'Grupo " & K1 & "'!C23"),INDIRECT("'Grupo " & K1 & "'!C22")),INDIRECT("'Grupo " & K1 & "'!B12"):INDIRECT("'Grupo " & K1 & "'!G15"),2,FALSE)} -> 4027 | P3: {=VLOOKUP(INDIRECT("'Grupo " & K1 & "'!J22"),INDIRECT("'Grupo " & K1 & "'!B12"):INDIRECT("'Grupo " & K1 & "'!J15"),2,FALSE)} -> 4459
C4: {=VLOOKUP(INDIRECT("'Grupo " & B2 & "'!J22"),INDIRECT("'Grupo " & B2 & "'!B12"):INDIRECT("'Grupo " & B2 & "'!J15"),2,FALSE)} -> 4606 | D4: {=VLOOKUP(IF(INDIRECT("'Grupo " & B2 & "'!J22")=INDIRECT("'Grupo " & B2 & "'!C22"),INDIRECT("'Grupo " & B2 & "'!C23"),INDIRECT("'Grupo " & B2 & "'!C22")),INDIRECT("'Grupo " & B2 & "'!B12"):INDIRECT("'Grupo " & B2 & "'!G15"),2,FALSE)} -> 4050 | F4: {=VLOOKUP(IF(INDIRECT("'Grupo " & B2 & "'!J22")=INDIRECT("'Grupo " & B2 & "'!C22"),INDIRECT("'Grupo " & B2 & "'!C23"),INDIRECT("'Grupo " & B2 & "'!C22")),INDIRECT("'Grupo " & B2 & "'!B12"):INDIRECT("'Grupo " & B2 & "'!G15"),2,FALSE)} -> 4050 | G4: {=VLOOKUP(INDIRECT("'Grupo " & B2 & "'!J22"),INDIRECT("'Grupo " & B2 & "'!B12"):INDIRECT("'Grupo " & B2 & "'!J15"),2,FALSE)} -> 4606 | L4: {=VLOOKUP(INDIRECT("'Grupo " & K1 & "'!J24"),INDIRECT("'Grupo " & K1 & "'!B12"):INDIRECT("'Grupo " & K1 & "'!J15"),2,FALSE)} -> #N/A | M4: {=VLOOKUP(IF(INDIRECT("'Grupo " & K1 & "'!J24")=INDIRECT("'Grupo " & K1 & "'!C24"),INDIRECT("'Grupo " & K1 & "'!C25"),INDIRECT("'Grupo " & K1 & "'!C24")),INDIRECT("'Grupo " & K1 & "'!B12"):INDIRECT("'Grupo " & K1 & "'!G15"),2,FALSE)} -> #N/A | O4: {=VLOOKUP(IF(INDIRECT("'Grupo " & K1 & "'!J24")=INDIRECT("'Grupo " & K1 & "'!C24"),INDIRECT("'Grupo " & K1 & "'!C25"),INDIRECT("'Grupo " & K1 & "'!C24")),INDIRECT("'Grupo " & K1 & "'!B12"):INDIRECT("'Grupo " & K1 & "'!G15"),2,FALSE)} -> #N/A | P4: {=VLOOKUP(INDIRECT("'Grupo " & K1 & "'!J24"),INDIRECT("'Grupo " & K1 & "'!B12"):INDIRECT("'Grupo " & K1 & "'!J15"),2,FALSE)} -> #N/A
B5: =B2+1 -> 2 | C5: {=VLOOKUP(INDIRECT("'Grupo " & B5 & "'!J18"),INDIRECT("'Grupo " & B5 & "'!B12"):INDIRECT("'Grupo " & B5 & "'!J15"),2,FALSE)} -> 4025 | D5: {=VLOOKUP(IF(INDIRECT("'Grupo " & B5 & "'!J18")=INDIRECT("'Grupo " & B5 & "'!C18"),INDIRECT("'Grupo " & B5 & "'!C19"),INDIRECT("'Grupo " & B5 & "'!C18")),INDIRECT("'Grupo " & B5 & "'!B12"):INDIRECT("'Grupo " & B5 & "'!G15"),2,FALSE)} -> 4825 | F5: {=VLOOKUP(IF(INDIRECT("'Grupo " & B5 & "'!J18")=INDIRECT("'Grupo " & B5 & "'!C18"),INDIRECT("'Grupo " & B5 & "'!C19"),INDIRECT("'Grupo " & B5 & "'!C18")),INDIRECT("'Grupo " & B5 & "'!B12"):INDIRECT("'Grupo " & B5 & "'!G15"),2,FALSE)} -> 4825 | G5: {=VLOOKUP(INDIRECT("'Grupo " & B5 & "'!J18"),INDIRECT("'Grupo " & B5 & "'!B12"):INDIRECT("'Grupo " & B5 & "'!J15"),2,FALSE)} -> 4025 | L5: {=VLOOKUP(INDIRECT("'Grupo " & K1 & "'!J26"),INDIRECT("'Grupo " & K1 & "'!B12"):INDIRECT("'Grupo " & K1 & "'!J15"),2,FALSE)} -> #N/A | M5: {=VLOOKUP(IF(INDIRECT("'Grupo " & K1 & "'!J26")=INDIRECT("'Grupo " & K1 & "'!C26"),INDIRECT("'Grupo " & K1 & "'!C27"),INDIRECT("'Grupo " & K1 & "'!C26")),INDIRECT("'Grupo " & K1 & "'!B12"):INDIRECT("'Grupo " & K1 & "'!G15"),2,FALSE)} -> #N/A | O5: {=VLOOKUP(IF(INDIRECT("'Grupo " & K1 & "'!J26")=INDIRECT("'Grupo " & K1 & "'!C26"),INDIRECT("'Grupo " & K1 & "'!C27"),INDIRECT("'Grupo " & K1 & "'!C26")),INDIRECT("'Grupo " & K1 & "'!B12"):INDIRECT("'Grupo " & K1 & "'!G15"),2,FALSE)} -> #N/A | P5: {=VLOOKUP(INDIRECT("'Grupo " & K1 & "'!J26"),INDIRECT("'Grupo " & K1 & "'!B12"):INDIRECT("'Grupo " & K1 & "'!J15"),2,FALSE)} -> #N/A
C6: {=VLOOKUP(INDIRECT("'Grupo " & B5 & "'!J20"),INDIRECT("'Grupo " & B5 & "'!B12"):INDIRECT("'Grupo " & B5 & "'!J15"),2,FALSE)} -> 4025 | D6: {=VLOOKUP(IF(INDIRECT("'Grupo " & B5 & "'!J20")=INDIRECT("'Grupo " & B5 & "'!C20"),INDIRECT("'Grupo " & B5 & "'!C21"),INDIRECT("'Grupo " & B5 & "'!C20")),INDIRECT("'Grupo " & B5 & "'!B12"):INDIRECT("'Grupo " & B5 & "'!G15"),2,FALSE)} -> 4778 | F6: {=VLOOKUP(IF(INDIRECT("'Grupo " & B5 & "'!J20")=INDIRECT("'Grupo " & B5 & "'!C20"),INDIRECT("'Grupo " & B5 & "'!C21"),INDIRECT("'Grupo " & B5 & "'!C20")),INDIRECT("'Grupo " & B5 & "'!B12"):INDIRECT("'Grupo " & B5 & "'!G15"),2,FALSE)} -> 4778 | G6: {=VLOOKUP(INDIRECT("'Grupo " & B5 & "'!J20"),INDIRECT("'Grupo " & B5 & "'!B12"):INDIRECT("'Grupo " & B5 & "'!J15"),2,FALSE)} -> 4025 | L6: {=VLOOKUP(INDIRECT("'Grupo " & K1 & "'!J28"),INDIRECT("'Grupo " & K1 & "'!B12"):INDIRECT("'Grupo " & K1 & "'!J15"),2,FALSE)} -> #N/A | M6: {=VLOOKUP(IF(INDIRECT("'Grupo " & K1 & "'!J28")=INDIRECT("'Grupo " & K1 & "'!C28"),INDIRECT("'Grupo " & K1 & "'!C29"),INDIRECT("'Grupo " & K1 & "'!C28")),INDIRECT("'Grupo " & K1 & "'!B12"):INDIRECT("'Grupo " & K1 & "'!G15"),2,FALSE)} -> #N/A | O6: {=VLOOKUP(IF(INDIRECT("'Grupo " & K1 & "'!J28")=INDIRECT("'Grupo " & K1 & "'!C28"),INDIRECT("'Grupo " & K1 & "'!C29"),INDIRECT("'Grupo " & K1 & "'!C28")),INDIRECT("'Grupo " & K1 & "'!B12"):INDIRECT("'Grupo " & K1 & "'!G15"),2,FALSE)} -> #N/A | P6: {=VLOOKUP(INDIRECT("'Grupo " & K1 & "'!J28"),INDIRECT("'Grupo " & K1 & "'!B12"):INDIRECT("'Grupo " & K1 & "'!J15"),2,FALSE)} -> #N/A
C7: {=VLOOKUP(INDIRECT("'Grupo " & B5 & "'!J22"),INDIRECT("'Grupo " & B5 & "'!B12"):INDIRECT("'Grupo " & B5 & "'!J15"),2,FALSE)} -> 4825 | D7: {=VLOOKUP(IF(INDIRECT("'Grupo " & B5 & "'!J22")=INDIRECT("'Grupo " & B5 & "'!C22"),INDIRECT("'Grupo " & B5 & "'!C23"),INDIRECT("'Grupo " & B5 & "'!C22")),INDIRECT("'Grupo " & B5 & "'!B12"):INDIRECT("'Grupo " & B5 & "'!G15"),2,FALSE)} -> 4778 | F7: {=VLOOKUP(IF(INDIRECT("'Grupo " & B5 & "'!J22")=INDIRECT("'Grupo " & B5 & "'!C22"),INDIRECT("'Grupo " & B5 & "'!C23"),INDIRECT("'Grupo " & B5 & "'!C22")),INDIRECT("'Grupo " & B5 & "'!B12"):INDIRECT("'Grupo " & B5 & "'!G15"),2,FALSE)} -> 4778 | G7: {=VLOOKUP(INDIRECT("'Grupo " & B5 & "'!J22"),INDIRECT("'Grupo " & B5 & "'!B12"):INDIRECT("'Grupo " & B5 & "'!J15"),2,FALSE)} -> 4825
B8: =B5+1 -> 3 | C8: {=VLOOKUP(INDIRECT("'Grupo " & B8 & "'!J18"),INDIRECT("'Grupo " & B8 & "'!B12"):INDIRECT("'Grupo " & B8 & "'!J15"),2,FALSE)} -> 3787 | D8: {=VLOOKUP(IF(INDIRECT("'Grupo " & B8 & "'!J18")=INDIRECT("'Grupo " & B8 & "'!C18"),INDIRECT("'Grupo " & B8 & "'!C19"),INDIRECT("'Grupo " & B8 & "'!C18")),INDIRECT("'Grupo " & B8 & "'!B12"):INDIRECT("'Grupo " & B8 & "'!G15"),2,FALSE)} -> 4740 | F8: {=VLOOKUP(IF(INDIRECT("'Grupo " & B8 & "'!J18")=INDIRECT("'Grupo " & B8 & "'!C18"),INDIRECT("'Grupo " & B8 & "'!C19"),INDIRECT("'Grupo " & B8 & "'!C18")),INDIRECT("'Grupo " & B8 & "'!B12"):INDIRECT("'Grupo " & B8 & "'!G15"),2,FALSE)} -> 4740 | G8: {=VLOOKUP(INDIRECT("'Grupo " & B8 & "'!J18"),INDIRECT("'Grupo " & B8 & "'!B12"):INDIRECT("'Grupo " & B8 & "'!J15"),2,FALSE)} -> 3787
C9: {=VLOOKUP(INDIRECT("'Grupo " & B8 & "'!J20"),INDIRECT("'Grupo " & B8 & "'!B12"):INDIRECT("'Grupo " & B8 & "'!J15"),2,FALSE)} -> 3787 | D9: {=VLOOKUP(IF(INDIRECT("'Grupo " & B8 & "'!J20")=INDIRECT("'Grupo " & B8 & "'!C20"),INDIRECT("'Grupo " & B8 & "'!C21"),INDIRECT("'Grupo " & B8 & "'!C20")),INDIRECT("'Grupo " & B8 & "'!B12"):INDIRECT("'Grupo " & B8 & "'!G15"),2,FALSE)} -> 4465 | F9: {=VLOOKUP(IF(INDIRECT("'Grupo " & B8 & "'!J20")=INDIRECT("'Grupo " & B8 & "'!C20"),INDIRECT("'Grupo " & B8 & "'!C21"),INDIRECT("'Grupo " & B8 & "'!C20")),INDIRECT("'Grupo " & B8 & "'!B12"):INDIRECT("'Grupo " & B8 & "'!G15"),2,FALSE)} -> 4465 | G9: {=VLOOKUP(INDIRECT("'Grupo " & B8 & "'!J20"),INDIRECT("'Grupo " & B8 & "'!B12"):INDIRECT("'Grupo " & B8 & "'!J15"),2,FALSE)} -> 3787
C10: {=VLOOKUP(INDIRECT("'Grupo " & B8 & "'!J22"),INDIRECT("'Grupo " & B8 & "'!B12"):INDIRECT("'Grupo " & B8 & "'!J15"),2,FALSE)} -> 4465 | D10: {=VLOOKUP(IF(INDIRECT("'Grupo " & B8 & "'!J22")=INDIRECT("'Grupo " & B8 & "'!C22"),INDIRECT("'Grupo " & B8 & "'!C23"),INDIRECT("'Grupo " & B8 & "'!C22")),INDIRECT("'Grupo " & B8 & "'!B12"):INDIRECT("'Grupo " & B8 & "'!G15"),2,FALSE)} -> 4740 | F10: {=VLOOKUP(IF(INDIRECT("'Grupo " & B8 & "'!J22")=INDIRECT("'Grupo " & B8 & "'!C22"),INDIRECT("'Grupo " & B8 & "'!C23"),INDIRECT("'Grupo " & B8 & "'!C22")),INDIRECT("'Grupo " & B8 & "'!B12"):INDIRECT("'Grupo " & B8 & "'!G15"),2,FALSE)} -> 4740 | G10: {=VLOOKUP(INDIRECT("'Grupo " & B8 & "'!J22"),INDIRECT("'Grupo " & B8 & "'!B12"):INDIRECT("'Grupo " & B8 & "'!J15"),2,FALSE)} -> 4465
B11: =B8+1 -> 4 | C11: {=VLOOKUP(INDIRECT("'Grupo " & B11 & "'!J18"),INDIRECT("'Grupo " & B11 & "'!B12"):INDIRECT("'Grupo " & B11 & "'!J15"),2,FALSE)} -> 4297 | D11: {=VLOOKUP(IF(INDIRECT("'Grupo " & B11 & "'!J18")=INDIRECT("'Grupo " & B11 & "'!C18"),INDIRECT("'Grupo " & B11 & "'!C19"),INDIRECT("'Grupo " & B11 & "'!C18")),INDIRECT("'Grupo " & B11 & "'!B12"):INDIRECT("'Grupo " & B11 & "'!G15"),2,FALSE)} -> 4726 | F11: {=VLOOKUP(IF(INDIRECT("'Grupo " & B11 & "'!J18")=INDIRECT("'Grupo " & B11 & "'!C18"),INDIRECT("'Grupo " & B11 & "'!C19"),INDIRECT("'Grupo " & B11 & "'!C18")),INDIRECT("'Grupo " & B11 & "'!B12"):INDIRECT("'Grupo " & B11 & "'!G15"),2,FALSE)} -> 4726 | G11: {=VLOOKUP(INDIRECT("'Grupo " & B11 & "'!J18"),INDIRECT("'Grupo " & B11 & "'!B12"):INDIRECT("'Grupo " & B11 & "'!J15"),2,FALSE)} -> 4297
C12: {=VLOOKUP(INDIRECT("'Grupo " & B11 & "'!J20"),INDIRECT("'Grupo " & B11 & "'!B12"):INDIRECT("'Grupo " & B11 & "'!J15"),2,FALSE)} -> 4297 | D12: {=VLOOKUP(IF(INDIRECT("'Grupo " & B11 & "'!J20")=INDIRECT("'Grupo " & B11 & "'!C20"),INDIRECT("'Grupo " & B11 & "'!C21"),INDIRECT("'Grupo " & B11 & "'!C20")),INDIRECT("'Grupo " & B11 & "'!B12"):INDIRECT("'Grupo " & B11 & "'!G15"),2,FALSE)} -> 4706 | F12: {=VLOOKUP(IF(INDIRECT("'Grupo " & B11 & "'!J20")=INDIRECT("'Grupo " & B11 & "'!C20"),INDIRECT("'Grupo " & B11 & "'!C21"),INDIRECT("'Grupo " & B11 & "'!C20")),INDIRECT("'Grupo " & B11 & "'!B12"):INDIRECT("'Grupo " & B11 & "'!G15"),2,FALSE)} -> 4706 | G12: {=VLOOKUP(INDIRECT("'Grupo " & B11 & "'!J20"),INDIRECT("'Grupo " & B11 & "'!B12"):INDIRECT("'Grupo " & B11 & "'!J15"),2,FALSE)} -> 4297
C13: {=VLOOKUP(INDIRECT("'Grupo " & B11 & "'!J22"),INDIRECT("'Grupo " & B11 & "'!B12"):INDIRECT("'Grupo " & B11 & "'!J15"),2,FALSE)} -> 4706 | D13: {=VLOOKUP(IF(INDIRECT("'Grupo " & B11 & "'!J22")=INDIRECT("'Grupo " & B11 & "'!C22"),INDIRECT("'Grupo " & B11 & "'!C23"),INDIRECT("'Grupo " & B11 & "'!C22")),INDIRECT("'Grupo " & B11 & "'!B12"):INDIRECT("'Grupo " & B11 & "'!G15"),2,FALSE)} -> 4726 | F13: {=VLOOKUP(IF(INDIRECT("'Grupo " & B11 & "'!J22")=INDIRECT("'Grupo " & B11 & "'!C22"),INDIRECT("'Grupo " & B11 & "'!C23"),INDIRECT("'Grupo " & B11 & "'!C22")),INDIRECT("'Grupo " & B11 & "'!B12"):INDIRECT("'Grupo " & B11 & "'!G15"),2,FALSE)} -> 4726 | G13: {=VLOOKUP(INDIRECT("'Grupo " & B11 & "'!J22"),INDIRECT("'Grupo " & B11 & "'!B12"):INDIRECT("'Grupo " & B11 & "'!J15"),2,FALSE)} -> 4706
B14: =B11+1 -> 5 | C14: {=VLOOKUP(INDIRECT("'Grupo " & B14 & "'!J18"),INDIRECT("'Grupo " & B14 & "'!B12"):INDIRECT("'Grupo " & B14 & "'!J15"),2,FALSE)} -> 4026 | D14: {=VLOOKUP(IF(INDIRECT("'Grupo " & B14 & "'!J18")=INDIRECT("'Grupo " & B14 & "'!C18"),INDIRECT("'Grupo " & B14 & "'!C19"),INDIRECT("'Grupo " & B14 & "'!C18")),INDIRECT("'Grupo " & B14 & "'!B12"):INDIRECT("'Grupo " & B14 & "'!G15"),2,FALSE)} -> 4547 | F14: {=VLOOKUP(IF(INDIRECT("'Grupo " & B14 & "'!J18")=INDIRECT("'Grupo " & B14 & "'!C18"),INDIRECT("'Grupo " & B14 & "'!C19"),INDIRECT("'Grupo " & B14 & "'!C18")),INDIRECT("'Grupo " & B14 & "'!B12"):INDIRECT("'Grupo " & B14 & "'!G15"),2,FALSE)} -> 4547 | G14: {=VLOOKUP(INDIRECT("'Grupo " & B14 & "'!J18"),INDIRECT("'Grupo " & B14 & "'!B12"):INDIRECT("'Grupo " & B14 & "'!J15"),2,FALSE)} -> 4026
C15: {=VLOOKUP(INDIRECT("'Grupo " & B14 & "'!J20"),INDIRECT("'Grupo " & B14 & "'!B12"):INDIRECT("'Grupo " & B14 & "'!J15"),2,FALSE)} -> 4026 | D15: {=VLOOKUP(IF(INDIRECT("'Grupo " & B14 & "'!J20")=INDIRECT("'Grupo " & B14 & "'!C20"),INDIRECT("'Grupo " & B14 & "'!C21"),INDIRECT("'Grupo " & B14 & "'!C20")),INDIRECT("'Grupo " & B14 & "'!B12"):INDIRECT("'Grupo " & B14 & "'!G15"),2,FALSE)} -> 3987 | F15: {=VLOOKUP(IF(INDIRECT("'Grupo " & B14 & "'!J20")=INDIRECT("'Grupo " & B14 & "'!C20"),INDIRECT("'Grupo " & B14 & "'!C21"),INDIRECT("'Grupo " & B14 & "'!C20")),INDIRECT("'Grupo " & B14 & "'!B12"):INDIRECT("'Grupo " & B14 & "'!G15"),2,FALSE)} -> 3987 | G15: {=VLOOKUP(INDIRECT("'Grupo " & B14 & "'!J20"),INDIRECT("'Grupo " & B14 & "'!B12"):INDIRECT("'Grupo " & B14 & "'!J15"),2,FALSE)} -> 4026
C16: {=VLOOKUP(INDIRECT("'Grupo " & B14 & "'!J22"),INDIRECT("'Grupo " & B14 & "'!B12"):INDIRECT("'Grupo " & B14 & "'!J15"),2,FALSE)} -> 3987 | D16: {=VLOOKUP(IF(INDIRECT("'Grupo " & B14 & "'!J22")=INDIRECT("'Grupo " & B14 & "'!C22"),INDIRECT("'Grupo " & B14 & "'!C23"),INDIRECT("'Grupo " & B14 & "'!C22")),INDIRECT("'Grupo " & B14 & "'!B12"):INDIRECT("'Grupo " & B14 & "'!G15"),2,FALSE)} -> 4547 | F16: {=VLOOKUP(IF(INDIRECT("'Grupo " & B14 & "'!J22")=INDIRECT("'Grupo " & B14 & "'!C22"),INDIRECT("'Grupo " & B14 & "'!C23"),INDIRECT("'Grupo " & B14 & "'!C22")),INDIRECT("'Grupo " & B14 & "'!B12"):INDIRECT("'Grupo " & B14 & "'!G15"),2,FALSE)} -> 4547 | G16: {=VLOOKUP(INDIRECT("'Grupo " & B14 & "'!J22"),INDIRECT("'Grupo " & B14 & "'!B12"):INDIRECT("'Grupo " & B14 & "'!J15"),2,FALSE)} -> 3987
B17: =B14+1 -> 6 | C17: {=VLOOKUP(INDIRECT("'Grupo " & B17 & "'!J18"),INDIRECT("'Grupo " & B17 & "'!B12"):INDIRECT("'Grupo " & B17 & "'!J15"),2,FALSE)} -> 4181 | D17: {=VLOOKUP(IF(INDIRECT("'Grupo " & B17 & "'!J18")=INDIRECT("'Grupo " & B17 & "'!C18"),INDIRECT("'Grupo " & B17 & "'!C19"),INDIRECT("'Grupo " & B17 & "'!C18")),INDIRECT("'Grupo " & B17 & "'!B12"):INDIRECT("'Grupo " & B17 & "'!G15"),2,FALSE)} -> 4686 | F17: {=VLOOKUP(IF(INDIRECT("'Grupo " & B17 & "'!J18")=INDIRECT("'Grupo " & B17 & "'!C18"),INDIRECT("'Grupo " & B17 & "'!C19"),INDIRECT("'Grupo " & B17 & "'!C18")),INDIRECT("'Grupo " & B17 & "'!B12"):INDIRECT("'Grupo " & B17 & "'!G15"),2,FALSE)} -> 4686 | G17: {=VLOOKUP(INDIRECT("'Grupo " & B17 & "'!J18"),INDIRECT("'Grupo " & B17 & "'!B12"):INDIRECT("'Grupo " & B17 & "'!J15"),2,FALSE)} -> 4181
C18: {=VLOOKUP(INDIRECT("'Grupo " & B17 & "'!J20"),INDIRECT("'Grupo " & B17 & "'!B12"):INDIRECT("'Grupo " & B17 & "'!J15"),2,FALSE)} -> 4181 | D18: {=VLOOKUP(IF(INDIRECT("'Grupo " & B17 & "'!J20")=INDIRECT("'Grupo " & B17 & "'!C20"),INDIRECT("'Grupo " & B17 & "'!C21"),INDIRECT("'Grupo " & B17 & "'!C20")),INDIRECT("'Grupo " & B17 & "'!B12"):INDIRECT("'Grupo " & B17 & "'!G15"),2,FALSE)} -> 4121 | F18: {=VLOOKUP(IF(INDIRECT("'Grupo " & B17 & "'!J20")=INDIRECT("'Grupo " & B17 & "'!C20"),INDIRECT("'Grupo " & B17 & "'!C21"),INDIRECT("'Grupo " & B17 & "'!C20")),INDIRECT("'Grupo " & B17 & "'!B12"):INDIRECT("'Grupo " & B17 & "'!G15"),2,FALSE)} -> 4121 | G18: {=VLOOKUP(INDIRECT("'Grupo " & B17 & "'!J20"),INDIRECT("'Grupo " & B17 & "'!B12"):INDIRECT("'Grupo " & B17 & "'!J15"),2,FALSE)} -> 4181
C19: {=VLOOKUP(INDIRECT("'Grupo " & B17 & "'!J22"),INDIRECT("'Grupo " & B17 & "'!B12"):INDIRECT("'Grupo " & B17 & "'!J15"),2,FALSE)} -> 4121 | D19: {=VLOOKUP(IF(INDIRECT("'Grupo " & B17 & "'!J22")=INDIRECT("'Grupo " & B17 & "'!C22"),INDIRECT("'Grupo " & B17 & "'!C23"),INDIRECT("'Grupo " & B17 & "'!C22")),INDIRECT("'Grupo " & B17 & "'!B12"):INDIRECT("'Grupo " & B17 & "'!G15"),2,FALSE)} -> 4686 | F19: {=VLOOKUP(IF(INDIRECT("'Grupo " & B17 & "'!J22")=INDIRECT("'Grupo " & B17 & "'!C22"),INDIRECT("'Grupo " & B17 & "'!C23"),INDIRECT("'Grupo " & B17 & "'!C22")),INDIRECT("'Grupo " & B17 & "'!B12"):INDIRECT("'Grupo " & B17 & "'!G15"),2,FALSE)} -> 4686 | G19: {=VLOOKUP(INDIRECT("'Grupo " & B17 & "'!J22"),INDIRECT("'Grupo " & B17 & "'!B12"):INDIRECT("'Grupo " & B17 & "'!J15"),2,FALSE)} -> 4121
B20: =B17+1 -> 7 | C20: {=VLOOKUP(INDIRECT("'Grupo " & B20 & "'!J18"),INDIRECT("'Grupo " & B20 & "'!B12"):INDIRECT("'Grupo " & B20 & "'!J15"),2,FALSE)} -> 3988 | D20: {=VLOOKUP(IF(INDIRECT("'Grupo " & B20 & "'!J18")=INDIRECT("'Grupo " & B20 & "'!C18"),INDIRECT("'Grupo " & B20 & "'!C19"),INDIRECT("'Grupo " & B20 & "'!C18")),INDIRECT("'Grupo " & B20 & "'!B12"):INDIRECT("'Grupo " & B20 & "'!G15"),2,FALSE)} -> 4607 | F20: {=VLOOKUP(IF(INDIRECT("'Grupo " & B20 & "'!J18")=INDIRECT("'Grupo " & B20 & "'!C18"),INDIRECT("'Grupo " & B20 & "'!C19"),INDIRECT("'Grupo " & B20 & "'!C18")),INDIRECT("'Grupo " & B20 & "'!B12"):INDIRECT("'Grupo " & B20 & "'!G15"),2,FALSE)} -> 4607 | G20: {=VLOOKUP(INDIRECT("'Grupo " & B20 & "'!J18"),INDIRECT("'Grupo " & B20 & "'!B12"):INDIRECT("'Grupo " & B20 & "'!J15"),2,FALSE)} -> 3988
C21: {=VLOOKUP(INDIRECT("'Grupo " & B20 & "'!J20"),INDIRECT("'Grupo " & B20 & "'!B12"):INDIRECT("'Grupo " & B20 & "'!J15"),2,FALSE)} -> 3988 | D21: {=VLOOKUP(IF(INDIRECT("'Grupo " & B20 & "'!J20")=INDIRECT("'Grupo " & B20 & "'!C20"),INDIRECT("'Grupo " & B20 & "'!C21"),INDIRECT("'Grupo " & B20 & "'!C20")),INDIRECT("'Grupo " & B20 & "'!B12"):INDIRECT("'Grupo " & B20 & "'!G15"),2,FALSE)} -> 4437 | F21: {=VLOOKUP(IF(INDIRECT("'Grupo " & B20 & "'!J20")=INDIRECT("'Grupo " & B20 & "'!C20"),INDIRECT("'Grupo " & B20 & "'!C21"),INDIRECT("'Grupo " & B20 & "'!C20")),INDIRECT("'Grupo " & B20 & "'!B12"):INDIRECT("'Grupo " & B20 & "'!G15"),2,FALSE)} -> 4437 | G21: {=VLOOKUP(INDIRECT("'Grupo " & B20 & "'!J20"),INDIRECT("'Grupo " & B20 & "'!B12"):INDIRECT("'Grupo " & B20 & "'!J15"),2,FALSE)} -> 3988
C22: {=VLOOKUP(INDIRECT("'Grupo " & B20 & "'!J22"),INDIRECT("'Grupo " & B20 & "'!B12"):INDIRECT("'Grupo " & B20 & "'!J15"),2,FALSE)} -> 4437 | D22: {=VLOOKUP(IF(INDIRECT("'Grupo " & B20 & "'!J22")=INDIRECT("'Grupo " & B20 & "'!C22"),INDIRECT("'Grupo " & B20 & "'!C23"),INDIRECT("'Grupo " & B20 & "'!C22")),INDIRECT("'Grupo " & B20 & "'!B12"):INDIRECT("'Grupo " & B20 & "'!G15"),2,FALSE)} -> 4607 | F22: {=VLOOKUP(IF(INDIRECT("'Grupo " & B20 & "'!J22")=INDIRECT("'Grupo " & B20 & "'!C22"),INDIRECT("'Grupo " & B20 & "'!C23"),INDIRECT("'Grupo " & B20 & "'!C22")),INDIRECT("'Grupo " & B20 & "'!B12"):INDIRECT("'Grupo " & B20 & "'!G15"),2,FALSE)} -> 4607 | G22: {=VLOOKUP(INDIRECT("'Grupo " & B20 & "'!J22"),INDIRECT("'Grupo " & B20 & "'!B12"):INDIRECT("'Grupo " & B20 & "'!J15"),2,FALSE)} -> 4437
B23: =B20+1 -> 8 | C23: {=VLOOKUP(INDIRECT("'Grupo " & B23 & "'!J18"),INDIRECT("'Grupo " & B23 & "'!B12"):INDIRECT("'Grupo " & B23 & "'!J15"),2,FALSE)} -> 3875 | D23: {=VLOOKUP(IF(INDIRECT("'Grupo " & B23 & "'!J18")=INDIRECT("'Grupo " & B23 & "'!C18"),INDIRECT("'Grupo " & B23 & "'!C19"),INDIRECT("'Grupo " & B23 & "'!C18")),INDIRECT("'Grupo " & B23 & "'!B12"):INDIRECT("'Grupo " & B23 & "'!G15"),2,FALSE)} -> 4180 | F23: {=VLOOKUP(IF(INDIRECT("'Grupo " & B23 & "'!J18")=INDIRECT("'Grupo " & B23 & "'!C18"),INDIRECT("'Grupo " & B23 & "'!C19"),INDIRECT("'Grupo " & B23 & "'!C18")),INDIRECT("'Grupo " & B23 & "'!B12"):INDIRECT("'Grupo " & B23 & "'!G15"),2,FALSE)} -> 4180 | G23: {=VLOOKUP(INDIRECT("'Grupo " & B23 & "'!J18"),INDIRECT("'Grupo " & B23 & "'!B12"):INDIRECT("'Grupo " & B23 & "'!J15"),2,FALSE)} -> 3875
C24: {=VLOOKUP(INDIRECT("'Grupo " & B23 & "'!J20"),INDIRECT("'Grupo " & B23 & "'!B12"):INDIRECT("'Grupo " & B23 & "'!J15"),2,FALSE)} -> 3875 | D24: {=VLOOKUP(IF(INDIRECT("'Grupo " & B23 & "'!J20")=INDIRECT("'Grupo " & B23 & "'!C20"),INDIRECT("'Grupo " & B23 & "'!C21"),INDIRECT("'Grupo " & B23 & "'!C20")),INDIRECT("'Grupo " & B23 & "'!B12"):INDIRECT("'Grupo " & B23 & "'!G15"),2,FALSE)} -> 4353 | F24: {=VLOOKUP(IF(INDIRECT("'Grupo " & B23 & "'!J20")=INDIRECT("'Grupo " & B23 & "'!C20"),INDIRECT("'Grupo " & B23 & "'!C21"),INDIRECT("'Grupo " & B23 & "'!C20")),INDIRECT("'Grupo " & B23 & "'!B12"):INDIRECT("'Grupo " & B23 & "'!G15"),2,FALSE)} -> 4353 | G24: {=VLOOKUP(INDIRECT("'Grupo " & B23 & "'!J20"),INDIRECT("'Grupo " & B23 & "'!B12"):INDIRECT("'Grupo " & B23 & "'!J15"),2,FALSE)} -> 3875
C25: {=VLOOKUP(INDIRECT("'Grupo " & B23 & "'!J22"),INDIRECT("'Grupo " & B23 & "'!B12"):INDIRECT("'Grupo " & B23 & "'!J15"),2,FALSE)} -> 4353 | D25: {=VLOOKUP(IF(INDIRECT("'Grupo " & B23 & "'!J22")=INDIRECT("'Grupo " & B23 & "'!C22"),INDIRECT("'Grupo " & B23 & "'!C23"),INDIRECT("'Grupo " & B23 & "'!C22")),INDIRECT("'Grupo " & B23 & "'!B12"):INDIRECT("'Grupo " & B23 & "'!G15"),2,FALSE)} -> 4180 | F25: {=VLOOKUP(IF(INDIRECT("'Grupo " & B23 & "'!J22")=INDIRECT("'Grupo " & B23 & "'!C22"),INDIRECT("'Grupo " & B23 & "'!C23"),INDIRECT("'Grupo " & B23 & "'!C22")),INDIRECT("'Grupo " & B23 & "'!B12"):INDIRECT("'Grupo " & B23 & "'!G15"),2,FALSE)} -> 4180 | G25: {=VLOOKUP(INDIRECT("'Grupo " & B23 & "'!J22"),INDIRECT("'Grupo " & B23 & "'!B12"):INDIRECT("'Grupo " & B23 & "'!J15"),2,FALSE)} -> 4353
B26: =B23+1 -> 9 | C26: {=VLOOKUP(INDIRECT("'Grupo " & B26 & "'!J18"),INDIRECT("'Grupo " & B26 & "'!B12"):INDIRECT("'Grupo " & B26 & "'!J15"),2,FALSE)} -> 4177 | D26: {=VLOOKUP(IF(INDIRECT("'Grupo " & B26 & "'!J18")=INDIRECT("'Grupo " & B26 & "'!C18"),INDIRECT("'Grupo " & B26 & "'!C19"),INDIRECT("'Grupo " & B26 & "'!C18")),INDIRECT("'Grupo " & B26 & "'!B12"):INDIRECT("'Grupo " & B26 & "'!G15"),2,FALSE)} -> 4857 | F26: {=VLOOKUP(IF(INDIRECT("'Grupo " & B26 & "'!J18")=INDIRECT("'Grupo " & B26 & "'!C18"),INDIRECT("'Grupo " & B26 & "'!C19"),INDIRECT("'Grupo " & B26 & "'!C18")),INDIRECT("'Grupo " & B26 & "'!B12"):INDIRECT("'Grupo " & B26 & "'!G15"),2,FALSE)} -> 4857 | G26: {=VLOOKUP(INDIRECT("'Grupo " & B26 & "'!J18"),INDIRECT("'Grupo " & B26 & "'!B12"):INDIRECT("'Grupo " & B26 & "'!J15"),2,FALSE)} -> 4177
C27: {=VLOOKUP(INDIRECT("'Grupo " & B26 & "'!J20"),INDIRECT("'Grupo " & B26 & "'!B12"):INDIRECT("'Grupo " & B26 & "'!J15"),2,FALSE)} -> 4177 | D27: {=VLOOKUP(IF(INDIRECT("'Grupo " & B26 & "'!J20")=INDIRECT("'Grupo " & B26 & "'!C20"),INDIRECT("'Grupo " & B26 & "'!C21"),INDIRECT("'Grupo " & B26 & "'!C20")),INDIRECT("'Grupo " & B26 & "'!B12"):INDIRECT("'Grupo " & B26 & "'!G15"),2,FALSE)} -> 4122 | F27: {=VLOOKUP(IF(INDIRECT("'Grupo " & B26 & "'!J20")=INDIRECT("'Grupo " & B26 & "'!C20"),INDIRECT("'Grupo " & B26 & "'!C21"),INDIRECT("'Grupo " & B26 & "'!C20")),INDIRECT("'Grupo " & B26 & "'!B12"):INDIRECT("'Grupo " & B26 & "'!G15"),2,FALSE)} -> 4122 | G27: {=VLOOKUP(INDIRECT("'Grupo " & B26 & "'!J20"),INDIRECT("'Grupo " & B26 & "'!B12"):INDIRECT("'Grupo " & B26 & "'!J15"),2,FALSE)} -> 4177
C28: {=VLOOKUP(INDIRECT("'Grupo " & B26 & "'!J22"),INDIRECT("'Grupo " & B26 & "'!B12"):INDIRECT("'Grupo " & B26 & "'!J15"),2,FALSE)} -> 4122 | D28: {=VLOOKUP(IF(INDIRECT("'Grupo " & B26 & "'!J22")=INDIRECT("'Grupo " & B26 & "'!C22"),INDIRECT("'Grupo " & B26 & "'!C23"),INDIRECT("'Grupo " & B26 & "'!C22")),INDIRECT("'Grupo " & B26 & "'!B12"):INDIRECT("'Grupo " & B26 & "'!G15"),2,FALSE)} -> 4857 | F28: {=VLOOKUP(IF(INDIRECT("'Grupo " & B26 & "'!J22")=INDIRECT("'Grupo " & B26 & "'!C22"),INDIRECT("'Grupo " & B26 & "'!C23"),INDIRECT("'Grupo " & B26 & "'!C22")),INDIRECT("'Grupo " & B26 & "'!B12"):INDIRECT("'Grupo " & B26 & "'!G15"),2,FALSE)} -> 4857 | G28: {=VLOOKUP(INDIRECT("'Grupo " & B26 & "'!J22"),INDIRECT("'Grupo " & B26 & "'!B12"):INDIRECT("'Grupo " & B26 & "'!J15"),2,FALSE)} -> 4122
B29: =B26+1 -> 10 | C29: {=VLOOKUP(INDIRECT("'Grupo " & B29 & "'!J18"),INDIRECT("'Grupo " & B29 & "'!B12"):INDIRECT("'Grupo " & B29 & "'!J15"),2,FALSE)} -> 5005 | D29: {=VLOOKUP(IF(INDIRECT("'Grupo " & B29 & "'!J18")=INDIRECT("'Grupo " & B29 & "'!C18"),INDIRECT("'Grupo " & B29 & "'!C19"),INDIRECT("'Grupo " & B29 & "'!C18")),INDIRECT("'Grupo " & B29 & "'!B12"):INDIRECT("'Grupo " & B29 & "'!G15"),2,FALSE)} -> 4859 | F29: {=VLOOKUP(IF(INDIRECT("'Grupo " & B29 & "'!J18")=INDIRECT("'Grupo " & B29 & "'!C18"),INDIRECT("'Grupo " & B29 & "'!C19"),INDIRECT("'Grupo " & B29 & "'!C18")),INDIRECT("'Grupo " & B29 & "'!B12"):INDIRECT("'Grupo " & B29 & "'!G15"),2,FALSE)} -> 4859 | G29: {=VLOOKUP(INDIRECT("'Grupo " & B29 & "'!J18"),INDIRECT("'Grupo " & B29 & "'!B12"):INDIRECT("'Grupo " & B29 & "'!J15"),2,FALSE)} -> 5005
C30: {=VLOOKUP(INDIRECT("'Grupo " & B29 & "'!J20"),INDIRECT("'Grupo " & B29 & "'!B12"):INDIRECT("'Grupo " & B29 & "'!J15"),2,FALSE)} -> 5005 | D30: {=VLOOKUP(IF(INDIRECT("'Grupo " & B29 & "'!J20")=INDIRECT("'Grupo " & B29 & "'!C20"),INDIRECT("'Grupo " & B29 & "'!C21"),INDIRECT("'Grupo " & B29 & "'!C20")),INDIRECT("'Grupo " & B29 & "'!B12"):INDIRECT("'Grupo " & B29 & "'!G15"),2,FALSE)} -> 4381 | F30: {=VLOOKUP(IF(INDIRECT("'Grupo " & B29 & "'!J20")=INDIRECT("'Grupo " & B29 & "'!C20"),INDIRECT("'Grupo " & B29 & "'!C21"),INDIRECT("'Grupo " & B29 & "'!C20")),INDIRECT("'Grupo " & B29 & "'!B12"):INDIRECT("'Grupo " & B29 & "'!G15"),2,FALSE)} -> 4381 | G30: {=VLOOKUP(INDIRECT("'Grupo " & B29 & "'!J20"),INDIRECT("'Grupo " & B29 & "'!B12"):INDIRECT("'Grupo " & B29 & "'!J15"),2,FALSE)} -> 5005
C31: {=VLOOKUP(INDIRECT("'Grupo " & B29 & "'!J22"),INDIRECT("'Grupo " & B29 & "'!B12"):INDIRECT("'Grupo " & B29 & "'!J15"),2,FALSE)} -> 4381 | D31: {=VLOOKUP(IF(INDIRECT("'Grupo " & B29 & "'!J22")=INDIRECT("'Grupo " & B29 & "'!C22"),INDIRECT("'Grupo " & B29 & "'!C23"),INDIRECT("'Grupo " & B29 & "'!C22")),INDIRECT("'Grupo " & B29 & "'!B12"):INDIRECT("'Grupo " & B29 & "'!G15"),2,FALSE)} -> 4859 | F31: {=VLOOKUP(IF(INDIRECT("'Grupo " & B29 & "'!J22")=INDIRECT("'Grupo " & B29 & "'!C22"),INDIRECT("'Grupo " & B29 & "'!C23"),INDIRECT("'Grupo " & B29 & "'!C22")),INDIRECT("'Grupo " & B29 & "'!B12"):INDIRECT("'Grupo " & B29 & "'!G15"),2,FALSE)} -> 4859 | G31: {=VLOOKUP(INDIRECT("'Grupo " & B29 & "'!J22"),INDIRECT("'Grupo " & B29 & "'!B12"):INDIRECT("'Grupo " & B29 & "'!J15"),2,FALSE)} -> 4381
B32: =B29+1 -> 11 | C32: {=VLOOKUP(INDIRECT("'Grupo " & B32 & "'!J18"),INDIRECT("'Grupo " & B32 & "'!B12"):INDIRECT("'Grupo " & B32 & "'!J15"),2,FALSE)} -> 4679 | D32: {=VLOOKUP(IF(INDIRECT("'Grupo " & B32 & "'!J18")=INDIRECT("'Grupo " & B32 & "'!C18"),INDIRECT("'Grupo " & B32 & "'!C19"),INDIRECT("'Grupo " & B32 & "'!C18")),INDIRECT("'Grupo " & B32 & "'!B12"):INDIRECT("'Grupo " & B32 & "'!G15"),2,FALSE)} -> 4312 | F32: {=VLOOKUP(IF(INDIRECT("'Grupo " & B32 & "'!J18")=INDIRECT("'Grupo " & B32 & "'!C18"),INDIRECT("'Grupo " & B32 & "'!C19"),INDIRECT("'Grupo " & B32 & "'!C18")),INDIRECT("'Grupo " & B32 & "'!B12"):INDIRECT("'Grupo " & B32 & "'!G15"),2,FALSE)} -> 4312 | G32: {=VLOOKUP(INDIRECT("'Grupo " & B32 & "'!J18"),INDIRECT("'Grupo " & B32 & "'!B12"):INDIRECT("'Grupo " & B32 & "'!J15"),2,FALSE)} -> 4679
C33: {=VLOOKUP(INDIRECT("'Grupo " & B32 & "'!J20"),INDIRECT("'Grupo " & B32 & "'!B12"):INDIRECT("'Grupo " & B32 & "'!J15"),2,FALSE)} -> 4679 | D33: {=VLOOKUP(IF(INDIRECT("'Grupo " & B32 & "'!J20")=INDIRECT("'Grupo " & B32 & "'!C20"),INDIRECT("'Grupo " & B32 & "'!C21"),INDIRECT("'Grupo " & B32 & "'!C20")),INDIRECT("'Grupo " & B32 & "'!B12"):INDIRECT("'Grupo " & B32 & "'!G15"),2,FALSE)} -> 4293 | F33: {=VLOOKUP(IF(INDIRECT("'Grupo " & B32 & "'!J20")=INDIRECT("'Grupo " & B32 & "'!C20"),INDIRECT("'Grupo " & B32 & "'!C21"),INDIRECT("'Grupo " & B32 & "'!C20")),INDIRECT("'Grupo " & B32 & "'!B12"):INDIRECT("'Grupo " & B32 & "'!G15"),2,FALSE)} -> 4293 | G33: {=VLOOKUP(INDIRECT("'Grupo " & B32 & "'!J20"),INDIRECT("'Grupo " & B32 & "'!B12"):INDIRECT("'Grupo " & B32 & "'!J15"),2,FALSE)} -> 4679
C34: {=VLOOKUP(INDIRECT("'Grupo " & B32 & "'!J22"),INDIRECT("'Grupo " & B32 & "'!B12"):INDIRECT("'Grupo " & B32 & "'!J15"),2,FALSE)} -> 4293 | D34: {=VLOOKUP(IF(INDIRECT("'Grupo " & B32 & "'!J22")=INDIRECT("'Grupo " & B32 & "'!C22"),INDIRECT("'Grupo " & B32 & "'!C23"),INDIRECT("'Grupo " & B32 & "'!C22")),INDIRECT("'Grupo " & B32 & "'!B12"):INDIRECT("'Grupo " & B32 & "'!G15"),2,FALSE)} -> 4312 | F34: {=VLOOKUP(IF(INDIRECT("'Grupo " & B32 & "'!J22")=INDIRECT("'Grupo " & B32 & "'!C22"),INDIRECT("'Grupo " & B32 & "'!C23"),INDIRECT("'Grupo " & B32 & "'!C22")),INDIRECT("'Grupo " & B32 & "'!B12"):INDIRECT("'Grupo " & B32 & "'!G15"),2,FALSE)} -> 4312 | G34: {=VLOOKUP(INDIRECT("'Grupo " & B32 & "'!J22"),INDIRECT("'Grupo " & B32 & "'!B12"):INDIRECT("'Grupo " & B32 & "'!J15"),2,FALSE)} -> 4293
B35: =B32+1 -> 12 | C35: {=VLOOKUP(INDIRECT("'Grupo " & B35 & "'!J18"),INDIRECT("'Grupo " & B35 & "'!B12"):INDIRECT("'Grupo " & B35 & "'!J15"),2,FALSE)} -> 4325 | D35: {=VLOOKUP(IF(INDIRECT("'Grupo " & B35 & "'!J18")=INDIRECT("'Grupo " & B35 & "'!C18"),INDIRECT("'Grupo " & B35 & "'!C19"),INDIRECT("'Grupo " & B35 & "'!C18")),INDIRECT("'Grupo " & B35 & "'!B12"):INDIRECT("'Grupo " & B35 & "'!G15"),2,FALSE)} -> 4702 | F35: {=VLOOKUP(IF(INDIRECT("'Grupo " & B35 & "'!J18")=INDIRECT("'Grupo " & B35 & "'!C18"),INDIRECT("'Grupo " & B35 & "'!C19"),INDIRECT("'Grupo " & B35 & "'!C18")),INDIRECT("'Grupo " & B35 & "'!B12"):INDIRECT("'Grupo " & B35 & "'!G15"),2,FALSE)} -> 4702 | G35: {=VLOOKUP(INDIRECT("'Grupo " & B35 & "'!J18"),INDIRECT("'Grupo " & B35 & "'!B12"):INDIRECT("'Grupo " & B35 & "'!J15"),2,FALSE)} -> 4325
C36: {=VLOOKUP(INDIRECT("'Grupo " & B35 & "'!J20"),INDIRECT("'Grupo " & B35 & "'!B12"):INDIRECT("'Grupo " & B35 & "'!J15"),2,FALSE)} -> 4351 | D36: {=VLOOKUP(IF(INDIRECT("'Grupo " & B35 & "'!J20")=INDIRECT("'Grupo " & B35 & "'!C20"),INDIRECT("'Grupo " & B35 & "'!C21"),INDIRECT("'Grupo " & B35 & "'!C20")),INDIRECT("'Grupo " & B35 & "'!B12"):INDIRECT("'Grupo " & B35 & "'!G15"),2,FALSE)} -> 4325 | F36: {=VLOOKUP(IF(INDIRECT("'Grupo " & B35 & "'!J20")=INDIRECT("'Grupo " & B35 & "'!C20"),INDIRECT("'Grupo " & B35 & "'!C21"),INDIRECT("'Grupo " & B35 & "'!C20")),INDIRECT("'Grupo " & B35 & "'!B12"):INDIRECT("'Grupo " & B35 & "'!G15"),2,FALSE)} -> 4325 | G36: {=VLOOKUP(INDIRECT("'Grupo " & B35 & "'!J20"),INDIRECT("'Grupo " & B35 & "'!B12"):INDIRECT("'Grupo " & B35 & "'!J15"),2,FALSE)} -> 4351
C37: {=VLOOKUP(INDIRECT("'Grupo " & B35 & "'!J22"),INDIRECT("'Grupo " & B35 & "'!B12"):INDIRECT("'Grupo " & B35 & "'!J15"),2,FALSE)} -> 4351 | D37: {=VLOOKUP(IF(INDIRECT("'Grupo " & B35 & "'!J22")=INDIRECT("'Grupo " & B35 & "'!C22"),INDIRECT("'Grupo " & B35 & "'!C23"),INDIRECT("'Grupo " & B35 & "'!C22")),INDIRECT("'Grupo " & B35 & "'!B12"):INDIRECT("'Grupo " & B35 & "'!G15"),2,FALSE)} -> 4702 | F37: {=VLOOKUP(IF(INDIRECT("'Grupo " & B35 & "'!J22")=INDIRECT("'Grupo " & B35 & "'!C22"),INDIRECT("'Grupo " & B35 & "'!C23"),INDIRECT("'Grupo " & B35 & "'!C22")),INDIRECT("'Grupo " & B35 & "'!B12"):INDIRECT("'Grupo " & B35 & "'!G15"),2,FALSE)} -> 4702 | G37: {=VLOOKUP(INDIRECT("'Grupo " & B35 & "'!J22"),INDIRECT("'Grupo " & B35 & "'!B12"):INDIRECT("'Grupo " & B35 & "'!J15"),2,FALSE)} -> 4351
B38: =B35+1 -> 13 | C38: {=VLOOKUP(INDIRECT("'Grupo " & B38 & "'!J18"),INDIRECT("'Grupo " & B38 & "'!B12"):INDIRECT("'Grupo " & B38 & "'!J15"),2,FALSE)} -> 4458 | D38: {=VLOOKUP(IF(INDIRECT("'Grupo " & B38 & "'!J18")=INDIRECT("'Grupo " & B38 & "'!C18"),INDIRECT("'Grupo " & B38 & "'!C19"),INDIRECT("'Grupo " & B38 & "'!C18")),INDIRECT("'Grupo " & B38 & "'!B12"):INDIRECT("'Grupo " & B38 & "'!G15"),2,FALSE)} -> 4829 | F38: {=VLOOKUP(IF(INDIRECT("'Grupo " & B38 & "'!J18")=INDIRECT("'Grupo " & B38 & "'!C18"),INDIRECT("'Grupo " & B38 & "'!C19"),INDIRECT("'Grupo " & B38 & "'!C18")),INDIRECT("'Grupo " & B38 & "'!B12"):INDIRECT("'Grupo " & B38 & "'!G15"),2,FALSE)} -> 4829 | G38: {=VLOOKUP(INDIRECT("'Grupo " & B38 & "'!J18"),INDIRECT("'Grupo " & B38 & "'!B12"):INDIRECT("'Grupo " & B38 & "'!J15"),2,FALSE)} -> 4458
C39: {=VLOOKUP(INDIRECT("'Grupo " & B38 & "'!J20"),INDIRECT("'Grupo " & B38 & "'!B12"):INDIRECT("'Grupo " & B38 & "'!J15"),2,FALSE)} -> 4458 | D39: {=VLOOKUP(IF(INDIRECT("'Grupo " & B38 & "'!J20")=INDIRECT("'Grupo " & B38 & "'!C20"),INDIRECT("'Grupo " & B38 & "'!C21"),INDIRECT("'Grupo " & B38 & "'!C20")),INDIRECT("'Grupo " & B38 & "'!B12"):INDIRECT("'Grupo " & B38 & "'!G15"),2,FALSE)} -> 4227 | F39: {=VLOOKUP(IF(INDIRECT("'Grupo " & B38 & "'!J20")=INDIRECT("'Grupo " & B38 & "'!C20"),INDIRECT("'Grupo " & B38 & "'!C21"),INDIRECT("'Grupo " & B38 & "'!C20")),INDIRECT("'Grupo " & B38 & "'!B12"):INDIRECT("'Grupo " & B38 & "'!G15"),2,FALSE)} -> 4227 | G39: {=VLOOKUP(INDIRECT("'Grupo " & B38 & "'!J20"),INDIRECT("'Grupo " & B38 & "'!B12"):INDIRECT("'Grupo " & B38 & "'!J15"),2,FALSE)} -> 4458
C40: {=VLOOKUP(INDIRECT("'Grupo " & B38 & "'!J22"),INDIRECT("'Grupo " & B38 & "'!B12"):INDIRECT("'Grupo " & B38 & "'!J15"),2,FALSE)} -> 4227 | D40: {=VLOOKUP(IF(INDIRECT("'Grupo " & B38 & "'!J22")=INDIRECT("'Grupo " & B38 & "'!C22"),INDIRECT("'Grupo " & B38 & "'!C23"),INDIRECT("'Grupo " & B38 & "'!C22")),INDIRECT("'Grupo " & B38 & "'!B12"):INDIRECT("'Grupo " & B38 & "'!G15"),2,FALSE)} -> 4829 | F40: {=VLOOKUP(IF(INDIRECT("'Grupo " & B38 & "'!J22")=INDIRECT("'Grupo " & B38 & "'!C22"),INDIRECT("'Grupo " & B38 & "'!C23"),INDIRECT("'Grupo " & B38 & "'!C22")),INDIRECT("'Grupo " & B38 & "'!B12"):INDIRECT("'Grupo " & B38 & "'!G15"),2,FALSE)} -> 4829 | G40: {=VLOOKUP(INDIRECT("'Grupo " & B38 & "'!J22"),INDIRECT("'Grupo " & B38 & "'!B12"):INDIRECT("'Grupo " & B38 & "'!J15"),2,FALSE)} -> 4227
...

Sheet Ranking Final
A1: Ranking | B1: CARNE | C1: NOMBRE | D1: CLUB | E1: PUNTOS
A2: 1 | B2: 3790 | C2: FABIAN ROJAS VARELA | D2: SAN CARLOS | E2: 774
A3: 2 | B3: 4025 | C3: GABRIEL CORRALES BARRANTES | D3: ESPARZA | E3: 733
A4: 3 | B4: 3787 | C4: ISAAC RIVERA TORRES | D4: CURRIDABAT | E4: 679
A5: 4 | B5: 4297 | C5: JESÉ DAVID CHAVES MUÑOZ | D5: ESPARZA | E5: 663
A6: 5 | B6: 3988 | C6: JACKY CHENG FENG | D6: ESCAZÚ | E6: 638
A7: 6 | B7: 4026 | C7: IAN GABRIEL VILLEGAS SALAS | D7: SAN CARLOS | E7: 634
A8: 7 | B8: 4181 | C8: JUAN MARTÍN ARCE VÁSQUEZ | D8: SAN CARLOS | E8: 631
A9: 8 | B9: 3875 | C9: CALEB CASCANTE MARIN | D9: ESCAZÚ | E9: 619
A10: 8 | B10: 4177 | C10: RODOLFO ALBERTO CHAVES LEON | D10: ESPARZA | E10: 619
A11: 10 | B11: 4679 | C11: TOMAS IGNACIO UGALDE HERNANDEZ | D11: CCDR SAN JOSÉ | E11: 612
A12: 11 | B12: 5005 | C12: ADRIAN ARTAVIA MORALES | D12: MONTES DE OCA | E12: 593
A13: 12 | B13: 4151 | C13: ISAAC DAVID CASTRO DÍAZ | D13: SAN CARLOS | E13: 583
... A207: 68 | B207: 4469 | C207: Luis Daniel Quiros Alvarado | D207: A | E207: 420

Sheet Inscripciones
B1: Ranking Nacional
B2: U13 MASCULINO
B4: CARNÉ | C4: NOMBRE | D4: CLUB | E4: RANKING | F4: PUNTOS | G4: Grupo
A5: =G5+0.1 -> 1.1 | B5: 3790 | C5: FABIAN ROJAS VARELA | D5: SAN CARLOS | E5: 1 | F5: 712 | G5: 1
A6: =G6+0.2 -> 1.2 | B6: 4050 | C6: FABIÁN OBANDO VARGAS | D6: ALAJUELA | E6: 38 | F6: 489 | G6: 1
A7: =G7+0.3 -> 1.3 | B7: 4606 | C7: LUCA JIMÉNEZ CHAVES | D7: ESCAZÚ | E7: 41 | F7: 483 | G7: 1
A8: =G8+0.1 -> 2.1 | B8: 4025 | C8: GABRIEL CORRALES BARRANTES | D8: ESPARZA | E8: 2 | F8: 698 | G8: 2
A9: =G9+0.2 -> 2.2 | B9: 4778 | C9: JOSE PABLO DELGADO FERNANDEZ | D9: SAN CARLOS | E9: 39 | F9: 488 | G9: 2
A10: =G10+0.3 -> 2.3 | B10: 4825 | C10: SANTIAGO MELENDEZ MONTERO | D10: PÉREZ ZELEDÓN | E10: 42 | F10: 483 | G10: 2
A11: =G11+0.1 -> 3.1 | B11: 3787 | C11: ISAAC RIVERA TORRES | D11: CURRIDABAT | E11: 3 | F11: 624 | G11: 3
A12: =G12+0.2 -> 3.2 | B12: 4465 | C12: JULIÁN ZUÑIGA AGÜERO | D12: ESPARZA | E12: 36 | F12: 492 | G12: 3
A13: =G13+0.3 -> 3.3 | B13: 4740 | C13: TOMÁS AGUILAR JIMÉNEZ | D13: SANTA ANA | E13: 43 | F13: 474 | G13: 3
A14: =G14+0.1 -> 4.1 | B14: 4297 | C14: JESÉ DAVID CHAVES MUÑOZ | D14: ESPARZA | E14: 4 | F14: 619 | G14: 4
A15: =G15+0.2 -> 4.2 | B15: 4706 | C15: ISAAC RÍOS FERNÁNDEZ | D15: CCDR SAN JOSÉ | E15: 35 | F15: 492 | G15: 4
A16: =G16+0.3 -> 4.3 | B16: 4726 | C16: DIEGO WU WU | D16: ESCAZÚ | E16: 44 | F16: 473 | G16: 4
A17: =G17+0.1 -> 5.1 | B17: 4026 | C17: IAN GABRIEL VILLEGAS SALAS | D17: SAN CARLOS | E17: 5 | F17: 617 | G17: 5
A18: =G18+0.2 -> 5.2 | B18: 3987 | C18: JOSÉ DANIEL FERNÁNDEZ HERRERA | D18: ESCAZÚ | E18: 34 | F18: 494 | G18: 5
A19: =G19+0.3 -> 5.3 | B19: 4547 | C19: LEONARDO COTO RAMIREZ | D19: GUARCO | E19: 45 | F19: 473 | G19: 5
A20: =G20+0.1 -> 6.1 | B20: 4181 | C20: JUAN MARTÍN ARCE VÁSQUEZ | D20: SAN CARLOS | E20: 6 | F20: 612 | G20: 6
A21: =G21+0.2 -> 6.2 | B21: 4121 | C21: ANDRÉS CHACÓN ALTAMIRANO | D21: CURRIDABAT | E21: 32 | F21: 498 | G21: 6
A22: =G22+0.3 -> 6.3 | B22: 4686 | C22: SANTHIAGO SOTO BNADO | D22: ESCAZÚ | E22: 49 | F22: 463 | G22: 6
A23: =G23+0.1 -> 7.1 | B23: 3988 | C23: JACKY CHENG FENG | D23: ESCAZÚ | E23: 7 | F23: 606 | G23: 7
A24: =G24+0.2 -> 7.2 | B24: 4437 | C24: MATHIAS HAY GRANADOS | D24: CORREDORES | E24: 31 | F24: 502 | G24: 7
A25: =G25+0.3 -> 7.3 | B25: 4607 | C25: IGNACIO CABEZAS ROJAS | D25: ALAJUELA | E25: 46 | F25: 471 | G25: 7
A26: =G26+0.1 -> 8.1 | B26: 3875 | C26: CALEB CASCANTE MARIN | D26: ESCAZÚ | E26: 8 | F26: 585 | G26: 8
A27: =G27+0.2 -> 8.2 | B27: 4353 | C27: IVAN ANDRÉS RODRÍGUEZ DURÁN | D27: SAN CARLOS | E27: 27 | F27: 514 | G27: 8
A28: =G28+0.3 -> 8.3 | B28: 4180 | C28: ESTEBAN CHAVES GALLO | D28: CORREDORES | E28: 50 | F28: 463 | G28: 8
A29: =G29+0.1 -> 9.1 | B29: 4177 | C29: RODOLFO ALBERTO CHAVES LEON | D29: ESPARZA | E29: 9 | F29: 583 | G29: 9
A30: =G30+0.2 -> 9.2 | B30: 4122 | C30: BRYAN ALVAREZ SOLIS | D30: ESCAZÚ | E30: 30 | F30: 503 | G30: 9
A31: =G31+0.3 -> 9.3 | B31: 4857 | C31: SEBASTIAN VARGAS ZAMORA | D31: SAN CARLOS | E31: 51 | F31: 462 | G31: 9
A32: =G32+0.1 -> 10.1 | B32: 5005 | C32: ADRIAN ARTAVIA MORALES | D32: MONTES DE OCA | E32: 10 | F32: 578 | G32: 10
A33: =G33+0.2 -> 10.2 | B33: 4381 | C33: ALEJANDRO PADILLA SOLERA | D33: ESCAZÚ | E33: 26 | F33: 515 | G33: 10
A34: =G34+0.3 -> 10.3 | B34: 4859 | C34: ISAAC MATHÍAS ROJAS SOLANO | D34: ASERRÍ | E34: 52 | F34: 462 | G34: 10
A35: =G35+0.1 -> 11.1 | B35: 4679 | C35: TOMAS IGNACIO UGALDE HERNANDEZ | D35: CCDR SAN JOSÉ | E35: 11 | F35: 574 | G35: 11
A36: =G36+0.2 -> 11.2 | B36: 4293 | C36: MIKEL MORA JIMÉNEZ | D36: ESPARZA | E36: 25 | F36: 516 | G36: 11
A37: =G37+0.3 -> 11.3 | B37: 4312 | C37: BRANDON VENEGAS MURILLO | D37: ESCAZÚ | E37: 53 | F37: 462 | G37: 11
A38: =G38+0.1 -> 12.1 | B38: 4325 | C38: BENJAMIN CALDERON CECILIANO | D38: CURRIDABAT | E38: 12 | F38: 565 | G38: 12
A39: =G39+0.2 -> 12.2 | B39: 4351 | C39: DANIEL GARRO OBALDÍA | D39: SANTA ANA | E39: 21 | F39: 535 | G39: 12
A40: =G40+0.3 -> 12.3 | B40: 4702 | C40: FABIAN JOSUÉ CISNEROS VARGAS | D40: ESPARZA | E40: 54 | F40: 462 | G40: 12
A41: =G41+0.1 -> 13.1 | B41: 4458 | C41: MATHIAS QUESADA CASTILLO | D41: ESPARZA | E41: 13 | F41: 563 | G41: 13
...

Sheet Grupo 1
B2: #VALUE!
L5: En Caso de ocupar 3 de 5, mostrar columnas H - I En caso de 2 de 2, ocultarlas.
G7: Fecha: | J7: =TODAY() -> 46288
B9: Categoría | D9: =Inscripciones!B2 -> U13 MASCULINO | E9: Grupo nº | F9: 1 | G9: Mesa nº
B11: Orden | C11: Carné | D11: Jugadores | E11: Lugar | F11: Ranking | G11: Puntos
A12: =F9+0.1 -> 1.1 | B12: 1 | C12: =VLOOKUP(A12,Inscripciones!A5:G167,2,FALSE) -> 3790 | D12: =IF(ISBLANK(C12),"",VLOOKUP(C12,Inscripciones!$B$5:$F$200,2,FALSE)) -> FABIAN ROJAS VARELA | E12: =IF(ISBLANK(C12),"",VLOOKUP(C12,Inscripciones!$B$5:$F$200,3,FALSE)) -> SAN CARLOS | F12: =IF(ISBLANK(C12),"",VLOOKUP(C12,Inscripciones!$B$5:$F$200,4,FALSE)) -> 1 | G12: =IF(ISBLANK(C12),"",VLOOKUP(C12,Inscripciones!$B$5:$F$200,5,FALSE)) -> 712 | J12: =IF(ISBLANK(J11)," ",(E18+F18+G18+E20+F20+G20+H18+I18+H20+I20)/(E19+F19+G19+E21+F21+G21+H19+I19+H21+I21))
A13: =F9+0.2 -> 1.2 | B13: 2 | C13: =VLOOKUP(A13,Inscripciones!A5:G168,2,FALSE) -> 4050 | D13: =IF(ISBLANK(C13),"",VLOOKUP(C13,Inscripciones!$B$5:$F$200,2,FALSE)) -> FABIÁN OBANDO VARGAS | E13: =IF(ISBLANK(C13),"",VLOOKUP(C13,Inscripciones!$B$5:$F$200,3,FALSE)) -> ALAJUELA | F13: =IF(ISBLANK(C13),"",VLOOKUP(C13,Inscripciones!$B$5:$F$200,4,FALSE)) -> 38 | G13: =IF(ISBLANK(C13),"",VLOOKUP(C13,Inscripciones!$B$5:$F$200,5,FALSE)) -> 489 | J13: =IF(ISBLANK(J11)," ",(E21+F21+G21+E22+F22+G22+H21+I21+H22+I22)/(E20+F20+G20+E23+F23+G23+H20+I20+H23+I23))
A14: =+F9+0.3 -> 1.3 | B14: 3 | C14: =VLOOKUP(A14,Inscripciones!A6:G169,2,FALSE) -> 4606 | D14: =IF(ISBLANK(C14),"",VLOOKUP(C14,Inscripciones!$B$7:$F$200,2,FALSE)) -> LUCA JIMÉNEZ CHAVES | E14: =IF(ISBLANK(C14),"",VLOOKUP(C14,Inscripciones!$B$7:$F$200,3,FALSE)) -> ESCAZÚ | F14: =IF(ISBLANK(C14),"",VLOOKUP(C14,Inscripciones!$B$7:$F$200,4,FALSE)) -> 41 | G14: =IF(ISBLANK(C14),"",VLOOKUP(C14,Inscripciones!$B$7:$F$200,5,FALSE)) -> 483 | J14: =IF(ISBLANK(J11)," ",(E19+F19+G19+E23+F23+G23+H19+I19+H23+I23)/(E18+F18+G18+E22+F22+G22+H18+I18+H22+I22))
B17: Partida | D17: JUGADOR | E17: 1º set | F17: 2º set | G17: 3º set | H17: 4º set | I17: 5º set | J17: Ganador
B18: 1 | C18: 1 | D18: =D12 -> FABIAN ROJAS VARELA | E18: 11 | F18: 11 | J18: {=IF(AND(TRIM(E18)="WO",TRIM(E19)="WO"),"",IF(TRIM(E19)="WO",C18,IF(TRIM(E18)="WO",C19,IF(SUMPRODUCT(--(E18:I18>E19:I19))>SUMPRODUCT(--(E19:I19>E18:I18)),C18,IF(SUMPRODUCT(--(E19:I19>E18:I18))>SUMPRODUCT(--(E18:I18>E19:I19)),C19,"")))))} -> 1
C19: 3 | D19: =D14 -> LUCA JIMÉNEZ CHAVES | E19: 2 | F19: 2
B20: 2 | C20: 1 | D20: =D12 -> FABIAN ROJAS VARELA | E20: 11 | F20: 11 | J20: {=IF(AND(TRIM(E20)="WO",TRIM(E21)="WO"),"",IF(TRIM(E21)="WO",C20,IF(TRIM(E20)="WO",C21,IF(SUMPRODUCT(--(E20:I20>E21:I21))>SUMPRODUCT(--(E21:I21>E20:I20)),C20,IF(SUMPRODUCT(--(E21:I21>E20:I20))>SUMPRODUCT(--(E20:I20>E21:I21)),C21,"")))))} -> 1
C21: 2 | D21: =D13 -> FABIÁN OBANDO VARGAS | E21: 6 | F21: 6
B22: 3 | C22: 2 | D22: =D13 -> FABIÁN OBANDO VARGAS | E22: 11 | F22: 11 | G22: 10 | J22: {=IF(AND(TRIM(E22)="WO",TRIM(E23)="WO"),"",IF(TRIM(E23)="WO",C22,IF(TRIM(E22)="WO",C23,IF(SUMPRODUCT(--(E22:I22>E23:I23))>SUMPRODUCT(--(E23:I23>E22:I22)),C22,IF(SUMPRODUCT(--(E23:I23>E22:I22))>SUMPRODUCT(--(E22:I22>E23:I23)),C23,"")))))} -> 3
C23: 3 | D23: =D14 -> LUCA JIMÉNEZ CHAVES | E23: 2 | F23: 13 | G23: 12
C32: Clasificados (# de carne) | F32: Revisión de Camisas y Raquetas
C33: Carnet | D33: Nombre | F33: Revisión de nombres y resultados
C34: 3790 | D34: =IF(ISBLANK(C34),"",VLOOKUP(C34,Inscripciones!$B$5:$F$200,2,FALSE)) -> FABIAN ROJAS VARELA | F34: Árbitro
C35: 4606 | D35: =IF(ISBLANK(C35),"",VLOOKUP(C35,Inscripciones!$B$5:$F$200,2,FALSE)) -> LUCA JIMÉNEZ CHAVES | F35: Marque si hay informe

Sheet Grupo 2
B2: #VALUE!
L5: En Caso de ocupar 3 de 5, mostrar columnas H - I En caso de 2 de 2, ocultarlas.
G7: Fecha: | J7: =TODAY() -> 46288
B9: Categoría | D9: =Inscripciones!B2 -> U13 MASCULINO | E9: Grupo nº | F9: 2 | G9: Mesa nº
B11: Orden | C11: Carné | D11: Jugadores | E11: Lugar | F11: Ranking | G11: Puntos
A12: =F9+0.1 -> 2.1 | B12: 1 | C12: =VLOOKUP(A12,Inscripciones!A5:G167,2,FALSE) -> 4025 | D12: =IF(ISBLANK(C12),"",VLOOKUP(C12,Inscripciones!$B$5:$F$200,2,FALSE)) -> GABRIEL CORRALES BARRANTES | E12: =IF(ISBLANK(C12),"",VLOOKUP(C12,Inscripciones!$B$5:$F$200,3,FALSE)) -> ESPARZA | F12: =IF(ISBLANK(C12),"",VLOOKUP(C12,Inscripciones!$B$5:$F$200,4,FALSE)) -> 2 | G12: =IF(ISBLANK(C12),"",VLOOKUP(C12,Inscripciones!$B$5:$F$200,5,FALSE)) -> 698 | J12: =IF(ISBLANK(J11)," ",(E18+F18+G18+E20+F20+G20+H18+I18+H20+I20)/(E19+F19+G19+E21+F21+G21+H19+I19+H21+I21))
A13: =F9+0.2 -> 2.2 | B13: 2 | C13: =VLOOKUP(A13,Inscripciones!A5:G168,2,FALSE) -> 4778 | D13: =IF(ISBLANK(C13),"",VLOOKUP(C13,Inscripciones!$B$5:$F$200,2,FALSE)) -> JOSE PABLO DELGADO FERNANDEZ | E13: =IF(ISBLANK(C13),"",VLOOKUP(C13,Inscripciones!$B$5:$F$200,3,FALSE)) -> SAN CARLOS | F13: =IF(ISBLANK(C13),"",VLOOKUP(C13,Inscripciones!$B$5:$F$200,4,FALSE)) -> 39 | G13: =IF(ISBLANK(C13),"",VLOOKUP(C13,Inscripciones!$B$5:$F$200,5,FALSE)) -> 488 | J13: =IF(ISBLANK(J11)," ",(E21+F21+G21+E22+F22+G22+H21+I21+H22+I22)/(E20+F20+G20+E23+F23+G23+H20+I20+H23+I23))
A14: =+F9+0.3 -> 2.3 | B14: 3 | C14: =VLOOKUP(A14,Inscripciones!A6:G169,2,FALSE) -> 4825 | D14: =IF(ISBLANK(C14),"",VLOOKUP(C14,Inscripciones!$B$7:$F$200,2,FALSE)) -> SANTIAGO MELENDEZ MONTERO | E14: =IF(ISBLANK(C14),"",VLOOKUP(C14,Inscripciones!$B$7:$F$200,3,FALSE)) -> PÉREZ ZELEDÓN | F14: =IF(ISBLANK(C14),"",VLOOKUP(C14,Inscripciones!$B$7:$F$200,4,FALSE)) -> 42 | G14: =IF(ISBLANK(C14),"",VLOOKUP(C14,Inscripciones!$B$7:$F$200,5,FALSE)) -> 483 | J14: =IF(ISBLANK(J11)," ",(E19+F19+G19+E23+F23+G23+H19+I19+H23+I23)/(E18+F18+G18+E22+F22+G22+H18+I18+H22+I22))
B17: Partida | D17: JUGADOR | E17: 1º set | F17: 2º set | G17: 3º set | H17: 4º set | I17: 5º set | J17: Ganador
B18: 1 | C18: 1 | D18: =D12 -> GABRIEL CORRALES BARRANTES | E18: 11 | F18: 11 | J18: {=IF(AND(TRIM(E18)="WO",TRIM(E19)="WO"),"",IF(TRIM(E19)="WO",C18,IF(TRIM(E18)="WO",C19,IF(SUMPRODUCT(--(E18:I18>E19:I19))>SUMPRODUCT(--(E19:I19>E18:I18)),C18,IF(SUMPRODUCT(--(E19:I19>E18:I18))>SUMPRODUCT(--(E18:I18>E19:I19)),C19,"")))))} -> 1
C19: 3 | D19: =D14 -> SANTIAGO MELENDEZ MONTERO | E19: 5 | F19: 2
B20: 2 | C20: 1 | D20: =D12 -> GABRIEL CORRALES BARRANTES | E20: 11 | F20: 11 | J20: {=IF(AND(TRIM(E20)="WO",TRIM(E21)="WO"),"",IF(TRIM(E21)="WO",C20,IF(TRIM(E20)="WO",C21,IF(SUMPRODUCT(--(E20:I20>E21:I21))>SUMPRODUCT(--(E21:I21>E20:I20)),C20,IF(SUMPRODUCT(--(E21:I21>E20:I20))>SUMPRODUCT(--(E20:I20>E21:I21)),C21,"")))))} -> 1
C21: 2 | D21: =D13 -> JOSE PABLO DELGADO FERNANDEZ | E21: 1 | F21: 5
B22: 3 | C22: 2 | D22: =D13 -> JOSE PABLO DELGADO FERNANDEZ | E22: 1 | F22: 11 | G22: 6 | J22: {=IF(AND(TRIM(E22)="WO",TRIM(E23)="WO"),"",IF(TRIM(E23)="WO",C22,IF(TRIM(E22)="WO",C23,IF(SUMPRODUCT(--(E22:I22>E23:I23))>SUMPRODUCT(--(E23:I23>E22:I22)),C22,IF(SUMPRODUCT(--(E23:I23>E22:I22))>SUMPRODUCT(--(E22:I22>E23:I23)),C23,"")))))} -> 3
C23: 3 | D23: =D14 -> SANTIAGO MELENDEZ MONTERO | E23: 11 | F23: 3 | G23: 11
C32: Clasificados (# de carne) | F32: Revisión de Camisas y Raquetas
C33: Carnet | D33: Nombre | F33: Revisión de nombres y resultados
C34: 4025 | D34: =IF(ISBLANK(C34),"",VLOOKUP(C34,Inscripciones!$B$5:$F$200,2,FALSE)) -> GABRIEL CORRALES BARRANTES | F34: Árbitro
C35: 4825 | D35: =IF(ISBLANK(C35),"",VLOOKUP(C35,Inscripciones!$B$5:$F$200,2,FALSE)) -> SANTIAGO MELENDEZ MONTERO | F35: Marque si hay informe

Sheet Grupo 3
B2: #VALUE!
L5: En Caso de ocupar 3 de 5, mostrar columnas H - I En caso de 2 de 2, ocultarlas.
G7: Fecha: | J7: =TODAY() -> 46288
B9: Categoría | D9: =Inscripciones!B2 -> U13 MASCULINO | E9: Grupo nº | F9: 3 | G9: Mesa nº
B11: Orden | C11: Carné | D11: Jugadores | E11: Lugar | F11: Ranking | G11: Puntos
A12: =F9+0.1 -> 3.1 | B12: 1 | C12: =VLOOKUP(A12,Inscripciones!A5:G167,2,FALSE) -> 3787 | D12: =IF(ISBLANK(C12),"",VLOOKUP(C12,Inscripciones!$B$5:$F$200,2,FALSE)) -> ISAAC RIVERA TORRES | E12: =IF(ISBLANK(C12),"",VLOOKUP(C12,Inscripciones!$B$5:$F$200,3,FALSE)) -> CURRIDABAT | F12: =IF(ISBLANK(C12),"",VLOOKUP(C12,Inscripciones!$B$5:$F$200,4,FALSE)) -> 3 | G12: =IF(ISBLANK(C12),"",VLOOKUP(C12,Inscripciones!$B$5:$F$200,5,FALSE)) -> 624 | J12: =IF(ISBLANK(J11)," ",(E18+F18+G18+E20+F20+G20+H18+I18+H20+I20)/(E19+F19+G19+E21+F21+G21+H19+I19+H21+I21))
A13: =F9+0.2 -> 3.2 | B13: 2 | C13: =VLOOKUP(A13,Inscripciones!A5:G168,2,FALSE) -> 4465 | D13: =IF(ISBLANK(C13),"",VLOOKUP(C13,Inscripciones!$B$5:$F$200,2,FALSE)) -> JULIÁN ZUÑIGA AGÜERO | E13: =IF(ISBLANK(C13),"",VLOOKUP(C13,Inscripciones!$B$5:$F$200,3,FALSE)) -> ESPARZA | F13: =IF(ISBLANK(C13),"",VLOOKUP(C13,Inscripciones!$B$5:$F$200,4,FALSE)) -> 36 | G13: =IF(ISBLANK(C13),"",VLOOKUP(C13,Inscripciones!$B$5:$F$200,5,FALSE)) -> 492 | J13: =IF(ISBLANK(J11)," ",(E21+F21+G21+E22+F22+G22+H21+I21+H22+I22)/(E20+F20+G20+E23+F23+G23+H20+I20+H23+I23))
A14: =+F9+0.3 -> 3.3 | B14: 3 | C14: =VLOOKUP(A14,Inscripciones!A6:G169,2,FALSE) -> 4740 | D14: =IF(ISBLANK(C14),"",VLOOKUP(C14,Inscripciones!$B$7:$F$200,2,FALSE)) -> TOMÁS AGUILAR JIMÉNEZ | E14: =IF(ISBLANK(C14),"",VLOOKUP(C14,Inscripciones!$B$7:$F$200,3,FALSE)) -> SANTA ANA | F14: =IF(ISBLANK(C14),"",VLOOKUP(C14,Inscripciones!$B$7:$F$200,4,FALSE)) -> 43 | G14: =IF(ISBLANK(C14),"",VLOOKUP(C14,Inscripciones!$B$7:$F$200,5,FALSE)) -> 474 | J14: =IF(ISBLANK(J11)," ",(E19+F19+G19+E23+F23+G23+H19+I19+H23+I23)/(E18+F18+G18+E22+F22+G22+H18+I18+H22+I22))
B17: Partida | D17: JUGADOR | E17: 1º set | F17: 2º set | G17: 3º set | H17: 4º set | I17: 5º set | J17: Ganador
B18: 1 | C18: 1 | D18: =D12 -> ISAAC RIVERA TORRES | E18: 11 | F18: 11 | J18: 1
C19: 3 | D19: =D14 -> TOMÁS AGUILAR JIMÉNEZ | E19: 2 | F19: 2
B20: 2 | C20: 1 | D20: =D12 -> ISAAC RIVERA TORRES | E20: 11 | F20: 11 | J20: 1
C21: 2 | D21: =D13 -> JULIÁN ZUÑIGA AGÜERO | E21: 7 | F21: 7
B22: 3 | C22: 2 | D22: =D13 -> JULIÁN ZUÑIGA AGÜERO | E22: 11 | F22: 11 | J22: 2
C23: 3 | D23: =D14 -> TOMÁS AGUILAR JIMÉNEZ | E23: 4 | F23: 7
C32: Clasificados (# de carne) | F32: Revisión de Camisas y Raquetas
C33: Carnet | D33: Nombre | F33: Revisión de nombres y resultados
C34: 3787 | D34: =IF(ISBLANK(C34),"",VLOOKUP(C34,Inscripciones!$B$5:$F$200,2,FALSE)) -> ISAAC RIVERA TORRES | F34: Árbitro
C35: 4465 | D35: =IF(ISBLANK(C35),"",VLOOKUP(C35,Inscripciones!$B$5:$F$200,2,FALSE)) -> JULIÁN ZUÑIGA AGÜERO | F35: Marque si hay informe

Sheet Grupo 4
B2: #VALUE!
L5: En Caso de ocupar 3 de 5, mostrar columnas H - I En caso de 2 de 2, ocultarlas.
G7: Fecha: | J7: =TODAY() -> 46288
B9: Categoría | D9: =Inscripciones!B2 -> U13 MASCULINO | E9: Grupo nº | F9: 4 | G9: Mesa nº
B11: Orden | C11: Carné | D11: Jugadores | E11: Lugar | F11: Ranking | G11: Puntos
A12: =F9+0.1 -> 4.1 | B12: 1 | C12: =VLOOKUP(A12,Inscripciones!A5:G167,2,FALSE) -> 4297 | D12: =IF(ISBLANK(C12),"",VLOOKUP(C12,Inscripciones!$B$5:$F$200,2,FALSE)) -> JESÉ DAVID CHAVES MUÑOZ | E12: =IF(ISBLANK(C12),"",VLOOKUP(C12,Inscripciones!$B$5:$F$200,3,FALSE)) -> ESPARZA | F12: =IF(ISBLANK(C12),"",VLOOKUP(C12,Inscripciones!$B$5:$F$200,4,FALSE)) -> 4 | G12: =IF(ISBLANK(C12),"",VLOOKUP(C12,Inscripciones!$B$5:$F$200,5,FALSE)) -> 619 | J12: =IF(ISBLANK(J11)," ",(E18+F18+G18+E20+F20+G20+H18+I18+H20+I20)/(E19+F19+G19+E21+F21+G21+H19+I19+H21+I21))
A13: =F9+0.2 -> 4.2 | B13: 2 | C13: =VLOOKUP(A13,Inscripciones!A5:G168,2,FALSE) -> 4706 | D13: =IF(ISBLANK(C13),"",VLOOKUP(C13,Inscripciones!$B$5:$F$200,2,FALSE)) -> ISAAC RÍOS FERNÁNDEZ | E13: =IF(ISBLANK(C13),"",VLOOKUP(C13,Inscripciones!$B$5:$F$200,3,FALSE)) -> CCDR SAN JOSÉ | F13: =IF(ISBLANK(C13),"",VLOOKUP(C13,Inscripciones!$B$5:$F$200,4,FALSE)) -> 35 | G13: =IF(ISBLANK(C13),"",VLOOKUP(C13,Inscripciones!$B$5:$F$200,5,FALSE)) -> 492 | J13: =IF(ISBLANK(J11)," ",(E21+F21+G21+E22+F22+G22+H21+I21+H22+I22)/(E20+F20+G20+E23+F23+G23+H20+I20+H23+I23))
A14: =+F9+0.3 -> 4.3 | B14: 3 | C14: =VLOOKUP(A14,Inscripciones!A6:G169,2,FALSE) -> 4726 | D14: =IF(ISBLANK(C14),"",VLOOKUP(C14,Inscripciones!$B$7:$F$200,2,FALSE)) -> DIEGO WU WU | E14: =IF(ISBLANK(C14),"",VLOOKUP(C14,Inscripciones!$B$7:$F$200,3,FALSE)) -> ESCAZÚ | F14: =IF(ISBLANK(C14),"",VLOOKUP(C14,Inscripciones!$B$7:$F$200,4,FALSE)) -> 44 | G14: =IF(ISBLANK(C14),"",VLOOKUP(C14,Inscripciones!$B$7:$F$200,5,FALSE)) -> 473 | J14: =IF(ISBLANK(J11)," ",(E19+F19+G19+E23+F23+G23+H19+I19+H23+I23)/(E18+F18+G18+E22+F22+G22+H18+I18+H22+I22))
B17: Partida | D17: JUGADOR | E17: 1º set | F17: 2º set | G17: 3º set | H17: 4º set | I17: 5º set | J17: Ganador
B18: 1 | C18: 1 | D18: =D12 -> JESÉ DAVID CHAVES MUÑOZ | E18: 11 | F18: 11 | J18: {=IF(AND(TRIM(E18)="WO",TRIM(E19)="WO"),"",IF(TRIM(E19)="WO",C18,IF(TRIM(E18)="WO",C19,IF(SUMPRODUCT(--(E18:I18>E19:I19))>SUMPRODUCT(--(E19:I19>E18:I18)),C18,IF(SUMPRODUCT(--(E19:I19>E18:I18))>SUMPRODUCT(--(E18:I18>E19:I19)),C19,"")))))} -> 1
C19: 3 | D19: =D14 -> DIEGO WU WU | E19: 5 | F19: 5
B20: 2 | C20: 1 | D20: =D12 -> JESÉ DAVID CHAVES MUÑOZ | E20: 11 | F20: 11 | J20: {=IF(AND(TRIM(E20)="WO",TRIM(E21)="WO"),"",IF(TRIM(E21)="WO",C20,IF(TRIM(E20)="WO",C21,IF(SUMPRODUCT(--(E20:I20>E21:I21))>SUMPRODUCT(--(E21:I21>E20:I20)),C20,IF(SUMPRODUCT(--(E21:I21>E20:I20))>SUMPRODUCT(--(E20:I20>E21:I21)),C21,"")))))} -> 1
C21: 2 | D21: =D13 -> ISAAC RÍOS FERNÁNDEZ | E21: 7 | F21: 2
B22: 3 | C22: 2 | D22: =D13 -> ISAAC RÍOS FERNÁNDEZ | E22: 11 | F22: 11 | J22: {=IF(AND(TRIM(E22)="WO",TRIM(E23)="WO"),"",IF(TRIM(E23)="WO",C22,IF(TRIM(E22)="WO",C23,IF(SUMPRODUCT(--(E22:I22>E23:I23))>SUMPRODUCT(--(E23:I23>E22:I22)),C22,IF(SUMPRODUCT(--(E23:I23>E22:I22))>SUMPRODUCT(--(E22:I22>E23:I23)),C23,"")))))} -> 2
C23: 3 | D23: =D14 -> DIEGO WU WU | E23: 6 | F23: 4
C32: Clasificados (# de carne) | F32: Revisión de Camisas y Raquetas
C33: Carnet | D33: Nombre | F33: Revisión de nombres y resultados
C34: 4297 | D34: =IF(ISBLANK(C34),"",VLOOKUP(C34,Inscripciones!$B$5:$F$200,2,FALSE)) -> JESÉ DAVID CHAVES MUÑOZ | F34: Árbitro
C35: 4706 | D35: =IF(ISBLANK(C35),"",VLOOKUP(C35,Inscripciones!$B$5:$F$200,2,FALSE)) -> ISAAC RÍOS FERNÁNDEZ | F35: Marque si hay informe

Sheet Grupo 5
B2: #VALUE!
L5: En Caso de ocupar 3 de 5, mostrar columnas H - I En caso de 2 de 2, ocultarlas.
G7: Fecha: | J7: =TODAY() -> 46288
B9: Categoría | D9: =Inscripciones!B2 -> U13 MASCULINO | E9: Grupo nº | F9: 5 | G9: Mesa nº
B11: Orden | C11: Carné | D11: Jugadores | E11: Lugar | F11: Ranking | G11: Puntos
A12: =F9+0.1 -> 5.1 | B12: 1 | C12: =VLOOKUP(A12,Inscripciones!A5:G167,2,FALSE) -> 4026 | D12: =IF(ISBLANK(C12),"",VLOOKUP(C12,Inscripciones!$B$5:$F$200,2,FALSE)) -> IAN GABRIEL VILLEGAS SALAS | E12: =IF(ISBLANK(C12),"",VLOOKUP(C12,Inscripciones!$B$5:$F$200,3,FALSE)) -> SAN CARLOS | F12: =IF(ISBLANK(C12),"",VLOOKUP(C12,Inscripciones!$B$5:$F$200,4,FALSE)) -> 5 | G12: =IF(ISBLANK(C12),"",VLOOKUP(C12,Inscripciones!$B$5:$F$200,5,FALSE)) -> 617 | J12: =IF(ISBLANK(J11)," ",(E18+F18+G18+E20+F20+G20+H18+I18+H20+I20)/(E19+F19+G19+E21+F21+G21+H19+I19+H21+I21))
A13: =F9+0.2 -> 5.2 | B13: 2 | C13: =VLOOKUP(A13,Inscripciones!A5:G168,2,FALSE) -> 3987 | D13: =IF(ISBLANK(C13),"",VLOOKUP(C13,Inscripciones!$B$5:$F$200,2,FALSE)) -> JOSÉ DANIEL FERNÁNDEZ HERRERA | E13: =IF(ISBLANK(C13),"",VLOOKUP(C13,Inscripciones!$B$5:$F$200,3,FALSE)) -> ESCAZÚ | F13: =IF(ISBLANK(C13),"",VLOOKUP(C13,Inscripciones!$B$5:$F$200,4,FALSE)) -> 34 | G13: =IF(ISBLANK(C13),"",VLOOKUP(C13,Inscripciones!$B$5:$F$200,5,FALSE)) -> 494 | J13: =IF(ISBLANK(J11)," ",(E21+F21+G21+E22+F22+G22+H21+I21+H22+I22)/(E20+F20+G20+E23+F23+G23+H20+I20+H23+I23))
A14: =+F9+0.3 -> 5.3 | B14: 3 | C14: =VLOOKUP(A14,Inscripciones!A6:G169,2,FALSE) -> 4547 | D14: =IF(ISBLANK(C14),"",VLOOKUP(C14,Inscripciones!$B$7:$F$200,2,FALSE)) -> LEONARDO COTO RAMIREZ | E14: =IF(ISBLANK(C14),"",VLOOKUP(C14,Inscripciones!$B$7:$F$200,3,FALSE)) -> GUARCO | F14: =IF(ISBLANK(C14),"",VLOOKUP(C14,Inscripciones!$B$7:$F$200,4,FALSE)) -> 45 | G14: =IF(ISBLANK(C14),"",VLOOKUP(C14,Inscripciones!$B$7:$F$200,5,FALSE)) -> 473 | J14: =IF(ISBLANK(J11)," ",(E19+F19+G19+E23+F23+G23+H19+I19+H23+I23)/(E18+F18+G18+E22+F22+G22+H18+I18+H22+I22))
B17: Partida | D17: JUGADOR | E17: 1º set | F17: 2º set | G17: 3º set | H17: 4º set | I17: 5º set | J17: Ganador
B18: 1 | C18: 1 | D18: =D12 -> IAN GABRIEL VILLEGAS SALAS | E18: 11 | F18: 11 | J18: {=IF(AND(TRIM(E18)="WO",TRIM(E19)="WO"),"",IF(TRIM(E19)="WO",C18,IF(TRIM(E18)="WO",C19,IF(SUMPRODUCT(--(E18:I18>E19:I19))>SUMPRODUCT(--(E19:I19>E18:I18)),C18,IF(SUMPRODUCT(--(E19:I19>E18:I18))>SUMPRODUCT(--(E18:I18>E19:I19)),C19,"")))))} -> 1
C19: 3 | D19: =D14 -> LEONARDO COTO RAMIREZ | E19: 2 | F19: 2
B20: 2 | C20: 1 | D20: =D12 -> IAN GABRIEL VILLEGAS SALAS | E20: 11 | F20: 11 | J20: {=IF(AND(TRIM(E20)="WO",TRIM(E21)="WO"),"",IF(TRIM(E21)="WO",C20,IF(TRIM(E20)="WO",C21,IF(SUMPRODUCT(--(E20:I20>E21:I21))>SUMPRODUCT(--(E21:I21>E20:I20)),C20,IF(SUMPRODUCT(--(E21:I21>E20:I20))>SUMPRODUCT(--(E20:I20>E21:I21)),C21,"")))))} -> 1
C21: 2 | D21: =D13 -> JOSÉ DANIEL FERNÁNDEZ HERRERA | E21: 4 | F21: 4
B22: 3 | C22: 2 | D22: =D13 -> JOSÉ DANIEL FERNÁNDEZ HERRERA | E22: 11 | F22: 11 | J22: {=IF(AND(TRIM(E22)="WO",TRIM(E23)="WO"),"",IF(TRIM(E23)="WO",C22,IF(TRIM(E22)="WO",C23,IF(SUMPRODUCT(--(E22:I22>E23:I23))>SUMPRODUCT(--(E23:I23>E22:I22)),C22,IF(SUMPRODUCT(--(E23:I23>E22:I22))>SUMPRODUCT(--(E22:I22>E23:I23)),C23,"")))))} -> 2
C23: 3 | D23: =D14 -> LEONARDO COTO RAMIREZ | E23: 4 | F23: 4
C32: Clasificados (# de carne) | F32: Revisión de Camisas y Raquetas
C33: Carnet | D33: Nombre | F33: Revisión de nombres y resultados
C34: 4026 | D34: =IF(ISBLANK(C34),"",VLOOKUP(C34,Inscripciones!$B$5:$F$200,2,FALSE)) -> IAN GABRIEL VILLEGAS SALAS | F34: Árbitro
C35: 3987 | D35: =IF(ISBLANK(C35),"",VLOOKUP(C35,Inscripciones!$B$5:$F$200,2,FALSE)) -> JOSÉ DANIEL FERNÁNDEZ HERRERA | F35: Marque si hay informe

Sheet Grupo 6
B2: #VALUE!
L5: En Caso de ocupar 3 de 5, mostrar columnas H - I En caso de 2 de 2, ocultarlas.
G7: Fecha: | J7: =TODAY() -> 46288
B9: Categoría | D9: =Inscripciones!B2 -> U13 MASCULINO | E9: Grupo nº | F9: 6 | G9: Mesa nº
B11: Orden | C11: Carné | D11: Jugadores | E11: Lugar | F11: Ranking | G11: Puntos
