Workbook
Name a: #REF!
Name a: #REF!
Name acdb: #REF!
Name acdb: #REF!
Name ACDB1: #REF!
Name ACDB1: #REF!
Name acdf: #REF!
Name acdh: #REF!
Name acdo: #REF!
Name aceq: [1]AE!$A:$IV
Name aceq: #REF!
Name acif: #REF!
Name acin: #REF!
Name ACIN1: #REF!
Name acti: #REF!
Name avc: [2]DORSAL!$A$2:$G$120
Name avc: #REF!
Name datos: [3]Datos!$A$2:$G$140
Name datos: #REF!
Name dorsal: [2]DORSAL!$A$2:$G$120
Name dorsal: #REF!
Name EQ: [4]EQU!$A:$IV
Name EQ: #REF!
Name IN: [4]IND!$A:$IV
Name IN: #REF!
Name IND: [5]IN!$A$3:$IV$102
Name IND: #REF!
Name IPC_Member: #REF!
Name JBS: [6]JB!$A$1:$E$100
Name JBS: #REF!
Name JGS: #REF!
Name JUG: [7]Jug!$A$2:$D$13
Name JUG: #REF!
Name PC: #REF!
Name PCS: #REF!
Name PLAYERS: [8]Players!$B$4:$H$124
Name PLAYERS: #REF!
Name RK: #REF!
Name RKJB: #REF!
Name RKJG: #REF!
Name SI: #REF!
Name sssss: #REF!

Sheet Sheet1

Sheet Tabulación
C1: Ganadores | F1: Perdedores | K1: 14 | L1: {=VLOOKUP(INDIRECT("'Grupo " & K1 & "'!J18"),INDIRECT("'Grupo " & K1 & "'!B12"):INDIRECT("'Grupo " & K1 & "'!J15"),2,FALSE)} -> #REF! | M1: {=VLOOKUP(IF(INDIRECT("'Grupo " & K1 & "'!J18")=INDIRECT("'Grupo " & K1 & "'!C18"),INDIRECT("'Grupo " & K1 & "'!C19"),INDIRECT("'Grupo " & K1 & "'!C18")),INDIRECT("'Grupo " & K1 & "'!B12"):INDIRECT("'Grupo " & K1 & "'!G15"),2,FALSE)} -> #REF! | O1: {=VLOOKUP(IF(INDIRECT("'Grupo " & K1 & "'!J18")=INDIRECT("'Grupo " & K1 & "'!C18"),INDIRECT("'Grupo " & K1 & "'!C19"),INDIRECT("'Grupo " & K1 & "'!C18")),INDIRECT("'Grupo " & K1 & "'!B12"):INDIRECT("'Grupo " & K1 & "'!G15"),2,FALSE)} -> #REF! | P1: {=VLOOKUP(INDIRECT("'Grupo " & K1 & "'!J18"),INDIRECT("'Grupo " & K1 & "'!B12"):INDIRECT("'Grupo " & K1 & "'!J15"),2,FALSE)} -> #REF!
B2: 1 | C2: {=VLOOKUP(INDIRECT("'Grupo " & B2 & "'!J18"),INDIRECT("'Grupo " & B2 & "'!B12"):INDIRECT("'Grupo " & B2 & "'!J15"),2,FALSE)} -> 4159 | D2: {=VLOOKUP(IF(INDIRECT("'Grupo " & B2 & "'!J18")=INDIRECT("'Grupo " & B2 & "'!C18"),INDIRECT("'Grupo " & B2 & "'!C19"),INDIRECT("'Grupo " & B2 & "'!C18")),INDIRECT("'Grupo " & B2 & "'!B12"):INDIRECT("'Grupo " & B2 & "'!G15"),2,FALSE)} -> 4276 | F2: {=VLOOKUP(IF(INDIRECT("'Grupo " & B2 & "'!J18")=INDIRECT("'Grupo " & B2 & "'!C18"),INDIRECT("'Grupo " & B2 & "'!C19"),INDIRECT("'Grupo " & B2 & "'!C18")),INDIRECT("'Grupo " & B2 & "'!B12"):INDIRECT("'Grupo " & B2 & "'!G15"),2,FALSE)} -> 4276 | G2: {=VLOOKUP(INDIRECT("'Grupo " & B2 & "'!J18"),INDIRECT("'Grupo " & B2 & "'!B12"):INDIRECT("'Grupo " & B2 & "'!J15"),2,FALSE)} -> 4159 | L2: {=VLOOKUP(INDIRECT("'Grupo " & K1 & "'!J20"),INDIRECT("'Grupo " & K1 & "'!B12"):INDIRECT("'Grupo " & K1 & "'!J15"),2,FALSE)} -> #REF! | M2: {=VLOOKUP(IF(INDIRECT("'Grupo " & K1 & "'!J20")=INDIRECT("'Grupo " & K1 & "'!C20"),INDIRECT("'Grupo " & K1 & "'!C21"),INDIRECT("'Grupo " & K1 & "'!C20")),INDIRECT("'Grupo " & K1 & "'!B12"):INDIRECT("'Grupo " & K1 & "'!G15"),2,FALSE)} -> #REF! | O2: {=VLOOKUP(IF(INDIRECT("'Grupo " & K1 & "'!J20")=INDIRECT("'Grupo " & K1 & "'!C20"),INDIRECT("'Grupo " & K1 & "'!C21"),INDIRECT("'Grupo " & K1 & "'!C20")),INDIRECT("'Grupo " & K1 & "'!B12"):INDIRECT("'Grupo " & K1 & "'!G15"),2,FALSE)} -> #REF! | P2: {=VLOOKUP(INDIRECT("'Grupo " & K1 & "'!J20"),INDIRECT("'Grupo " & K1 & "'!B12"):INDIRECT("'Grupo " & K1 & "'!J15"),2,FALSE)} -> #REF!
C3: {=VLOOKUP(INDIRECT("'Grupo " & B2 & "'!J20"),INDIRECT("'Grupo " & B2 & "'!B12"):INDIRECT("'Grupo " & B2 & "'!J15"),2,FALSE)} -> 4159 | D3: {=VLOOKUP(IF(INDIRECT("'Grupo " & B2 & "'!J20")=INDIRECT("'Grupo " & B2 & "'!C20"),INDIRECT("'Grupo " & B2 & "'!C21"),INDIRECT("'Grupo " & B2 & "'!C20")),INDIRECT("'Grupo " & B2 & "'!B12"):INDIRECT("'Grupo " & B2 & "'!G15"),2,FALSE)} -> 4601 | F3: {=VLOOKUP(IF(INDIRECT("'Grupo " & B2 & "'!J20")=INDIRECT("'Grupo " & B2 & "'!C20"),INDIRECT("'Grupo " & B2 & "'!C21"),INDIRECT("'Grupo " & B2 & "'!C20")),INDIRECT("'Grupo " & B2 & "'!B12"):INDIRECT("'Grupo " & B2 & "'!G15"),2,FALSE)} -> 4601 | G3: {=VLOOKUP(INDIRECT("'Grupo " & B2 & "'!J20"),INDIRECT("'Grupo " & B2 & "'!B12"):INDIRECT("'Grupo " & B2 & "'!J15"),2,FALSE)} -> 4159 | L3: {=VLOOKUP(INDIRECT("'Grupo " & K1 & "'!J22"),INDIRECT("'Grupo " & K1 & "'!B12"):INDIRECT("'Grupo " & K1 & "'!J15"),2,FALSE)} -> #REF! | M3: {=VLOOKUP(IF(INDIRECT("'Grupo " & K1 & "'!J22")=INDIRECT("'Grupo " & K1 & "'!C22"),INDIRECT("'Grupo " & K1 & "'!C23"),INDIRECT("'Grupo " & K1 & "'!C22")),INDIRECT("'Grupo " & K1 & "'!B12"):INDIRECT("'Grupo " & K1 & "'!G15"),2,FALSE)} -> #REF! | O3: {=VLOOKUP(IF(INDIRECT("'Grupo " & K1 & "'!J22")=INDIRECT("'Grupo " & K1 & "'!C22"),INDIRECT("'Grupo " & K1 & "'!C23"),INDIRECT("'Grupo " & K1 & "'!C22")),INDIRECT("'Grupo " & K1 & "'!B12"):INDIRECT("'Grupo " & K1 & "'!G15"),2,FALSE)} -> #REF! | P3: {=VLOOKUP(INDIRECT("'Grupo " & K1 & "'!J22"),INDIRECT("'Grupo " & K1 & "'!B12"):INDIRECT("'Grupo " & K1 & "'!J15"),2,FALSE)} -> #REF!
C4: {=VLOOKUP(INDIRECT("'Grupo " & B2 & "'!J22"),INDIRECT("'Grupo " & B2 & "'!B12"):INDIRECT("'Grupo " & B2 & "'!J15"),2,FALSE)} -> 4276 | D4: {=VLOOKUP(IF(INDIRECT("'Grupo " & B2 & "'!J22")=INDIRECT("'Grupo " & B2 & "'!C22"),INDIRECT("'Grupo " & B2 & "'!C23"),INDIRECT("'Grupo " & B2 & "'!C22")),INDIRECT("'Grupo " & B2 & "'!B12"):INDIRECT("'Grupo " & B2 & "'!G15"),2,FALSE)} -> 4601 | F4: {=VLOOKUP(IF(INDIRECT("'Grupo " & B2 & "'!J22")=INDIRECT("'Grupo " & B2 & "'!C22"),INDIRECT("'Grupo " & B2 & "'!C23"),INDIRECT("'Grupo " & B2 & "'!C22")),INDIRECT("'Grupo " & B2 & "'!B12"):INDIRECT("'Grupo " & B2 & "'!G15"),2,FALSE)} -> 4601 | G4: {=VLOOKUP(INDIRECT("'Grupo " & B2 & "'!J22"),INDIRECT("'Grupo " & B2 & "'!B12"):INDIRECT("'Grupo " & B2 & "'!J15"),2,FALSE)} -> 4276 | L4: {=VLOOKUP(INDIRECT("'Grupo " & K1 & "'!J24"),INDIRECT("'Grupo " & K1 & "'!B12"):INDIRECT("'Grupo " & K1 & "'!J15"),2,FALSE)} -> #REF! | M4: {=VLOOKUP(IF(INDIRECT("'Grupo " & K1 & "'!J24")=INDIRECT("'Grupo " & K1 & "'!C24"),INDIRECT("'Grupo " & K1 & "'!C25"),INDIRECT("'Grupo " & K1 & "'!C24")),INDIRECT("'Grupo " & K1 & "'!B12"):INDIRECT("'Grupo " & K1 & "'!G15"),2,FALSE)} -> #REF! | O4: {=VLOOKUP(IF(INDIRECT("'Grupo " & K1 & "'!J24")=INDIRECT("'Grupo " & K1 & "'!C24"),INDIRECT("'Grupo " & K1 & "'!C25"),INDIRECT("'Grupo " & K1 & "'!C24")),INDIRECT("'Grupo " & K1 & "'!B12"):INDIRECT("'Grupo " & K1 & "'!G15"),2,FALSE)} -> #REF! | P4: {=VLOOKUP(INDIRECT("'Grupo " & K1 & "'!J24"),INDIRECT("'Grupo " & K1 & "'!B12"):INDIRECT("'Grupo " & K1 & "'!J15"),2,FALSE)} -> #REF!
B5: =B2+1 -> 2 | C5: {=VLOOKUP(INDIRECT("'Grupo " & B5 & "'!J18"),INDIRECT("'Grupo " & B5 & "'!B12"):INDIRECT("'Grupo " & B5 & "'!J15"),2,FALSE)} -> 4101 | D5: {=VLOOKUP(IF(INDIRECT("'Grupo " & B5 & "'!J18")=INDIRECT("'Grupo " & B5 & "'!C18"),INDIRECT("'Grupo " & B5 & "'!C19"),INDIRECT("'Grupo " & B5 & "'!C18")),INDIRECT("'Grupo " & B5 & "'!B12"):INDIRECT("'Grupo " & B5 & "'!G15"),2,FALSE)} -> 4164 | F5: {=VLOOKUP(IF(INDIRECT("'Grupo " & B5 & "'!J18")=INDIRECT("'Grupo " & B5 & "'!C18"),INDIRECT("'Grupo " & B5 & "'!C19"),INDIRECT("'Grupo " & B5 & "'!C18")),INDIRECT("'Grupo " & B5 & "'!B12"):INDIRECT("'Grupo " & B5 & "'!G15"),2,FALSE)} -> 4164 | G5: {=VLOOKUP(INDIRECT("'Grupo " & B5 & "'!J18"),INDIRECT("'Grupo " & B5 & "'!B12"):INDIRECT("'Grupo " & B5 & "'!J15"),2,FALSE)} -> 4101 | L5: {=VLOOKUP(INDIRECT("'Grupo " & K1 & "'!J26"),INDIRECT("'Grupo " & K1 & "'!B12"):INDIRECT("'Grupo " & K1 & "'!J15"),2,FALSE)} -> #REF! | M5: {=VLOOKUP(IF(INDIRECT("'Grupo " & K1 & "'!J26")=INDIRECT("'Grupo " & K1 & "'!C26"),INDIRECT("'Grupo " & K1 & "'!C27"),INDIRECT("'Grupo " & K1 & "'!C26")),INDIRECT("'Grupo " & K1 & "'!B12"):INDIRECT("'Grupo " & K1 & "'!G15"),2,FALSE)} -> #REF! | O5: {=VLOOKUP(IF(INDIRECT("'Grupo " & K1 & "'!J26")=INDIRECT("'Grupo " & K1 & "'!C26"),INDIRECT("'Grupo " & K1 & "'!C27"),INDIRECT("'Grupo " & K1 & "'!C26")),INDIRECT("'Grupo " & K1 & "'!B12"):INDIRECT("'Grupo " & K1 & "'!G15"),2,FALSE)} -> #REF! | P5: {=VLOOKUP(INDIRECT("'Grupo " & K1 & "'!J26"),INDIRECT("'Grupo " & K1 & "'!B12"):INDIRECT("'Grupo " & K1 & "'!J15"),2,FALSE)} -> #REF!
C6: {=VLOOKUP(INDIRECT("'Grupo " & B5 & "'!J20"),INDIRECT("'Grupo " & B5 & "'!B12"):INDIRECT("'Grupo " & B5 & "'!J15"),2,FALSE)} -> 4101 | D6: {=VLOOKUP(IF(INDIRECT("'Grupo " & B5 & "'!J20")=INDIRECT("'Grupo " & B5 & "'!C20"),INDIRECT("'Grupo " & B5 & "'!C21"),INDIRECT("'Grupo " & B5 & "'!C20")),INDIRECT("'Grupo " & B5 & "'!B12"):INDIRECT("'Grupo " & B5 & "'!G15"),2,FALSE)} -> 4348 | F6: {=VLOOKUP(IF(INDIRECT("'Grupo " & B5 & "'!J20")=INDIRECT("'Grupo " & B5 & "'!C20"),INDIRECT("'Grupo " & B5 & "'!C21"),INDIRECT("'Grupo " & B5 & "'!C20")),INDIRECT("'Grupo " & B5 & "'!B12"):INDIRECT("'Grupo " & B5 & "'!G15"),2,FALSE)} -> 4348 | G6: {=VLOOKUP(INDIRECT("'Grupo " & B5 & "'!J20"),INDIRECT("'Grupo " & B5 & "'!B12"):INDIRECT("'Grupo " & B5 & "'!J15"),2,FALSE)} -> 4101 | L6: {=VLOOKUP(INDIRECT("'Grupo " & K1 & "'!J28"),INDIRECT("'Grupo " & K1 & "'!B12"):INDIRECT("'Grupo " & K1 & "'!J15"),2,FALSE)} -> #REF! | M6: {=VLOOKUP(IF(INDIRECT("'Grupo " & K1 & "'!J28")=INDIRECT("'Grupo " & K1 & "'!C28"),INDIRECT("'Grupo " & K1 & "'!C29"),INDIRECT("'Grupo " & K1 & "'!C28")),INDIRECT("'Grupo " & K1 & "'!B12"):INDIRECT("'Grupo " & K1 & "'!G15"),2,FALSE)} -> #REF! | O6: {=VLOOKUP(IF(INDIRECT("'Grupo " & K1 & "'!J28")=INDIRECT("'Grupo " & K1 & "'!C28"),INDIRECT("'Grupo " & K1 & "'!C29"),INDIRECT("'Grupo " & K1 & "'!C28")),INDIRECT("'Grupo " & K1 & "'!B12"):INDIRECT("'Grupo " & K1 & "'!G15"),2,FALSE)} -> #REF! | P6: {=VLOOKUP(INDIRECT("'Grupo " & K1 & "'!J28"),INDIRECT("'Grupo " & K1 & "'!B12"):INDIRECT("'Grupo " & K1 & "'!J15"),2,FALSE)} -> #REF!
C7: {=VLOOKUP(INDIRECT("'Grupo " & B5 & "'!J22"),INDIRECT("'Grupo " & B5 & "'!B12"):INDIRECT("'Grupo " & B5 & "'!J15"),2,FALSE)} -> 4348 | D7: {=VLOOKUP(IF(INDIRECT("'Grupo " & B5 & "'!J22")=INDIRECT("'Grupo " & B5 & "'!C22"),INDIRECT("'Grupo " & B5 & "'!C23"),INDIRECT("'Grupo " & B5 & "'!C22")),INDIRECT("'Grupo " & B5 & "'!B12"):INDIRECT("'Grupo " & B5 & "'!G15"),2,FALSE)} -> 4164 | F7: {=VLOOKUP(IF(INDIRECT("'Grupo " & B5 & "'!J22")=INDIRECT("'Grupo " & B5 & "'!C22"),INDIRECT("'Grupo " & B5 & "'!C23"),INDIRECT("'Grupo " & B5 & "'!C22")),INDIRECT("'Grupo " & B5 & "'!B12"):INDIRECT("'Grupo " & B5 & "'!G15"),2,FALSE)} -> 4164 | G7: {=VLOOKUP(INDIRECT("'Grupo " & B5 & "'!J22"),INDIRECT("'Grupo " & B5 & "'!B12"):INDIRECT("'Grupo " & B5 & "'!J15"),2,FALSE)} -> 4348
B8: =B5+1 -> 3 | C8: {=VLOOKUP(INDIRECT("'Grupo " & B8 & "'!J18"),INDIRECT("'Grupo " & B8 & "'!B12"):INDIRECT("'Grupo " & B8 & "'!J15"),2,FALSE)} -> 3918 | D8: {=VLOOKUP(IF(INDIRECT("'Grupo " & B8 & "'!J18")=INDIRECT("'Grupo " & B8 & "'!C18"),INDIRECT("'Grupo " & B8 & "'!C19"),INDIRECT("'Grupo " & B8 & "'!C18")),INDIRECT("'Grupo " & B8 & "'!B12"):INDIRECT("'Grupo " & B8 & "'!G15"),2,FALSE)} -> 4535 | F8: {=VLOOKUP(IF(INDIRECT("'Grupo " & B8 & "'!J18")=INDIRECT("'Grupo " & B8 & "'!C18"),INDIRECT("'Grupo " & B8 & "'!C19"),INDIRECT("'Grupo " & B8 & "'!C18")),INDIRECT("'Grupo " & B8 & "'!B12"):INDIRECT("'Grupo " & B8 & "'!G15"),2,FALSE)} -> 4535 | G8: {=VLOOKUP(INDIRECT("'Grupo " & B8 & "'!J18"),INDIRECT("'Grupo " & B8 & "'!B12"):INDIRECT("'Grupo " & B8 & "'!J15"),2,FALSE)} -> 3918
C9: {=VLOOKUP(INDIRECT("'Grupo " & B8 & "'!J20"),INDIRECT("'Grupo " & B8 & "'!B12"):INDIRECT("'Grupo " & B8 & "'!J15"),2,FALSE)} -> 3918 | D9: {=VLOOKUP(IF(INDIRECT("'Grupo " & B8 & "'!J20")=INDIRECT("'Grupo " & B8 & "'!C20"),INDIRECT("'Grupo " & B8 & "'!C21"),INDIRECT("'Grupo " & B8 & "'!C20")),INDIRECT("'Grupo " & B8 & "'!B12"):INDIRECT("'Grupo " & B8 & "'!G15"),2,FALSE)} -> 3907 | F9: {=VLOOKUP(IF(INDIRECT("'Grupo " & B8 & "'!J20")=INDIRECT("'Grupo " & B8 & "'!C20"),INDIRECT("'Grupo " & B8 & "'!C21"),INDIRECT("'Grupo " & B8 & "'!C20")),INDIRECT("'Grupo " & B8 & "'!B12"):INDIRECT("'Grupo " & B8 & "'!G15"),2,FALSE)} -> 3907 | G9: {=VLOOKUP(INDIRECT("'Grupo " & B8 & "'!J20"),INDIRECT("'Grupo " & B8 & "'!B12"):INDIRECT("'Grupo " & B8 & "'!J15"),2,FALSE)} -> 3918
C10: {=VLOOKUP(INDIRECT("'Grupo " & B8 & "'!J22"),INDIRECT("'Grupo " & B8 & "'!B12"):INDIRECT("'Grupo " & B8 & "'!J15"),2,FALSE)} -> 3907 | D10: {=VLOOKUP(IF(INDIRECT("'Grupo " & B8 & "'!J22")=INDIRECT("'Grupo " & B8 & "'!C22"),INDIRECT("'Grupo " & B8 & "'!C23"),INDIRECT("'Grupo " & B8 & "'!C22")),INDIRECT("'Grupo " & B8 & "'!B12"):INDIRECT("'Grupo " & B8 & "'!G15"),2,FALSE)} -> 4535 | F10: {=VLOOKUP(IF(INDIRECT("'Grupo " & B8 & "'!J22")=INDIRECT("'Grupo " & B8 & "'!C22"),INDIRECT("'Grupo " & B8 & "'!C23"),INDIRECT("'Grupo " & B8 & "'!C22")),INDIRECT("'Grupo " & B8 & "'!B12"):INDIRECT("'Grupo " & B8 & "'!G15"),2,FALSE)} -> 4535 | G10: {=VLOOKUP(INDIRECT("'Grupo " & B8 & "'!J22"),INDIRECT("'Grupo " & B8 & "'!B12"):INDIRECT("'Grupo " & B8 & "'!J15"),2,FALSE)} -> 3907
B11: =B8+1 -> 4 | C11: {=VLOOKUP(INDIRECT("'Grupo " & B11 & "'!J18"),INDIRECT("'Grupo " & B11 & "'!B12"):INDIRECT("'Grupo " & B11 & "'!J15"),2,FALSE)} -> 4176 | D11: {=VLOOKUP(IF(INDIRECT("'Grupo " & B11 & "'!J18")=INDIRECT("'Grupo " & B11 & "'!C18"),INDIRECT("'Grupo " & B11 & "'!C19"),INDIRECT("'Grupo " & B11 & "'!C18")),INDIRECT("'Grupo " & B11 & "'!B12"):INDIRECT("'Grupo " & B11 & "'!G15"),2,FALSE)} -> 4380 | F11: {=VLOOKUP(IF(INDIRECT("'Grupo " & B11 & "'!J18")=INDIRECT("'Grupo " & B11 & "'!C18"),INDIRECT("'Grupo " & B11 & "'!C19"),INDIRECT("'Grupo " & B11 & "'!C18")),INDIRECT("'Grupo " & B11 & "'!B12"):INDIRECT("'Grupo " & B11 & "'!G15"),2,FALSE)} -> 4380 | G11: {=VLOOKUP(INDIRECT("'Grupo " & B11 & "'!J18"),INDIRECT("'Grupo " & B11 & "'!B12"):INDIRECT("'Grupo " & B11 & "'!J15"),2,FALSE)} -> 4176
C12: {=VLOOKUP(INDIRECT("'Grupo " & B11 & "'!J20"),INDIRECT("'Grupo " & B11 & "'!B12"):INDIRECT("'Grupo " & B11 & "'!J15"),2,FALSE)} -> 4176 | D12: {=VLOOKUP(IF(INDIRECT("'Grupo " & B11 & "'!J20")=INDIRECT("'Grupo " & B11 & "'!C20"),INDIRECT("'Grupo " & B11 & "'!C21"),INDIRECT("'Grupo " & B11 & "'!C20")),INDIRECT("'Grupo " & B11 & "'!B12"):INDIRECT("'Grupo " & B11 & "'!G15"),2,FALSE)} -> 4212 | F12: {=VLOOKUP(IF(INDIRECT("'Grupo " & B11 & "'!J20")=INDIRECT("'Grupo " & B11 & "'!C20"),INDIRECT("'Grupo " & B11 & "'!C21"),INDIRECT("'Grupo " & B11 & "'!C20")),INDIRECT("'Grupo " & B11 & "'!B12"):INDIRECT("'Grupo " & B11 & "'!G15"),2,FALSE)} -> 4212 | G12: {=VLOOKUP(INDIRECT("'Grupo " & B11 & "'!J20"),INDIRECT("'Grupo " & B11 & "'!B12"):INDIRECT("'Grupo " & B11 & "'!J15"),2,FALSE)} -> 4176
C13: {=VLOOKUP(INDIRECT("'Grupo " & B11 & "'!J22"),INDIRECT("'Grupo " & B11 & "'!B12"):INDIRECT("'Grupo " & B11 & "'!J15"),2,FALSE)} -> 4212 | D13: {=VLOOKUP(IF(INDIRECT("'Grupo " & B11 & "'!J22")=INDIRECT("'Grupo " & B11 & "'!C22"),INDIRECT("'Grupo " & B11 & "'!C23"),INDIRECT("'Grupo " & B11 & "'!C22")),INDIRECT("'Grupo " & B11 & "'!B12"):INDIRECT("'Grupo " & B11 & "'!G15"),2,FALSE)} -> 4380 | F13: {=VLOOKUP(IF(INDIRECT("'Grupo " & B11 & "'!J22")=INDIRECT("'Grupo " & B11 & "'!C22"),INDIRECT("'Grupo " & B11 & "'!C23"),INDIRECT("'Grupo " & B11 & "'!C22")),INDIRECT("'Grupo " & B11 & "'!B12"):INDIRECT("'Grupo " & B11 & "'!G15"),2,FALSE)} -> 4380 | G13: {=VLOOKUP(INDIRECT("'Grupo " & B11 & "'!J22"),INDIRECT("'Grupo " & B11 & "'!B12"):INDIRECT("'Grupo " & B11 & "'!J15"),2,FALSE)} -> 4212
B14: =B11+1 -> 5 | C14: {=VLOOKUP(INDIRECT("'Grupo " & B14 & "'!J18"),INDIRECT("'Grupo " & B14 & "'!B12"):INDIRECT("'Grupo " & B14 & "'!J15"),2,FALSE)} -> 4673 | D14: {=VLOOKUP(IF(INDIRECT("'Grupo " & B14 & "'!J18")=INDIRECT("'Grupo " & B14 & "'!C18"),INDIRECT("'Grupo " & B14 & "'!C19"),INDIRECT("'Grupo " & B14 & "'!C18")),INDIRECT("'Grupo " & B14 & "'!B12"):INDIRECT("'Grupo " & B14 & "'!G15"),2,FALSE)} -> 4274 | F14: {=VLOOKUP(IF(INDIRECT("'Grupo " & B14 & "'!J18")=INDIRECT("'Grupo " & B14 & "'!C18"),INDIRECT("'Grupo " & B14 & "'!C19"),INDIRECT("'Grupo " & B14 & "'!C18")),INDIRECT("'Grupo " & B14 & "'!B12"):INDIRECT("'Grupo " & B14 & "'!G15"),2,FALSE)} -> 4274 | G14: {=VLOOKUP(INDIRECT("'Grupo " & B14 & "'!J18"),INDIRECT("'Grupo " & B14 & "'!B12"):INDIRECT("'Grupo " & B14 & "'!J15"),2,FALSE)} -> 4673
C15: {=VLOOKUP(INDIRECT("'Grupo " & B14 & "'!J20"),INDIRECT("'Grupo " & B14 & "'!B12"):INDIRECT("'Grupo " & B14 & "'!J15"),2,FALSE)} -> 4274 | D15: {=VLOOKUP(IF(INDIRECT("'Grupo " & B14 & "'!J20")=INDIRECT("'Grupo " & B14 & "'!C20"),INDIRECT("'Grupo " & B14 & "'!C21"),INDIRECT("'Grupo " & B14 & "'!C20")),INDIRECT("'Grupo " & B14 & "'!B12"):INDIRECT("'Grupo " & B14 & "'!G15"),2,FALSE)} -> 4579 | F15: {=VLOOKUP(IF(INDIRECT("'Grupo " & B14 & "'!J20")=INDIRECT("'Grupo " & B14 & "'!C20"),INDIRECT("'Grupo " & B14 & "'!C21"),INDIRECT("'Grupo " & B14 & "'!C20")),INDIRECT("'Grupo " & B14 & "'!B12"):INDIRECT("'Grupo " & B14 & "'!G15"),2,FALSE)} -> 4579 | G15: {=VLOOKUP(INDIRECT("'Grupo " & B14 & "'!J20"),INDIRECT("'Grupo " & B14 & "'!B12"):INDIRECT("'Grupo " & B14 & "'!J15"),2,FALSE)} -> 4274
C16: {=VLOOKUP(INDIRECT("'Grupo " & B14 & "'!J22"),INDIRECT("'Grupo " & B14 & "'!B12"):INDIRECT("'Grupo " & B14 & "'!J15"),2,FALSE)} -> 4579 | D16: {=VLOOKUP(IF(INDIRECT("'Grupo " & B14 & "'!J22")=INDIRECT("'Grupo " & B14 & "'!C22"),INDIRECT("'Grupo " & B14 & "'!C23"),INDIRECT("'Grupo " & B14 & "'!C22")),INDIRECT("'Grupo " & B14 & "'!B12"):INDIRECT("'Grupo " & B14 & "'!G15"),2,FALSE)} -> 4673 | F16: {=VLOOKUP(IF(INDIRECT("'Grupo " & B14 & "'!J22")=INDIRECT("'Grupo " & B14 & "'!C22"),INDIRECT("'Grupo " & B14 & "'!C23"),INDIRECT("'Grupo " & B14 & "'!C22")),INDIRECT("'Grupo " & B14 & "'!B12"):INDIRECT("'Grupo " & B14 & "'!G15"),2,FALSE)} -> 4673 | G16: {=VLOOKUP(INDIRECT("'Grupo " & B14 & "'!J22"),INDIRECT("'Grupo " & B14 & "'!B12"):INDIRECT("'Grupo " & B14 & "'!J15"),2,FALSE)} -> 4579
B17: =B14+1 -> 6 | C17: {=VLOOKUP(INDIRECT("'Grupo " & B17 & "'!J18"),INDIRECT("'Grupo " & B17 & "'!B12"):INDIRECT("'Grupo " & B17 & "'!J15"),2,FALSE)} -> 4273 | D17: {=VLOOKUP(IF(INDIRECT("'Grupo " & B17 & "'!J18")=INDIRECT("'Grupo " & B17 & "'!C18"),INDIRECT("'Grupo " & B17 & "'!C19"),INDIRECT("'Grupo " & B17 & "'!C18")),INDIRECT("'Grupo " & B17 & "'!B12"):INDIRECT("'Grupo " & B17 & "'!G15"),2,FALSE)} -> 3912 | F17: {=VLOOKUP(IF(INDIRECT("'Grupo " & B17 & "'!J18")=INDIRECT("'Grupo " & B17 & "'!C18"),INDIRECT("'Grupo " & B17 & "'!C19"),INDIRECT("'Grupo " & B17 & "'!C18")),INDIRECT("'Grupo " & B17 & "'!B12"):INDIRECT("'Grupo " & B17 & "'!G15"),2,FALSE)} -> 3912 | G17: {=VLOOKUP(INDIRECT("'Grupo " & B17 & "'!J18"),INDIRECT("'Grupo " & B17 & "'!B12"):INDIRECT("'Grupo " & B17 & "'!J15"),2,FALSE)} -> 4273
C18: {=VLOOKUP(INDIRECT("'Grupo " & B17 & "'!J20"),INDIRECT("'Grupo " & B17 & "'!B12"):INDIRECT("'Grupo " & B17 & "'!J15"),2,FALSE)} -> 4273 | D18: {=VLOOKUP(IF(INDIRECT("'Grupo " & B17 & "'!J20")=INDIRECT("'Grupo " & B17 & "'!C20"),INDIRECT("'Grupo " & B17 & "'!C21"),INDIRECT("'Grupo " & B17 & "'!C20")),INDIRECT("'Grupo " & B17 & "'!B12"):INDIRECT("'Grupo " & B17 & "'!G15"),2,FALSE)} -> 4047 | F18: {=VLOOKUP(IF(INDIRECT("'Grupo " & B17 & "'!J20")=INDIRECT("'Grupo " & B17 & "'!C20"),INDIRECT("'Grupo " & B17 & "'!C21"),INDIRECT("'Grupo " & B17 & "'!C20")),INDIRECT("'Grupo " & B17 & "'!B12"):INDIRECT("'Grupo " & B17 & "'!G15"),2,FALSE)} -> 4047 | G18: {=VLOOKUP(INDIRECT("'Grupo " & B17 & "'!J20"),INDIRECT("'Grupo " & B17 & "'!B12"):INDIRECT("'Grupo " & B17 & "'!J15"),2,FALSE)} -> 4273
C19: {=VLOOKUP(INDIRECT("'Grupo " & B17 & "'!J22"),INDIRECT("'Grupo " & B17 & "'!B12"):INDIRECT("'Grupo " & B17 & "'!J15"),2,FALSE)} -> 3912 | D19: {=VLOOKUP(IF(INDIRECT("'Grupo " & B17 & "'!J22")=INDIRECT("'Grupo " & B17 & "'!C22"),INDIRECT("'Grupo " & B17 & "'!C23"),INDIRECT("'Grupo " & B17 & "'!C22")),INDIRECT("'Grupo " & B17 & "'!B12"):INDIRECT("'Grupo " & B17 & "'!G15"),2,FALSE)} -> 4047 | F19: {=VLOOKUP(IF(INDIRECT("'Grupo " & B17 & "'!J22")=INDIRECT("'Grupo " & B17 & "'!C22"),INDIRECT("'Grupo " & B17 & "'!C23"),INDIRECT("'Grupo " & B17 & "'!C22")),INDIRECT("'Grupo " & B17 & "'!B12"):INDIRECT("'Grupo " & B17 & "'!G15"),2,FALSE)} -> 4047 | G19: {=VLOOKUP(INDIRECT("'Grupo " & B17 & "'!J22"),INDIRECT("'Grupo " & B17 & "'!B12"):INDIRECT("'Grupo " & B17 & "'!J15"),2,FALSE)} -> 3912
B20: =B17+1 -> 7 | C20: {=VLOOKUP(INDIRECT("'Grupo " & B20 & "'!J18"),INDIRECT("'Grupo " & B20 & "'!B12"):INDIRECT("'Grupo " & B20 & "'!J15"),2,FALSE)} -> 4100 | D20: {=VLOOKUP(IF(INDIRECT("'Grupo " & B20 & "'!J18")=INDIRECT("'Grupo " & B20 & "'!C18"),INDIRECT("'Grupo " & B20 & "'!C19"),INDIRECT("'Grupo " & B20 & "'!C18")),INDIRECT("'Grupo " & B20 & "'!B12"):INDIRECT("'Grupo " & B20 & "'!G15"),2,FALSE)} -> 4278 | F20: {=VLOOKUP(IF(INDIRECT("'Grupo " & B20 & "'!J18")=INDIRECT("'Grupo " & B20 & "'!C18"),INDIRECT("'Grupo " & B20 & "'!C19"),INDIRECT("'Grupo " & B20 & "'!C18")),INDIRECT("'Grupo " & B20 & "'!B12"):INDIRECT("'Grupo " & B20 & "'!G15"),2,FALSE)} -> 4278 | G20: {=VLOOKUP(INDIRECT("'Grupo " & B20 & "'!J18"),INDIRECT("'Grupo " & B20 & "'!B12"):INDIRECT("'Grupo " & B20 & "'!J15"),2,FALSE)} -> 4100
C21: {=VLOOKUP(INDIRECT("'Grupo " & B20 & "'!J20"),INDIRECT("'Grupo " & B20 & "'!B12"):INDIRECT("'Grupo " & B20 & "'!J15"),2,FALSE)} -> 4100 | D21: {=VLOOKUP(IF(INDIRECT("'Grupo " & B20 & "'!J20")=INDIRECT("'Grupo " & B20 & "'!C20"),INDIRECT("'Grupo " & B20 & "'!C21"),INDIRECT("'Grupo " & B20 & "'!C20")),INDIRECT("'Grupo " & B20 & "'!B12"):INDIRECT("'Grupo " & B20 & "'!G15"),2,FALSE)} -> 4104 | F21: {=VLOOKUP(IF(INDIRECT("'Grupo " & B20 & "'!J20")=INDIRECT("'Grupo " & B20 & "'!C20"),INDIRECT("'Grupo " & B20 & "'!C21"),INDIRECT("'Grupo " & B20 & "'!C20")),INDIRECT("'Grupo " & B20 & "'!B12"):INDIRECT("'Grupo " & B20 & "'!G15"),2,FALSE)} -> 4104 | G21: {=VLOOKUP(INDIRECT("'Grupo " & B20 & "'!J20"),INDIRECT("'Grupo " & B20 & "'!B12"):INDIRECT("'Grupo " & B20 & "'!J15"),2,FALSE)} -> 4100
C22: {=VLOOKUP(INDIRECT("'Grupo " & B20 & "'!J22"),INDIRECT("'Grupo " & B20 & "'!B12"):INDIRECT("'Grupo " & B20 & "'!J15"),2,FALSE)} -> 4104 | D22: {=VLOOKUP(IF(INDIRECT("'Grupo " & B20 & "'!J22")=INDIRECT("'Grupo " & B20 & "'!C22"),INDIRECT("'Grupo " & B20 & "'!C23"),INDIRECT("'Grupo " & B20 & "'!C22")),INDIRECT("'Grupo " & B20 & "'!B12"):INDIRECT("'Grupo " & B20 & "'!G15"),2,FALSE)} -> 4278 | F22: {=VLOOKUP(IF(INDIRECT("'Grupo " & B20 & "'!J22")=INDIRECT("'Grupo " & B20 & "'!C22"),INDIRECT("'Grupo " & B20 & "'!C23"),INDIRECT("'Grupo " & B20 & "'!C22")),INDIRECT("'Grupo " & B20 & "'!B12"):INDIRECT("'Grupo " & B20 & "'!G15"),2,FALSE)} -> 4278 | G22: {=VLOOKUP(INDIRECT("'Grupo " & B20 & "'!J22"),INDIRECT("'Grupo " & B20 & "'!B12"):INDIRECT("'Grupo " & B20 & "'!J15"),2,FALSE)} -> 4104
B23: =B20+1 -> 8 | C23: {=VLOOKUP(INDIRECT("'Grupo " & B23 & "'!J18"),INDIRECT("'Grupo " & B23 & "'!B12"):INDIRECT("'Grupo " & B23 & "'!J15"),2,FALSE)} -> 4183 | D23: {=VLOOKUP(IF(INDIRECT("'Grupo " & B23 & "'!J18")=INDIRECT("'Grupo " & B23 & "'!C18"),INDIRECT("'Grupo " & B23 & "'!C19"),INDIRECT("'Grupo " & B23 & "'!C18")),INDIRECT("'Grupo " & B23 & "'!B12"):INDIRECT("'Grupo " & B23 & "'!G15"),2,FALSE)} -> 4787 | F23: {=VLOOKUP(IF(INDIRECT("'Grupo " & B23 & "'!J18")=INDIRECT("'Grupo " & B23 & "'!C18"),INDIRECT("'Grupo " & B23 & "'!C19"),INDIRECT("'Grupo " & B23 & "'!C18")),INDIRECT("'Grupo " & B23 & "'!B12"):INDIRECT("'Grupo " & B23 & "'!G15"),2,FALSE)} -> 4787 | G23: {=VLOOKUP(INDIRECT("'Grupo " & B23 & "'!J18"),INDIRECT("'Grupo " & B23 & "'!B12"):INDIRECT("'Grupo " & B23 & "'!J15"),2,FALSE)} -> 4183
C24: {=VLOOKUP(INDIRECT("'Grupo " & B23 & "'!J20"),INDIRECT("'Grupo " & B23 & "'!B12"):INDIRECT("'Grupo " & B23 & "'!J15"),2,FALSE)} -> 4183 | D24: {=VLOOKUP(IF(INDIRECT("'Grupo " & B23 & "'!J20")=INDIRECT("'Grupo " & B23 & "'!C20"),INDIRECT("'Grupo " & B23 & "'!C21"),INDIRECT("'Grupo " & B23 & "'!C20")),INDIRECT("'Grupo " & B23 & "'!B12"):INDIRECT("'Grupo " & B23 & "'!G15"),2,FALSE)} -> 4275 | F24: {=VLOOKUP(IF(INDIRECT("'Grupo " & B23 & "'!J20")=INDIRECT("'Grupo " & B23 & "'!C20"),INDIRECT("'Grupo " & B23 & "'!C21"),INDIRECT("'Grupo " & B23 & "'!C20")),INDIRECT("'Grupo " & B23 & "'!B12"):INDIRECT("'Grupo " & B23 & "'!G15"),2,FALSE)} -> 4275 | G24: {=VLOOKUP(INDIRECT("'Grupo " & B23 & "'!J20"),INDIRECT("'Grupo " & B23 & "'!B12"):INDIRECT("'Grupo " & B23 & "'!J15"),2,FALSE)} -> 4183
C25: {=VLOOKUP(INDIRECT("'Grupo " & B23 & "'!J22"),INDIRECT("'Grupo " & B23 & "'!B12"):INDIRECT("'Grupo " & B23 & "'!J15"),2,FALSE)} -> 4275 | D25: {=VLOOKUP(IF(INDIRECT("'Grupo " & B23 & "'!J22")=INDIRECT("'Grupo " & B23 & "'!C22"),INDIRECT("'Grupo " & B23 & "'!C23"),INDIRECT("'Grupo " & B23 & "'!C22")),INDIRECT("'Grupo " & B23 & "'!B12"):INDIRECT("'Grupo " & B23 & "'!G15"),2,FALSE)} -> 4787 | F25: {=VLOOKUP(IF(INDIRECT("'Grupo " & B23 & "'!J22")=INDIRECT("'Grupo " & B23 & "'!C22"),INDIRECT("'Grupo " & B23 & "'!C23"),INDIRECT("'Grupo " & B23 & "'!C22")),INDIRECT("'Grupo " & B23 & "'!B12"):INDIRECT("'Grupo " & B23 & "'!G15"),2,FALSE)} -> 4787 | G25: {=VLOOKUP(INDIRECT("'Grupo " & B23 & "'!J22"),INDIRECT("'Grupo " & B23 & "'!B12"):INDIRECT("'Grupo " & B23 & "'!J15"),2,FALSE)} -> 4275
B26: 9 | C26: {=VLOOKUP(INDIRECT("'Grupo " & B26 & "'!J18"),INDIRECT("'Grupo " & B26 & "'!B12"):INDIRECT("'Grupo " & B26 & "'!J15"),2,FALSE)} -> 4191 | D26: {=VLOOKUP(IF(INDIRECT("'Grupo " & B26 & "'!J18")=INDIRECT("'Grupo " & B26 & "'!C18"),INDIRECT("'Grupo " & B26 & "'!C19"),INDIRECT("'Grupo " & B26 & "'!C18")),INDIRECT("'Grupo " & B26 & "'!B12"):INDIRECT("'Grupo " & B26 & "'!G15"),2,FALSE)} -> 4470 | F26: {=VLOOKUP(IF(INDIRECT("'Grupo " & B26 & "'!J18")=INDIRECT("'Grupo " & B26 & "'!C18"),INDIRECT("'Grupo " & B26 & "'!C19"),INDIRECT("'Grupo " & B26 & "'!C18")),INDIRECT("'Grupo " & B26 & "'!B12"):INDIRECT("'Grupo " & B26 & "'!G15"),2,FALSE)} -> 4470 | G26: {=VLOOKUP(INDIRECT("'Grupo " & B26 & "'!J18"),INDIRECT("'Grupo " & B26 & "'!B12"):INDIRECT("'Grupo " & B26 & "'!J15"),2,FALSE)} -> 4191
C27: {=VLOOKUP(INDIRECT("'Grupo " & B26 & "'!J20"),INDIRECT("'Grupo " & B26 & "'!B12"):INDIRECT("'Grupo " & B26 & "'!J15"),2,FALSE)} -> 3828 | D27: {=VLOOKUP(IF(INDIRECT("'Grupo " & B26 & "'!J20")=INDIRECT("'Grupo " & B26 & "'!C20"),INDIRECT("'Grupo " & B26 & "'!C21"),INDIRECT("'Grupo " & B26 & "'!C20")),INDIRECT("'Grupo " & B26 & "'!B12"):INDIRECT("'Grupo " & B26 & "'!G15"),2,FALSE)} -> 4433 | F27: {=VLOOKUP(IF(INDIRECT("'Grupo " & B26 & "'!J20")=INDIRECT("'Grupo " & B26 & "'!C20"),INDIRECT("'Grupo " & B26 & "'!C21"),INDIRECT("'Grupo " & B26 & "'!C20")),INDIRECT("'Grupo " & B26 & "'!B12"):INDIRECT("'Grupo " & B26 & "'!G15"),2,FALSE)} -> 4433 | G27: {=VLOOKUP(INDIRECT("'Grupo " & B26 & "'!J20"),INDIRECT("'Grupo " & B26 & "'!B12"):INDIRECT("'Grupo " & B26 & "'!J15"),2,FALSE)} -> 3828
C28: {=VLOOKUP(INDIRECT("'Grupo " & B26 & "'!J22"),INDIRECT("'Grupo " & B26 & "'!B12"):INDIRECT("'Grupo " & B26 & "'!J15"),2,FALSE)} -> 3828 | D28: {=VLOOKUP(IF(INDIRECT("'Grupo " & B26 & "'!J22")=INDIRECT("'Grupo " & B26 & "'!C22"),INDIRECT("'Grupo " & B26 & "'!C23"),INDIRECT("'Grupo " & B26 & "'!C22")),INDIRECT("'Grupo " & B26 & "'!B12"):INDIRECT("'Grupo " & B26 & "'!G15"),2,FALSE)} -> 4191 | F28: {=VLOOKUP(IF(INDIRECT("'Grupo " & B26 & "'!J22")=INDIRECT("'Grupo " & B26 & "'!C22"),INDIRECT("'Grupo " & B26 & "'!C23"),INDIRECT("'Grupo " & B26 & "'!C22")),INDIRECT("'Grupo " & B26 & "'!B12"):INDIRECT("'Grupo " & B26 & "'!G15"),2,FALSE)} -> 4191 | G28: {=VLOOKUP(INDIRECT("'Grupo " & B26 & "'!J22"),INDIRECT("'Grupo " & B26 & "'!B12"):INDIRECT("'Grupo " & B26 & "'!J15"),2,FALSE)} -> 3828
C29: {=VLOOKUP(INDIRECT("'Grupo " & B26 & "'!J24"),INDIRECT("'Grupo " & B26 & "'!B12"):INDIRECT("'Grupo " & B26 & "'!J15"),2,FALSE)} -> 4470 | D29: {=VLOOKUP(IF(INDIRECT("'Grupo " & B26 & "'!J24")=INDIRECT("'Grupo " & B26 & "'!C24"),INDIRECT("'Grupo " & B26 & "'!C25"),INDIRECT("'Grupo " & B26 & "'!C24")),INDIRECT("'Grupo " & B26 & "'!B12"):INDIRECT("'Grupo " & B26 & "'!G15"),2,FALSE)} -> 4433 | F29: {=VLOOKUP(IF(INDIRECT("'Grupo " & B26 & "'!J24")=INDIRECT("'Grupo " & B26 & "'!C24"),INDIRECT("'Grupo " & B26 & "'!C25"),INDIRECT("'Grupo " & B26 & "'!C24")),INDIRECT("'Grupo " & B26 & "'!B12"):INDIRECT("'Grupo " & B26 & "'!G15"),2,FALSE)} -> 4433 | G29: {=VLOOKUP(INDIRECT("'Grupo " & B26 & "'!J24"),INDIRECT("'Grupo " & B26 & "'!B12"):INDIRECT("'Grupo " & B26 & "'!J15"),2,FALSE)} -> 4470
C30: {=VLOOKUP(INDIRECT("'Grupo " & B26 & "'!J26"),INDIRECT("'Grupo " & B26 & "'!B12"):INDIRECT("'Grupo " & B26 & "'!J15"),2,FALSE)} -> 4191 | D30: {=VLOOKUP(IF(INDIRECT("'Grupo " & B26 & "'!J26")=INDIRECT("'Grupo " & B26 & "'!C26"),INDIRECT("'Grupo " & B26 & "'!C27"),INDIRECT("'Grupo " & B26 & "'!C26")),INDIRECT("'Grupo " & B26 & "'!B12"):INDIRECT("'Grupo " & B26 & "'!G15"),2,FALSE)} -> 4433 | F30: {=VLOOKUP(IF(INDIRECT("'Grupo " & B26 & "'!J26")=INDIRECT("'Grupo " & B26 & "'!C26"),INDIRECT("'Grupo " & B26 & "'!C27"),INDIRECT("'Grupo " & B26 & "'!C26")),INDIRECT("'Grupo " & B26 & "'!B12"):INDIRECT("'Grupo " & B26 & "'!G15"),2,FALSE)} -> 4433 | G30: {=VLOOKUP(INDIRECT("'Grupo " & B26 & "'!J26"),INDIRECT("'Grupo " & B26 & "'!B12"):INDIRECT("'Grupo " & B26 & "'!J15"),2,FALSE)} -> 4191
C31: {=VLOOKUP(INDIRECT("'Grupo " & B26 & "'!J28"),INDIRECT("'Grupo " & B26 & "'!B12"):INDIRECT("'Grupo " & B26 & "'!J15"),2,FALSE)} -> 3828 | D31: {=VLOOKUP(IF(INDIRECT("'Grupo " & B26 & "'!J28")=INDIRECT("'Grupo " & B26 & "'!C28"),INDIRECT("'Grupo " & B26 & "'!C29"),INDIRECT("'Grupo " & B26 & "'!C28")),INDIRECT("'Grupo " & B26 & "'!B12"):INDIRECT("'Grupo " & B26 & "'!G15"),2,FALSE)} -> 4470 | F31: {=VLOOKUP(IF(INDIRECT("'Grupo " & B26 & "'!J28")=INDIRECT("'Grupo " & B26 & "'!C28"),INDIRECT("'Grupo " & B26 & "'!C29"),INDIRECT("'Grupo " & B26 & "'!C28")),INDIRECT("'Grupo " & B26 & "'!B12"):INDIRECT("'Grupo " & B26 & "'!G15"),2,FALSE)} -> 4470 | G31: {=VLOOKUP(INDIRECT("'Grupo " & B26 & "'!J28"),INDIRECT("'Grupo " & B26 & "'!B12"):INDIRECT("'Grupo " & B26 & "'!J15"),2,FALSE)} -> 3828

Sheet Ranking Final
A1: Ranking | B1: CARNE | C1: NOMBRE | D1: CLUB | E1: PUNTOS
A2: 1 | B2: 4159 | C2: MARÍA FERNANDA ZELEDÓN HERRERA | D2: ESPARZA | E2: 764
A3: 2 | B3: 4101 | C3: ABIGAIL QUIROS BALTODANO | D3: ESPARZA | E3: 701
A4: 3 | B4: 3918 | C4: MARIANA SOTO CALDERON | D4: ESPARZA | E4: 689
A5: 4 | B5: 4274 | C5: MARÍA PAULA HERNÁNDEZ ZÚÑIGA | D5: ESCAZÚ | E5: 645
A6: 5 | B6: 4176 | C6: LÍA SOFÍA SOLÍS VÁSQUEZ | D6: ESPARZA | E6: 644
A7: 6 | B7: 4273 | C7: JAQUELINE HERNÁNDEZ ZUÑIGA | D7: ESCAZÚ | E7: 632
A8: 7 | B8: 4100 | C8: BRENDA HERRERA RIVAS | D8: ESPARZA | E8: 628
A9: 8 | B9: 4183 | C9: MONSERRAT RODRÍGUEZ SOLÍS | D9: SAN CARLOS | E9: 601
A10: 9 | B10: 4191 | C10: ISABELA CHACÓN ALVARADO | D10: CCDR SAN JOSÉ | E10: 581
A11: 10 | B11: 4275 | C11: CLARISSA MORA JIMÉNEZ | D11: ESPARZA | E11: 562
A12: 11 | B12: 4047 | C12: MARIANGEL JIMENEZ QUESADA | D12: ESPARZA | E12: 556
A13: 11 | B13: 3828 | C13: AMANDA CHEN CEN | D13: ESCAZÚ | E13: 556
... A110: 39 | B110: 4817 | C110: ASHLEY VALENTINA QUIRÓS CALDERÓN | D110: OREAMUNOT3 AMETROTEME | E110: 420

Sheet Inscripciones
B1: Ranking Nacional
B2: U13 FEMENINO
B4: CARNÉ | C4: NOMBRE | D4: CLUB | E4: RANKING | F4: PUNTOS | G4: Grupo
A5: =G5+0.1 -> 1.1 | B5: 4159 | C5: MARÍA FERNANDA ZELEDÓN HERRERA | D5: ESPARZA | E5: 1 | F5: 706 | G5: 1
A6: =G6+0.2 -> 1.2 | B6: 4601 | C6: ANNETTE CARRANZA SOLÍS | D6: ESCAZÚ | E6: 18 | F6: 504 | G6: 1
A7: =G7+0.3 -> 1.3 | B7: 4276 | C7: SILOÉ MUÑOZ CÓRDOBA | D7: ESPARZA | E7: 19 | F7: 502 | G7: 1
A8: =G8+0.1 -> 2.1 | B8: 4101 | C8: ABIGAIL QUIROS BALTODANO | D8: ESPARZA | E8: 2 | F8: 668 | G8: 2
A9: =G9+0.2 -> 2.2 | B9: 4348 | C9: AMANDA PEREZ CABEZAS | D9: CORREDORES | E9: 17 | F9: 505 | G9: 2
A10: =G10+0.3 -> 2.3 | B10: 4164 | C10: FIORELLA PEREIRA OBANDO | D10: CURRIDABAT | E10: 21 | F10: 491 | G10: 2
A11: =G11+0.1 -> 3.1 | B11: 3918 | C11: MARIANA SOTO CALDERON | D11: ESPARZA | E11: 3 | F11: 640 | G11: 3
A12: =G12+0.2 -> 3.2 | B12: 3907 | C12: LUCIANA CASCANTE BARBOZA | D12: ASERRÍ | E12: 16 | F12: 507 | G12: 3
A13: =G13+0.3 -> 3.3 | B13: 4535 | C13: VALENTINA LOPEZ ALVARADO | D13: ALAJUELA | E13: 24 | F13: 483 | G13: 3
A14: =G14+0.1 -> 4.1 | B14: 4176 | C14: LÍA SOFÍA SOLÍS VÁSQUEZ | D14: ESPARZA | E14: 4 | F14: 622 | G14: 4
A15: =G15+0.2 -> 4.2 | B15: 4212 | C15: FIORELLA RETANA AGUILAR | D15: CURRIDABAT | E15: 15 | F15: 512 | G15: 4
A16: =G16+0.3 -> 4.3 | B16: 4380 | C16: VALENTINA FERNANDEZ REYES | D16: ESCAZÚ | E16: 23 | F16: 483 | G16: 4
A17: =G17+0.1 -> 5.1 | B17: 4274 | C17: MARÍA PAULA HERNÁNDEZ ZÚÑIGA | D17: ESCAZÚ | E17: 5 | F17: 617 | G17: 5
A18: =G18+0.2 -> 5.2 | B18: 4579 | C18: EMMA GIOCONDA BERTARIONI ARAYA | D18: ESPARZA | E18: 14 | F18: 526 | G18: 5
A19: =G19+0.3 -> 5.3 | B19: 4673 | C19: ALINA CHACON RETANA | D19: SAN CARLOS | E19: 25 | F19: 483 | G19: 5
A20: =G20+0.1 -> 6.1 | B20: 4273 | C20: JAQUELINE HERNÁNDEZ ZUÑIGA | D20: ESCAZÚ | E20: 6 | F20: 603 | G20: 6
A21: =G21+0.2 -> 6.2 | B21: 4047 | C21: MARIANGEL JIMENEZ QUESADA | D21: ESPARZA | E21: 11 | F21: 566 | G21: 6
A22: =G22+0.3 -> 6.3 | B22: 3912 | C22: AMBAR PADILLA GRANADOS | D22: PÉREZ ZELEDÓN | E22: 26 | F22: 473 | G22: 6
A23: =G23+0.1 -> 7.1 | B23: 4100 | C23: BRENDA HERRERA RIVAS | D23: ESPARZA | E23: 7 | F23: 602 | G23: 7
A24: =G24+0.2 -> 7.2 | B24: 4104 | C24: ARIANA SANCHEZ DELGADO | D24: ESCAZÚ | E24: 12 | F24: 549 | G24: 7
A25: =G25+0.3 -> 7.3 | B25: 4278 | C25: EMA MELISSA ANGULO CRUZ | D25: ASERRÍ | E25: 28 | F25: 470 | G25: 7
A26: =G26+0.1 -> 8.1 | B26: 4183 | C26: MONSERRAT RODRÍGUEZ SOLÍS | D26: SAN CARLOS | E26: 8 | F26: 572 | G26: 8
A27: =G27+0.2 -> 8.2 | B27: 4275 | C27: CLARISSA MORA JIMÉNEZ | D27: ESPARZA | E27: 10 | F27: 566 | G27: 8
A28: =G28+0.3 -> 8.3 | B28: 4787 | C28: KENYA DEL VALLE ARAO | D28: CURRIDABAT | E28: 30 | F28: 466 | G28: 8
A29: =G29+0.1 -> 9.1 | B29: 4191 | C29: ISABELA CHACÓN ALVARADO | D29: CCDR SAN JOSÉ | E29: 9 | F29: 571 | G29: 9
A30: =G30+0.2 -> 9.2 | B30: 3828 | C30: AMANDA CHEN CEN | D30: ESCAZÚ | E30: 13 | F30: 527 | G30: 9
A31: =G31+0.3 -> 9.3 | B31: 4470 | C31: MARIPAZ VALVERDE VARELA | D31: ESPARZA | E31: 31 | F31: 466 | G31: 9
A32: =G32+0.4 -> 9.4 | B32: 4433 | C32: PAULA ALFARO MORA | D32: ASERRÍ | E32: 32 | F32: 462 | G32: 9
A33: =G33+0.2 -> 0.2 | B33: X | C33: BYE | D33: BYE
A34: =G34+0.3 -> 0.3
A35: =G35+0.1 -> 0.1
A36: =G36+0.2 -> 0.2
A37: =G37+0.3 -> 0.3
A38: =G38+0.1 -> 0.1
A39: =G39+0.2 -> 0.2
A40: =G40+0.3 -> 0.3
A41: =G41+0.1 -> 0.1
...

Sheet Hoja1

Sheet Grupo 1
L5: En Caso de ocupar 3 de 5, mostrar columnas H - I En caso de 2 de 2, ocultarlas.
G7: Fecha: | J7: =TODAY() -> 46288
B9: Categoría | D9: =Inscripciones!B2 -> U13 FEMENINO | E9: Grupo nº | F9: 1 | G9: Mesa nº
B11: Orden | C11: Carné | D11: Jugadores | E11: Lugar | F11: Ranking | G11: Puntos
A12: =F9+0.1 -> 1.1 | B12: 1 | C12: =VLOOKUP(A12,Inscripciones!A5:G167,2,FALSE) -> 4159 | D12: =IF(ISBLANK(C12),"",VLOOKUP(C12,Inscripciones!$B$5:$F$200,2,FALSE)) -> MARÍA FERNANDA ZELEDÓN HERRERA | E12: =IF(ISBLANK(C12),"",VLOOKUP(C12,Inscripciones!$B$5:$F$200,3,FALSE)) -> ESPARZA | F12: =IF(ISBLANK(C12),"",VLOOKUP(C12,Inscripciones!$B$5:$F$200,4,FALSE)) -> 1 | G12: =IF(ISBLANK(C12),"",VLOOKUP(C12,Inscripciones!$B$5:$F$200,5,FALSE)) -> 706 | J12: =IF(ISBLANK(J11)," ",(E18+F18+G18+E20+F20+G20+H18+I18+H20+I20)/(E19+F19+G19+E21+F21+G21+H19+I19+H21+I21))
A13: =F9+0.2 -> 1.2 | B13: 2 | C13: =VLOOKUP(A13,Inscripciones!A5:G168,2,FALSE) -> 4601 | D13: =IF(ISBLANK(C13),"",VLOOKUP(C13,Inscripciones!$B$5:$F$200,2,FALSE)) -> ANNETTE CARRANZA SOLÍS | E13: =IF(ISBLANK(C13),"",VLOOKUP(C13,Inscripciones!$B$5:$F$200,3,FALSE)) -> ESCAZÚ | F13: =IF(ISBLANK(C13),"",VLOOKUP(C13,Inscripciones!$B$5:$F$200,4,FALSE)) -> 18 | G13: =IF(ISBLANK(C13),"",VLOOKUP(C13,Inscripciones!$B$5:$F$200,5,FALSE)) -> 504 | J13: =IF(ISBLANK(J11)," ",(E21+F21+G21+E22+F22+G22+H21+I21+H22+I22)/(E20+F20+G20+E23+F23+G23+H20+I20+H23+I23))
A14: =+F9+0.3 -> 1.3 | B14: 3 | C14: =VLOOKUP(A14,Inscripciones!A6:G169,2,FALSE) -> 4276 | D14: =IF(ISBLANK(C14),"",VLOOKUP(C14,Inscripciones!$B$7:$F$200,2,FALSE)) -> SILOÉ MUÑOZ CÓRDOBA | E14: =IF(ISBLANK(C14),"",VLOOKUP(C14,Inscripciones!$B$7:$F$200,3,FALSE)) -> ESPARZA | F14: =IF(ISBLANK(C14),"",VLOOKUP(C14,Inscripciones!$B$7:$F$200,4,FALSE)) -> 19 | G14: =IF(ISBLANK(C14),"",VLOOKUP(C14,Inscripciones!$B$7:$F$200,5,FALSE)) -> 502 | J14: =IF(ISBLANK(J11)," ",(E19+F19+G19+E23+F23+G23+H19+I19+H23+I23)/(E18+F18+G18+E22+F22+G22+H18+I18+H22+I22))
B17: Partida | D17: JUGADOR | E17: 1º set | F17: 2º set | G17: 3º set | H17: 4º set | I17: 5º set | J17: Ganador
B18: 1 | C18: 1 | D18: =D12 -> MARÍA FERNANDA ZELEDÓN HERRERA | E18: 15 | F18: 11 | J18: {=IF(AND(TRIM(E18)="WO",TRIM(E19)="WO"),"",IF(TRIM(E19)="WO",C18,IF(TRIM(E18)="WO",C19,IF(SUMPRODUCT(--(E18:I18>E19:I19))>SUMPRODUCT(--(E19:I19>E18:I18)),C18,IF(SUMPRODUCT(--(E19:I19>E18:I18))>SUMPRODUCT(--(E18:I18>E19:I19)),C19,"")))))} -> 1
C19: 3 | D19: =D14 -> SILOÉ MUÑOZ CÓRDOBA | E19: 13 | F19: 7
B20: 2 | C20: 1 | D20: =D12 -> MARÍA FERNANDA ZELEDÓN HERRERA | E20: 11 | F20: 11 | J20: {=IF(AND(TRIM(E20)="WO",TRIM(E21)="WO"),"",IF(TRIM(E21)="WO",C20,IF(TRIM(E20)="WO",C21,IF(SUMPRODUCT(--(E20:I20>E21:I21))>SUMPRODUCT(--(E21:I21>E20:I20)),C20,IF(SUMPRODUCT(--(E21:I21>E20:I20))>SUMPRODUCT(--(E20:I20>E21:I21)),C21,"")))))} -> 1
C21: 2 | D21: =D13 -> ANNETTE CARRANZA SOLÍS | E21: 2 | F21: 9
B22: 3 | C22: 2 | D22: =D13 -> ANNETTE CARRANZA SOLÍS | E22: 7 | F22: 11 | G22: 9 | J22: {=IF(AND(TRIM(E22)="WO",TRIM(E23)="WO"),"",IF(TRIM(E23)="WO",C22,IF(TRIM(E22)="WO",C23,IF(SUMPRODUCT(--(E22:I22>E23:I23))>SUMPRODUCT(--(E23:I23>E22:I22)),C22,IF(SUMPRODUCT(--(E23:I23>E22:I22))>SUMPRODUCT(--(E22:I22>E23:I23)),C23,"")))))} -> 3
C23: 3 | D23: =D14 -> SILOÉ MUÑOZ CÓRDOBA | E23: 11 | F23: 8 | G23: 11
C32: Clasificados (# de carne) | F32: Revisión de Camisas y Raquetas
C33: Carnet | D33: Nombre | F33: Revisión de nombres y resultados
C34: 4159 | D34: =IF(ISBLANK(C34),"",VLOOKUP(C34,Inscripciones!$B$5:$F$200,2,FALSE)) -> MARÍA FERNANDA ZELEDÓN HERRERA | F34: Árbitro
C35: 4276 | D35: =IF(ISBLANK(C35),"",VLOOKUP(C35,Inscripciones!$B$5:$F$200,2,FALSE)) -> SILOÉ MUÑOZ CÓRDOBA | F35: Marque si hay informe

Sheet Grupo 2
L5: En Caso de ocupar 3 de 5, mostrar columnas H - I En caso de 2 de 2, ocultarlas.
G7: Fecha: | J7: =TODAY() -> 46288
B9: Categoría | D9: =Inscripciones!B2 -> U13 FEMENINO | E9: Grupo nº | F9: 2 | G9: Mesa nº
B11: Orden | C11: Carné | D11: Jugadores | E11: Lugar | F11: Ranking | G11: Puntos
A12: =F9+0.1 -> 2.1 | B12: 1 | C12: =VLOOKUP(A12,Inscripciones!A5:G167,2,FALSE) -> 4101 | D12: =IF(ISBLANK(C12),"",VLOOKUP(C12,Inscripciones!$B$5:$F$200,2,FALSE)) -> ABIGAIL QUIROS BALTODANO | E12: =IF(ISBLANK(C12),"",VLOOKUP(C12,Inscripciones!$B$5:$F$200,3,FALSE)) -> ESPARZA | F12: =IF(ISBLANK(C12),"",VLOOKUP(C12,Inscripciones!$B$5:$F$200,4,FALSE)) -> 2 | G12: =IF(ISBLANK(C12),"",VLOOKUP(C12,Inscripciones!$B$5:$F$200,5,FALSE)) -> 668 | J12: =IF(ISBLANK(J11)," ",(E18+F18+G18+E20+F20+G20+H18+I18+H20+I20)/(E19+F19+G19+E21+F21+G21+H19+I19+H21+I21))
A13: =F9+0.2 -> 2.2 | B13: 2 | C13: =VLOOKUP(A13,Inscripciones!A5:G168,2,FALSE) -> 4348 | D13: =IF(ISBLANK(C13),"",VLOOKUP(C13,Inscripciones!$B$5:$F$200,2,FALSE)) -> AMANDA PEREZ CABEZAS | E13: =IF(ISBLANK(C13),"",VLOOKUP(C13,Inscripciones!$B$5:$F$200,3,FALSE)) -> CORREDORES | F13: =IF(ISBLANK(C13),"",VLOOKUP(C13,Inscripciones!$B$5:$F$200,4,FALSE)) -> 17 | G13: =IF(ISBLANK(C13),"",VLOOKUP(C13,Inscripciones!$B$5:$F$200,5,FALSE)) -> 505 | J13: =IF(ISBLANK(J11)," ",(E21+F21+G21+E22+F22+G22+H21+I21+H22+I22)/(E20+F20+G20+E23+F23+G23+H20+I20+H23+I23))
A14: =+F9+0.3 -> 2.3 | B14: 3 | C14: =VLOOKUP(A14,Inscripciones!A6:G169,2,FALSE) -> 4164 | D14: =IF(ISBLANK(C14),"",VLOOKUP(C14,Inscripciones!$B$7:$F$200,2,FALSE)) -> FIORELLA PEREIRA OBANDO | E14: =IF(ISBLANK(C14),"",VLOOKUP(C14,Inscripciones!$B$7:$F$200,3,FALSE)) -> CURRIDABAT | F14: =IF(ISBLANK(C14),"",VLOOKUP(C14,Inscripciones!$B$7:$F$200,4,FALSE)) -> 21 | G14: =IF(ISBLANK(C14),"",VLOOKUP(C14,Inscripciones!$B$7:$F$200,5,FALSE)) -> 491 | J14: =IF(ISBLANK(J11)," ",(E19+F19+G19+E23+F23+G23+H19+I19+H23+I23)/(E18+F18+G18+E22+F22+G22+H18+I18+H22+I22))
B17: Partida | D17: JUGADOR | E17: 1º set | F17: 2º set | G17: 3º set | H17: 4º set | I17: 5º set | J17: Ganador
B18: 1 | C18: 1 | D18: =D12 -> ABIGAIL QUIROS BALTODANO | E18: 11 | F18: 11 | J18: {=IF(AND(TRIM(E18)="WO",TRIM(E19)="WO"),"",IF(TRIM(E19)="WO",C18,IF(TRIM(E18)="WO",C19,IF(SUMPRODUCT(--(E18:I18>E19:I19))>SUMPRODUCT(--(E19:I19>E18:I18)),C18,IF(SUMPRODUCT(--(E19:I19>E18:I18))>SUMPRODUCT(--(E18:I18>E19:I19)),C19,"")))))} -> 1
C19: 3 | D19: =D14 -> FIORELLA PEREIRA OBANDO | E19: 5 | F19: 3
B20: 2 | C20: 1 | D20: =D12 -> ABIGAIL QUIROS BALTODANO | E20: 11 | F20: 11 | J20: {=IF(AND(TRIM(E20)="WO",TRIM(E21)="WO"),"",IF(TRIM(E21)="WO",C20,IF(TRIM(E20)="WO",C21,IF(SUMPRODUCT(--(E20:I20>E21:I21))>SUMPRODUCT(--(E21:I21>E20:I20)),C20,IF(SUMPRODUCT(--(E21:I21>E20:I20))>SUMPRODUCT(--(E20:I20>E21:I21)),C21,"")))))} -> 1
C21: 2 | D21: =D13 -> AMANDA PEREZ CABEZAS | E21: 5 | F21: 5
B22: 3 | C22: 2 | D22: =D13 -> AMANDA PEREZ CABEZAS | E22: 11 | F22: 11 | J22: {=IF(AND(TRIM(E22)="WO",TRIM(E23)="WO"),"",IF(TRIM(E23)="WO",C22,IF(TRIM(E22)="WO",C23,IF(SUMPRODUCT(--(E22:I22>E23:I23))>SUMPRODUCT(--(E23:I23>E22:I22)),C22,IF(SUMPRODUCT(--(E23:I23>E22:I22))>SUMPRODUCT(--(E22:I22>E23:I23)),C23,"")))))} -> 2
C23: 3 | D23: =D14 -> FIORELLA PEREIRA OBANDO | E23: 2 | F23: 8
C32: Clasificados (# de carne) | F32: Revisión de Camisas y Raquetas
C33: Carnet | D33: Nombre | F33: Revisión de nombres y resultados
C34: 4101 | D34: =IF(ISBLANK(C34),"",VLOOKUP(C34,Inscripciones!$B$5:$F$200,2,FALSE)) -> ABIGAIL QUIROS BALTODANO | F34: Árbitro
C35: 4348 | D35: =IF(ISBLANK(C35),"",VLOOKUP(C35,Inscripciones!$B$5:$F$200,2,FALSE)) -> AMANDA PEREZ CABEZAS | F35: Marque si hay informe

Sheet Grupo 3
L5: En Caso de ocupar 3 de 5, mostrar columnas H - I En caso de 2 de 2, ocultarlas.
G7: Fecha: | J7: =TODAY() -> 46288
B9: Categoría | D9: =Inscripciones!B2 -> U13 FEMENINO | E9: Grupo nº | F9: 3 | G9: Mesa nº
B11: Orden | C11: Carné | D11: Jugadores | E11: Lugar | F11: Ranking | G11: Puntos
A12: =F9+0.1 -> 3.1 | B12: 1 | C12: =VLOOKUP(A12,Inscripciones!A5:G167,2,FALSE) -> 3918 | D12: =IF(ISBLANK(C12),"",VLOOKUP(C12,Inscripciones!$B$5:$F$200,2,FALSE)) -> MARIANA SOTO CALDERON | E12: =IF(ISBLANK(C12),"",VLOOKUP(C12,Inscripciones!$B$5:$F$200,3,FALSE)) -> ESPARZA | F12: =IF(ISBLANK(C12),"",VLOOKUP(C12,Inscripciones!$B$5:$F$200,4,FALSE)) -> 3 | G12: =IF(ISBLANK(C12),"",VLOOKUP(C12,Inscripciones!$B$5:$F$200,5,FALSE)) -> 640 | J12: =IF(ISBLANK(J11)," ",(E18+F18+G18+E20+F20+G20+H18+I18+H20+I20)/(E19+F19+G19+E21+F21+G21+H19+I19+H21+I21))
A13: =F9+0.2 -> 3.2 | B13: 2 | C13: =VLOOKUP(A13,Inscripciones!A5:G168,2,FALSE) -> 3907 | D13: =IF(ISBLANK(C13),"",VLOOKUP(C13,Inscripciones!$B$5:$F$200,2,FALSE)) -> LUCIANA CASCANTE BARBOZA | E13: =IF(ISBLANK(C13),"",VLOOKUP(C13,Inscripciones!$B$5:$F$200,3,FALSE)) -> ASERRÍ | F13: =IF(ISBLANK(C13),"",VLOOKUP(C13,Inscripciones!$B$5:$F$200,4,FALSE)) -> 16 | G13: =IF(ISBLANK(C13),"",VLOOKUP(C13,Inscripciones!$B$5:$F$200,5,FALSE)) -> 507 | J13: =IF(ISBLANK(J11)," ",(E21+F21+G21+E22+F22+G22+H21+I21+H22+I22)/(E20+F20+G20+E23+F23+G23+H20+I20+H23+I23))
A14: =+F9+0.3 -> 3.3 | B14: 3 | C14: =VLOOKUP(A14,Inscripciones!A6:G169,2,FALSE) -> 4535 | D14: =IF(ISBLANK(C14),"",VLOOKUP(C14,Inscripciones!$B$7:$F$200,2,FALSE)) -> VALENTINA LOPEZ ALVARADO | E14: =IF(ISBLANK(C14),"",VLOOKUP(C14,Inscripciones!$B$7:$F$200,3,FALSE)) -> ALAJUELA | F14: =IF(ISBLANK(C14),"",VLOOKUP(C14,Inscripciones!$B$7:$F$200,4,FALSE)) -> 24 | G14: =IF(ISBLANK(C14),"",VLOOKUP(C14,Inscripciones!$B$7:$F$200,5,FALSE)) -> 483 | J14: =IF(ISBLANK(J11)," ",(E19+F19+G19+E23+F23+G23+H19+I19+H23+I23)/(E18+F18+G18+E22+F22+G22+H18+I18+H22+I22))
B17: Partida | D17: JUGADOR | E17: 1º set | F17: 2º set | G17: 3º set | H17: 4º set | I17: 5º set | J17: Ganador
B18: 1 | C18: 1 | D18: =D12 -> MARIANA SOTO CALDERON | E18: 11 | F18: 11 | J18: {=IF(AND(TRIM(E18)="WO",TRIM(E19)="WO"),"",IF(TRIM(E19)="WO",C18,IF(TRIM(E18)="WO",C19,IF(SUMPRODUCT(--(E18:I18>E19:I19))>SUMPRODUCT(--(E19:I19>E18:I18)),C18,IF(SUMPRODUCT(--(E19:I19>E18:I18))>SUMPRODUCT(--(E18:I18>E19:I19)),C19,"")))))} -> 1
C19: 3 | D19: =D14 -> VALENTINA LOPEZ ALVARADO | E19: 2 | F19: 2
B20: 2 | C20: 1 | D20: =D12 -> MARIANA SOTO CALDERON | E20: 11 | F20: 11 | J20: {=IF(AND(TRIM(E20)="WO",TRIM(E21)="WO"),"",IF(TRIM(E21)="WO",C20,IF(TRIM(E20)="WO",C21,IF(SUMPRODUCT(--(E20:I20>E21:I21))>SUMPRODUCT(--(E21:I21>E20:I20)),C20,IF(SUMPRODUCT(--(E21:I21>E20:I20))>SUMPRODUCT(--(E20:I20>E21:I21)),C21,"")))))} -> 1
C21: 2 | D21: =D13 -> LUCIANA CASCANTE BARBOZA | E21: 7 | F21: 3
B22: 3 | C22: 2 | D22: =D13 -> LUCIANA CASCANTE BARBOZA | E22: 11 | F22: 11 | J22: {=IF(AND(TRIM(E22)="WO",TRIM(E23)="WO"),"",IF(TRIM(E23)="WO",C22,IF(TRIM(E22)="WO",C23,IF(SUMPRODUCT(--(E22:I22>E23:I23))>SUMPRODUCT(--(E23:I23>E22:I22)),C22,IF(SUMPRODUCT(--(E23:I23>E22:I22))>SUMPRODUCT(--(E22:I22>E23:I23)),C23,"")))))} -> 2
C23: 3 | D23: =D14 -> VALENTINA LOPEZ ALVARADO | E23: 7 | F23: 3
C32: Clasificados (# de carne) | F32: Revisión de Camisas y Raquetas
C33: Carnet | D33: Nombre | F33: Revisión de nombres y resultados
C34: 3918 | D34: =IF(ISBLANK(C34),"",VLOOKUP(C34,Inscripciones!$B$5:$F$200,2,FALSE)) -> MARIANA SOTO CALDERON | F34: Árbitro
C35: 3907 | D35: =IF(ISBLANK(C35),"",VLOOKUP(C35,Inscripciones!$B$5:$F$200,2,FALSE)) -> LUCIANA CASCANTE BARBOZA | F35: Marque si hay informe

Sheet Grupo 4
L5: En Caso de ocupar 3 de 5, mostrar columnas H - I En caso de 2 de 2, ocultarlas.
G7: Fecha: | J7: =TODAY() -> 46288
B9: Categoría | D9: =Inscripciones!B2 -> U13 FEMENINO | E9: Grupo nº | F9: 4 | G9: Mesa nº
B11: Orden | C11: Carné | D11: Jugadores | E11: Lugar | F11: Ranking | G11: Puntos
A12: =F9+0.1 -> 4.1 | B12: 1 | C12: =VLOOKUP(A12,Inscripciones!A5:G167,2,FALSE) -> 4176 | D12: =IF(ISBLANK(C12),"",VLOOKUP(C12,Inscripciones!$B$5:$F$200,2,FALSE)) -> LÍA SOFÍA SOLÍS VÁSQUEZ | E12: =IF(ISBLANK(C12),"",VLOOKUP(C12,Inscripciones!$B$5:$F$200,3,FALSE)) -> ESPARZA | F12: =IF(ISBLANK(C12),"",VLOOKUP(C12,Inscripciones!$B$5:$F$200,4,FALSE)) -> 4 | G12: =IF(ISBLANK(C12),"",VLOOKUP(C12,Inscripciones!$B$5:$F$200,5,FALSE)) -> 622 | J12: =IF(ISBLANK(J11)," ",(E18+F18+G18+E20+F20+G20+H18+I18+H20+I20)/(E19+F19+G19+E21+F21+G21+H19+I19+H21+I21))
A13: =F9+0.2 -> 4.2 | B13: 2 | C13: =VLOOKUP(A13,Inscripciones!A5:G168,2,FALSE) -> 4212 | D13: =IF(ISBLANK(C13),"",VLOOKUP(C13,Inscripciones!$B$5:$F$200,2,FALSE)) -> FIORELLA RETANA AGUILAR | E13: =IF(ISBLANK(C13),"",VLOOKUP(C13,Inscripciones!$B$5:$F$200,3,FALSE)) -> CURRIDABAT | F13: =IF(ISBLANK(C13),"",VLOOKUP(C13,Inscripciones!$B$5:$F$200,4,FALSE)) -> 15 | G13: =IF(ISBLANK(C13),"",VLOOKUP(C13,Inscripciones!$B$5:$F$200,5,FALSE)) -> 512 | J13: =IF(ISBLANK(J11)," ",(E21+F21+G21+E22+F22+G22+H21+I21+H22+I22)/(E20+F20+G20+E23+F23+G23+H20+I20+H23+I23))
A14: =+F9+0.3 -> 4.3 | B14: 3 | C14: =VLOOKUP(A14,Inscripciones!A6:G169,2,FALSE) -> 4380 | D14: =IF(ISBLANK(C14),"",VLOOKUP(C14,Inscripciones!$B$7:$F$200,2,FALSE)) -> VALENTINA FERNANDEZ REYES | E14: =IF(ISBLANK(C14),"",VLOOKUP(C14,Inscripciones!$B$7:$F$200,3,FALSE)) -> ESCAZÚ | F14: =IF(ISBLANK(C14),"",VLOOKUP(C14,Inscripciones!$B$7:$F$200,4,FALSE)) -> 23 | G14: =IF(ISBLANK(C14),"",VLOOKUP(C14,Inscripciones!$B$7:$F$200,5,FALSE)) -> 483 | J14: =IF(ISBLANK(J11)," ",(E19+F19+G19+E23+F23+G23+H19+I19+H23+I23)/(E18+F18+G18+E22+F22+G22+H18+I18+H22+I22))
B17: Partida | D17: JUGADOR | E17: 1º set | F17: 2º set | G17: 3º set | H17: 4º set | I17: 5º set | J17: Ganador
B18: 1 | C18: 1 | D18: =D12 -> LÍA SOFÍA SOLÍS VÁSQUEZ | E18: 11 | F18: 11 | J18: {=IF(AND(TRIM(E18)="WO",TRIM(E19)="WO"),"",IF(TRIM(E19)="WO",C18,IF(TRIM(E18)="WO",C19,IF(SUMPRODUCT(--(E18:I18>E19:I19))>SUMPRODUCT(--(E19:I19>E18:I18)),C18,IF(SUMPRODUCT(--(E19:I19>E18:I18))>SUMPRODUCT(--(E18:I18>E19:I19)),C19,"")))))} -> 1
C19: 3 | D19: =D14 -> VALENTINA FERNANDEZ REYES | E19: 4 | F19: 3
B20: 2 | C20: 1 | D20: =D12 -> LÍA SOFÍA SOLÍS VÁSQUEZ | E20: 11 | F20: 11 | J20: {=IF(AND(TRIM(E20)="WO",TRIM(E21)="WO"),"",IF(TRIM(E21)="WO",C20,IF(TRIM(E20)="WO",C21,IF(SUMPRODUCT(--(E20:I20>E21:I21))>SUMPRODUCT(--(E21:I21>E20:I20)),C20,IF(SUMPRODUCT(--(E21:I21>E20:I20))>SUMPRODUCT(--(E20:I20>E21:I21)),C21,"")))))} -> 1
C21: 2 | D21: =D13 -> FIORELLA RETANA AGUILAR | E21: 5 | F21: 8
B22: 3 | C22: 2 | D22: =D13 -> FIORELLA RETANA AGUILAR | E22: 11 | F22: 11 | J22: {=IF(AND(TRIM(E22)="WO",TRIM(E23)="WO"),"",IF(TRIM(E23)="WO",C22,IF(TRIM(E22)="WO",C23,IF(SUMPRODUCT(--(E22:I22>E23:I23))>SUMPRODUCT(--(E23:I23>E22:I22)),C22,IF(SUMPRODUCT(--(E23:I23>E22:I22))>SUMPRODUCT(--(E22:I22>E23:I23)),C23,"")))))} -> 2
C23: 3 | D23: =D14 -> VALENTINA FERNANDEZ REYES | E23: 7 | F23: 7
C32: Clasificados (# de carne) | F32: Revisión de Camisas y Raquetas
C33: Carnet | D33: Nombre | F33: Revisión de nombres y resultados
C34: 4176 | D34: =IF(ISBLANK(C34),"",VLOOKUP(C34,Inscripciones!$B$5:$F$200,2,FALSE)) -> LÍA SOFÍA SOLÍS VÁSQUEZ | F34: Árbitro
C35: 4212 | D35: =IF(ISBLANK(C35),"",VLOOKUP(C35,Inscripciones!$B$5:$F$200,2,FALSE)) -> FIORELLA RETANA AGUILAR | F35: Marque si hay informe

Sheet Grupo 5
L5: En Caso de ocupar 3 de 5, mostrar columnas H - I En caso de 2 de 2, ocultarlas.
G7: Fecha: | J7: =TODAY() -> 46288
B9: Categoría | D9: =Inscripciones!B2 -> U13 FEMENINO | E9: Grupo nº | F9: 5 | G9: Mesa nº
B11: Orden | C11: Carné | D11: Jugadores | E11: Lugar | F11: Ranking | G11: Puntos
A12: =F9+0.1 -> 5.1 | B12: 1 | C12: =VLOOKUP(A12,Inscripciones!A5:G167,2,FALSE) -> 4274 | D12: =IF(ISBLANK(C12),"",VLOOKUP(C12,Inscripciones!$B$5:$F$200,2,FALSE)) -> MARÍA PAULA HERNÁNDEZ ZÚÑIGA | E12: =IF(ISBLANK(C12),"",VLOOKUP(C12,Inscripciones!$B$5:$F$200,3,FALSE)) -> ESCAZÚ | F12: =IF(ISBLANK(C12),"",VLOOKUP(C12,Inscripciones!$B$5:$F$200,4,FALSE)) -> 5 | G12: =IF(ISBLANK(C12),"",VLOOKUP(C12,Inscripciones!$B$5:$F$200,5,FALSE)) -> 617 | J12: =IF(ISBLANK(J11)," ",(E18+F18+G18+E20+F20+G20+H18+I18+H20+I20)/(E19+F19+G19+E21+F21+G21+H19+I19+H21+I21))
A13: =F9+0.2 -> 5.2 | B13: 2 | C13: =VLOOKUP(A13,Inscripciones!A5:G168,2,FALSE) -> 4579 | D13: =IF(ISBLANK(C13),"",VLOOKUP(C13,Inscripciones!$B$5:$F$200,2,FALSE)) -> EMMA GIOCONDA BERTARIONI ARAYA | E13: =IF(ISBLANK(C13),"",VLOOKUP(C13,Inscripciones!$B$5:$F$200,3,FALSE)) -> ESPARZA | F13: =IF(ISBLANK(C13),"",VLOOKUP(C13,Inscripciones!$B$5:$F$200,4,FALSE)) -> 14 | G13: =IF(ISBLANK(C13),"",VLOOKUP(C13,Inscripciones!$B$5:$F$200,5,FALSE)) -> 526 | J13: =IF(ISBLANK(J11)," ",(E21+F21+G21+E22+F22+G22+H21+I21+H22+I22)/(E20+F20+G20+E23+F23+G23+H20+I20+H23+I23))
A14: =+F9+0.3 -> 5.3 | B14: 3 | C14: =VLOOKUP(A14,Inscripciones!A6:G169,2,FALSE) -> 4673 | D14: =IF(ISBLANK(C14),"",VLOOKUP(C14,Inscripciones!$B$7:$F$200,2,FALSE)) -> ALINA CHACON RETANA | E14: =IF(ISBLANK(C14),"",VLOOKUP(C14,Inscripciones!$B$7:$F$200,3,FALSE)) -> SAN CARLOS | F14: =IF(ISBLANK(C14),"",VLOOKUP(C14,Inscripciones!$B$7:$F$200,4,FALSE)) -> 25 | G14: =IF(ISBLANK(C14),"",VLOOKUP(C14,Inscripciones!$B$7:$F$200,5,FALSE)) -> 483 | J14: =IF(ISBLANK(J11)," ",(E19+F19+G19+E23+F23+G23+H19+I19+H23+I23)/(E18+F18+G18+E22+F22+G22+H18+I18+H22+I22))
B17: Partida | D17: JUGADOR | E17: 1º set | F17: 2º set | G17: 3º set | H17: 4º set | I17: 5º set | J17: Ganador
B18: 1 | C18: 1 | D18: =D12 -> MARÍA PAULA HERNÁNDEZ ZÚÑIGA | E18: 8 | F18: 8 | J18: {=IF(AND(TRIM(E18)="WO",TRIM(E19)="WO"),"",IF(TRIM(E19)="WO",C18,IF(TRIM(E18)="WO",C19,IF(SUMPRODUCT(--(E18:I18>E19:I19))>SUMPRODUCT(--(E19:I19>E18:I18)),C18,IF(SUMPRODUCT(--(E19:I19>E18:I18))>SUMPRODUCT(--(E18:I18>E19:I19)),C19,"")))))} -> 3
C19: 3 | D19: =D14 -> ALINA CHACON RETANA | E19: 11 | F19: 11
B20: 2 | C20: 1 | D20: =D12 -> MARÍA PAULA HERNÁNDEZ ZÚÑIGA | E20: 11 | F20: 11 | J20: {=IF(AND(TRIM(E20)="WO",TRIM(E21)="WO"),"",IF(TRIM(E21)="WO",C20,IF(TRIM(E20)="WO",C21,IF(SUMPRODUCT(--(E20:I20>E21:I21))>SUMPRODUCT(--(E21:I21>E20:I20)),C20,IF(SUMPRODUCT(--(E21:I21>E20:I20))>SUMPRODUCT(--(E20:I20>E21:I21)),C21,"")))))} -> 1
C21: 2 | D21: =D13 -> EMMA GIOCONDA BERTARIONI ARAYA | E21: 2 | F21: 3
B22: 3 | C22: 2 | D22: =D13 -> EMMA GIOCONDA BERTARIONI ARAYA | E22: 11 | F22: 12 | J22: {=IF(AND(TRIM(E22)="WO",TRIM(E23)="WO"),"",IF(TRIM(E23)="WO",C22,IF(TRIM(E22)="WO",C23,IF(SUMPRODUCT(--(E22:I22>E23:I23))>SUMPRODUCT(--(E23:I23>E22:I22)),C22,IF(SUMPRODUCT(--(E23:I23>E22:I22))>SUMPRODUCT(--(E22:I22>E23:I23)),C23,"")))))} -> 2
C23: 3 | D23: =D14 -> ALINA CHACON RETANA | E23: 9 | F23: 10
C32: Clasificados (# de carne) | F32: Revisión de Camisas y Raquetas
C33: Carnet | D33: Nombre | F33: Revisión de nombres y resultados
C34: 4274 | D34: =IF(ISBLANK(C34),"",VLOOKUP(C34,Inscripciones!$B$5:$F$200,2,FALSE)) -> MARÍA PAULA HERNÁNDEZ ZÚÑIGA | F34: Árbitro
C35: 4673 | D35: =IF(ISBLANK(C35),"",VLOOKUP(C35,Inscripciones!$B$5:$F$200,2,FALSE)) -> ALINA CHACON RETANA | F35: Marque si hay informe

Sheet Grupo 6
L5: En Caso de ocupar 3 de 5, mostrar columnas H - I En caso de 2 de 2, ocultarlas.
G7: Fecha: | J7: =TODAY() -> 46288
B9: Categoría | D9: =Inscripciones!B2 -> U13 FEMENINO | E9: Grupo nº | F9: 6 | G9: Mesa nº
B11: Orden | C11: Carné | D11: Jugadores | E11: Lugar | F11: Ranking | G11: Puntos
A12: =F9+0.1 -> 6.1 | B12: 1 | C12: =VLOOKUP(A12,Inscripciones!A5:G167,2,FALSE) -> 4273 | D12: =IF(ISBLANK(C12),"",VLOOKUP(C12,Inscripciones!$B$5:$F$200,2,FALSE)) -> JAQUELINE HERNÁNDEZ ZUÑIGA | E12: =IF(ISBLANK(C12),"",VLOOKUP(C12,Inscripciones!$B$5:$F$200,3,FALSE)) -> ESCAZÚ | F12: =IF(ISBLANK(C12),"",VLOOKUP(C12,Inscripciones!$B$5:$F$200,4,FALSE)) -> 6 | G12: =IF(ISBLANK(C12),"",VLOOKUP(C12,Inscripciones!$B$5:$F$200,5,FALSE)) -> 603 | J12: =IF(ISBLANK(J11)," ",(E18+F18+G18+E20+F20+G20+H18+I18+H20+I20)/(E19+F19+G19+E21+F21+G21+H19+I19+H21+I21))
A13: =F9+0.2 -> 6.2 | B13: 2 | C13: =VLOOKUP(A13,Inscripciones!A5:G168,2,FALSE) -> 4047 | D13: =IF(ISBLANK(C13),"",VLOOKUP(C13,Inscripciones!$B$5:$F$200,2,FALSE)) -> MARIANGEL JIMENEZ QUESADA | E13: =IF(ISBLANK(C13),"",VLOOKUP(C13,Inscripciones!$B$5:$F$200,3,FALSE)) -> ESPARZA | F13: =IF(ISBLANK(C13),"",VLOOKUP(C13,Inscripciones!$B$5:$F$200,4,FALSE)) -> 11 | G13: =IF(ISBLANK(C13),"",VLOOKUP(C13,Inscripciones!$B$5:$F$200,5,FALSE)) -> 566 | J13: =IF(ISBLANK(J11)," ",(E21+F21+G21+E22+F22+G22+H21+I21+H22+I22)/(E20+F20+G20+E23+F23+G23+H20+I20+H23+I23))
A14: =+F9+0.3 -> 6.3 | B14: 3 | C14: =VLOOKUP(A14,Inscripciones!A6:G169,2,FALSE) -> 3912 | D14: =IF(ISBLANK(C14),"",VLOOKUP(C14,Inscripciones!$B$7:$F$200,2,FALSE)) -> AMBAR PADILLA GRANADOS | E14: =IF(ISBLANK(C14),"",VLOOKUP(C14,Inscripciones!$B$7:$F$200,3,FALSE)) -> PÉREZ ZELEDÓN | F14: =IF(ISBLANK(C14),"",VLOOKUP(C14,Inscripciones!$B$7:$F$200,4,FALSE)) -> 26 | G14: =IF(ISBLANK(C14),"",VLOOKUP(C14,Inscripciones!$B$7:$F$200,5,FALSE)) -> 473 | J14: =IF(ISBLANK(J11)," ",(E19+F19+G19+E23+F23+G23+H19+I19+H23+I23)/(E18+F18+G18+E22+F22+G22+H18+I18+H22+I22))
B17: Partida | D17: JUGADOR | E17: 1º set | F17: 2º set | G17: 3º set | H17: 4º set | I17: 5º set | J17: Ganador
B18: 1 | C18: 1 | D18: =D12 -> JAQUELINE HERNÁNDEZ ZUÑIGA | E18: 11 | F18: 11 | J18: {=IF(AND(TRIM(E18)="WO",TRIM(E19)="WO"),"",IF(TRIM(E19)="WO",C18,IF(TRIM(E18)="WO",C19,IF(SUMPRODUCT(--(E18:I18>E19:I19))>SUMPRODUCT(--(E19:I19>E18:I18)),C18,IF(SUMPRODUCT(--(E19:I19>E18:I18))>SUMPRODUCT(--(E18:I18>E19:I19)),C19,"")))))} -> 1
C19: 3 | D19: =D14 -> AMBAR PADILLA GRANADOS | E19: 5 | F19: 8
B20: 2 | C20: 1 | D20: =D12 -> JAQUELINE HERNÁNDEZ ZUÑIGA | E20: 11 | F20: 14 | J20: {=IF(AND(TRIM(E20)="WO",TRIM(E21)="WO"),"",IF(TRIM(E21)="WO",C20,IF(TRIM(E20)="WO",C21,IF(SUMPRODUCT(--(E20:I20>E21:I21))>SUMPRODUCT(--(E21:I21>E20:I20)),C20,IF(SUMPRODUCT(--(E21:I21>E20:I20))>SUMPRODUCT(--(E20:I20>E21:I21)),C21,"")))))} -> 1
C21: 2 | D21: =D13 -> MARIANGEL JIMENEZ QUESADA | E21: 4 | F21: 12
B22: 3 | C22: 2 | D22: =D13 -> MARIANGEL JIMENEZ QUESADA | E22: 9 | F22: 4 | J22: {=IF(AND(TRIM(E22)="WO",TRIM(E23)="WO"),"",IF(TRIM(E23)="WO",C22,IF(TRIM(E22)="WO",C23,IF(SUMPRODUCT(--(E22:I22>E23:I23))>SUMPRODUCT(--(E23:I23>E22:I22)),C22,IF(SUMPRODUCT(--(E23:I23>E22:I22))>SUMPRODUCT(--(E22:I22>E23:I23)),C23,"")))))} -> 3
C23: 3 | D23: =D14 -> AMBAR PADILLA GRANADOS | E23: 11 | F23: 11
C32: Clasificados (# de carne) | F32: Revisión de Camisas y Raquetas
C33: Carnet | D33: Nombre | F33: Revisión de nombres y resultados
C34: 4273 | D34: =IF(ISBLANK(C34),"",VLOOKUP(C34,Inscripciones!$B$5:$F$200,2,FALSE)) -> JAQUELINE HERNÁNDEZ ZUÑIGA | F34: Árbitro
C35: 3912 | D35: =IF(ISBLANK(C35),"",VLOOKUP(C35,Inscripciones!$B$5:$F$200,2,FALSE)) -> AMBAR PADILLA GRANADOS | F35: Marque si hay informe

Sheet Grupo 7
L5: En Caso de ocupar 3 de 5, mostrar columnas H - I En caso de 2 de 2, ocultarlas.
G7: Fecha: | J7: =TODAY() -> 46288
B9: Categoría | D9: =Inscripciones!B2 -> U13 FEMENINO | E9: Grupo nº | F9: 7 | G9: Mesa nº
B11: Orden | C11: Carné | D11: Jugadores | E11: Lugar | F11: Ranking | G11: Puntos
A12: =F9+0.1 -> 7.1 | B12: 1 | C12: =VLOOKUP(A12,Inscripciones!A5:G167,2,FALSE) -> 4100 | D12: =IF(ISBLANK(C12),"",VLOOKUP(C12,Inscripciones!$B$5:$F$200,2,FALSE)) -> BRENDA HERRERA RIVAS | E12: =IF(ISBLANK(C12),"",VLOOKUP(C12,Inscripciones!$B$5:$F$200,3,FALSE)) -> ESPARZA | F12: =IF(ISBLANK(C12),"",VLOOKUP(C12,Inscripciones!$B$5:$F$200,4,FALSE)) -> 7 | G12: =IF(ISBLANK(C12),"",VLOOKUP(C12,Inscripciones!$B$5:$F$200,5,FALSE)) -> 602 | J12: =IF(ISBLANK(J11)," ",(E18+F18+G18+E20+F20+G20+H18+I18+H20+I20)/(E19+F19+G19+E21+F21+G21+H19+I19+H21+I21))
A13: =F9+0.2 -> 7.2 | B13: 2 | C13: =VLOOKUP(A13,Inscripciones!A5:G168,2,FALSE) -> 4104 | D13: =IF(ISBLANK(C13),"",VLOOKUP(C13,Inscripciones!$B$5:$F$200,2,FALSE)) -> ARIANA SANCHEZ DELGADO | E13: =IF(ISBLANK(C13),"",VLOOKUP(C13,Inscripciones!$B$5:$F$200,3,FALSE)) -> ESCAZÚ | F13: =IF(ISBLANK(C13),"",VLOOKUP(C13,Inscripciones!$B$5:$F$200,4,FALSE)) -> 12 | G13: =IF(ISBLANK(C13),"",VLOOKUP(C13,Inscripciones!$B$5:$F$200,5,FALSE)) -> 549 | J13: =IF(ISBLANK(J11)," ",(E21+F21+G21+E22+F22+G22+H21+I21+H22+I22)/(E20+F20+G20+E23+F23+G23+H20+I20+H23+I23))
A14: =+F9+0.3 -> 7.3 | B14: 3 | C14: =VLOOKUP(A14,Inscripciones!A6:G169,2,FALSE) -> 4278 | D14: =IF(ISBLANK(C14),"",VLOOKUP(C14,Inscripciones!$B$7:$F$200,2,FALSE)) -> EMA MELISSA ANGULO CRUZ | E14: =IF(ISBLANK(C14),"",VLOOKUP(C14,Inscripciones!$B$7:$F$200,3,FALSE)) -> ASERRÍ | F14: =IF(ISBLANK(C14),"",VLOOKUP(C14,Inscripciones!$B$7:$F$200,4,FALSE)) -> 28 | G14: =IF(ISBLANK(C14),"",VLOOKUP(C14,Inscripciones!$B$7:$F$200,5,FALSE)) -> 470 | J14: =IF(ISBLANK(J11)," ",(E19+F19+G19+E23+F23+G23+H19+I19+H23+I23)/(E18+F18+G18+E22+F22+G22+H18+I18+H22+I22))
B17: Partida | D17: JUGADOR | E17: 1º set | F17: 2º set | G17: 3º set | H17: 4º set | I17: 5º set | J17: Ganador
B18: 1 | C18: 1 | D18: =D12 -> BRENDA HERRERA RIVAS | E18: 11 | F18: 11 | J18: {=IF(AND(TRIM(E18)="WO",TRIM(E19)="WO"),"",IF(TRIM(E19)="WO",C18,IF(TRIM(E18)="WO",C19,IF(SUMPRODUCT(--(E18:I18>E19:I19))>SUMPRODUCT(--(E19:I19>E18:I18)),C18,IF(SUMPRODUCT(--(E19:I19>E18:I18))>SUMPRODUCT(--(E18:I18>E19:I19)),C19,"")))))} -> 1
C19: 3 | D19: =D14 -> EMA MELISSA ANGULO CRUZ | E19: 6 | F19: 6
B20: 2 | C20: 1 | D20: =D12 -> BRENDA HERRERA RIVAS | E20: 11 | F20: 11 | J20: {=IF(AND(TRIM(E20)="WO",TRIM(E21)="WO"),"",IF(TRIM(E21)="WO",C20,IF(TRIM(E20)="WO",C21,IF(SUMPRODUCT(--(E20:I20>E21:I21))>SUMPRODUCT(--(E21:I21>E20:I20)),C20,IF(SUMPRODUCT(--(E21:I21>E20:I20))>SUMPRODUCT(--(E20:I20>E21:I21)),C21,"")))))} -> 1
C21: 2 | D21: =D13 -> ARIANA SANCHEZ DELGADO | E21: 4 | F21: 6
B22: 3 | C22: 2 | D22: =D13 -> ARIANA SANCHEZ DELGADO | E22: 11 | F22: 12 | J22: {=IF(AND(TRIM(E22)="WO",TRIM(E23)="WO"),"",IF(TRIM(E23)="WO",C22,IF(TRIM(E22)="WO",C23,IF(SUMPRODUCT(--(E22:I22>E23:I23))>SUMPRODUCT(--(E23:I23>E22:I22)),C22,IF(SUMPRODUCT(--(E23:I23>E22:I22))>SUMPRODUCT(--(E22:I22>E23:I23)),C23,"")))))} -> 2
C23: 3 | D23: =D14 -> EMA MELISSA ANGULO CRUZ | E23: 7 | F23: 10
C32: Clasificados (# de carne) | F32: Revisión de Camisas y Raquetas
C33: Carnet | D33: Nombre | F33: Revisión de nombres y resultados
C34: 4100 | D34: =IF(ISBLANK(C34),"",VLOOKUP(C34,Inscripciones!$B$5:$F$200,2,FALSE)) -> BRENDA HERRERA RIVAS | F34: Árbitro
C35: 4104 | D35: =IF(ISBLANK(C35),"",VLOOKUP(C35,Inscripciones!$B$5:$F$200,2,FALSE)) -> ARIANA SANCHEZ DELGADO | F35: Marque si hay informe

Sheet Grupo 8
L5: En Caso de ocupar 3 de 5, mostrar columnas H - I En caso de 2 de 2, ocultarlas.
G7: Fecha: | J7: =TODAY() -> 46288
B9: Categoría | D9: =Inscripciones!B2 -> U13 FEMENINO | E9: Grupo nº | F9: 8 | G9: Mesa nº
B11: Orden | C11: Carné | D11: Jugadores | E11: Lugar | F11: Ranking | G11: Puntos
