Workbook
Name a: #REF!
Name a: #REF!
Name acdb: #REF!
Name acdb: #REF!
Name ACDB1: #REF!
Name ACDB1: #REF!
Name acdf: #REF!
Name acdh: #REF!
Name acdo: #REF!
Name aceq: [1]AE!$A:$IV
Name aceq: #REF!
Name acif: #REF!
Name acin: #REF!
Name ACIN1: #REF!
Name acti: #REF!
Name avc: [2]DORSAL!$A$2:$G$120
Name avc: #REF!
Name datos: [3]Datos!$A$2:$G$140
Name datos: #REF!
Name dorsal: [2]DORSAL!$A$2:$G$120
Name dorsal: #REF!
Name EQ: [4]EQU!$A:$IV
Name EQ: #REF!
Name IN: [4]IND!$A:$IV
Name IN: #REF!
Name IND: [5]IN!$A$3:$IV$102
Name IND: #REF!
Name IPC_Member: #REF!
Name JBS: [6]JB!$A$1:$E$100
Name JBS: #REF!
Name JGS: #REF!
Name JUG: [7]Jug!$A$2:$D$13
Name JUG: #REF!
Name PC: #REF!
Name PCS: #REF!
Name PLAYERS: [8]Players!$B$4:$H$124
Name PLAYERS: #REF!
Name RK: #REF!
Name RKJB: #REF!
Name RKJG: #REF!
Name SI: #REF!
Name sssss: #REF!

Sheet Sheet1

Sheet Tabulación
C1: Ganadores | F1: Perdedores | K1: 14 | L1: {=VLOOKUP(INDIRECT("'Grupo " & K1 & "'!J18"),INDIRECT("'Grupo " & K1 & "'!B12"):INDIRECT("'Grupo " & K1 & "'!J15"),2,FALSE)} -> 4363 | M1: {=VLOOKUP(IF(INDIRECT("'Grupo " & K1 & "'!J18")=INDIRECT("'Grupo " & K1 & "'!C18"),INDIRECT("'Grupo " & K1 & "'!C19"),INDIRECT("'Grupo " & K1 & "'!C18")),INDIRECT("'Grupo " & K1 & "'!B12"):INDIRECT("'Grupo " & K1 & "'!G15"),2,FALSE)} -> 4851 | O1: {=VLOOKUP(IF(INDIRECT("'Grupo " & K1 & "'!J18")=INDIRECT("'Grupo " & K1 & "'!C18"),INDIRECT("'Grupo " & K1 & "'!C19"),INDIRECT("'Grupo " & K1 & "'!C18")),INDIRECT("'Grupo " & K1 & "'!B12"):INDIRECT("'Grupo " & K1 & "'!G15"),2,FALSE)} -> 4851 | P1: {=VLOOKUP(INDIRECT("'Grupo " & K1 & "'!J18"),INDIRECT("'Grupo " & K1 & "'!B12"):INDIRECT("'Grupo " & K1 & "'!J15"),2,FALSE)} -> 4363
B2: 1 | C2: {=VLOOKUP(INDIRECT("'Grupo " & B2 & "'!J18"),INDIRECT("'Grupo " & B2 & "'!B12"):INDIRECT("'Grupo " & B2 & "'!J15"),2,FALSE)} -> 2515 | D2: {=VLOOKUP(IF(INDIRECT("'Grupo " & B2 & "'!J18")=INDIRECT("'Grupo " & B2 & "'!C18"),INDIRECT("'Grupo " & B2 & "'!C19"),INDIRECT("'Grupo " & B2 & "'!C18")),INDIRECT("'Grupo " & B2 & "'!B12"):INDIRECT("'Grupo " & B2 & "'!G15"),2,FALSE)} -> 3670 | F2: {=VLOOKUP(IF(INDIRECT("'Grupo " & B2 & "'!J18")=INDIRECT("'Grupo " & B2 & "'!C18"),INDIRECT("'Grupo " & B2 & "'!C19"),INDIRECT("'Grupo " & B2 & "'!C18")),INDIRECT("'Grupo " & B2 & "'!B12"):INDIRECT("'Grupo " & B2 & "'!G15"),2,FALSE)} -> 3670 | G2: {=VLOOKUP(INDIRECT("'Grupo " & B2 & "'!J18"),INDIRECT("'Grupo " & B2 & "'!B12"):INDIRECT("'Grupo " & B2 & "'!J15"),2,FALSE)} -> 2515 | L2: {=VLOOKUP(INDIRECT("'Grupo " & K1 & "'!J20"),INDIRECT("'Grupo " & K1 & "'!B12"):INDIRECT("'Grupo " & K1 & "'!J15"),2,FALSE)} -> 4363 | M2: {=VLOOKUP(IF(INDIRECT("'Grupo " & K1 & "'!J20")=INDIRECT("'Grupo " & K1 & "'!C20"),INDIRECT("'Grupo " & K1 & "'!C21"),INDIRECT("'Grupo " & K1 & "'!C20")),INDIRECT("'Grupo " & K1 & "'!B12"):INDIRECT("'Grupo " & K1 & "'!G15"),2,FALSE)} -> 4056 | O2: {=VLOOKUP(IF(INDIRECT("'Grupo " & K1 & "'!J20")=INDIRECT("'Grupo " & K1 & "'!C20"),INDIRECT("'Grupo " & K1 & "'!C21"),INDIRECT("'Grupo " & K1 & "'!C20")),INDIRECT("'Grupo " & K1 & "'!B12"):INDIRECT("'Grupo " & K1 & "'!G15"),2,FALSE)} -> 4056 | P2: {=VLOOKUP(INDIRECT("'Grupo " & K1 & "'!J20"),INDIRECT("'Grupo " & K1 & "'!B12"):INDIRECT("'Grupo " & K1 & "'!J15"),2,FALSE)} -> 4363
C3: {=VLOOKUP(INDIRECT("'Grupo " & B2 & "'!J20"),INDIRECT("'Grupo " & B2 & "'!B12"):INDIRECT("'Grupo " & B2 & "'!J15"),2,FALSE)} -> 2515 | D3: {=VLOOKUP(IF(INDIRECT("'Grupo " & B2 & "'!J20")=INDIRECT("'Grupo " & B2 & "'!C20"),INDIRECT("'Grupo " & B2 & "'!C21"),INDIRECT("'Grupo " & B2 & "'!C20")),INDIRECT("'Grupo " & B2 & "'!B12"):INDIRECT("'Grupo " & B2 & "'!G15"),2,FALSE)} -> 4513 | F3: {=VLOOKUP(IF(INDIRECT("'Grupo " & B2 & "'!J20")=INDIRECT("'Grupo " & B2 & "'!C20"),INDIRECT("'Grupo " & B2 & "'!C21"),INDIRECT("'Grupo " & B2 & "'!C20")),INDIRECT("'Grupo " & B2 & "'!B12"):INDIRECT("'Grupo " & B2 & "'!G15"),2,FALSE)} -> 4513 | G3: {=VLOOKUP(INDIRECT("'Grupo " & B2 & "'!J20"),INDIRECT("'Grupo " & B2 & "'!B12"):INDIRECT("'Grupo " & B2 & "'!J15"),2,FALSE)} -> 2515 | L3: {=VLOOKUP(INDIRECT("'Grupo " & K1 & "'!J22"),INDIRECT("'Grupo " & K1 & "'!B12"):INDIRECT("'Grupo " & K1 & "'!J15"),2,FALSE)} -> 4056 | M3: {=VLOOKUP(IF(INDIRECT("'Grupo " & K1 & "'!J22")=INDIRECT("'Grupo " & K1 & "'!C22"),INDIRECT("'Grupo " & K1 & "'!C23"),INDIRECT("'Grupo " & K1 & "'!C22")),INDIRECT("'Grupo " & K1 & "'!B12"):INDIRECT("'Grupo " & K1 & "'!G15"),2,FALSE)} -> 4851 | O3: {=VLOOKUP(IF(INDIRECT("'Grupo " & K1 & "'!J22")=INDIRECT("'Grupo " & K1 & "'!C22"),INDIRECT("'Grupo " & K1 & "'!C23"),INDIRECT("'Grupo " & K1 & "'!C22")),INDIRECT("'Grupo " & K1 & "'!B12"):INDIRECT("'Grupo " & K1 & "'!G15"),2,FALSE)} -> 4851 | P3: {=VLOOKUP(INDIRECT("'Grupo " & K1 & "'!J22"),INDIRECT("'Grupo " & K1 & "'!B12"):INDIRECT("'Grupo " & K1 & "'!J15"),2,FALSE)} -> 4056
C4: {=VLOOKUP(INDIRECT("'Grupo " & B2 & "'!J22"),INDIRECT("'Grupo " & B2 & "'!B12"):INDIRECT("'Grupo " & B2 & "'!J15"),2,FALSE)} -> 4513 | D4: {=VLOOKUP(IF(INDIRECT("'Grupo " & B2 & "'!J22")=INDIRECT("'Grupo " & B2 & "'!C22"),INDIRECT("'Grupo " & B2 & "'!C23"),INDIRECT("'Grupo " & B2 & "'!C22")),INDIRECT("'Grupo " & B2 & "'!B12"):INDIRECT("'Grupo " & B2 & "'!G15"),2,FALSE)} -> 3670 | F4: {=VLOOKUP(IF(INDIRECT("'Grupo " & B2 & "'!J22")=INDIRECT("'Grupo " & B2 & "'!C22"),INDIRECT("'Grupo " & B2 & "'!C23"),INDIRECT("'Grupo " & B2 & "'!C22")),INDIRECT("'Grupo " & B2 & "'!B12"):INDIRECT("'Grupo " & B2 & "'!G15"),2,FALSE)} -> 3670 | G4: {=VLOOKUP(INDIRECT("'Grupo " & B2 & "'!J22"),INDIRECT("'Grupo " & B2 & "'!B12"):INDIRECT("'Grupo " & B2 & "'!J15"),2,FALSE)} -> 4513 | L4: {=VLOOKUP(INDIRECT("'Grupo " & K1 & "'!J24"),INDIRECT("'Grupo " & K1 & "'!B12"):INDIRECT("'Grupo " & K1 & "'!J15"),2,FALSE)} -> #N/A | M4: {=VLOOKUP(IF(INDIRECT("'Grupo " & K1 & "'!J24")=INDIRECT("'Grupo " & K1 & "'!C24"),INDIRECT("'Grupo " & K1 & "'!C25"),INDIRECT("'Grupo " & K1 & "'!C24")),INDIRECT("'Grupo " & K1 & "'!B12"):INDIRECT("'Grupo " & K1 & "'!G15"),2,FALSE)} -> #N/A | O4: {=VLOOKUP(IF(INDIRECT("'Grupo " & K1 & "'!J24")=INDIRECT("'Grupo " & K1 & "'!C24"),INDIRECT("'Grupo " & K1 & "'!C25"),INDIRECT("'Grupo " & K1 & "'!C24")),INDIRECT("'Grupo " & K1 & "'!B12"):INDIRECT("'Grupo " & K1 & "'!G15"),2,FALSE)} -> #N/A | P4: {=VLOOKUP(INDIRECT("'Grupo " & K1 & "'!J24"),INDIRECT("'Grupo " & K1 & "'!B12"):INDIRECT("'Grupo " & K1 & "'!J15"),2,FALSE)} -> #N/A
B5: =B2+1 -> 2 | C5: {=VLOOKUP(INDIRECT("'Grupo " & B5 & "'!J18"),INDIRECT("'Grupo " & B5 & "'!B12"):INDIRECT("'Grupo " & B5 & "'!J15"),2,FALSE)} -> 4144 | D5: {=VLOOKUP(IF(INDIRECT("'Grupo " & B5 & "'!J18")=INDIRECT("'Grupo " & B5 & "'!C18"),INDIRECT("'Grupo " & B5 & "'!C19"),INDIRECT("'Grupo " & B5 & "'!C18")),INDIRECT("'Grupo " & B5 & "'!B12"):INDIRECT("'Grupo " & B5 & "'!G15"),2,FALSE)} -> 2582 | F5: {=VLOOKUP(IF(INDIRECT("'Grupo " & B5 & "'!J18")=INDIRECT("'Grupo " & B5 & "'!C18"),INDIRECT("'Grupo " & B5 & "'!C19"),INDIRECT("'Grupo " & B5 & "'!C18")),INDIRECT("'Grupo " & B5 & "'!B12"):INDIRECT("'Grupo " & B5 & "'!G15"),2,FALSE)} -> 2582 | G5: {=VLOOKUP(INDIRECT("'Grupo " & B5 & "'!J18"),INDIRECT("'Grupo " & B5 & "'!B12"):INDIRECT("'Grupo " & B5 & "'!J15"),2,FALSE)} -> 4144 | L5: {=VLOOKUP(INDIRECT("'Grupo " & K1 & "'!J26"),INDIRECT("'Grupo " & K1 & "'!B12"):INDIRECT("'Grupo " & K1 & "'!J15"),2,FALSE)} -> #N/A | M5: {=VLOOKUP(IF(INDIRECT("'Grupo " & K1 & "'!J26")=INDIRECT("'Grupo " & K1 & "'!C26"),INDIRECT("'Grupo " & K1 & "'!C27"),INDIRECT("'Grupo " & K1 & "'!C26")),INDIRECT("'Grupo " & K1 & "'!B12"):INDIRECT("'Grupo " & K1 & "'!G15"),2,FALSE)} -> #N/A | O5: {=VLOOKUP(IF(INDIRECT("'Grupo " & K1 & "'!J26")=INDIRECT("'Grupo " & K1 & "'!C26"),INDIRECT("'Grupo " & K1 & "'!C27"),INDIRECT("'Grupo " & K1 & "'!C26")),INDIRECT("'Grupo " & K1 & "'!B12"):INDIRECT("'Grupo " & K1 & "'!G15"),2,FALSE)} -> #N/A | P5: {=VLOOKUP(INDIRECT("'Grupo " & K1 & "'!J26"),INDIRECT("'Grupo " & K1 & "'!B12"):INDIRECT("'Grupo " & K1 & "'!J15"),2,FALSE)} -> #N/A
C6: {=VLOOKUP(INDIRECT("'Grupo " & B5 & "'!J20"),INDIRECT("'Grupo " & B5 & "'!B12"):INDIRECT("'Grupo " & B5 & "'!J15"),2,FALSE)} -> 2513 | D6: {=VLOOKUP(IF(INDIRECT("'Grupo " & B5 & "'!J20")=INDIRECT("'Grupo " & B5 & "'!C20"),INDIRECT("'Grupo " & B5 & "'!C21"),INDIRECT("'Grupo " & B5 & "'!C20")),INDIRECT("'Grupo " & B5 & "'!B12"):INDIRECT("'Grupo " & B5 & "'!G15"),2,FALSE)} -> 2582 | F6: {=VLOOKUP(IF(INDIRECT("'Grupo " & B5 & "'!J20")=INDIRECT("'Grupo " & B5 & "'!C20"),INDIRECT("'Grupo " & B5 & "'!C21"),INDIRECT("'Grupo " & B5 & "'!C20")),INDIRECT("'Grupo " & B5 & "'!B12"):INDIRECT("'Grupo " & B5 & "'!G15"),2,FALSE)} -> 2582 | G6: {=VLOOKUP(INDIRECT("'Grupo " & B5 & "'!J20"),INDIRECT("'Grupo " & B5 & "'!B12"):INDIRECT("'Grupo " & B5 & "'!J15"),2,FALSE)} -> 2513 | L6: {=VLOOKUP(INDIRECT("'Grupo " & K1 & "'!J28"),INDIRECT("'Grupo " & K1 & "'!B12"):INDIRECT("'Grupo " & K1 & "'!J15"),2,FALSE)} -> #N/A | M6: {=VLOOKUP(IF(INDIRECT("'Grupo " & K1 & "'!J28")=INDIRECT("'Grupo " & K1 & "'!C28"),INDIRECT("'Grupo " & K1 & "'!C29"),INDIRECT("'Grupo " & K1 & "'!C28")),INDIRECT("'Grupo " & K1 & "'!B12"):INDIRECT("'Grupo " & K1 & "'!G15"),2,FALSE)} -> #N/A | O6: {=VLOOKUP(IF(INDIRECT("'Grupo " & K1 & "'!J28")=INDIRECT("'Grupo " & K1 & "'!C28"),INDIRECT("'Grupo " & K1 & "'!C29"),INDIRECT("'Grupo " & K1 & "'!C28")),INDIRECT("'Grupo " & K1 & "'!B12"):INDIRECT("'Grupo " & K1 & "'!G15"),2,FALSE)} -> #N/A | P6: {=VLOOKUP(INDIRECT("'Grupo " & K1 & "'!J28"),INDIRECT("'Grupo " & K1 & "'!B12"):INDIRECT("'Grupo " & K1 & "'!J15"),2,FALSE)} -> #N/A
C7: {=VLOOKUP(INDIRECT("'Grupo " & B5 & "'!J22"),INDIRECT("'Grupo " & B5 & "'!B12"):INDIRECT("'Grupo " & B5 & "'!J15"),2,FALSE)} -> 4144 | D7: {=VLOOKUP(IF(INDIRECT("'Grupo " & B5 & "'!J22")=INDIRECT("'Grupo " & B5 & "'!C22"),INDIRECT("'Grupo " & B5 & "'!C23"),INDIRECT("'Grupo " & B5 & "'!C22")),INDIRECT("'Grupo " & B5 & "'!B12"):INDIRECT("'Grupo " & B5 & "'!G15"),2,FALSE)} -> 2513 | F7: {=VLOOKUP(IF(INDIRECT("'Grupo " & B5 & "'!J22")=INDIRECT("'Grupo " & B5 & "'!C22"),INDIRECT("'Grupo " & B5 & "'!C23"),INDIRECT("'Grupo " & B5 & "'!C22")),INDIRECT("'Grupo " & B5 & "'!B12"):INDIRECT("'Grupo " & B5 & "'!G15"),2,FALSE)} -> 2513 | G7: {=VLOOKUP(INDIRECT("'Grupo " & B5 & "'!J22"),INDIRECT("'Grupo " & B5 & "'!B12"):INDIRECT("'Grupo " & B5 & "'!J15"),2,FALSE)} -> 4144
B8: =B5+1 -> 3 | C8: {=VLOOKUP(INDIRECT("'Grupo " & B8 & "'!J18"),INDIRECT("'Grupo " & B8 & "'!B12"):INDIRECT("'Grupo " & B8 & "'!J15"),2,FALSE)} -> 4034 | D8: {=VLOOKUP(IF(INDIRECT("'Grupo " & B8 & "'!J18")=INDIRECT("'Grupo " & B8 & "'!C18"),INDIRECT("'Grupo " & B8 & "'!C19"),INDIRECT("'Grupo " & B8 & "'!C18")),INDIRECT("'Grupo " & B8 & "'!B12"):INDIRECT("'Grupo " & B8 & "'!G15"),2,FALSE)} -> 4415 | F8: {=VLOOKUP(IF(INDIRECT("'Grupo " & B8 & "'!J18")=INDIRECT("'Grupo " & B8 & "'!C18"),INDIRECT("'Grupo " & B8 & "'!C19"),INDIRECT("'Grupo " & B8 & "'!C18")),INDIRECT("'Grupo " & B8 & "'!B12"):INDIRECT("'Grupo " & B8 & "'!G15"),2,FALSE)} -> 4415 | G8: {=VLOOKUP(INDIRECT("'Grupo " & B8 & "'!J18"),INDIRECT("'Grupo " & B8 & "'!B12"):INDIRECT("'Grupo " & B8 & "'!J15"),2,FALSE)} -> 4034
C9: {=VLOOKUP(INDIRECT("'Grupo " & B8 & "'!J20"),INDIRECT("'Grupo " & B8 & "'!B12"):INDIRECT("'Grupo " & B8 & "'!J15"),2,FALSE)} -> 4034 | D9: {=VLOOKUP(IF(INDIRECT("'Grupo " & B8 & "'!J20")=INDIRECT("'Grupo " & B8 & "'!C20"),INDIRECT("'Grupo " & B8 & "'!C21"),INDIRECT("'Grupo " & B8 & "'!C20")),INDIRECT("'Grupo " & B8 & "'!B12"):INDIRECT("'Grupo " & B8 & "'!G15"),2,FALSE)} -> 2847 | F9: {=VLOOKUP(IF(INDIRECT("'Grupo " & B8 & "'!J20")=INDIRECT("'Grupo " & B8 & "'!C20"),INDIRECT("'Grupo " & B8 & "'!C21"),INDIRECT("'Grupo " & B8 & "'!C20")),INDIRECT("'Grupo " & B8 & "'!B12"):INDIRECT("'Grupo " & B8 & "'!G15"),2,FALSE)} -> 2847 | G9: {=VLOOKUP(INDIRECT("'Grupo " & B8 & "'!J20"),INDIRECT("'Grupo " & B8 & "'!B12"):INDIRECT("'Grupo " & B8 & "'!J15"),2,FALSE)} -> 4034
C10: {=VLOOKUP(INDIRECT("'Grupo " & B8 & "'!J22"),INDIRECT("'Grupo " & B8 & "'!B12"):INDIRECT("'Grupo " & B8 & "'!J15"),2,FALSE)} -> 2847 | D10: {=VLOOKUP(IF(INDIRECT("'Grupo " & B8 & "'!J22")=INDIRECT("'Grupo " & B8 & "'!C22"),INDIRECT("'Grupo " & B8 & "'!C23"),INDIRECT("'Grupo " & B8 & "'!C22")),INDIRECT("'Grupo " & B8 & "'!B12"):INDIRECT("'Grupo " & B8 & "'!G15"),2,FALSE)} -> 4415 | F10: {=VLOOKUP(IF(INDIRECT("'Grupo " & B8 & "'!J22")=INDIRECT("'Grupo " & B8 & "'!C22"),INDIRECT("'Grupo " & B8 & "'!C23"),INDIRECT("'Grupo " & B8 & "'!C22")),INDIRECT("'Grupo " & B8 & "'!B12"):INDIRECT("'Grupo " & B8 & "'!G15"),2,FALSE)} -> 4415 | G10: {=VLOOKUP(INDIRECT("'Grupo " & B8 & "'!J22"),INDIRECT("'Grupo " & B8 & "'!B12"):INDIRECT("'Grupo " & B8 & "'!J15"),2,FALSE)} -> 2847
B11: =B8+1 -> 4 | C11: {=VLOOKUP(INDIRECT("'Grupo " & B11 & "'!J18"),INDIRECT("'Grupo " & B11 & "'!B12"):INDIRECT("'Grupo " & B11 & "'!J15"),2,FALSE)} -> 3472 | D11: {=VLOOKUP(IF(INDIRECT("'Grupo " & B11 & "'!J18")=INDIRECT("'Grupo " & B11 & "'!C18"),INDIRECT("'Grupo " & B11 & "'!C19"),INDIRECT("'Grupo " & B11 & "'!C18")),INDIRECT("'Grupo " & B11 & "'!B12"):INDIRECT("'Grupo " & B11 & "'!G15"),2,FALSE)} -> 4464 | F11: {=VLOOKUP(IF(INDIRECT("'Grupo " & B11 & "'!J18")=INDIRECT("'Grupo " & B11 & "'!C18"),INDIRECT("'Grupo " & B11 & "'!C19"),INDIRECT("'Grupo " & B11 & "'!C18")),INDIRECT("'Grupo " & B11 & "'!B12"):INDIRECT("'Grupo " & B11 & "'!G15"),2,FALSE)} -> 4464 | G11: {=VLOOKUP(INDIRECT("'Grupo " & B11 & "'!J18"),INDIRECT("'Grupo " & B11 & "'!B12"):INDIRECT("'Grupo " & B11 & "'!J15"),2,FALSE)} -> 3472
C12: {=VLOOKUP(INDIRECT("'Grupo " & B11 & "'!J20"),INDIRECT("'Grupo " & B11 & "'!B12"):INDIRECT("'Grupo " & B11 & "'!J15"),2,FALSE)} -> 3472 | D12: {=VLOOKUP(IF(INDIRECT("'Grupo " & B11 & "'!J20")=INDIRECT("'Grupo " & B11 & "'!C20"),INDIRECT("'Grupo " & B11 & "'!C21"),INDIRECT("'Grupo " & B11 & "'!C20")),INDIRECT("'Grupo " & B11 & "'!B12"):INDIRECT("'Grupo " & B11 & "'!G15"),2,FALSE)} -> 4248 | F12: {=VLOOKUP(IF(INDIRECT("'Grupo " & B11 & "'!J20")=INDIRECT("'Grupo " & B11 & "'!C20"),INDIRECT("'Grupo " & B11 & "'!C21"),INDIRECT("'Grupo " & B11 & "'!C20")),INDIRECT("'Grupo " & B11 & "'!B12"):INDIRECT("'Grupo " & B11 & "'!G15"),2,FALSE)} -> 4248 | G12: {=VLOOKUP(INDIRECT("'Grupo " & B11 & "'!J20"),INDIRECT("'Grupo " & B11 & "'!B12"):INDIRECT("'Grupo " & B11 & "'!J15"),2,FALSE)} -> 3472
C13: {=VLOOKUP(INDIRECT("'Grupo " & B11 & "'!J22"),INDIRECT("'Grupo " & B11 & "'!B12"):INDIRECT("'Grupo " & B11 & "'!J15"),2,FALSE)} -> 4464 | D13: {=VLOOKUP(IF(INDIRECT("'Grupo " & B11 & "'!J22")=INDIRECT("'Grupo " & B11 & "'!C22"),INDIRECT("'Grupo " & B11 & "'!C23"),INDIRECT("'Grupo " & B11 & "'!C22")),INDIRECT("'Grupo " & B11 & "'!B12"):INDIRECT("'Grupo " & B11 & "'!G15"),2,FALSE)} -> 4248 | F13: {=VLOOKUP(IF(INDIRECT("'Grupo " & B11 & "'!J22")=INDIRECT("'Grupo " & B11 & "'!C22"),INDIRECT("'Grupo " & B11 & "'!C23"),INDIRECT("'Grupo " & B11 & "'!C22")),INDIRECT("'Grupo " & B11 & "'!B12"):INDIRECT("'Grupo " & B11 & "'!G15"),2,FALSE)} -> 4248 | G13: {=VLOOKUP(INDIRECT("'Grupo " & B11 & "'!J22"),INDIRECT("'Grupo " & B11 & "'!B12"):INDIRECT("'Grupo " & B11 & "'!J15"),2,FALSE)} -> 4464
B14: =B11+1 -> 5 | C14: {=VLOOKUP(INDIRECT("'Grupo " & B14 & "'!J18"),INDIRECT("'Grupo " & B14 & "'!B12"):INDIRECT("'Grupo " & B14 & "'!J15"),2,FALSE)} -> 2895 | D14: {=VLOOKUP(IF(INDIRECT("'Grupo " & B14 & "'!J18")=INDIRECT("'Grupo " & B14 & "'!C18"),INDIRECT("'Grupo " & B14 & "'!C19"),INDIRECT("'Grupo " & B14 & "'!C18")),INDIRECT("'Grupo " & B14 & "'!B12"):INDIRECT("'Grupo " & B14 & "'!G15"),2,FALSE)} -> 3450 | F14: {=VLOOKUP(IF(INDIRECT("'Grupo " & B14 & "'!J18")=INDIRECT("'Grupo " & B14 & "'!C18"),INDIRECT("'Grupo " & B14 & "'!C19"),INDIRECT("'Grupo " & B14 & "'!C18")),INDIRECT("'Grupo " & B14 & "'!B12"):INDIRECT("'Grupo " & B14 & "'!G15"),2,FALSE)} -> 3450 | G14: {=VLOOKUP(INDIRECT("'Grupo " & B14 & "'!J18"),INDIRECT("'Grupo " & B14 & "'!B12"):INDIRECT("'Grupo " & B14 & "'!J15"),2,FALSE)} -> 2895
C15: {=VLOOKUP(INDIRECT("'Grupo " & B14 & "'!J20"),INDIRECT("'Grupo " & B14 & "'!B12"):INDIRECT("'Grupo " & B14 & "'!J15"),2,FALSE)} -> 2895 | D15: {=VLOOKUP(IF(INDIRECT("'Grupo " & B14 & "'!J20")=INDIRECT("'Grupo " & B14 & "'!C20"),INDIRECT("'Grupo " & B14 & "'!C21"),INDIRECT("'Grupo " & B14 & "'!C20")),INDIRECT("'Grupo " & B14 & "'!B12"):INDIRECT("'Grupo " & B14 & "'!G15"),2,FALSE)} -> 3898 | F15: {=VLOOKUP(IF(INDIRECT("'Grupo " & B14 & "'!J20")=INDIRECT("'Grupo " & B14 & "'!C20"),INDIRECT("'Grupo " & B14 & "'!C21"),INDIRECT("'Grupo " & B14 & "'!C20")),INDIRECT("'Grupo " & B14 & "'!B12"):INDIRECT("'Grupo " & B14 & "'!G15"),2,FALSE)} -> 3898 | G15: {=VLOOKUP(INDIRECT("'Grupo " & B14 & "'!J20"),INDIRECT("'Grupo " & B14 & "'!B12"):INDIRECT("'Grupo " & B14 & "'!J15"),2,FALSE)} -> 2895
C16: {=VLOOKUP(INDIRECT("'Grupo " & B14 & "'!J22"),INDIRECT("'Grupo " & B14 & "'!B12"):INDIRECT("'Grupo " & B14 & "'!J15"),2,FALSE)} -> 3450 | D16: {=VLOOKUP(IF(INDIRECT("'Grupo " & B14 & "'!J22")=INDIRECT("'Grupo " & B14 & "'!C22"),INDIRECT("'Grupo " & B14 & "'!C23"),INDIRECT("'Grupo " & B14 & "'!C22")),INDIRECT("'Grupo " & B14 & "'!B12"):INDIRECT("'Grupo " & B14 & "'!G15"),2,FALSE)} -> 3898 | F16: {=VLOOKUP(IF(INDIRECT("'Grupo " & B14 & "'!J22")=INDIRECT("'Grupo " & B14 & "'!C22"),INDIRECT("'Grupo " & B14 & "'!C23"),INDIRECT("'Grupo " & B14 & "'!C22")),INDIRECT("'Grupo " & B14 & "'!B12"):INDIRECT("'Grupo " & B14 & "'!G15"),2,FALSE)} -> 3898 | G16: {=VLOOKUP(INDIRECT("'Grupo " & B14 & "'!J22"),INDIRECT("'Grupo " & B14 & "'!B12"):INDIRECT("'Grupo " & B14 & "'!J15"),2,FALSE)} -> 3450
B17: =B14+1 -> 6 | C17: {=VLOOKUP(INDIRECT("'Grupo " & B17 & "'!J18"),INDIRECT("'Grupo " & B17 & "'!B12"):INDIRECT("'Grupo " & B17 & "'!J15"),2,FALSE)} -> 2623 | D17: {=VLOOKUP(IF(INDIRECT("'Grupo " & B17 & "'!J18")=INDIRECT("'Grupo " & B17 & "'!C18"),INDIRECT("'Grupo " & B17 & "'!C19"),INDIRECT("'Grupo " & B17 & "'!C18")),INDIRECT("'Grupo " & B17 & "'!B12"):INDIRECT("'Grupo " & B17 & "'!G15"),2,FALSE)} -> 4528 | F17: {=VLOOKUP(IF(INDIRECT("'Grupo " & B17 & "'!J18")=INDIRECT("'Grupo " & B17 & "'!C18"),INDIRECT("'Grupo " & B17 & "'!C19"),INDIRECT("'Grupo " & B17 & "'!C18")),INDIRECT("'Grupo " & B17 & "'!B12"):INDIRECT("'Grupo " & B17 & "'!G15"),2,FALSE)} -> 4528 | G17: {=VLOOKUP(INDIRECT("'Grupo " & B17 & "'!J18"),INDIRECT("'Grupo " & B17 & "'!B12"):INDIRECT("'Grupo " & B17 & "'!J15"),2,FALSE)} -> 2623
C18: {=VLOOKUP(INDIRECT("'Grupo " & B17 & "'!J20"),INDIRECT("'Grupo " & B17 & "'!B12"):INDIRECT("'Grupo " & B17 & "'!J15"),2,FALSE)} -> 2623 | D18: {=VLOOKUP(IF(INDIRECT("'Grupo " & B17 & "'!J20")=INDIRECT("'Grupo " & B17 & "'!C20"),INDIRECT("'Grupo " & B17 & "'!C21"),INDIRECT("'Grupo " & B17 & "'!C20")),INDIRECT("'Grupo " & B17 & "'!B12"):INDIRECT("'Grupo " & B17 & "'!G15"),2,FALSE)} -> 4463 | F18: {=VLOOKUP(IF(INDIRECT("'Grupo " & B17 & "'!J20")=INDIRECT("'Grupo " & B17 & "'!C20"),INDIRECT("'Grupo " & B17 & "'!C21"),INDIRECT("'Grupo " & B17 & "'!C20")),INDIRECT("'Grupo " & B17 & "'!B12"):INDIRECT("'Grupo " & B17 & "'!G15"),2,FALSE)} -> 4463 | G18: {=VLOOKUP(INDIRECT("'Grupo " & B17 & "'!J20"),INDIRECT("'Grupo " & B17 & "'!B12"):INDIRECT("'Grupo " & B17 & "'!J15"),2,FALSE)} -> 2623
C19: {=VLOOKUP(INDIRECT("'Grupo " & B17 & "'!J22"),INDIRECT("'Grupo " & B17 & "'!B12"):INDIRECT("'Grupo " & B17 & "'!J15"),2,FALSE)} -> 4463 | D19: {=VLOOKUP(IF(INDIRECT("'Grupo " & B17 & "'!J22")=INDIRECT("'Grupo " & B17 & "'!C22"),INDIRECT("'Grupo " & B17 & "'!C23"),INDIRECT("'Grupo " & B17 & "'!C22")),INDIRECT("'Grupo " & B17 & "'!B12"):INDIRECT("'Grupo " & B17 & "'!G15"),2,FALSE)} -> 4528 | F19: {=VLOOKUP(IF(INDIRECT("'Grupo " & B17 & "'!J22")=INDIRECT("'Grupo " & B17 & "'!C22"),INDIRECT("'Grupo " & B17 & "'!C23"),INDIRECT("'Grupo " & B17 & "'!C22")),INDIRECT("'Grupo " & B17 & "'!B12"):INDIRECT("'Grupo " & B17 & "'!G15"),2,FALSE)} -> 4528 | G19: {=VLOOKUP(INDIRECT("'Grupo " & B17 & "'!J22"),INDIRECT("'Grupo " & B17 & "'!B12"):INDIRECT("'Grupo " & B17 & "'!J15"),2,FALSE)} -> 4463
B20: =B17+1 -> 7 | C20: {=VLOOKUP(INDIRECT("'Grupo " & B20 & "'!J18"),INDIRECT("'Grupo " & B20 & "'!B12"):INDIRECT("'Grupo " & B20 & "'!J15"),2,FALSE)} -> 3153 | D20: {=VLOOKUP(IF(INDIRECT("'Grupo " & B20 & "'!J18")=INDIRECT("'Grupo " & B20 & "'!C18"),INDIRECT("'Grupo " & B20 & "'!C19"),INDIRECT("'Grupo " & B20 & "'!C18")),INDIRECT("'Grupo " & B20 & "'!B12"):INDIRECT("'Grupo " & B20 & "'!G15"),2,FALSE)} -> 4284 | F20: {=VLOOKUP(IF(INDIRECT("'Grupo " & B20 & "'!J18")=INDIRECT("'Grupo " & B20 & "'!C18"),INDIRECT("'Grupo " & B20 & "'!C19"),INDIRECT("'Grupo " & B20 & "'!C18")),INDIRECT("'Grupo " & B20 & "'!B12"):INDIRECT("'Grupo " & B20 & "'!G15"),2,FALSE)} -> 4284 | G20: {=VLOOKUP(INDIRECT("'Grupo " & B20 & "'!J18"),INDIRECT("'Grupo " & B20 & "'!B12"):INDIRECT("'Grupo " & B20 & "'!J15"),2,FALSE)} -> 3153
C21: {=VLOOKUP(INDIRECT("'Grupo " & B20 & "'!J20"),INDIRECT("'Grupo " & B20 & "'!B12"):INDIRECT("'Grupo " & B20 & "'!J15"),2,FALSE)} -> 3153 | D21: {=VLOOKUP(IF(INDIRECT("'Grupo " & B20 & "'!J20")=INDIRECT("'Grupo " & B20 & "'!C20"),INDIRECT("'Grupo " & B20 & "'!C21"),INDIRECT("'Grupo " & B20 & "'!C20")),INDIRECT("'Grupo " & B20 & "'!B12"):INDIRECT("'Grupo " & B20 & "'!G15"),2,FALSE)} -> 4677 | F21: {=VLOOKUP(IF(INDIRECT("'Grupo " & B20 & "'!J20")=INDIRECT("'Grupo " & B20 & "'!C20"),INDIRECT("'Grupo " & B20 & "'!C21"),INDIRECT("'Grupo " & B20 & "'!C20")),INDIRECT("'Grupo " & B20 & "'!B12"):INDIRECT("'Grupo " & B20 & "'!G15"),2,FALSE)} -> 4677 | G21: {=VLOOKUP(INDIRECT("'Grupo " & B20 & "'!J20"),INDIRECT("'Grupo " & B20 & "'!B12"):INDIRECT("'Grupo " & B20 & "'!J15"),2,FALSE)} -> 3153
C22: {=VLOOKUP(INDIRECT("'Grupo " & B20 & "'!J22"),INDIRECT("'Grupo " & B20 & "'!B12"):INDIRECT("'Grupo " & B20 & "'!J15"),2,FALSE)} -> 4284 | D22: {=VLOOKUP(IF(INDIRECT("'Grupo " & B20 & "'!J22")=INDIRECT("'Grupo " & B20 & "'!C22"),INDIRECT("'Grupo " & B20 & "'!C23"),INDIRECT("'Grupo " & B20 & "'!C22")),INDIRECT("'Grupo " & B20 & "'!B12"):INDIRECT("'Grupo " & B20 & "'!G15"),2,FALSE)} -> 4677 | F22: {=VLOOKUP(IF(INDIRECT("'Grupo " & B20 & "'!J22")=INDIRECT("'Grupo " & B20 & "'!C22"),INDIRECT("'Grupo " & B20 & "'!C23"),INDIRECT("'Grupo " & B20 & "'!C22")),INDIRECT("'Grupo " & B20 & "'!B12"):INDIRECT("'Grupo " & B20 & "'!G15"),2,FALSE)} -> 4677 | G22: {=VLOOKUP(INDIRECT("'Grupo " & B20 & "'!J22"),INDIRECT("'Grupo " & B20 & "'!B12"):INDIRECT("'Grupo " & B20 & "'!J15"),2,FALSE)} -> 4284
B23: =B20+1 -> 8 | C23: {=VLOOKUP(INDIRECT("'Grupo " & B23 & "'!J18"),INDIRECT("'Grupo " & B23 & "'!B12"):INDIRECT("'Grupo " & B23 & "'!J15"),2,FALSE)} -> 3839 | D23: {=VLOOKUP(IF(INDIRECT("'Grupo " & B23 & "'!J18")=INDIRECT("'Grupo " & B23 & "'!C18"),INDIRECT("'Grupo " & B23 & "'!C19"),INDIRECT("'Grupo " & B23 & "'!C18")),INDIRECT("'Grupo " & B23 & "'!B12"):INDIRECT("'Grupo " & B23 & "'!G15"),2,FALSE)} -> 4641 | F23: {=VLOOKUP(IF(INDIRECT("'Grupo " & B23 & "'!J18")=INDIRECT("'Grupo " & B23 & "'!C18"),INDIRECT("'Grupo " & B23 & "'!C19"),INDIRECT("'Grupo " & B23 & "'!C18")),INDIRECT("'Grupo " & B23 & "'!B12"):INDIRECT("'Grupo " & B23 & "'!G15"),2,FALSE)} -> 4641 | G23: {=VLOOKUP(INDIRECT("'Grupo " & B23 & "'!J18"),INDIRECT("'Grupo " & B23 & "'!B12"):INDIRECT("'Grupo " & B23 & "'!J15"),2,FALSE)} -> 3839
C24: {=VLOOKUP(INDIRECT("'Grupo " & B23 & "'!J20"),INDIRECT("'Grupo " & B23 & "'!B12"):INDIRECT("'Grupo " & B23 & "'!J15"),2,FALSE)} -> 4002 | D24: {=VLOOKUP(IF(INDIRECT("'Grupo " & B23 & "'!J20")=INDIRECT("'Grupo " & B23 & "'!C20"),INDIRECT("'Grupo " & B23 & "'!C21"),INDIRECT("'Grupo " & B23 & "'!C20")),INDIRECT("'Grupo " & B23 & "'!B12"):INDIRECT("'Grupo " & B23 & "'!G15"),2,FALSE)} -> 3839 | F24: {=VLOOKUP(IF(INDIRECT("'Grupo " & B23 & "'!J20")=INDIRECT("'Grupo " & B23 & "'!C20"),INDIRECT("'Grupo " & B23 & "'!C21"),INDIRECT("'Grupo " & B23 & "'!C20")),INDIRECT("'Grupo " & B23 & "'!B12"):INDIRECT("'Grupo " & B23 & "'!G15"),2,FALSE)} -> 3839 | G24: {=VLOOKUP(INDIRECT("'Grupo " & B23 & "'!J20"),INDIRECT("'Grupo " & B23 & "'!B12"):INDIRECT("'Grupo " & B23 & "'!J15"),2,FALSE)} -> 4002
C25: {=VLOOKUP(INDIRECT("'Grupo " & B23 & "'!J22"),INDIRECT("'Grupo " & B23 & "'!B12"):INDIRECT("'Grupo " & B23 & "'!J15"),2,FALSE)} -> 4002 | D25: {=VLOOKUP(IF(INDIRECT("'Grupo " & B23 & "'!J22")=INDIRECT("'Grupo " & B23 & "'!C22"),INDIRECT("'Grupo " & B23 & "'!C23"),INDIRECT("'Grupo " & B23 & "'!C22")),INDIRECT("'Grupo " & B23 & "'!B12"):INDIRECT("'Grupo " & B23 & "'!G15"),2,FALSE)} -> 4641 | F25: {=VLOOKUP(IF(INDIRECT("'Grupo " & B23 & "'!J22")=INDIRECT("'Grupo " & B23 & "'!C22"),INDIRECT("'Grupo " & B23 & "'!C23"),INDIRECT("'Grupo " & B23 & "'!C22")),INDIRECT("'Grupo " & B23 & "'!B12"):INDIRECT("'Grupo " & B23 & "'!G15"),2,FALSE)} -> 4641 | G25: {=VLOOKUP(INDIRECT("'Grupo " & B23 & "'!J22"),INDIRECT("'Grupo " & B23 & "'!B12"):INDIRECT("'Grupo " & B23 & "'!J15"),2,FALSE)} -> 4002
B26: =B23+1 -> 9 | C26: {=VLOOKUP(INDIRECT("'Grupo " & B26 & "'!J18"),INDIRECT("'Grupo " & B26 & "'!B12"):INDIRECT("'Grupo " & B26 & "'!J15"),2,FALSE)} -> 3836 | D26: {=VLOOKUP(IF(INDIRECT("'Grupo " & B26 & "'!J18")=INDIRECT("'Grupo " & B26 & "'!C18"),INDIRECT("'Grupo " & B26 & "'!C19"),INDIRECT("'Grupo " & B26 & "'!C18")),INDIRECT("'Grupo " & B26 & "'!B12"):INDIRECT("'Grupo " & B26 & "'!G15"),2,FALSE)} -> 4115 | F26: {=VLOOKUP(IF(INDIRECT("'Grupo " & B26 & "'!J18")=INDIRECT("'Grupo " & B26 & "'!C18"),INDIRECT("'Grupo " & B26 & "'!C19"),INDIRECT("'Grupo " & B26 & "'!C18")),INDIRECT("'Grupo " & B26 & "'!B12"):INDIRECT("'Grupo " & B26 & "'!G15"),2,FALSE)} -> 4115 | G26: {=VLOOKUP(INDIRECT("'Grupo " & B26 & "'!J18"),INDIRECT("'Grupo " & B26 & "'!B12"):INDIRECT("'Grupo " & B26 & "'!J15"),2,FALSE)} -> 3836
C27: {=VLOOKUP(INDIRECT("'Grupo " & B26 & "'!J20"),INDIRECT("'Grupo " & B26 & "'!B12"):INDIRECT("'Grupo " & B26 & "'!J15"),2,FALSE)} -> 3836 | D27: {=VLOOKUP(IF(INDIRECT("'Grupo " & B26 & "'!J20")=INDIRECT("'Grupo " & B26 & "'!C20"),INDIRECT("'Grupo " & B26 & "'!C21"),INDIRECT("'Grupo " & B26 & "'!C20")),INDIRECT("'Grupo " & B26 & "'!B12"):INDIRECT("'Grupo " & B26 & "'!G15"),2,FALSE)} -> 3234 | F27: {=VLOOKUP(IF(INDIRECT("'Grupo " & B26 & "'!J20")=INDIRECT("'Grupo " & B26 & "'!C20"),INDIRECT("'Grupo " & B26 & "'!C21"),INDIRECT("'Grupo " & B26 & "'!C20")),INDIRECT("'Grupo " & B26 & "'!B12"):INDIRECT("'Grupo " & B26 & "'!G15"),2,FALSE)} -> 3234 | G27: {=VLOOKUP(INDIRECT("'Grupo " & B26 & "'!J20"),INDIRECT("'Grupo " & B26 & "'!B12"):INDIRECT("'Grupo " & B26 & "'!J15"),2,FALSE)} -> 3836
C28: {=VLOOKUP(INDIRECT("'Grupo " & B26 & "'!J22"),INDIRECT("'Grupo " & B26 & "'!B12"):INDIRECT("'Grupo " & B26 & "'!J15"),2,FALSE)} -> 4115 | D28: {=VLOOKUP(IF(INDIRECT("'Grupo " & B26 & "'!J22")=INDIRECT("'Grupo " & B26 & "'!C22"),INDIRECT("'Grupo " & B26 & "'!C23"),INDIRECT("'Grupo " & B26 & "'!C22")),INDIRECT("'Grupo " & B26 & "'!B12"):INDIRECT("'Grupo " & B26 & "'!G15"),2,FALSE)} -> 3234 | F28: {=VLOOKUP(IF(INDIRECT("'Grupo " & B26 & "'!J22")=INDIRECT("'Grupo " & B26 & "'!C22"),INDIRECT("'Grupo " & B26 & "'!C23"),INDIRECT("'Grupo " & B26 & "'!C22")),INDIRECT("'Grupo " & B26 & "'!B12"):INDIRECT("'Grupo " & B26 & "'!G15"),2,FALSE)} -> 3234 | G28: {=VLOOKUP(INDIRECT("'Grupo " & B26 & "'!J22"),INDIRECT("'Grupo " & B26 & "'!B12"):INDIRECT("'Grupo " & B26 & "'!J15"),2,FALSE)} -> 4115
B29: =B26+1 -> 10 | C29: {=VLOOKUP(INDIRECT("'Grupo " & B29 & "'!J18"),INDIRECT("'Grupo " & B29 & "'!B12"):INDIRECT("'Grupo " & B29 & "'!J15"),2,FALSE)} -> 3671 | D29: {=VLOOKUP(IF(INDIRECT("'Grupo " & B29 & "'!J18")=INDIRECT("'Grupo " & B29 & "'!C18"),INDIRECT("'Grupo " & B29 & "'!C19"),INDIRECT("'Grupo " & B29 & "'!C18")),INDIRECT("'Grupo " & B29 & "'!B12"):INDIRECT("'Grupo " & B29 & "'!G15"),2,FALSE)} -> 4236 | F29: {=VLOOKUP(IF(INDIRECT("'Grupo " & B29 & "'!J18")=INDIRECT("'Grupo " & B29 & "'!C18"),INDIRECT("'Grupo " & B29 & "'!C19"),INDIRECT("'Grupo " & B29 & "'!C18")),INDIRECT("'Grupo " & B29 & "'!B12"):INDIRECT("'Grupo " & B29 & "'!G15"),2,FALSE)} -> 4236 | G29: {=VLOOKUP(INDIRECT("'Grupo " & B29 & "'!J18"),INDIRECT("'Grupo " & B29 & "'!B12"):INDIRECT("'Grupo " & B29 & "'!J15"),2,FALSE)} -> 3671
C30: {=VLOOKUP(INDIRECT("'Grupo " & B29 & "'!J20"),INDIRECT("'Grupo " & B29 & "'!B12"):INDIRECT("'Grupo " & B29 & "'!J15"),2,FALSE)} -> 3449 | D30: {=VLOOKUP(IF(INDIRECT("'Grupo " & B29 & "'!J20")=INDIRECT("'Grupo " & B29 & "'!C20"),INDIRECT("'Grupo " & B29 & "'!C21"),INDIRECT("'Grupo " & B29 & "'!C20")),INDIRECT("'Grupo " & B29 & "'!B12"):INDIRECT("'Grupo " & B29 & "'!G15"),2,FALSE)} -> 3671 | F30: {=VLOOKUP(IF(INDIRECT("'Grupo " & B29 & "'!J20")=INDIRECT("'Grupo " & B29 & "'!C20"),INDIRECT("'Grupo " & B29 & "'!C21"),INDIRECT("'Grupo " & B29 & "'!C20")),INDIRECT("'Grupo " & B29 & "'!B12"):INDIRECT("'Grupo " & B29 & "'!G15"),2,FALSE)} -> 3671 | G30: {=VLOOKUP(INDIRECT("'Grupo " & B29 & "'!J20"),INDIRECT("'Grupo " & B29 & "'!B12"):INDIRECT("'Grupo " & B29 & "'!J15"),2,FALSE)} -> 3449
C31: {=VLOOKUP(INDIRECT("'Grupo " & B29 & "'!J22"),INDIRECT("'Grupo " & B29 & "'!B12"):INDIRECT("'Grupo " & B29 & "'!J15"),2,FALSE)} -> 4236 | D31: {=VLOOKUP(IF(INDIRECT("'Grupo " & B29 & "'!J22")=INDIRECT("'Grupo " & B29 & "'!C22"),INDIRECT("'Grupo " & B29 & "'!C23"),INDIRECT("'Grupo " & B29 & "'!C22")),INDIRECT("'Grupo " & B29 & "'!B12"):INDIRECT("'Grupo " & B29 & "'!G15"),2,FALSE)} -> 3449 | F31: {=VLOOKUP(IF(INDIRECT("'Grupo " & B29 & "'!J22")=INDIRECT("'Grupo " & B29 & "'!C22"),INDIRECT("'Grupo " & B29 & "'!C23"),INDIRECT("'Grupo " & B29 & "'!C22")),INDIRECT("'Grupo " & B29 & "'!B12"):INDIRECT("'Grupo " & B29 & "'!G15"),2,FALSE)} -> 3449 | G31: {=VLOOKUP(INDIRECT("'Grupo " & B29 & "'!J22"),INDIRECT("'Grupo " & B29 & "'!B12"):INDIRECT("'Grupo " & B29 & "'!J15"),2,FALSE)} -> 4236
B32: =B29+1 -> 11 | C32: {=VLOOKUP(INDIRECT("'Grupo " & B32 & "'!J18"),INDIRECT("'Grupo " & B32 & "'!B12"):INDIRECT("'Grupo " & B32 & "'!J15"),2,FALSE)} -> 3499 | D32: {=VLOOKUP(IF(INDIRECT("'Grupo " & B32 & "'!J18")=INDIRECT("'Grupo " & B32 & "'!C18"),INDIRECT("'Grupo " & B32 & "'!C19"),INDIRECT("'Grupo " & B32 & "'!C18")),INDIRECT("'Grupo " & B32 & "'!B12"):INDIRECT("'Grupo " & B32 & "'!G15"),2,FALSE)} -> 4833 | F32: {=VLOOKUP(IF(INDIRECT("'Grupo " & B32 & "'!J18")=INDIRECT("'Grupo " & B32 & "'!C18"),INDIRECT("'Grupo " & B32 & "'!C19"),INDIRECT("'Grupo " & B32 & "'!C18")),INDIRECT("'Grupo " & B32 & "'!B12"):INDIRECT("'Grupo " & B32 & "'!G15"),2,FALSE)} -> 4833 | G32: {=VLOOKUP(INDIRECT("'Grupo " & B32 & "'!J18"),INDIRECT("'Grupo " & B32 & "'!B12"):INDIRECT("'Grupo " & B32 & "'!J15"),2,FALSE)} -> 3499
C33: {=VLOOKUP(INDIRECT("'Grupo " & B32 & "'!J20"),INDIRECT("'Grupo " & B32 & "'!B12"):INDIRECT("'Grupo " & B32 & "'!J15"),2,FALSE)} -> 3499 | D33: {=VLOOKUP(IF(INDIRECT("'Grupo " & B32 & "'!J20")=INDIRECT("'Grupo " & B32 & "'!C20"),INDIRECT("'Grupo " & B32 & "'!C21"),INDIRECT("'Grupo " & B32 & "'!C20")),INDIRECT("'Grupo " & B32 & "'!B12"):INDIRECT("'Grupo " & B32 & "'!G15"),2,FALSE)} -> 2801 | F33: {=VLOOKUP(IF(INDIRECT("'Grupo " & B32 & "'!J20")=INDIRECT("'Grupo " & B32 & "'!C20"),INDIRECT("'Grupo " & B32 & "'!C21"),INDIRECT("'Grupo " & B32 & "'!C20")),INDIRECT("'Grupo " & B32 & "'!B12"):INDIRECT("'Grupo " & B32 & "'!G15"),2,FALSE)} -> 2801 | G33: {=VLOOKUP(INDIRECT("'Grupo " & B32 & "'!J20"),INDIRECT("'Grupo " & B32 & "'!B12"):INDIRECT("'Grupo " & B32 & "'!J15"),2,FALSE)} -> 3499
C34: {=VLOOKUP(INDIRECT("'Grupo " & B32 & "'!J22"),INDIRECT("'Grupo " & B32 & "'!B12"):INDIRECT("'Grupo " & B32 & "'!J15"),2,FALSE)} -> 2801 | D34: {=VLOOKUP(IF(INDIRECT("'Grupo " & B32 & "'!J22")=INDIRECT("'Grupo " & B32 & "'!C22"),INDIRECT("'Grupo " & B32 & "'!C23"),INDIRECT("'Grupo " & B32 & "'!C22")),INDIRECT("'Grupo " & B32 & "'!B12"):INDIRECT("'Grupo " & B32 & "'!G15"),2,FALSE)} -> 4833 | F34: {=VLOOKUP(IF(INDIRECT("'Grupo " & B32 & "'!J22")=INDIRECT("'Grupo " & B32 & "'!C22"),INDIRECT("'Grupo " & B32 & "'!C23"),INDIRECT("'Grupo " & B32 & "'!C22")),INDIRECT("'Grupo " & B32 & "'!B12"):INDIRECT("'Grupo " & B32 & "'!G15"),2,FALSE)} -> 4833 | G34: {=VLOOKUP(INDIRECT("'Grupo " & B32 & "'!J22"),INDIRECT("'Grupo " & B32 & "'!B12"):INDIRECT("'Grupo " & B32 & "'!J15"),2,FALSE)} -> 2801
B35: =B32+1 -> 12 | C35: {=VLOOKUP(INDIRECT("'Grupo " & B35 & "'!J18"),INDIRECT("'Grupo " & B35 & "'!B12"):INDIRECT("'Grupo " & B35 & "'!J15"),2,FALSE)} -> 3696 | D35: {=VLOOKUP(IF(INDIRECT("'Grupo " & B35 & "'!J18")=INDIRECT("'Grupo " & B35 & "'!C18"),INDIRECT("'Grupo " & B35 & "'!C19"),INDIRECT("'Grupo " & B35 & "'!C18")),INDIRECT("'Grupo " & B35 & "'!B12"):INDIRECT("'Grupo " & B35 & "'!G15"),2,FALSE)} -> 4790 | F35: {=VLOOKUP(IF(INDIRECT("'Grupo " & B35 & "'!J18")=INDIRECT("'Grupo " & B35 & "'!C18"),INDIRECT("'Grupo " & B35 & "'!C19"),INDIRECT("'Grupo " & B35 & "'!C18")),INDIRECT("'Grupo " & B35 & "'!B12"):INDIRECT("'Grupo " & B35 & "'!G15"),2,FALSE)} -> 4790 | G35: {=VLOOKUP(INDIRECT("'Grupo " & B35 & "'!J18"),INDIRECT("'Grupo " & B35 & "'!B12"):INDIRECT("'Grupo " & B35 & "'!J15"),2,FALSE)} -> 3696
C36: {=VLOOKUP(INDIRECT("'Grupo " & B35 & "'!J20"),INDIRECT("'Grupo " & B35 & "'!B12"):INDIRECT("'Grupo " & B35 & "'!J15"),2,FALSE)} -> 3468 | D36: {=VLOOKUP(IF(INDIRECT("'Grupo " & B35 & "'!J20")=INDIRECT("'Grupo " & B35 & "'!C20"),INDIRECT("'Grupo " & B35 & "'!C21"),INDIRECT("'Grupo " & B35 & "'!C20")),INDIRECT("'Grupo " & B35 & "'!B12"):INDIRECT("'Grupo " & B35 & "'!G15"),2,FALSE)} -> 3696 | F36: {=VLOOKUP(IF(INDIRECT("'Grupo " & B35 & "'!J20")=INDIRECT("'Grupo " & B35 & "'!C20"),INDIRECT("'Grupo " & B35 & "'!C21"),INDIRECT("'Grupo " & B35 & "'!C20")),INDIRECT("'Grupo " & B35 & "'!B12"):INDIRECT("'Grupo " & B35 & "'!G15"),2,FALSE)} -> 3696 | G36: {=VLOOKUP(INDIRECT("'Grupo " & B35 & "'!J20"),INDIRECT("'Grupo " & B35 & "'!B12"):INDIRECT("'Grupo " & B35 & "'!J15"),2,FALSE)} -> 3468
C37: {=VLOOKUP(INDIRECT("'Grupo " & B35 & "'!J22"),INDIRECT("'Grupo " & B35 & "'!B12"):INDIRECT("'Grupo " & B35 & "'!J15"),2,FALSE)} -> 3468 | D37: {=VLOOKUP(IF(INDIRECT("'Grupo " & B35 & "'!J22")=INDIRECT("'Grupo " & B35 & "'!C22"),INDIRECT("'Grupo " & B35 & "'!C23"),INDIRECT("'Grupo " & B35 & "'!C22")),INDIRECT("'Grupo " & B35 & "'!B12"):INDIRECT("'Grupo " & B35 & "'!G15"),2,FALSE)} -> 4790 | F37: {=VLOOKUP(IF(INDIRECT("'Grupo " & B35 & "'!J22")=INDIRECT("'Grupo " & B35 & "'!C22"),INDIRECT("'Grupo " & B35 & "'!C23"),INDIRECT("'Grupo " & B35 & "'!C22")),INDIRECT("'Grupo " & B35 & "'!B12"):INDIRECT("'Grupo " & B35 & "'!G15"),2,FALSE)} -> 4790 | G37: {=VLOOKUP(INDIRECT("'Grupo " & B35 & "'!J22"),INDIRECT("'Grupo " & B35 & "'!B12"):INDIRECT("'Grupo " & B35 & "'!J15"),2,FALSE)} -> 3468
B38: =B35+1 -> 13 | C38: {=VLOOKUP(INDIRECT("'Grupo " & B38 & "'!J18"),INDIRECT("'Grupo " & B38 & "'!B12"):INDIRECT("'Grupo " & B38 & "'!J15"),2,FALSE)} -> 3309 | D38: {=VLOOKUP(IF(INDIRECT("'Grupo " & B38 & "'!J18")=INDIRECT("'Grupo " & B38 & "'!C18"),INDIRECT("'Grupo " & B38 & "'!C19"),INDIRECT("'Grupo " & B38 & "'!C18")),INDIRECT("'Grupo " & B38 & "'!B12"):INDIRECT("'Grupo " & B38 & "'!G15"),2,FALSE)} -> 4327 | F38: {=VLOOKUP(IF(INDIRECT("'Grupo " & B38 & "'!J18")=INDIRECT("'Grupo " & B38 & "'!C18"),INDIRECT("'Grupo " & B38 & "'!C19"),INDIRECT("'Grupo " & B38 & "'!C18")),INDIRECT("'Grupo " & B38 & "'!B12"):INDIRECT("'Grupo " & B38 & "'!G15"),2,FALSE)} -> 4327 | G38: {=VLOOKUP(INDIRECT("'Grupo " & B38 & "'!J18"),INDIRECT("'Grupo " & B38 & "'!B12"):INDIRECT("'Grupo " & B38 & "'!J15"),2,FALSE)} -> 3309
C39: {=VLOOKUP(INDIRECT("'Grupo " & B38 & "'!J20"),INDIRECT("'Grupo " & B38 & "'!B12"):INDIRECT("'Grupo " & B38 & "'!J15"),2,FALSE)} -> 3458 | D39: {=VLOOKUP(IF(INDIRECT("'Grupo " & B38 & "'!J20")=INDIRECT("'Grupo " & B38 & "'!C20"),INDIRECT("'Grupo " & B38 & "'!C21"),INDIRECT("'Grupo " & B38 & "'!C20")),INDIRECT("'Grupo " & B38 & "'!B12"):INDIRECT("'Grupo " & B38 & "'!G15"),2,FALSE)} -> 3309 | F39: {=VLOOKUP(IF(INDIRECT("'Grupo " & B38 & "'!J20")=INDIRECT("'Grupo " & B38 & "'!C20"),INDIRECT("'Grupo " & B38 & "'!C21"),INDIRECT("'Grupo " & B38 & "'!C20")),INDIRECT("'Grupo " & B38 & "'!B12"):INDIRECT("'Grupo " & B38 & "'!G15"),2,FALSE)} -> 3309 | G39: {=VLOOKUP(INDIRECT("'Grupo " & B38 & "'!J20"),INDIRECT("'Grupo " & B38 & "'!B12"):INDIRECT("'Grupo " & B38 & "'!J15"),2,FALSE)} -> 3458
C40: {=VLOOKUP(INDIRECT("'Grupo " & B38 & "'!J22"),INDIRECT("'Grupo " & B38 & "'!B12"):INDIRECT("'Grupo " & B38 & "'!J15"),2,FALSE)} -> 3458 | D40: {=VLOOKUP(IF(INDIRECT("'Grupo " & B38 & "'!J22")=INDIRECT("'Grupo " & B38 & "'!C22"),INDIRECT("'Grupo " & B38 & "'!C23"),INDIRECT("'Grupo " & B38 & "'!C22")),INDIRECT("'Grupo " & B38 & "'!B12"):INDIRECT("'Grupo " & B38 & "'!G15"),2,FALSE)} -> 4327 | F40: {=VLOOKUP(IF(INDIRECT("'Grupo " & B38 & "'!J22")=INDIRECT("'Grupo " & B38 & "'!C22"),INDIRECT("'Grupo " & B38 & "'!C23"),INDIRECT("'Grupo " & B38 & "'!C22")),INDIRECT("'Grupo " & B38 & "'!B12"):INDIRECT("'Grupo " & B38 & "'!G15"),2,FALSE)} -> 4327 | G40: {=VLOOKUP(INDIRECT("'Grupo " & B38 & "'!J22"),INDIRECT("'Grupo " & B38 & "'!B12"):INDIRECT("'Grupo " & B38 & "'!J15"),2,FALSE)} -> 3458
...

Sheet Ranking Final
A1: Ranking | B1: CARNE | C1: NOMBRE | D1: CLUB | E1: PUNTOS
A2: 1 | B2: 2515 | C2: GABRIEL CHAVEZ QUIROS | D2: SANTA ANA | E2: 729
A3: 2 | B3: 2582 | C3: ALEJANDRO MONTOYA MORERA | D3: ALAJUELA - UNA | E3: 682
A4: 3 | B4: 2623 | C4: MATEO MONGE ARROYO | D4: SANTA ANA | E4: 679
A5: 4 | B5: 2895 | C5: ANDRES JOSE VEGA VALERIO | D5: ALAJUELA - UCR | E5: 664
A6: 5 | B6: 3472 | C6: JAYDRICK SHAMALL BAKER CRAWFORD | D6: ASERRÍ - UCR | E6: 655
A7: 6 | B7: 4034 | C7: IAN DAVID GARRO ALONSO | D7: CCDR SAN JOSÉ | E7: 652
A8: 7 | B8: 3153 | C8: ARIEL IGNACIO BARTELS BARQUERO | D8: PÉREZ ZELEDÓN - UNA | E8: 608
A9: 8 | B9: 3671 | C9: NICOLAS OVARES CASTRO | D9: SANTA ANA | E9: 601
A10: 9 | B10: 3499 | C10: ESTEBAN MURILLO CHAVES | D10: UCR-PÉREZ ZELEDÓN | E10: 591
A11: 10 | B11: 3836 | C11: LUCIANO QUIROS AVILA | D11: ESCAZÚ | E11: 587
A12: 11 | B12: 3839 | C12: ALBERTO BLANCO LEDEZMA | D12: PÉREZ ZELEDÓN | E12: 584
A13: 12 | B13: 3747 | C13: LUIS ALONSO VILLALOBOS CAMPOS | D13: ESPARZA | E13: 567
... A748: 76 | B748: 4683 | C748: DANIEL BARBOZA FLORES | D748: PEREZ ZELEDÓN | E748: 420

Sheet Inscripciones
B1: Ranking Menor
B2: U19 MASCULINO
B4: CARNÉ | C4: NOMBRE | D4: CLUB | E4: RANKING | F4: PUNTOS | G4: Grupo
A5: =G5+0.1 -> 1.1 | B5: 2515 | C5: GABRIEL CHAVEZ QUIROS | D5: SANTA ANA | E5: 1 | F5: 716 | G5: 1
A6: =G6+0.2 -> 1.2 | B6: 4513 | C6: GABRIEL ANTONIO AMADOR GARITA | D6: CCDR SANTA CRUZ | E6: 37 | F6: 492 | G6: 1
A7: =G7+0.3 -> 1.3 | B7: 3670 | C7: KAY MATHIAS PERAZA MURILLO | D7: ASERRÍ | E7: 38 | F7: 492 | G7: 1
A8: =G8+0.1 -> 2.1 | B8: 2582 | C8: ALEJANDRO MONTOYA MORERA | D8: ALAJUELA - UNA | E8: 2 | F8: 698 | G8: 2
A9: =G9+0.2 -> 2.2 | B9: 2513 | C9: SEBASTIAN CHAVEZ QUIROS | D9: SANTA ANA | E9: 35 | F9: 493 | G9: 2
A10: =G10+0.3 -> 2.3 | B10: 4144 | C10: ANDRÉS PARRA CHACÓN | D10: SANTO DOMINGO | E10: 40 | F10: 485 | G10: 2
A11: =G11+0.1 -> 3.1 | B11: 4034 | C11: IAN DAVID GARRO ALONSO | D11: CCDR SAN JOSÉ | E11: 3 | F11: 645 | G11: 3
A12: =G12+0.2 -> 3.2 | B12: 2847 | C12: LUIS GAEL SILES LOBO | D12: ESPARZA | E12: 34 | F12: 493 | G12: 3
A13: =G13+0.3 -> 3.3 | B13: 4415 | C13: ALEJANDRO CRUZ BONILLA | D13: ALAJUELA | E13: 45 | F13: 482 | G13: 3
A14: =G14+0.1 -> 4.1 | B14: 3472 | C14: JAYDRICK SHAMALL BAKER CRAWFORD | D14: ASERRÍ - UCR | E14: 4 | F14: 626 | G14: 4
A15: =G15+0.2 -> 4.2 | B15: 4248 | C15: ALEJANDRO COTO RAMIREZ | D15: GUARCO | E15: 33 | F15: 493 | G15: 4
A16: =G16+0.3 -> 4.3 | B16: 4464 | C16: ISAAC GAMBOA MORERA | D16: ESPARZA | E16: 42 | F16: 483 | G16: 4
A17: =G17+0.1 -> 5.1 | B17: 2895 | C17: ANDRES JOSE VEGA VALERIO | D17: ALAJUELA - UCR | E17: 5 | F17: 613 | G17: 5
A18: =G18+0.2 -> 5.2 | B18: 3898 | C18: JOSUE CALVO CRUZ | D18: CCDR SAN JOSÉ | E18: 32 | F18: 493 | G18: 5
A19: =G19+0.3 -> 5.3 | B19: 3450 | C19: OSWALDO IGNACIO SILVA NOVOA | D19: SANTA ANA | E19: 49 | F19: 473 | G19: 5
A20: =G20+0.1 -> 6.1 | B20: 2623 | C20: MATEO MONGE ARROYO | D20: SANTA ANA | E20: 6 | F20: 611 | G20: 6
A21: =G21+0.2 -> 6.2 | B21: 4463 | C21: ISAAC ANDRÉS LEAL CHACÓN | D21: ESPARZA | E21: 30 | F21: 499 | G21: 6
A22: =G22+0.3 -> 6.3 | B22: 4528 | C22: BRAD GÓMEZ CASTILLO | D22: ESCAZÚ | E22: 48 | F22: 474 | G22: 6
A23: =G23+0.1 -> 7.1 | B23: 3153 | C23: ARIEL IGNACIO BARTELS BARQUERO | D23: PÉREZ ZELEDÓN - UNA | E23: 7 | F23: 597 | G23: 7
A24: =G24+0.2 -> 7.2 | B24: 4677 | C24: SANTIAGO GUARDADO ROJAS | D24: SAN CARLOS | E24: 28 | F24: 501 | G24: 7
A25: =G25+0.3 -> 7.3 | B25: 4284 | C25: IAN SOLÍS CARRANZA | D25: SANTO DOMINGO | E25: 50 | F25: 472 | G25: 7
A26: =G26+0.1 -> 8.1 | B26: 3839 | C26: ALBERTO BLANCO LEDEZMA | D26: PÉREZ ZELEDÓN | E26: 8 | F26: 588 | G26: 8
A27: =G27+0.2 -> 8.2 | B27: 4002 | C27: ISMAEL CÁRDENAS ACOSTA | D27: CCDR SAN JOSÉ | E27: 27 | F27: 502 | G27: 8
A28: =G28+0.3 -> 8.3 | B28: 4641 | C28: JOSEPH BRENES QUESADA | D28: GUARCO | E28: 51 | F28: 472 | G28: 8
A29: =G29+0.1 -> 9.1 | B29: 3836 | C29: LUCIANO QUIROS AVILA | D29: ESCAZÚ | E29: 9 | F29: 578 | G29: 9
A30: =G30+0.2 -> 9.2 | B30: 3234 | C30: LUKAS CECILIANO ESQUIVEL | D30: PÉREZ ZELEDÓN | E30: 28 | F30: 501 | G30: 9
A31: =G31+0.3 -> 9.3 | B31: 4115 | C31: JOSEPH ANGEL LOPEZ ARAUZ | D31: ATM SANTA CRUZ | E31: 53 | F31: 471 | G31: 9
A32: =G32+0.1 -> 10.1 | B32: 3671 | C32: NICOLAS OVARES CASTRO | D32: SANTA ANA | E32: 10 | F32: 575 | G32: 10
A33: =G33+0.2 -> 10.2 | B33: 3449 | C33: REINEL ANTONIO VANEGAS LACAYO | D33: ALAJUELA | E33: 26 | F33: 505 | G33: 10
A34: =G34+0.3 -> 10.3 | B34: 4236 | C34: SANTIAGO BRENES HERRERA | D34: CURRIDABAT | E34: 58 | F34: 462 | G34: 10
A35: =G35+0.1 -> 11.1 | B35: 3499 | C35: ESTEBAN MURILLO CHAVES | D35: UCR-PÉREZ ZELEDÓN | E35: 11 | F35: 569 | G35: 11
A36: =G36+0.2 -> 11.2 | B36: 2801 | C36: IAN VARGAS JIMENEZ | D36: CCDR SAN JOSÉ | E36: 25 | F36: 507 | G36: 11
A37: =G37+0.3 -> 11.3 | B37: 4833 | C37: JESÚS ADRIÁN VÁSQUEZ TURCIOS | D37: ASERRÍ | E37: 59 | F37: 462 | G37: 11
A38: =G38+0.1 -> 12.1 | B38: 3696 | C38: NICOLAS CECILIANO ESQUIVEL | D38: PÉREZ ZELEDÓN | E38: 12 | F38: 565 | G38: 12
A39: =G39+0.2 -> 12.2 | B39: 3468 | C39: DANIEL DAVID ALPIZAR VILLALOBOS | D39: ASERRÍ | E39: 24 | F39: 508 | G39: 12
A40: =G40+0.3 -> 12.3 | B40: 4790 | C40: JOSEMARIO ARREDONDO CORDERO | D40: CCDR SAN JOSÉ | E40: 62 | F40: 461 | G40: 12
A41: =G41+0.1 -> 13.1 | B41: 3309 | C41: SEBASTIAN MASIS MURILLO | D41: GUARCO | E41: 13 | F41: 558 | G41: 13
...

Sheet Grupo 1
B2: #VALUE!
L5: En Caso de ocupar 3 de 5, mostrar columnas H - I En caso de 2 de 2, ocultarlas.
G7: Fecha: | J7: =TODAY() -> 46288
B9: Categoría | D9: =Inscripciones!B2 -> U19 MASCULINO | E9: Grupo nº | F9: 1 | G9: Mesa nº
B11: Orden | C11: Carné | D11: Jugadores | E11: Lugar | F11: Ranking | G11: Puntos
A12: =F9+0.1 -> 1.1 | B12: 1 | C12: =VLOOKUP(A12,Inscripciones!A5:G167,2,FALSE) -> 2515 | D12: =IF(ISBLANK(C12),"",VLOOKUP(C12,Inscripciones!$B$5:$F$200,2,FALSE)) -> GABRIEL CHAVEZ QUIROS | E12: =IF(ISBLANK(C12),"",VLOOKUP(C12,Inscripciones!$B$5:$F$200,3,FALSE)) -> SANTA ANA | F12: =IF(ISBLANK(C12),"",VLOOKUP(C12,Inscripciones!$B$5:$F$200,4,FALSE)) -> 1 | G12: =IF(ISBLANK(C12),"",VLOOKUP(C12,Inscripciones!$B$5:$F$200,5,FALSE)) -> 716 | J12: =IF(ISBLANK(J11)," ",(E18+F18+G18+E20+F20+G20+H18+I18+H20+I20)/(E19+F19+G19+E21+F21+G21+H19+I19+H21+I21))
A13: =F9+0.2 -> 1.2 | B13: 2 | C13: =VLOOKUP(A13,Inscripciones!A5:G168,2,FALSE) -> 4513 | D13: =IF(ISBLANK(C13),"",VLOOKUP(C13,Inscripciones!$B$5:$F$200,2,FALSE)) -> GABRIEL ANTONIO AMADOR GARITA | E13: =IF(ISBLANK(C13),"",VLOOKUP(C13,Inscripciones!$B$5:$F$200,3,FALSE)) -> CCDR SANTA CRUZ | F13: =IF(ISBLANK(C13),"",VLOOKUP(C13,Inscripciones!$B$5:$F$200,4,FALSE)) -> 37 | G13: =IF(ISBLANK(C13),"",VLOOKUP(C13,Inscripciones!$B$5:$F$200,5,FALSE)) -> 492 | J13: =IF(ISBLANK(J11)," ",(E21+F21+G21+E22+F22+G22+H21+I21+H22+I22)/(E20+F20+G20+E23+F23+G23+H20+I20+H23+I23))
A14: =+F9+0.3 -> 1.3 | B14: 3 | C14: =VLOOKUP(A14,Inscripciones!A6:G169,2,FALSE) -> 3670 | D14: =IF(ISBLANK(C14),"",VLOOKUP(C14,Inscripciones!$B$7:$F$200,2,FALSE)) -> KAY MATHIAS PERAZA MURILLO | E14: =IF(ISBLANK(C14),"",VLOOKUP(C14,Inscripciones!$B$7:$F$200,3,FALSE)) -> ASERRÍ | F14: =IF(ISBLANK(C14),"",VLOOKUP(C14,Inscripciones!$B$7:$F$200,4,FALSE)) -> 38 | G14: =IF(ISBLANK(C14),"",VLOOKUP(C14,Inscripciones!$B$7:$F$200,5,FALSE)) -> 492 | J14: =IF(ISBLANK(J11)," ",(E19+F19+G19+E23+F23+G23+H19+I19+H23+I23)/(E18+F18+G18+E22+F22+G22+H18+I18+H22+I22))
B17: Partida | D17: JUGADOR | E17: 1º set | F17: 2º set | G17: 3º set | H17: 4º set | I17: 5º set | J17: Ganador
B18: 1 | C18: 1 | D18: =D12 -> GABRIEL CHAVEZ QUIROS | E18: 11 | F18: 11 | J18: {=IF(AND(TRIM(E18)="WO",TRIM(E19)="WO"),"",IF(TRIM(E19)="WO",C18,IF(TRIM(E18)="WO",C19,IF(SUMPRODUCT(--(E18:I18>E19:I19))>SUMPRODUCT(--(E19:I19>E18:I18)),C18,IF(SUMPRODUCT(--(E19:I19>E18:I18))>SUMPRODUCT(--(E18:I18>E19:I19)),C19,"")))))} -> 1
C19: 3 | D19: =D14 -> KAY MATHIAS PERAZA MURILLO | E19: 0 | F19: 3
B20: 2 | C20: 1 | D20: =D12 -> GABRIEL CHAVEZ QUIROS | E20: 11 | F20: 11 | J20: {=IF(AND(TRIM(E20)="WO",TRIM(E21)="WO"),"",IF(TRIM(E21)="WO",C20,IF(TRIM(E20)="WO",C21,IF(SUMPRODUCT(--(E20:I20>E21:I21))>SUMPRODUCT(--(E21:I21>E20:I20)),C20,IF(SUMPRODUCT(--(E21:I21>E20:I20))>SUMPRODUCT(--(E20:I20>E21:I21)),C21,"")))))} -> 1
C21: 2 | D21: =D13 -> GABRIEL ANTONIO AMADOR GARITA | E21: 2 | F21: 7
B22: 3 | C22: 2 | D22: =D13 -> GABRIEL ANTONIO AMADOR GARITA | E22: 11 | F22: 12 | J22: {=IF(AND(TRIM(E22)="WO",TRIM(E23)="WO"),"",IF(TRIM(E23)="WO",C22,IF(TRIM(E22)="WO",C23,IF(SUMPRODUCT(--(E22:I22>E23:I23))>SUMPRODUCT(--(E23:I23>E22:I22)),C22,IF(SUMPRODUCT(--(E23:I23>E22:I22))>SUMPRODUCT(--(E22:I22>E23:I23)),C23,"")))))} -> 2
C23: 3 | D23: =D14 -> KAY MATHIAS PERAZA MURILLO | E23: 3 | F23: 10
C32: Clasificados (# de carne) | F32: Revisión de Camisas y Raquetas
C33: Carnet | D33: Nombre | F33: Revisión de nombres y resultados
C34: 2515 | D34: =IF(ISBLANK(C34),"",VLOOKUP(C34,Inscripciones!$B$5:$F$200,2,FALSE)) -> GABRIEL CHAVEZ QUIROS | F34: Árbitro
C35: 4513 | D35: =IF(ISBLANK(C35),"",VLOOKUP(C35,Inscripciones!$B$5:$F$200,2,FALSE)) -> GABRIEL ANTONIO AMADOR GARITA | F35: Marque si hay informe

Sheet Grupo 2
B2: #VALUE!
L5: En Caso de ocupar 3 de 5, mostrar columnas H - I En caso de 2 de 2, ocultarlas.
G7: Fecha: | J7: =TODAY() -> 46288
B9: Categoría | D9: =Inscripciones!B2 -> U19 MASCULINO | E9: Grupo nº | F9: 2 | G9: Mesa nº
B11: Orden | C11: Carné | D11: Jugadores | E11: Lugar | F11: Ranking | G11: Puntos
A12: =F9+0.1 -> 2.1 | B12: 1 | C12: =VLOOKUP(A12,Inscripciones!A5:G167,2,FALSE) -> 2582 | D12: =IF(ISBLANK(C12),"",VLOOKUP(C12,Inscripciones!$B$5:$F$200,2,FALSE)) -> ALEJANDRO MONTOYA MORERA | E12: =IF(ISBLANK(C12),"",VLOOKUP(C12,Inscripciones!$B$5:$F$200,3,FALSE)) -> ALAJUELA - UNA | F12: =IF(ISBLANK(C12),"",VLOOKUP(C12,Inscripciones!$B$5:$F$200,4,FALSE)) -> 2 | G12: =IF(ISBLANK(C12),"",VLOOKUP(C12,Inscripciones!$B$5:$F$200,5,FALSE)) -> 698 | J12: =IF(ISBLANK(J11)," ",(E18+F18+G18+E20+F20+G20+H18+I18+H20+I20)/(E19+F19+G19+E21+F21+G21+H19+I19+H21+I21))
A13: =F9+0.2 -> 2.2 | B13: 2 | C13: =VLOOKUP(A13,Inscripciones!A5:G168,2,FALSE) -> 2513 | D13: =IF(ISBLANK(C13),"",VLOOKUP(C13,Inscripciones!$B$5:$F$200,2,FALSE)) -> SEBASTIAN CHAVEZ QUIROS | E13: =IF(ISBLANK(C13),"",VLOOKUP(C13,Inscripciones!$B$5:$F$200,3,FALSE)) -> SANTA ANA | F13: =IF(ISBLANK(C13),"",VLOOKUP(C13,Inscripciones!$B$5:$F$200,4,FALSE)) -> 35 | G13: =IF(ISBLANK(C13),"",VLOOKUP(C13,Inscripciones!$B$5:$F$200,5,FALSE)) -> 493 | J13: =IF(ISBLANK(J11)," ",(E21+F21+G21+E22+F22+G22+H21+I21+H22+I22)/(E20+F20+G20+E23+F23+G23+H20+I20+H23+I23))
A14: =+F9+0.3 -> 2.3 | B14: 3 | C14: =VLOOKUP(A14,Inscripciones!A6:G169,2,FALSE) -> 4144 | D14: =IF(ISBLANK(C14),"",VLOOKUP(C14,Inscripciones!$B$7:$F$200,2,FALSE)) -> ANDRÉS PARRA CHACÓN | E14: =IF(ISBLANK(C14),"",VLOOKUP(C14,Inscripciones!$B$7:$F$200,3,FALSE)) -> SANTO DOMINGO | F14: =IF(ISBLANK(C14),"",VLOOKUP(C14,Inscripciones!$B$7:$F$200,4,FALSE)) -> 40 | G14: =IF(ISBLANK(C14),"",VLOOKUP(C14,Inscripciones!$B$7:$F$200,5,FALSE)) -> 485 | J14: =IF(ISBLANK(J11)," ",(E19+F19+G19+E23+F23+G23+H19+I19+H23+I23)/(E18+F18+G18+E22+F22+G22+H18+I18+H22+I22))
B17: Partida | D17: JUGADOR | E17: 1º set | F17: 2º set | G17: 3º set | H17: 4º set | I17: 5º set | J17: Ganador
B18: 1 | C18: 1 | D18: =D12 -> ALEJANDRO MONTOYA MORERA | E18: wo | F18: wo | J18: {=IF(AND(TRIM(E18)="WO",TRIM(E19)="WO"),"",IF(TRIM(E19)="WO",C18,IF(TRIM(E18)="WO",C19,IF(SUMPRODUCT(--(E18:I18>E19:I19))>SUMPRODUCT(--(E19:I19>E18:I18)),C18,IF(SUMPRODUCT(--(E19:I19>E18:I18))>SUMPRODUCT(--(E18:I18>E19:I19)),C19,"")))))} -> 3
C19: 3 | D19: =D14 -> ANDRÉS PARRA CHACÓN | E19: 11 | F19: 11
B20: 2 | C20: 1 | D20: =D12 -> ALEJANDRO MONTOYA MORERA | E20: wo | F20: wo | J20: {=IF(AND(TRIM(E20)="WO",TRIM(E21)="WO"),"",IF(TRIM(E21)="WO",C20,IF(TRIM(E20)="WO",C21,IF(SUMPRODUCT(--(E20:I20>E21:I21))>SUMPRODUCT(--(E21:I21>E20:I20)),C20,IF(SUMPRODUCT(--(E21:I21>E20:I20))>SUMPRODUCT(--(E20:I20>E21:I21)),C21,"")))))} -> 2
C21: 2 | D21: =D13 -> SEBASTIAN CHAVEZ QUIROS | E21: 11 | F21: 11
B22: 3 | C22: 2 | D22: =D13 -> SEBASTIAN CHAVEZ QUIROS | E22: 11 | F22: 9 | J22: {=IF(AND(TRIM(E22)="WO",TRIM(E23)="WO"),"",IF(TRIM(E23)="WO",C22,IF(TRIM(E22)="WO",C23,IF(SUMPRODUCT(--(E22:I22>E23:I23))>SUMPRODUCT(--(E23:I23>E22:I22)),C22,IF(SUMPRODUCT(--(E23:I23>E22:I22))>SUMPRODUCT(--(E22:I22>E23:I23)),C23,"")))))} -> 3
C23: 3 | D23: =D14 -> ANDRÉS PARRA CHACÓN | E23: 13 | F23: 11
C32: Clasificados (# de carne) | F32: Revisión de Camisas y Raquetas
C33: Carnet | D33: Nombre | F33: Revisión de nombres y resultados
C34: 4144 | D34: =IF(ISBLANK(C34),"",VLOOKUP(C34,Inscripciones!$B$5:$F$200,2,FALSE)) -> ANDRÉS PARRA CHACÓN | F34: Árbitro
C35: 2513 | D35: =IF(ISBLANK(C35),"",VLOOKUP(C35,Inscripciones!$B$5:$F$200,2,FALSE)) -> SEBASTIAN CHAVEZ QUIROS | F35: Marque si hay informe

Sheet Grupo 3
B2: #VALUE!
L5: En Caso de ocupar 3 de 5, mostrar columnas H - I En caso de 2 de 2, ocultarlas.
G7: Fecha: | J7: =TODAY() -> 46288
B9: Categoría | D9: =Inscripciones!B2 -> U19 MASCULINO | E9: Grupo nº | F9: 3 | G9: Mesa nº
B11: Orden | C11: Carné | D11: Jugadores | E11: Lugar | F11: Ranking | G11: Puntos
A12: =F9+0.1 -> 3.1 | B12: 1 | C12: =VLOOKUP(A12,Inscripciones!A5:G167,2,FALSE) -> 4034 | D12: =IF(ISBLANK(C12),"",VLOOKUP(C12,Inscripciones!$B$5:$F$200,2,FALSE)) -> IAN DAVID GARRO ALONSO | E12: =IF(ISBLANK(C12),"",VLOOKUP(C12,Inscripciones!$B$5:$F$200,3,FALSE)) -> CCDR SAN JOSÉ | F12: =IF(ISBLANK(C12),"",VLOOKUP(C12,Inscripciones!$B$5:$F$200,4,FALSE)) -> 3 | G12: =IF(ISBLANK(C12),"",VLOOKUP(C12,Inscripciones!$B$5:$F$200,5,FALSE)) -> 645 | J12: =IF(ISBLANK(J11)," ",(E18+F18+G18+E20+F20+G20+H18+I18+H20+I20)/(E19+F19+G19+E21+F21+G21+H19+I19+H21+I21))
A13: =F9+0.2 -> 3.2 | B13: 2 | C13: =VLOOKUP(A13,Inscripciones!A5:G168,2,FALSE) -> 2847 | D13: =IF(ISBLANK(C13),"",VLOOKUP(C13,Inscripciones!$B$5:$F$200,2,FALSE)) -> LUIS GAEL SILES LOBO | E13: =IF(ISBLANK(C13),"",VLOOKUP(C13,Inscripciones!$B$5:$F$200,3,FALSE)) -> ESPARZA | F13: =IF(ISBLANK(C13),"",VLOOKUP(C13,Inscripciones!$B$5:$F$200,4,FALSE)) -> 34 | G13: =IF(ISBLANK(C13),"",VLOOKUP(C13,Inscripciones!$B$5:$F$200,5,FALSE)) -> 493 | J13: =IF(ISBLANK(J11)," ",(E21+F21+G21+E22+F22+G22+H21+I21+H22+I22)/(E20+F20+G20+E23+F23+G23+H20+I20+H23+I23))
A14: =+F9+0.3 -> 3.3 | B14: 3 | C14: =VLOOKUP(A14,Inscripciones!A6:G169,2,FALSE) -> 4415 | D14: =IF(ISBLANK(C14),"",VLOOKUP(C14,Inscripciones!$B$7:$F$200,2,FALSE)) -> ALEJANDRO CRUZ BONILLA | E14: =IF(ISBLANK(C14),"",VLOOKUP(C14,Inscripciones!$B$7:$F$200,3,FALSE)) -> ALAJUELA | F14: =IF(ISBLANK(C14),"",VLOOKUP(C14,Inscripciones!$B$7:$F$200,4,FALSE)) -> 45 | G14: =IF(ISBLANK(C14),"",VLOOKUP(C14,Inscripciones!$B$7:$F$200,5,FALSE)) -> 482 | J14: =IF(ISBLANK(J11)," ",(E19+F19+G19+E23+F23+G23+H19+I19+H23+I23)/(E18+F18+G18+E22+F22+G22+H18+I18+H22+I22))
B17: Partida | D17: JUGADOR | E17: 1º set | F17: 2º set | G17: 3º set | H17: 4º set | I17: 5º set | J17: Ganador
B18: 1 | C18: 1 | D18: =D12 -> IAN DAVID GARRO ALONSO | E18: 11 | F18: 11 | J18: {=IF(AND(TRIM(E18)="WO",TRIM(E19)="WO"),"",IF(TRIM(E19)="WO",C18,IF(TRIM(E18)="WO",C19,IF(SUMPRODUCT(--(E18:I18>E19:I19))>SUMPRODUCT(--(E19:I19>E18:I18)),C18,IF(SUMPRODUCT(--(E19:I19>E18:I18))>SUMPRODUCT(--(E18:I18>E19:I19)),C19,"")))))} -> 1
C19: 3 | D19: =D14 -> ALEJANDRO CRUZ BONILLA | E19: 0 | F19: 5
B20: 2 | C20: 1 | D20: =D12 -> IAN DAVID GARRO ALONSO | E20: 11 | F20: 11 | J20: {=IF(AND(TRIM(E20)="WO",TRIM(E21)="WO"),"",IF(TRIM(E21)="WO",C20,IF(TRIM(E20)="WO",C21,IF(SUMPRODUCT(--(E20:I20>E21:I21))>SUMPRODUCT(--(E21:I21>E20:I20)),C20,IF(SUMPRODUCT(--(E21:I21>E20:I20))>SUMPRODUCT(--(E20:I20>E21:I21)),C21,"")))))} -> 1
C21: 2 | D21: =D13 -> LUIS GAEL SILES LOBO | E21: 3 | F21: 6
B22: 3 | C22: 2 | D22: =D13 -> LUIS GAEL SILES LOBO | E22: 12 | F22: 11 | J22: {=IF(AND(TRIM(E22)="WO",TRIM(E23)="WO"),"",IF(TRIM(E23)="WO",C22,IF(TRIM(E22)="WO",C23,IF(SUMPRODUCT(--(E22:I22>E23:I23))>SUMPRODUCT(--(E23:I23>E22:I22)),C22,IF(SUMPRODUCT(--(E23:I23>E22:I22))>SUMPRODUCT(--(E22:I22>E23:I23)),C23,"")))))} -> 2
C23: 3 | D23: =D14 -> ALEJANDRO CRUZ BONILLA | E23: 10 | F23: 4
C32: Clasificados (# de carne) | F32: Revisión de Camisas y Raquetas
C33: Carnet | D33: Nombre | F33: Revisión de nombres y resultados
C34: 4034 | D34: =IF(ISBLANK(C34),"",VLOOKUP(C34,Inscripciones!$B$5:$F$200,2,FALSE)) -> IAN DAVID GARRO ALONSO | F34: Árbitro
C35: 2847 | D35: =IF(ISBLANK(C35),"",VLOOKUP(C35,Inscripciones!$B$5:$F$200,2,FALSE)) -> LUIS GAEL SILES LOBO | F35: Marque si hay informe

Sheet Grupo 4
B2: #VALUE!
L5: En Caso de ocupar 3 de 5, mostrar columnas H - I En caso de 2 de 2, ocultarlas.
G7: Fecha: | J7: =TODAY() -> 46288
B9: Categoría | D9: =Inscripciones!B2 -> U19 MASCULINO | E9: Grupo nº | F9: 4 | G9: Mesa nº
B11: Orden | C11: Carné | D11: Jugadores | E11: Lugar | F11: Ranking | G11: Puntos
A12: =F9+0.1 -> 4.1 | B12: 1 | C12: =VLOOKUP(A12,Inscripciones!A5:G167,2,FALSE) -> 3472 | D12: =IF(ISBLANK(C12),"",VLOOKUP(C12,Inscripciones!$B$5:$F$200,2,FALSE)) -> JAYDRICK SHAMALL BAKER CRAWFORD | E12: =IF(ISBLANK(C12),"",VLOOKUP(C12,Inscripciones!$B$5:$F$200,3,FALSE)) -> ASERRÍ - UCR | F12: =IF(ISBLANK(C12),"",VLOOKUP(C12,Inscripciones!$B$5:$F$200,4,FALSE)) -> 4 | G12: =IF(ISBLANK(C12),"",VLOOKUP(C12,Inscripciones!$B$5:$F$200,5,FALSE)) -> 626 | J12: =IF(ISBLANK(J11)," ",(E18+F18+G18+E20+F20+G20+H18+I18+H20+I20)/(E19+F19+G19+E21+F21+G21+H19+I19+H21+I21))
A13: =F9+0.2 -> 4.2 | B13: 2 | C13: =VLOOKUP(A13,Inscripciones!A5:G168,2,FALSE) -> 4248 | D13: =IF(ISBLANK(C13),"",VLOOKUP(C13,Inscripciones!$B$5:$F$200,2,FALSE)) -> ALEJANDRO COTO RAMIREZ | E13: =IF(ISBLANK(C13),"",VLOOKUP(C13,Inscripciones!$B$5:$F$200,3,FALSE)) -> GUARCO | F13: =IF(ISBLANK(C13),"",VLOOKUP(C13,Inscripciones!$B$5:$F$200,4,FALSE)) -> 33 | G13: =IF(ISBLANK(C13),"",VLOOKUP(C13,Inscripciones!$B$5:$F$200,5,FALSE)) -> 493 | J13: =IF(ISBLANK(J11)," ",(E21+F21+G21+E22+F22+G22+H21+I21+H22+I22)/(E20+F20+G20+E23+F23+G23+H20+I20+H23+I23))
A14: =+F9+0.3 -> 4.3 | B14: 3 | C14: =VLOOKUP(A14,Inscripciones!A6:G169,2,FALSE) -> 4464 | D14: =IF(ISBLANK(C14),"",VLOOKUP(C14,Inscripciones!$B$7:$F$200,2,FALSE)) -> ISAAC GAMBOA MORERA | E14: =IF(ISBLANK(C14),"",VLOOKUP(C14,Inscripciones!$B$7:$F$200,3,FALSE)) -> ESPARZA | F14: =IF(ISBLANK(C14),"",VLOOKUP(C14,Inscripciones!$B$7:$F$200,4,FALSE)) -> 42 | G14: =IF(ISBLANK(C14),"",VLOOKUP(C14,Inscripciones!$B$7:$F$200,5,FALSE)) -> 483 | J14: =IF(ISBLANK(J11)," ",(E19+F19+G19+E23+F23+G23+H19+I19+H23+I23)/(E18+F18+G18+E22+F22+G22+H18+I18+H22+I22))
B17: Partida | D17: JUGADOR | E17: 1º set | F17: 2º set | G17: 3º set | H17: 4º set | I17: 5º set | J17: Ganador
B18: 1 | C18: 1 | D18: =D12 -> JAYDRICK SHAMALL BAKER CRAWFORD | E18: 11 | F18: 14 | J18: {=IF(AND(TRIM(E18)="WO",TRIM(E19)="WO"),"",IF(TRIM(E19)="WO",C18,IF(TRIM(E18)="WO",C19,IF(SUMPRODUCT(--(E18:I18>E19:I19))>SUMPRODUCT(--(E19:I19>E18:I18)),C18,IF(SUMPRODUCT(--(E19:I19>E18:I18))>SUMPRODUCT(--(E18:I18>E19:I19)),C19,"")))))} -> 1
C19: 3 | D19: =D14 -> ISAAC GAMBOA MORERA | E19: 5 | F19: 12
B20: 2 | C20: 1 | D20: =D12 -> JAYDRICK SHAMALL BAKER CRAWFORD | E20: 11 | F20: 11 | J20: {=IF(AND(TRIM(E20)="WO",TRIM(E21)="WO"),"",IF(TRIM(E21)="WO",C20,IF(TRIM(E20)="WO",C21,IF(SUMPRODUCT(--(E20:I20>E21:I21))>SUMPRODUCT(--(E21:I21>E20:I20)),C20,IF(SUMPRODUCT(--(E21:I21>E20:I20))>SUMPRODUCT(--(E20:I20>E21:I21)),C21,"")))))} -> 1
C21: 2 | D21: =D13 -> ALEJANDRO COTO RAMIREZ | E21: 3 | F21: 4
B22: 3 | C22: 2 | D22: =D13 -> ALEJANDRO COTO RAMIREZ | E22: 9 | F22: 12 | G22: 8 | J22: {=IF(AND(TRIM(E22)="WO",TRIM(E23)="WO"),"",IF(TRIM(E23)="WO",C22,IF(TRIM(E22)="WO",C23,IF(SUMPRODUCT(--(E22:I22>E23:I23))>SUMPRODUCT(--(E23:I23>E22:I22)),C22,IF(SUMPRODUCT(--(E23:I23>E22:I22))>SUMPRODUCT(--(E22:I22>E23:I23)),C23,"")))))} -> 3
C23: 3 | D23: =D14 -> ISAAC GAMBOA MORERA | E23: 11 | F23: 10 | G23: 11
C32: Clasificados (# de carne) | F32: Revisión de Camisas y Raquetas
C33: Carnet | D33: Nombre | F33: Revisión de nombres y resultados
C34: 3472 | D34: =IF(ISBLANK(C34),"",VLOOKUP(C34,Inscripciones!$B$5:$F$200,2,FALSE)) -> JAYDRICK SHAMALL BAKER CRAWFORD | F34: Árbitro
C35: 4464 | D35: =IF(ISBLANK(C35),"",VLOOKUP(C35,Inscripciones!$B$5:$F$200,2,FALSE)) -> ISAAC GAMBOA MORERA | F35: Marque si hay informe

Sheet Grupo 5
B2: #VALUE!
L5: En Caso de ocupar 3 de 5, mostrar columnas H - I En caso de 2 de 2, ocultarlas.
G7: Fecha: | J7: =TODAY() -> 46288
B9: Categoría | D9: =Inscripciones!B2 -> U19 MASCULINO | E9: Grupo nº | F9: 5 | G9: Mesa nº
B11: Orden | C11: Carné | D11: Jugadores | E11: Lugar | F11: Ranking | G11: Puntos
A12: =F9+0.1 -> 5.1 | B12: 1 | C12: =VLOOKUP(A12,Inscripciones!A5:G167,2,FALSE) -> 2895 | D12: =IF(ISBLANK(C12),"",VLOOKUP(C12,Inscripciones!$B$5:$F$200,2,FALSE)) -> ANDRES JOSE VEGA VALERIO | E12: =IF(ISBLANK(C12),"",VLOOKUP(C12,Inscripciones!$B$5:$F$200,3,FALSE)) -> ALAJUELA - UCR | F12: =IF(ISBLANK(C12),"",VLOOKUP(C12,Inscripciones!$B$5:$F$200,4,FALSE)) -> 5 | G12: =IF(ISBLANK(C12),"",VLOOKUP(C12,Inscripciones!$B$5:$F$200,5,FALSE)) -> 613 | J12: =IF(ISBLANK(J11)," ",(E18+F18+G18+E20+F20+G20+H18+I18+H20+I20)/(E19+F19+G19+E21+F21+G21+H19+I19+H21+I21))
A13: =F9+0.2 -> 5.2 | B13: 2 | C13: =VLOOKUP(A13,Inscripciones!A5:G168,2,FALSE) -> 3898 | D13: =IF(ISBLANK(C13),"",VLOOKUP(C13,Inscripciones!$B$5:$F$200,2,FALSE)) -> JOSUE CALVO CRUZ | E13: =IF(ISBLANK(C13),"",VLOOKUP(C13,Inscripciones!$B$5:$F$200,3,FALSE)) -> CCDR SAN JOSÉ | F13: =IF(ISBLANK(C13),"",VLOOKUP(C13,Inscripciones!$B$5:$F$200,4,FALSE)) -> 32 | G13: =IF(ISBLANK(C13),"",VLOOKUP(C13,Inscripciones!$B$5:$F$200,5,FALSE)) -> 493 | J13: =IF(ISBLANK(J11)," ",(E21+F21+G21+E22+F22+G22+H21+I21+H22+I22)/(E20+F20+G20+E23+F23+G23+H20+I20+H23+I23))
A14: =+F9+0.3 -> 5.3 | B14: 3 | C14: =VLOOKUP(A14,Inscripciones!A6:G169,2,FALSE) -> 3450 | D14: =IF(ISBLANK(C14),"",VLOOKUP(C14,Inscripciones!$B$7:$F$200,2,FALSE)) -> OSWALDO IGNACIO SILVA NOVOA | E14: =IF(ISBLANK(C14),"",VLOOKUP(C14,Inscripciones!$B$7:$F$200,3,FALSE)) -> SANTA ANA | F14: =IF(ISBLANK(C14),"",VLOOKUP(C14,Inscripciones!$B$7:$F$200,4,FALSE)) -> 49 | G14: =IF(ISBLANK(C14),"",VLOOKUP(C14,Inscripciones!$B$7:$F$200,5,FALSE)) -> 473 | J14: =IF(ISBLANK(J11)," ",(E19+F19+G19+E23+F23+G23+H19+I19+H23+I23)/(E18+F18+G18+E22+F22+G22+H18+I18+H22+I22))
B17: Partida | D17: JUGADOR | E17: 1º set | F17: 2º set | G17: 3º set | H17: 4º set | I17: 5º set | J17: Ganador
B18: 1 | C18: 1 | D18: =D12 -> ANDRES JOSE VEGA VALERIO | E18: 11 | F18: 11 | G18: 11 | J18: {=IF(AND(TRIM(E18)="WO",TRIM(E19)="WO"),"",IF(TRIM(E19)="WO",C18,IF(TRIM(E18)="WO",C19,IF(SUMPRODUCT(--(E18:I18>E19:I19))>SUMPRODUCT(--(E19:I19>E18:I18)),C18,IF(SUMPRODUCT(--(E19:I19>E18:I18))>SUMPRODUCT(--(E18:I18>E19:I19)),C19,"")))))} -> 1
C19: 3 | D19: =D14 -> OSWALDO IGNACIO SILVA NOVOA | E19: 5 | F19: 13 | G19: 8
B20: 2 | C20: 1 | D20: =D12 -> ANDRES JOSE VEGA VALERIO | E20: 11 | F20: 11 | J20: {=IF(AND(TRIM(E20)="WO",TRIM(E21)="WO"),"",IF(TRIM(E21)="WO",C20,IF(TRIM(E20)="WO",C21,IF(SUMPRODUCT(--(E20:I20>E21:I21))>SUMPRODUCT(--(E21:I21>E20:I20)),C20,IF(SUMPRODUCT(--(E21:I21>E20:I20))>SUMPRODUCT(--(E20:I20>E21:I21)),C21,"")))))} -> 1
C21: 2 | D21: =D13 -> JOSUE CALVO CRUZ | E21: 6 | F21: 5
B22: 3 | C22: 2 | D22: =D13 -> JOSUE CALVO CRUZ | E22: 5 | F22: 7 | J22: {=IF(AND(TRIM(E22)="WO",TRIM(E23)="WO"),"",IF(TRIM(E23)="WO",C22,IF(TRIM(E22)="WO",C23,IF(SUMPRODUCT(--(E22:I22>E23:I23))>SUMPRODUCT(--(E23:I23>E22:I22)),C22,IF(SUMPRODUCT(--(E23:I23>E22:I22))>SUMPRODUCT(--(E22:I22>E23:I23)),C23,"")))))} -> 3
C23: 3 | D23: =D14 -> OSWALDO IGNACIO SILVA NOVOA | E23: 11 | F23: 11
